Workbook

Sheet Summary
A1: Governance Practices: Final Equal-Weight Results | B1: Value
A2: Entries | B2: 112
A3: Final metrics | B3: G1-G7
A4: Weight per metric | B4: 1/7 = 14.29%
A5: Coverage gate | B5: None
A6: Unavailable data | B6: Zero in final score
A7: Mean score | B7: =AVERAGE(Scoring!S2:S113) -> 64.177296
A8: Median score | B8: =MEDIAN(Scoring!S2:S113) -> 70.214286
A9: Standard deviation | B9: 26.000086
A10: Minimum score | B10: =MIN(Scoring!S2:S113) -> 0
A11: Maximum score | B11: =MAX(Scoring!S2:S113) -> 100
A12: Mean observed coverage | B12: =AVERAGE(Coverage!J2:J113) -> 0.90178571
A13: Entries with all seven metrics observed | B13: =COUNTIF(Coverage!I2:I113,7) -> 68
A14: Interpretation | B14: Final scores reflect reported values and missingness because unavailable values score zero. Coverage is diagnostic only.
A15: Metric review | B15: See Metric Rules, Verification, Review Queue, Diagnostics, and Sensitivity.

Sheet Scoring
A1: Service | B1: Provider | C1: Solution category | D1: 024 structure status | E1: 108 bylaws status | F1: 050 board structure | G1: 950 other detail | H1: 048 community governance | I1: 029 accessibility status | J1: 035 equity status | K1: 044 privacy status | L1: G1 | M1: G2 | N1: G3 | O1: G4 | P1: G5 | Q1: G6 | R1: G7 | S1: Final score / 100 | T1: Rank | U1: Available metrics (of 7) | V1: Observed coverage | W1: Observed-only mean | X1: Data-quality notes
A2: 2i2c | B2: Code for Science and Society | C2: Authoring tool | D2: In progress | E2: Unknown | F2: Advisory board or steering committee | H2: None | I2: Considering | J2: Considering | K2: Implemented/available | L2: =Calc!B2 -> 67 | M2: =Calc!C2 -> 0 | N2: =Verification!F2 -> 100 | O2: =Calc!E2 -> 33 | P2: =Calc!F2 -> 33 | Q2: =Calc!G2 -> 100 | R2: =Calc!H2 -> 0 | S2: =AVERAGE(L2:R2) -> 47.571429 | T2: =RANK(S2,$S$2:$S$113,0)+(COUNTIF($S$2:$S$113,S2)-1)/2 -> 82.5 | U2: =Coverage!I2 -> 6 | V2: =Coverage!J2 -> 0.85714286 | W2: =IFERROR(SUMPRODUCT(L2:R2,Coverage!B2:H2)/U2,0) -> 55.5 | X2: 108_bylaws_status unavailable/unknown scored 0; No independent verification recorded
A3: Academic Preservation Trust (APTrust) | B3: Academic Preservation Trust (APTrust) | C3: Digital preservation service | D3: Implemented/available | E3: Implemented/available | F3: Multi-board governance | H3: Formal | I3: Considering | J3: Implemented/available | K3: Not planning | L3: =Calc!B3 -> 100 | M3: =Calc!C3 -> 100 | N3: =Verification!F3 -> 100 | O3: =Calc!E3 -> 33 | P3: =Calc!F3 -> 100 | Q3: =Calc!G3 -> 0 | R3: =Calc!H3 -> 100 | S3: =AVERAGE(L3:R3) -> 76.142857 | T3: =RANK(S3,$S$2:$S$113,0)+(COUNTIF($S$2:$S$113,S3)-1)/2 -> 44 | U3: =Coverage!I3 -> 7 | V3: =Coverage!J3 -> 1 | W3: =IFERROR(SUMPRODUCT(L3:R3,Coverage!B3:H3)/U3,0) -> 76.142857 | X3: No independent verification recorded
A4: AfricArXiv | B4: UbuntuNet Alliance | C4: Repository service | D4: Implemented/available | E4: Not planning | F4: Advisory board or steering committee | H4: Ad hoc | I4: In progress | J4: In progress | K4: Implemented/available | L4: =Calc!B4 -> 100 | M4: =Calc!C4 -> 0 | N4: =Verification!F4 -> 100 | O4: =Calc!E4 -> 67 | P4: =Calc!F4 -> 67 | Q4: =Calc!G4 -> 100 | R4: =Calc!H4 -> 50 | S4: =AVERAGE(L4:R4) -> 69.142857 | T4: =RANK(S4,$S$2:$S$113,0)+(COUNTIF($S$2:$S$113,S4)-1)/2 -> 58 | U4: =Coverage!I4 -> 7 | V4: =Coverage!J4 -> 1 | W4: =IFERROR(SUMPRODUCT(L4:R4,Coverage!B4:H4)/U4,0) -> 69.142857 | X4: No independent verification recorded
A5: Arches Heritage Data Management Platform | B5: Getty Conservation Institute (GCI) | C5: Data management planning tool or service | D5: Implemented/available | E5: Implemented/available | F5: Advisory board or steering committee | H5: Formal | I5: Implemented/available | J5: Not planning | K5: Not planning | L5: =Calc!B5 -> 100 | M5: =Calc!C5 -> 100 | N5: =Verification!F5 -> 100 | O5: =Calc!E5 -> 100 | P5: =Calc!F5 -> 0 | Q5: =Calc!G5 -> 0 | R5: =Calc!H5 -> 100 | S5: =AVERAGE(L5:R5) -> 71.428571 | T5: =RANK(S5,$S$2:$S$113,0)+(COUNTIF($S$2:$S$113,S5)-1)/2 -> 52 | U5: =Coverage!I5 -> 7 | V5: =Coverage!J5 -> 1 | W5: =IFERROR(SUMPRODUCT(L5:R5,Coverage!B5:H5)/U5,0) -> 71.428571 | X5: No independent verification recorded
A6: Archipelago Commons | B6: Metropolitan New York Library Council | C6: Digital library, collection or exhibit platform | Repository software | D6: Implemented/available | E6: Implemented/available | F6: Advisory board or steering committee | H6: Formal | I6: Implemented/available | J6: Implemented/available | K6: Considering | L6: =Calc!B6 -> 100 | M6: =Calc!C6 -> 100 | N6: =Verification!F6 -> 100 | O6: =Calc!E6 -> 100 | P6: =Calc!F6 -> 100 | Q6: =Calc!G6 -> 33 | R6: =Calc!H6 -> 100 | S6: =AVERAGE(L6:R6) -> 90.428571 | T6: =RANK(S6,$S$2:$S$113,0)+(COUNTIF($S$2:$S$113,S6)-1)/2 -> 23 | U6: =Coverage!I6 -> 7 | V6: =Coverage!J6 -> 1 | W6: =IFERROR(SUMPRODUCT(L6:R6,Coverage!B6:H6)/U6,0) -> 90.428571 | X6: No independent verification recorded
A7: Archival Resource Key | B7: ARK Alliance | C7: Standard, specification or protocol | D7: In progress | E7: Unknown | F7: Advisory board or steering committee | H7: Ad hoc | I7: In progress | J7: Considering | K7: Not applicable | L7: =Calc!B7 -> 67 | M7: =Calc!C7 -> 0 | N7: =Verification!F7 -> 100 | O7: =Calc!E7 -> 67 | P7: =Calc!F7 -> 33 | Q7: =Calc!G7 -> 0 | R7: =Calc!H7 -> 50 | S7: =AVERAGE(L7:R7) -> 45.285714 | T7: =RANK(S7,$S$2:$S$113,0)+(COUNTIF($S$2:$S$113,S7)-1)/2 -> 84.5 | U7: =Coverage!I7 -> 5 | V7: =Coverage!J7 -> 0.71428571 | W7: =IFERROR(SUMPRODUCT(L7:R7,Coverage!B7:H7)/U7,0) -> 63.4 | X7: 108_bylaws_status unavailable/unknown scored 0; 044_commitment_to_privacy_status unavailable/unknown scored 0; No independent verification recorded
A8: Archivematica | B8: Artefactual | C8: Digital preservation system | D8: Considering | E8: Considering | F8: None | H8: None | I8: Considering | J8: Considering | K8: Implemented/available | L8: =Calc!B8 -> 33 | M8: =Calc!C8 -> 33 | N8: =Verification!F8 -> 0 | O8: =Calc!E8 -> 33 | P8: =Calc!F8 -> 33 | Q8: =Calc!G8 -> 100 | R8: =Calc!H8 -> 0 | S8: =AVERAGE(L8:R8) -> 33.142857 | T8: =RANK(S8,$S$2:$S$113,0)+(COUNTIF($S$2:$S$113,S8)-1)/2 -> 99 | U8: =Coverage!I8 -> 7 | V8: =Coverage!J8 -> 1 | W8: =IFERROR(SUMPRODUCT(L8:R8,Coverage!B8:H8)/U8,0) -> 33.142857 | X8: No independent verification recorded
A9: ArchivesSpace | B9: ArchivesSpace | C9: Archive information management system | Discovery system | D9: Implemented/available | E9: Implemented/available | F9: Advisory board or steering committee | H9: Formal | I9: Implemented/available | J9: Implemented/available | K9: Implemented/available | L9: =Calc!B9 -> 100 | M9: =Calc!C9 -> 100 | N9: =Verification!F9 -> 100 | O9: =Calc!E9 -> 100 | P9: =Calc!F9 -> 100 | Q9: =Calc!G9 -> 100 | R9: =Calc!H9 -> 100 | S9: =AVERAGE(L9:R9) -> 100 | T9: =RANK(S9,$S$2:$S$113,0)+(COUNTIF($S$2:$S$113,S9)-1)/2 -> 4 | U9: =Coverage!I9 -> 7 | V9: =Coverage!J9 -> 1 | W9: =IFERROR(SUMPRODUCT(L9:R9,Coverage!B9:H9)/U9,0) -> 100 | X9: No independent verification recorded
A10: ARGOS | B10: OpenAIRE | C10: Data management planning tool or service | D10: Implemented/available | E10: Implemented/available | F10: Advisory board or steering committee | H10: Formal | I10: In progress | J10: Implemented/available | K10: Implemented/available | L10: =Calc!B10 -> 100 | M10: =Calc!C10 -> 100 | N10: =Verification!F10 -> 100 | O10: =Calc!E10 -> 67 | P10: =Calc!F10 -> 100 | Q10: =Calc!G10 -> 100 | R10: =Calc!H10 -> 100 | S10: =AVERAGE(L10:R10) -> 95.285714 | T10: =RANK(S10,$S$2:$S$113,0)+(COUNTIF($S$2:$S$113,S10)-1)/2 -> 12.5 | U10: =Coverage!I10 -> 7 | V10: =Coverage!J10 -> 1 | W10: =IFERROR(SUMPRODUCT(L10:R10,Coverage!B10:H10)/U10,0) -> 95.285714 | X10: No independent verification recorded
A11: arXiv | B11: Cornell University | C11: Repository service | D11: Implemented/available | E11: Implemented/available | F11: Multi-board governance | H11: Formal | I11: Implemented/available | J11: Unknown | K11: Implemented/available | L11: =Calc!B11 -> 100 | M11: =Calc!C11 -> 100 | N11: =Verification!F11 -> 100 | O11: =Calc!E11 -> 100 | P11: =Calc!F11 -> 0 | Q11: =Calc!G11 -> 100 | R11: =Calc!H11 -> 100 | S11: =AVERAGE(L11:R11) -> 85.714286 | T11: =RANK(S11,$S$2:$S$113,0)+(COUNTIF($S$2:$S$113,S11)-1)/2 -> 30 | U11: =Coverage!I11 -> 6 | V11: =Coverage!J11 -> 0.85714286 | W11: =IFERROR(SUMPRODUCT(L11:R11,Coverage!B11:H11)/U11,0) -> 100 | X11: 035_commitment_to_equity_status unavailable/unknown scored 0; No independent verification recorded
A12: AtoM | B12: Artefactual | C12: Archive information management system | D12: Considering | E12: Considering | I12: In progress | J12: Considering | K12: Implemented/available | L12: =Calc!B12 -> 33 | M12: =Calc!C12 -> 33 | N12: =Verification!F12 -> 0 | O12: =Calc!E12 -> 67 | P12: =Calc!F12 -> 33 | Q12: =Calc!G12 -> 100 | R12: =Calc!H12 -> 0 | S12: =AVERAGE(L12:R12) -> 38 | T12: =RANK(S12,$S$2:$S$113,0)+(COUNTIF($S$2:$S$113,S12)-1)/2 -> 93 | U12: =Coverage!I12 -> 5 | V12: =Coverage!J12 -> 0.71428571 | W12: =IFERROR(SUMPRODUCT(L12:R12,Coverage!B12:H12)/U12,0) -> 53.2 | X12: 048 community governance missing/unrecognized scored 0; No independent verification recorded
A13: Avalon Media System | B13: Indiana University Libraries | C13: Digital library, collection or exhibit platform | Repository software | D13: Implemented/available | E13: Implemented/available | F13: Advisory board or steering committee | H13: Formal | I13: In progress | J13: Considering | K13: Not planning | L13: =Calc!B13 -> 100 | M13: =Calc!C13 -> 100 | N13: =Verification!F13 -> 100 | O13: =Calc!E13 -> 67 | P13: =Calc!F13 -> 33 | Q13: =Calc!G13 -> 0 | R13: =Calc!H13 -> 100 | S13: =AVERAGE(L13:R13) -> 71.428571 | T13: =RANK(S13,$S$2:$S$113,0)+(COUNTIF($S$2:$S$113,S13)-1)/2 -> 52 | U13: =Coverage!I13 -> 7 | V13: =Coverage!J13 -> 1 | W13: =IFERROR(SUMPRODUCT(L13:R13,Coverage!B13:H13)/U13,0) -> 71.428571 | X13: No independent verification recorded
A14: Biodiversity Heritage Library | B14: BHL Consortium | C14: Digital library, collection or exhibit platform | Open scholarly dataset | Repository service | D14: Implemented/available | E14: Implemented/available | F14: Advisory board or steering committee | H14: Formal | I14: Considering | J14: Considering | K14: Implemented/available | L14: =Calc!B14 -> 100 | M14: =Calc!C14 -> 100 | N14: =Verification!F14 -> 100 | O14: =Calc!E14 -> 33 | P14: =Calc!F14 -> 33 | Q14: =Calc!G14 -> 100 | R14: =Calc!H14 -> 100 | S14: =AVERAGE(L14:R14) -> 80.857143 | T14: =RANK(S14,$S$2:$S$113,0)+(COUNTIF($S$2:$S$113,S14)-1)/2 -> 37 | U14: =Coverage!I14 -> 7 | V14: =Coverage!J14 -> 1 | W14: =IFERROR(SUMPRODUCT(L14:R14,Coverage!B14:H14)/U14,0) -> 80.857143 | X14: No independent verification recorded
A15: bioRxiv | B15: Cold Spring Harbor Laboratory | C15: Repository service | D15: In progress | E15: Unknown | F15: Advisory board or steering committee | H15: Ad hoc | I15: Considering | J15: In progress | K15: Implemented/available | L15: =Calc!B15 -> 67 | M15: =Calc!C15 -> 0 | N15: =Verification!F15 -> 100 | O15: =Calc!E15 -> 33 | P15: =Calc!F15 -> 67 | Q15: =Calc!G15 -> 100 | R15: =Calc!H15 -> 50 | S15: =AVERAGE(L15:R15) -> 59.571429 | T15: =RANK(S15,$S$2:$S$113,0)+(COUNTIF($S$2:$S$113,S15)-1)/2 -> 67 | U15: =Coverage!I15 -> 6 | V15: =Coverage!J15 -> 0.85714286 | W15: =IFERROR(SUMPRODUCT(L15:R15,Coverage!B15:H15)/U15,0) -> 69.5 | X15: 108_bylaws_status unavailable/unknown scored 0; No independent verification recorded
A16: BitCurator Environment | B16: BitCurator Consortium | C16: Digital preservation tool | D16: Implemented/available | E16: Implemented/available | F16: Advisory board or steering committee | H16: Formal | I16: Considering | J16: Implemented/available | K16: Implemented/available | L16: =Calc!B16 -> 100 | M16: =Calc!C16 -> 100 | N16: =Verification!F16 -> 100 | O16: =Calc!E16 -> 33 | P16: =Calc!F16 -> 100 | Q16: =Calc!G16 -> 100 | R16: =Calc!H16 -> 100 | S16: =AVERAGE(L16:R16) -> 90.428571 | T16: =RANK(S16,$S$2:$S$113,0)+(COUNTIF($S$2:$S$113,S16)-1)/2 -> 23 | U16: =Coverage!I16 -> 7 | V16: =Coverage!J16 -> 1 | W16: =IFERROR(SUMPRODUCT(L16:R16,Coverage!B16:H16)/U16,0) -> 90.428571 | X16: No independent verification recorded
A17: Blacklight | B17: Blacklight | C17: Discovery system | Integrated Library System (ILS) or Library Services Platform (LSP) | D17: In progress | E17: In progress | F17: None | H17: Ad hoc | I17: In progress | J17: In progress | K17: In progress | L17: =Calc!B17 -> 67 | M17: =Calc!C17 -> 67 | N17: =Verification!F17 -> 0 | O17: =Calc!E17 -> 67 | P17: =Calc!F17 -> 67 | Q17: =Calc!G17 -> 67 | R17: =Calc!H17 -> 50 | S17: =AVERAGE(L17:R17) -> 55 | T17: =RANK(S17,$S$2:$S$113,0)+(COUNTIF($S$2:$S$113,S17)-1)/2 -> 73 | U17: =Coverage!I17 -> 7 | V17: =Coverage!J17 -> 1 | W17: =IFERROR(SUMPRODUCT(L17:R17,Coverage!B17:H17)/U17,0) -> 55 | X17: No independent verification recorded
A18: BrCRIS | B18: IBICT | C18: Discovery system | Research profiling system | D18: Unknown | E18: Unknown | F18: Advisory board or steering committee | H18: Ad hoc | I18: In progress | J18: Considering | K18: Implemented/available | L18: =Calc!B18 -> 0 | M18: =Calc!C18 -> 0 | N18: =Verification!F18 -> 100 | O18: =Calc!E18 -> 67 | P18: =Calc!F18 -> 33 | Q18: =Calc!G18 -> 100 | R18: =Calc!H18 -> 50 | S18: =AVERAGE(L18:R18) -> 50 | T18: =RANK(S18,$S$2:$S$113,0)+(COUNTIF($S$2:$S$113,S18)-1)/2 -> 79 | U18: =Coverage!I18 -> 5 | V18: =Coverage!J18 -> 0.71428571 | W18: =IFERROR(SUMPRODUCT(L18:R18,Coverage!B18:H18)/U18,0) -> 70 | X18: 024_governance_structure_status unavailable/unknown scored 0; 108_bylaws_status unavailable/unknown scored 0; No independent verification recorded
A19: Browsertrix | B19: Webrecorder | C19: Digital library, collection or exhibit platform | Web archiving system | D19: Not planning | E19: Not planning | F19: None | H19: None | I19: Unknown | J19: Unknown | K19: Implemented/available | L19: =Calc!B19 -> 0 | M19: =Calc!C19 -> 0 | N19: =Verification!F19 -> 0 | O19: =Calc!E19 -> 0 | P19: =Calc!F19 -> 0 | Q19: =Calc!G19 -> 100 | R19: =Calc!H19 -> 0 | S19: =AVERAGE(L19:R19) -> 14.285714 | T19: =RANK(S19,$S$2:$S$113,0)+(COUNTIF($S$2:$S$113,S19)-1)/2 -> 108 | U19: =Coverage!I19 -> 5 | V19: =Coverage!J19 -> 0.71428571 | W19: =IFERROR(SUMPRODUCT(L19:R19,Coverage!B19:H19)/U19,0) -> 20 | X19: 029_web_accessibility_status unavailable/unknown scored 0; 035_commitment_to_equity_status unavailable/unknown scored 0; No independent verification recorded
A20: CLOCKSS | B20: CLOCKSS | C20: Digital preservation service | D20: Implemented/available | E20: Implemented/available | F20: Advisory board or steering committee | H20: Formal | I20: In progress | J20: Implemented/available | K20: Implemented/available | L20: =Calc!B20 -> 100 | M20: =Calc!C20 -> 100 | N20: =Verification!F20 -> 100 | O20: =Calc!E20 -> 67 | P20: =Calc!F20 -> 100 | Q20: =Calc!G20 -> 100 | R20: =Calc!H20 -> 100 | S20: =AVERAGE(L20:R20) -> 95.285714 | T20: =RANK(S20,$S$2:$S$113,0)+(COUNTIF($S$2:$S$113,S20)-1)/2 -> 12.5 | U20: =Coverage!I20 -> 7 | V20: =Coverage!J20 -> 1 | W20: =IFERROR(SUMPRODUCT(L20:R20,Coverage!B20:H20)/U20,0) -> 95.285714 | X20: No independent verification recorded
A21: COAR International Repository Directory (IRD) | B21: COAR | C21: Index or directory | D21: Implemented/available | E21: In progress | F21: Advisory board or steering committee | H21: Ad hoc | I21: Considering | J21: Implemented/available | K21: Not planning | L21: =Calc!B21 -> 100 | M21: =Calc!C21 -> 67 | N21: =Verification!F21 -> 100 | O21: =Calc!E21 -> 33 | P21: =Calc!F21 -> 100 | Q21: =Calc!G21 -> 0 | R21: =Calc!H21 -> 50 | S21: =AVERAGE(L21:R21) -> 64.285714 | T21: =RANK(S21,$S$2:$S$113,0)+(COUNTIF($S$2:$S$113,S21)-1)/2 -> 61 | U21: =Coverage!I21 -> 7 | V21: =Coverage!J21 -> 1 | W21: =IFERROR(SUMPRODUCT(L21:R21,Coverage!B21:H21)/U21,0) -> 64.285714 | X21: No independent verification recorded
A22: COAR Notify | B22: COAR | C22: Standard, specification or protocol | D22: Implemented/available | E22: Not planning | F22: Other | G22: Editorial Board | H22: Ad hoc | I22: Considering | J22: Implemented/available | K22: Not planning | L22: =Calc!B22 -> 100 | M22: =Calc!C22 -> 0 | N22: =Verification!F22 -> 0 | O22: =Calc!E22 -> 33 | P22: =Calc!F22 -> 100 | Q22: =Calc!G22 -> 0 | R22: =Calc!H22 -> 50 | S22: =AVERAGE(L22:R22) -> 40.428571 | T22: =RANK(S22,$S$2:$S$113,0)+(COUNTIF($S$2:$S$113,S22)-1)/2 -> 89 | U22: =Coverage!I22 -> 7 | V22: =Coverage!J22 -> 1 | W22: =IFERROR(SUMPRODUCT(L22:R22,Coverage!B22:H22)/U22,0) -> 40.428571 | X22: Review 050 Other response; override available; No independent verification recorded
A23: CollectiveAccess | B23: Whirl-i-Gig | C23: Archive information management system | Digital asset management system | Digital library, collection or exhibit platform | D23: Not planning | E23: Not planning | F23: None | H23: Ad hoc | I23: In progress | J23: Not planning | K23: Not planning | L23: =Calc!B23 -> 0 | M23: =Calc!C23 -> 0 | N23: =Verification!F23 -> 0 | O23: =Calc!E23 -> 67 | P23: =Calc!F23 -> 0 | Q23: =Calc!G23 -> 0 | R23: =Calc!H23 -> 50 | S23: =AVERAGE(L23:R23) -> 16.714286 | T23: =RANK(S23,$S$2:$S$113,0)+(COUNTIF($S$2:$S$113,S23)-1)/2 -> 106 | U23: =Coverage!I23 -> 7 | V23: =Coverage!J23 -> 1 | W23: =IFERROR(SUMPRODUCT(L23:R23,Coverage!B23:H23)/U23,0) -> 16.714286 | X23: No independent verification recorded
A24: CORE | B24: The Open University | C24: Discovery system | D24: Implemented/available | E24: Implemented/available | F24: Multi-board governance | H24: Formal | I24: Implemented/available | J24: Considering | K24: Implemented/available | L24: =Calc!B24 -> 100 | M24: =Calc!C24 -> 100 | N24: =Verification!F24 -> 100 | O24: =Calc!E24 -> 100 | P24: =Calc!F24 -> 33 | Q24: =Calc!G24 -> 100 | R24: =Calc!H24 -> 100 | S24: =AVERAGE(L24:R24) -> 90.428571 | T24: =RANK(S24,$S$2:$S$113,0)+(COUNTIF($S$2:$S$113,S24)-1)/2 -> 23 | U24: =Coverage!I24 -> 7 | V24: =Coverage!J24 -> 1 | W24: =IFERROR(SUMPRODUCT(L24:R24,Coverage!B24:H24)/U24,0) -> 90.428571 | X24: No independent verification recorded
A25: COUNTER Code of Practice | B25: COUNTER Metrics | C25: Standard, specification or protocol | D25: Implemented/available | E25: Implemented/available | F25: Multi-board governance | H25: Formal | I25: Implemented/available | J25: In progress | K25: Implemented/available | L25: =Calc!B25 -> 100 | M25: =Calc!C25 -> 100 | N25: =Verification!F25 -> 100 | O25: =Calc!E25 -> 100 | P25: =Calc!F25 -> 67 | Q25: =Calc!G25 -> 100 | R25: =Calc!H25 -> 100 | S25: =AVERAGE(L25:R25) -> 95.285714 | T25: =RANK(S25,$S$2:$S$113,0)+(COUNTIF($S$2:$S$113,S25)-1)/2 -> 12.5 | U25: =Coverage!I25 -> 7 | V25: =Coverage!J25 -> 1 | W25: =IFERROR(SUMPRODUCT(L25:R25,Coverage!B25:H25)/U25,0) -> 95.285714 | X25: No independent verification recorded
A26: Creative Commons Licenses | B26: Creative Commons | C26: Standard, specification or protocol | D26: Implemented/available | E26: Unknown | F26: Advisory board or steering committee | H26: None | I26: Considering | J26: In progress | K26: Implemented/available | L26: =Calc!B26 -> 100 | M26: =Calc!C26 -> 0 | N26: =Verification!F26 -> 100 | O26: =Calc!E26 -> 33 | P26: =Calc!F26 -> 67 | Q26: =Calc!G26 -> 100 | R26: =Calc!H26 -> 0 | S26: =AVERAGE(L26:R26) -> 57.142857 | T26: =RANK(S26,$S$2:$S$113,0)+(COUNTIF($S$2:$S$113,S26)-1)/2 -> 71 | U26: =Coverage!I26 -> 6 | V26: =Coverage!J26 -> 0.85714286 | W26: =IFERROR(SUMPRODUCT(L26:R26,Coverage!B26:H26)/U26,0) -> 66.666667 | X26: 108_bylaws_status unavailable/unknown scored 0; No independent verification recorded
A27: Crossref Metadata Retrieval | B27: Crossref | C27: Open scholarly dataset | D27: Implemented/available | E27: Implemented/available | F27: Multi-board governance | H27: Formal | I27: In progress | J27: Implemented/available | K27: Implemented/available | L27: =Calc!B27 -> 100 | M27: =Calc!C27 -> 100 | N27: =Verification!F27 -> 100 | O27: =Calc!E27 -> 67 | P27: =Calc!F27 -> 100 | Q27: =Calc!G27 -> 100 | R27: =Calc!H27 -> 100 | S27: =AVERAGE(L27:R27) -> 95.285714 | T27: =RANK(S27,$S$2:$S$113,0)+(COUNTIF($S$2:$S$113,S27)-1)/2 -> 12.5 | U27: =Coverage!I27 -> 7 | V27: =Coverage!J27 -> 1 | W27: =IFERROR(SUMPRODUCT(L27:R27,Coverage!B27:H27)/U27,0) -> 95.285714 | X27: No independent verification recorded
A28: D4Science Infrastructure | B28: National Research Council of Italy | C28: Computing framework | Informal scholarly communications | Repository service | D28: In progress | E28: Not planning | I28: Considering | J28: Considering | K28: Implemented/available | L28: =Calc!B28 -> 67 | M28: =Calc!C28 -> 0 | N28: =Verification!F28 -> 0 | O28: =Calc!E28 -> 33 | P28: =Calc!F28 -> 33 | Q28: =Calc!G28 -> 100 | R28: =Calc!H28 -> 0 | S28: =AVERAGE(L28:R28) -> 33.285714 | T28: =RANK(S28,$S$2:$S$113,0)+(COUNTIF($S$2:$S$113,S28)-1)/2 -> 97.5 | U28: =Coverage!I28 -> 5 | V28: =Coverage!J28 -> 0.71428571 | W28: =IFERROR(SUMPRODUCT(L28:R28,Coverage!B28:H28)/U28,0) -> 46.6 | X28: 048 community governance missing/unrecognized scored 0; No independent verification recorded
A29: DART (Digital Archivist's Resource Tool) | B29: Academic Preservation Trust (APTrust) | C29: Digital preservation tool | D29: Implemented/available | E29: Implemented/available | F29: Advisory board or steering committee | H29: Formal | I29: In progress | J29: Implemented/available | K29: Not planning | L29: =Calc!B29 -> 100 | M29: =Calc!C29 -> 100 | N29: =Verification!F29 -> 100 | O29: =Calc!E29 -> 67 | P29: =Calc!F29 -> 100 | Q29: =Calc!G29 -> 0 | R29: =Calc!H29 -> 100 | S29: =AVERAGE(L29:R29) -> 81 | T29: =RANK(S29,$S$2:$S$113,0)+(COUNTIF($S$2:$S$113,S29)-1)/2 -> 33 | U29: =Coverage!I29 -> 7 | V29: =Coverage!J29 -> 1 | W29: =IFERROR(SUMPRODUCT(L29:R29,Coverage!B29:H29)/U29,0) -> 81 | X29: No independent verification recorded
A30: Database Information System | B30: University Library of Regensburg | C30: Discovery system | Index or directory | D30: Implemented/available | E30: Unknown | F30: Advisory board or steering committee | H30: Ad hoc | I30: Unknown | J30: Unknown | K30: Implemented/available | L30: =Calc!B30 -> 100 | M30: =Calc!C30 -> 0 | N30: =Verification!F30 -> 100 | O30: =Calc!E30 -> 0 | P30: =Calc!F30 -> 0 | Q30: =Calc!G30 -> 100 | R30: =Calc!H30 -> 50 | S30: =AVERAGE(L30:R30) -> 50 | T30: =RANK(S30,$S$2:$S$113,0)+(COUNTIF($S$2:$S$113,S30)-1)/2 -> 79 | U30: =Coverage!I30 -> 4 | V30: =Coverage!J30 -> 0.57142857 | W30: =IFERROR(SUMPRODUCT(L30:R30,Coverage!B30:H30)/U30,0) -> 87.5 | X30: 108_bylaws_status unavailable/unknown scored 0; 029_web_accessibility_status unavailable/unknown scored 0; 035_commitment_to_equity_status unavailable/unknown scored 0; No independent verification recorded
A31: Data Citation Corpus | B31: Make Data Count | C31: Discovery system | Open scholarly dataset | D31: Implemented/available | E31: Not planning | F31: None | H31: Ad hoc | I31: Considering | J31: Not planning | K31: Implemented/available | L31: =Calc!B31 -> 100 | M31: =Calc!C31 -> 0 | N31: =Verification!F31 -> 0 | O31: =Calc!E31 -> 33 | P31: =Calc!F31 -> 0 | Q31: =Calc!G31 -> 100 | R31: =Calc!H31 -> 50 | S31: =AVERAGE(L31:R31) -> 40.428571 | T31: =RANK(S31,$S$2:$S$113,0)+(COUNTIF($S$2:$S$113,S31)-1)/2 -> 89 | U31: =Coverage!I31 -> 7 | V31: =Coverage!J31 -> 1 | W31: =IFERROR(SUMPRODUCT(L31:R31,Coverage!B31:H31)/U31,0) -> 40.428571 | X31: No independent verification recorded
A32: DataCite | B32: DataCite | C32: Discovery system | Persistent identifier service | D32: Implemented/available | E32: Implemented/available | F32: Advisory board or steering committee | H32: Formal | I32: In progress | J32: Implemented/available | K32: Implemented/available | L32: =Calc!B32 -> 100 | M32: =Calc!C32 -> 100 | N32: =Verification!F32 -> 100 | O32: =Calc!E32 -> 67 | P32: =Calc!F32 -> 100 | Q32: =Calc!G32 -> 100 | R32: =Calc!H32 -> 100 | S32: =AVERAGE(L32:R32) -> 95.285714 | T32: =RANK(S32,$S$2:$S$113,0)+(COUNTIF($S$2:$S$113,S32)-1)/2 -> 12.5 | U32: =Coverage!I32 -> 7 | V32: =Coverage!J32 -> 1 | W32: =IFERROR(SUMPRODUCT(L32:R32,Coverage!B32:H32)/U32,0) -> 95.285714 | X32: No independent verification recorded
A33: Data Stewardship Wizard | B33: DSW Team | C33: Data management planning tool or service | D33: Implemented/available | E33: Not planning | F33: Advisory board or steering committee | H33: Ad hoc | I33: In progress | J33: Implemented/available | K33: Not planning | L33: =Calc!B33 -> 100 | M33: =Calc!C33 -> 0 | N33: =Verification!F33 -> 100 | O33: =Calc!E33 -> 67 | P33: =Calc!F33 -> 100 | Q33: =Calc!G33 -> 0 | R33: =Calc!H33 -> 50 | S33: =AVERAGE(L33:R33) -> 59.571429 | T33: =RANK(S33,$S$2:$S$113,0)+(COUNTIF($S$2:$S$113,S33)-1)/2 -> 67 | U33: =Coverage!I33 -> 7 | V33: =Coverage!J33 -> 1 | W33: =IFERROR(SUMPRODUCT(L33:R33,Coverage!B33:H33)/U33,0) -> 59.571429 | X33: No independent verification recorded
A34: Dataverse | B34: Harvard University Institute for Quantitative Social Science (IQSS) | C34: Repository software | D34: Implemented/available | E34: Unknown | F34: None | H34: Ad hoc | I34: In progress | J34: Implemented/available | K34: Implemented/available | L34: =Calc!B34 -> 100 | M34: =Calc!C34 -> 0 | N34: =Verification!F34 -> 0 | O34: =Calc!E34 -> 67 | P34: =Calc!F34 -> 100 | Q34: =Calc!G34 -> 100 | R34: =Calc!H34 -> 50 | S34: =AVERAGE(L34:R34) -> 59.571429 | T34: =RANK(S34,$S$2:$S$113,0)+(COUNTIF($S$2:$S$113,S34)-1)/2 -> 67 | U34: =Coverage!I34 -> 6 | V34: =Coverage!J34 -> 0.85714286 | W34: =IFERROR(SUMPRODUCT(L34:R34,Coverage!B34:H34)/U34,0) -> 69.5 | X34: 108_bylaws_status unavailable/unknown scored 0; No independent verification recorded
A35: DLCM Backend | B35: DLCM Technology | C35: Archive information management system | Digital preservation system | D35: Implemented/available | E35: Not planning | F35: Advisory board or steering committee | H35: None | I35: Considering | J35: Not planning | K35: Considering | L35: =Calc!B35 -> 100 | M35: =Calc!C35 -> 0 | N35: =Verification!F35 -> 100 | O35: =Calc!E35 -> 33 | P35: =Calc!F35 -> 0 | Q35: =Calc!G35 -> 33 | R35: =Calc!H35 -> 0 | S35: =AVERAGE(L35:R35) -> 38 | T35: =RANK(S35,$S$2:$S$113,0)+(COUNTIF($S$2:$S$113,S35)-1)/2 -> 93 | U35: =Coverage!I35 -> 7 | V35: =Coverage!J35 -> 1 | W35: =IFERROR(SUMPRODUCT(L35:R35,Coverage!B35:H35)/U35,0) -> 38 | X35: No independent verification recorded
A36: DLCM Portal | B36: DLCM Technology | C36: Archive information management system | Digital preservation system | Software preservation service | D36: Implemented/available | E36: Not planning | F36: Advisory board or steering committee | H36: None | I36: Considering | J36: Not planning | K36: Considering | L36: =Calc!B36 -> 100 | M36: =Calc!C36 -> 0 | N36: =Verification!F36 -> 100 | O36: =Calc!E36 -> 33 | P36: =Calc!F36 -> 0 | Q36: =Calc!G36 -> 33 | R36: =Calc!H36 -> 0 | S36: =AVERAGE(L36:R36) -> 38 | T36: =RANK(S36,$S$2:$S$113,0)+(COUNTIF($S$2:$S$113,S36)-1)/2 -> 93 | U36: =Coverage!I36 -> 7 | V36: =Coverage!J36 -> 1 | W36: =IFERROR(SUMPRODUCT(L36:R36,Coverage!B36:H36)/U36,0) -> 38 | X36: No independent verification recorded
A37: DMP Tool | B37: California Digital Library | C37: Data management planning tool or service | D37: Not planning | E37: Not planning | F37: None | H37: None | I37: Implemented/available | J37: Not planning | K37: Implemented/available | L37: =Calc!B37 -> 0 | M37: =Calc!C37 -> 0 | N37: =Verification!F37 -> 0 | O37: =Calc!E37 -> 100 | P37: =Calc!F37 -> 0 | Q37: =Calc!G37 -> 100 | R37: =Calc!H37 -> 0 | S37: =AVERAGE(L37:R37) -> 28.571429 | T37: =RANK(S37,$S$2:$S$113,0)+(COUNTIF($S$2:$S$113,S37)-1)/2 -> 100 | U37: =Coverage!I37 -> 7 | V37: =Coverage!J37 -> 1 | W37: =IFERROR(SUMPRODUCT(L37:R37,Coverage!B37:H37)/U37,0) -> 28.571429 | X37: No independent verification recorded
A38: DOAJ (Directory of Open Access Journals) | B38: DOAJ Foundation | C38: Discovery system | Index or directory | Open scholarly dataset | D38: Implemented/available | E38: Implemented/available | F38: Advisory board or steering committee | Other | G38: Foundation Board & Advisory Board | H38: Formal | I38: Implemented/available | J38: Implemented/available | K38: Implemented/available | L38: =Calc!B38 -> 100 | M38: =Calc!C38 -> 100 | N38: =Verification!F38 -> 100 | O38: =Calc!E38 -> 100 | P38: =Calc!F38 -> 100 | Q38: =Calc!G38 -> 100 | R38: =Calc!H38 -> 100 | S38: =AVERAGE(L38:R38) -> 100 | T38: =RANK(S38,$S$2:$S$113,0)+(COUNTIF($S$2:$S$113,S38)-1)/2 -> 4 | U38: =Coverage!I38 -> 7 | V38: =Coverage!J38 -> 1 | W38: =IFERROR(SUMPRODUCT(L38:R38,Coverage!B38:H38)/U38,0) -> 100 | X38: No independent verification recorded
A39: dokieli | B39: dokieli | C39: Annotations system | Authoring tool | Informal scholarly communications | D39: Unknown | E39: Unknown | H39: None | I39: Implemented/available | J39: Unknown | K39: Not applicable | L39: =Calc!B39 -> 0 | M39: =Calc!C39 -> 0 | N39: =Verification!F39 -> 0 | O39: =Calc!E39 -> 100 | P39: =Calc!F39 -> 0 | Q39: =Calc!G39 -> 0 | R39: =Calc!H39 -> 0 | S39: =AVERAGE(L39:R39) -> 14.285714 | T39: =RANK(S39,$S$2:$S$113,0)+(COUNTIF($S$2:$S$113,S39)-1)/2 -> 108 | U39: =Coverage!I39 -> 2 | V39: =Coverage!J39 -> 0.28571429 | W39: =IFERROR(SUMPRODUCT(L39:R39,Coverage!B39:H39)/U39,0) -> 50 | X39: 024_governance_structure_status unavailable/unknown scored 0; 108_bylaws_status unavailable/unknown scored 0; 035_commitment_to_equity_status unavailable/unknown scored 0; 044_commitment_to_privacy_status unavailable/unknown scored 0; No independent verification recorded
A40: Dryad | B40: Dryad | C40: Repository service | D40: Implemented/available | E40: Implemented/available | F40: Other | H40: Formal | I40: Implemented/available | J40: In progress | K40: Implemented/available | L40: =Calc!B40 -> 100 | M40: =Calc!C40 -> 100 | N40: =Verification!F40 -> 0 | O40: =Calc!E40 -> 100 | P40: =Calc!F40 -> 67 | Q40: =Calc!G40 -> 100 | R40: =Calc!H40 -> 100 | S40: =AVERAGE(L40:R40) -> 81 | T40: =RANK(S40,$S$2:$S$113,0)+(COUNTIF($S$2:$S$113,S40)-1)/2 -> 33 | U40: =Coverage!I40 -> 7 | V40: =Coverage!J40 -> 1 | W40: =IFERROR(SUMPRODUCT(L40:R40,Coverage!B40:H40)/U40,0) -> 81 | X40: Review 050 Other response; override available; No independent verification recorded
...

Sheet Metric Rules
A1: Code | B1: Metric | C1: Source field(s) | D1: Exact weight | E1: Displayed weight | F1: Scoring criteria | G1: Unavailable-data treatment | H1: Why this metric is retained
A2: G1 | B2: Governance structure status | C2: 024_governance_structure_status | D2: 0.14285714 | E2: 14.29% | F2: Implemented/available=100; In progress=67; Considering=33; Not planning=0. | G2: Unknown, not applicable, blank, or unrecognized=0 in final score; omitted from observed-only diagnostics. Explicit negative response counts as observed zero. | H2: Reports whether a governance structure is implemented or at an earlier stated stage; the data show responses across the status ladder.
A3: G2 | B3: Bylaws or equivalent formal rules | C3: 108_bylaws_status | D3: 0.14285714 | E3: 14.29% | F3: Implemented/available=100; In progress=67; Considering=33; Not planning=0. | G3: Unknown, not applicable, blank, or unrecognized=0 in final score; omitted from observed-only diagnostics. Explicit negative response counts as observed zero. | H3: Captures written bylaws or equivalent rules as a distinct formal-governance element; report its comparatively high missingness.
A4: G3 | B4: Board or steering-body presence | C4: 050_board_structure + 950_board_structure_other | D4: 0.14285714 | E4: 14.29% | F4: Recognized advisory/steering or multi-board category=100; None=0; Other=100 only when field 950 substantiates a relevant board/committee; otherwise 0 pending review. | G4: Blank=0 and unavailable. Other is scored 0 provisionally and flagged unless field 950 supports a relevant body; reviewer override 0/100 available. None is an observed zero. | H4: Captures whether a board/steering body exists. Corrects the former error that credited the explicit response None.
A5: G4 | B5: Web accessibility status | C5: 029_web_accessibility_status | D5: 0.14285714 | E5: 14.29% | F5: Implemented/available=100; In progress=67; Considering=33; Not planning=0. | G5: Blank or unrecognized=0 and unavailable. Explicit None counts as observed zero. | H5: Captures the reported maturity of web accessibility status.
A6: G5 | B6: Equity commitment status | C6: 035_commitment_to_equity_status | D6: 0.14285714 | E6: 14.29% | F6: Implemented/available=100; In progress=67; Considering=33; Not planning=0. | G6: Unknown, not applicable, blank, or unrecognized=0 in final score; omitted from observed-only diagnostics. Explicit negative response counts as observed zero. | H6: Captures the reported maturity of explicit equity commitments.
A7: G6 | B7: Privacy commitment status | C7: 044_commitment_to_privacy_status | D7: 0.14285714 | E7: 14.29% | F7: Implemented/available=100; In progress=67; Considering=33; Not planning=0. | G7: Unknown, not applicable, blank, or unrecognized=0 in final score; omitted from observed-only diagnostics. Explicit negative response counts as observed zero. | H7: Captures the reported maturity of privacy commitments relevant to users and their data.
A8: G7 | B8: Community governance formality | C8: 048_community_governance_status | D8: 0.14285714 | E8: 14.29% | F8: Formal=100; Ad hoc=50; None=0. | G8: Unknown, not applicable, blank, or unrecognized=0 in final score; omitted from observed-only diagnostics. Explicit negative response counts as observed zero. | H8: Measures formal versus ad hoc community participation in governance; all source service names match the governance dataset.
A9: Total | D9: 1 | E9: 100.00% | H9: Exact weight per metric is 1/7; 14.29% is display rounding.

Sheet Methodology
A1: Methodology and interpretation | B1: Details
A2: Scope | B2: Seven indicators represent governance-structure status, formal rules, governing-body presence, community participation in governance, accessibility, equity, and privacy.
A3: Equal weighting | B3: Each top-level metric receives exactly 1/7 of the score (14.2857%; displayed as 14.29%). Equal weighting is a transparent design choice, not an empirically estimated claim of equal causal importance.
A4: Final formula | B4: Governance Practices Score = (G1 + G2 + G3 + G4 + G5 + G6 + G7) / 7. Each metric is scored from 0 to 100.
A5: No coverage gate | B5: Every infrastructure receives a score. There is no minimum coverage or eligibility rule; the denominator stays seven.
A6: Zero-fill assumption | B6: Unknown, Not applicable, blank, and unrecognized responses score zero in the final composite. This makes the score reflect reported performance and data completeness; zero does not prove absence of the underlying practice.
A7: Coverage diagnostics | B7: Observed metric count and observed coverage (count/7) are reported but do not gate scoring. Explicit negative responses such as Not planning or None count as observed zero. Unknown, N/A, blank, and unresolved status values are excluded from observed coverage.
A8: Observed-only mean | B8: Average the metric scores with observed data only. This is descriptive and uses a variable denominator; it is not the final score or primary zero-filled ranking.
A9: 048 source merge | B9: Community governance fields 048 and 049 are imported from the Community Engagement verification workbook and matched by exact service name. All 112 names match; the current Community Engagement index does not score 048 as a separate metric.
A10: 050 correction | B10: The prior binary rule awarded points to any nonblank value and therefore treated None as positive. The revised rule scores None=0 and requires field 950 evidence to count Other as a governing body. Other cases are flagged for review and may be overridden in Verification.
A11: Fields excluded from score | B11: 026 Governance records and 033 Transparent pricing are excluded as requested. Field 046 Values frameworks and 100 Board level remain descriptive; 046 contains heterogeneous frameworks and is blank for 76 entries, while 100 has only 15 responses. URLs and summaries are evidence/context, not additional metrics.
A12: Why 033 is excluded | B12: The prior source has 59 No direct costs and 47 Implemented/available responses. Treating both as fully transparent pricing places 94.6% at the score ceiling and conflates absence of charge with price transparency.
... A16: No bands | B16: No 70-point cutoff or high/medium/low performance bands are applied.

Sheet Parameters
A1: Parameter | B1: Value | C1: Explanation
A2: Number of metrics | B2: 7 | C2: G1 through G7
A3: Exact metric weight | B3: 0.14285714 | C3: Each metric contributes equally; exact weight sums to 100%.
A4: Displayed metric weight | B4: 14.29% | C4: Rounded display only.
A5: Final score denominator | B5: 7 | C5: Fixed for every infrastructure.
A6: Coverage eligibility threshold | B6: None | C6: Coverage is diagnostic only; all entries are scored.
A7: Unavailable-data treatment | B7: 0 | C7: Unknown, N/A, blank, or unrecognized values contribute zero to the final score.
A8: Status ladder | B8: 100 / 67 / 33 / 0 | C8: Implemented / In progress / Considering / Not planning.
A9: Community governance ladder | B9: 100 / 50 / 0 | C9: Formal / Ad hoc / None.
A10: 050 Other handling | B10: Review + override | C10: Use 950 description; score 100 only when a relevant board or committee is substantiated.

Sheet Diagnostics
A1: Metric | B1: Source field(s) | C1: Observed n | D1: Observed coverage | E1: Mean among observed | F1: Mean under zero-fill | G1: SD among observed | H1: % at 100 among observed | I1: % at 0 among observed | J1: Reading
A2: G1 Governance structure status | B2: 024_governance_structure_status | C2: 107 | D2: 0.95535714 | E2: 82.570093 | F2: 78.883929 | G2: 30.374335 | H2: 0.70093458 | I2: 0.065420561 | J2: Broad status variation; unknown values are zero-filled.
A3: G2 Bylaws or equivalent formal rules | B3: 108_bylaws_status | C3: 83 | D3: 0.74107143 | E3: 69.46988 | F3: 51.482143 | G3: 44.284224 | H3: 0.6626506 | I3: 0.26506024 | J3: 29 unknown values; zero-fill materially affects its mean.
A4: G3 Board or steering-body presence | B4: 050_board_structure + 950_board_structure_other | C4: 107 | D4: 0.95535714 | E4: 75.700935 | F4: 72.321429 | G4: 42.888949 | H4: 0.75700935 | I4: 0.24299065 | J4: Other values need review; explicit None correctly scores zero.
A5: G4 Web accessibility status | B5: 029_web_accessibility_status | C5: 102 | D5: 0.91071429 | E5: 62.754902 | F5: 57.151786 | G5: 32.533071 | H5: 0.33333333 | I5: 0.088235294 | J5: Accessibility applicability field is sparse; use status as recorded.
A6: G5 Equity commitment status | B6: 035_commitment_to_equity_status | C6: 103 | D6: 0.91964286 | E6: 62.106796 | F6: 57.116071 | G6: 35.477577 | H6: 0.38834951 | I6: 0.11650485 | J6: Equity commitment has good spread across status levels.
A7: G6 Privacy commitment status | B7: 044_commitment_to_privacy_status | C7: 99 | D7: 0.88392857 | E7: 79.454545 | F7: 70.232143 | G7: 36.938188 | H7: 0.73737374 | I7: 0.14141414 | J7: High implemented share; still retains non-ceiling variation.
A8: G7 Community governance formality | B8: 048_community_governance_status | C8: 106 | D8: 0.94642857 | E8: 65.566038 | F8: 62.053571 | G8: 37.844772 | H8: 0.49056604 | I8: 0.17924528 | J8: Community governance is sourced from the matched CE sheet; six blanks.
A10: Component summary | B10: Value
A11: Entries scored | B11: 112
A12: Metrics | B12: 7
A13: Weight per metric | B13: 1/7 = 14.2857% (display 14.29%)
A14: Mean zero-filled score | B14: 64.177296
A15: Median zero-filled score | B15: 70.214286
A16: Score standard deviation | B16: 26.000086
A17: Minimum score | B17: 0
A18: Maximum score | B18: 100
A19: Mean observed coverage | B19: 0.90178571
A20: All seven metrics observed | B20: 68
A21: Verification data | B21: verification_status and verification_notes are blank across the source entries.

Sheet Sensitivity
A1: Sensitivity variant | B1: Entries | C1: Spearman rho vs baseline | D1: Mean absolute score change | E1: Max absolute score change | F1: Entries moving >=10 ranks | G1: Interpretation
A2: Baseline: seven-metric zero-filled | B2: 112 | C2: 1 | D2: 0 | E2: 0 | F2: 0 | G2: Primary result; all entries scored.
A3: Observed-only mean | B3: 112 | C3: 0.9342237 | D3: 5.6517219 | E3: 47.857143 | F3: 40 | G3: Diagnostic only; variable denominator and partial coverage.
A4: Complete-data subset, same seven metrics | B4: 68 | C4: 1 | D4: 0 | E4: 0 | F4: 0 | G4: Sensitivity only; does not exclude other entries from the main score.
A5: Six-metric variant excluding G3 | B5: 112 | C5: 0.9798554 | D5: 4.7293793 | E5: 13.5 | F5: 12 | G5: Sensitivity check for the influence of board-presence metric; not the official metric set.
A7: Note | B7: G3 sensitivity uses provisional 050/950 coding. Refresh this workbook after reviewer overrides to update all result and sensitivity tables.

Sheet Coverage
A1: Service | B1: G1 observed | C1: G2 observed | D1: G3 observed | E1: G4 observed | F1: G5 observed | G1: G6 observed | H1: G7 observed | I1: Available metrics (of 7) | J1: Observed coverage | K1: Observed-only mean | L1: Zero-filled final score
A2: 2i2c | B2: 1 | C2: 0 | D2: 1 | E2: 1 | F2: 1 | G2: 1 | H2: 1 | I2: 6 | J2: 0.85714286 | K2: =Scoring!W2 -> 55.5 | L2: =Scoring!S2 -> 47.571429
A3: Academic Preservation Trust (APTrust) | B3: 1 | C3: 1 | D3: 1 | E3: 1 | F3: 1 | G3: 1 | H3: 1 | I3: 7 | J3: 1 | K3: =Scoring!W3 -> 76.142857 | L3: =Scoring!S3 -> 76.142857
A4: AfricArXiv | B4: 1 | C4: 1 | D4: 1 | E4: 1 | F4: 1 | G4: 1 | H4: 1 | I4: 7 | J4: 1 | K4: =Scoring!W4 -> 69.142857 | L4: =Scoring!S4 -> 69.142857
A5: Arches Heritage Data Management Platform | B5: 1 | C5: 1 | D5: 1 | E5: 1 | F5: 1 | G5: 1 | H5: 1 | I5: 7 | J5: 1 | K5: =Scoring!W5 -> 71.428571 | L5: =Scoring!S5 -> 71.428571
A6: Archipelago Commons | B6: 1 | C6: 1 | D6: 1 | E6: 1 | F6: 1 | G6: 1 | H6: 1 | I6: 7 | J6: 1 | K6: =Scoring!W6 -> 90.428571 | L6: =Scoring!S6 -> 90.428571
A7: Archival Resource Key | B7: 1 | C7: 0 | D7: 1 | E7: 1 | F7: 1 | G7: 0 | H7: 1 | I7: 5 | J7: 0.71428571 | K7: =Scoring!W7 -> 63.4 | L7: =Scoring!S7 -> 45.285714
A8: Archivematica | B8: 1 | C8: 1 | D8: 1 | E8: 1 | F8: 1 | G8: 1 | H8: 1 | I8: 7 | J8: 1 | K8: =Scoring!W8 -> 33.142857 | L8: =Scoring!S8 -> 33.142857
A9: ArchivesSpace | B9: 1 | C9: 1 | D9: 1 | E9: 1 | F9: 1 | G9: 1 | H9: 1 | I9: 7 | J9: 1 | K9: =Scoring!W9 -> 100 | L9: =Scoring!S9 -> 100
A10: ARGOS | B10: 1 | C10: 1 | D10: 1 | E10: 1 | F10: 1 | G10: 1 | H10: 1 | I10: 7 | J10: 1 | K10: =Scoring!W10 -> 95.285714 | L10: =Scoring!S10 -> 95.285714
A11: arXiv | B11: 1 | C11: 1 | D11: 1 | E11: 1 | F11: 0 | G11: 1 | H11: 1 | I11: 6 | J11: 0.85714286 | K11: =Scoring!W11 -> 100 | L11: =Scoring!S11 -> 85.714286
A12: AtoM | B12: 1 | C12: 1 | D12: 0 | E12: 1 | F12: 1 | G12: 1 | H12: 0 | I12: 5 | J12: 0.71428571 | K12: =Scoring!W12 -> 53.2 | L12: =Scoring!S12 -> 38
A13: Avalon Media System | B13: 1 | C13: 1 | D13: 1 | E13: 1 | F13: 1 | G13: 1 | H13: 1 | I13: 7 | J13: 1 | K13: =Scoring!W13 -> 71.428571 | L13: =Scoring!S13 -> 71.428571
... A113: Zotero | B113: 1 | C113: 1 | D113: 1 | E113: 1 | F113: 1 | G113: 1 | H113: 1 | I113: 7 | J113: 1 | K113: =Scoring!W113 -> 92.857143 | L113: =Scoring!S113 -> 92.857143

Sheet Verification
A1: Service | B1: 050 board structure | C1: 950 other detail | D1: Provisional G3 | E1: Reviewer override (0 or 100) | F1: Final G3 | G1: Review status | H1: Reviewer notes
A2: 2i2c | B2: Advisory board or steering committee | D2: 100 | F2: =IF(ISNUMBER(E2),E2,D2) -> 100 | G2: No G3 review flagged | H2: Allowed override values are 0 or 100; use only after checking the described body's role.
A3: Academic Preservation Trust (APTrust) | B3: Multi-board governance | D3: 100 | F3: =IF(ISNUMBER(E3),E3,D3) -> 100 | G3: No G3 review flagged | H3: Allowed override values are 0 or 100; use only after checking the described body's role.
A4: AfricArXiv | B4: Advisory board or steering committee | D4: 100 | F4: =IF(ISNUMBER(E4),E4,D4) -> 100 | G4: No G3 review flagged | H4: Allowed override values are 0 or 100; use only after checking the described body's role.
A5: Arches Heritage Data Management Platform | B5: Advisory board or steering committee | D5: 100 | F5: =IF(ISNUMBER(E5),E5,D5) -> 100 | G5: No G3 review flagged | H5: Allowed override values are 0 or 100; use only after checking the described body's role.
A6: Archipelago Commons | B6: Advisory board or steering committee | D6: 100 | F6: =IF(ISNUMBER(E6),E6,D6) -> 100 | G6: No G3 review flagged | H6: Allowed override values are 0 or 100; use only after checking the described body's role.
A7: Archival Resource Key | B7: Advisory board or steering committee | D7: 100 | F7: =IF(ISNUMBER(E7),E7,D7) -> 100 | G7: No G3 review flagged | H7: Allowed override values are 0 or 100; use only after checking the described body's role.
A8: Archivematica | B8: None | D8: 0 | F8: =IF(ISNUMBER(E8),E8,D8) -> 0 | G8: No G3 review flagged | H8: Allowed override values are 0 or 100; use only after checking the described body's role.
A9: ArchivesSpace | B9: Advisory board or steering committee | D9: 100 | F9: =IF(ISNUMBER(E9),E9,D9) -> 100 | G9: No G3 review flagged | H9: Allowed override values are 0 or 100; use only after checking the described body's role.
A10: ARGOS | B10: Advisory board or steering committee | D10: 100 | F10: =IF(ISNUMBER(E10),E10,D10) -> 100 | G10: No G3 review flagged | H10: Allowed override values are 0 or 100; use only after checking the described body's role.
A11: arXiv | B11: Multi-board governance | D11: 100 | F11: =IF(ISNUMBER(E11),E11,D11) -> 100 | G11: No G3 review flagged | H11: Allowed override values are 0 or 100; use only after checking the described body's role.
A12: AtoM | D12: 0 | F12: =IF(ISNUMBER(E12),E12,D12) -> 0 | G12: No G3 review flagged | H12: Allowed override values are 0 or 100; use only after checking the described body's role.
A13: Avalon Media System | B13: Advisory board or steering committee | D13: 100 | F13: =IF(ISNUMBER(E13),E13,D13) -> 100 | G13: No G3 review flagged | H13: Allowed override values are 0 or 100; use only after checking the described body's role.
A14: Biodiversity Heritage Library | B14: Advisory board or steering committee | D14: 100 | F14: =IF(ISNUMBER(E14),E14,D14) -> 100 | G14: No G3 review flagged | H14: Allowed override values are 0 or 100; use only after checking the described body's role.
A15: bioRxiv | B15: Advisory board or steering committee | D15: 100 | F15: =IF(ISNUMBER(E15),E15,D15) -> 100 | G15: No G3 review flagged | H15: Allowed override values are 0 or 100; use only after checking the described body's role.
A16: BitCurator Environment | B16: Advisory board or steering committee | D16: 100 | F16: =IF(ISNUMBER(E16),E16,D16) -> 100 | G16: No G3 review flagged | H16: Allowed override values are 0 or 100; use only after checking the described body's role.
A17: Blacklight | B17: None | D17: 0 | F17: =IF(ISNUMBER(E17),E17,D17) -> 0 | G17: No G3 review flagged | H17: Allowed override values are 0 or 100; use only after checking the described body's role.
A18: BrCRIS | B18: Advisory board or steering committee | D18: 100 | F18: =IF(ISNUMBER(E18),E18,D18) -> 100 | G18: No G3 review flagged | H18: Allowed override values are 0 or 100; use only after checking the described body's role.
A19: Browsertrix | B19: None | D19: 0 | F19: =IF(ISNUMBER(E19),E19,D19) -> 0 | G19: No G3 review flagged | H19: Allowed override values are 0 or 100; use only after checking the described body's role.
A20: CLOCKSS | B20: Advisory board or steering committee | D20: 100 | F20: =IF(ISNUMBER(E20),E20,D20) -> 100 | G20: No G3 review flagged | H20: Allowed override values are 0 or 100; use only after checking the described body's role.
A21: COAR International Repository Directory (IRD) | B21: Advisory board or steering committee | D21: 100 | F21: =IF(ISNUMBER(E21),E21,D21) -> 100 | G21: No G3 review flagged | H21: Allowed override values are 0 or 100; use only after checking the described body's role.
A22: COAR Notify | B22: Other | C22: Editorial Board | D22: 0 | F22: =IF(ISNUMBER(E22),E22,D22) -> 0 | G22: Review Other response | H22: Allowed override values are 0 or 100; use only after checking the described body's role.
A23: CollectiveAccess | B23: None | D23: 0 | F23: =IF(ISNUMBER(E23),E23,D23) -> 0 | G23: No G3 review flagged | H23: Allowed override values are 0 or 100; use only after checking the described body's role.
A24: CORE | B24: Multi-board governance | D24: 100 | F24: =IF(ISNUMBER(E24),E24,D24) -> 100 | G24: No G3 review flagged | H24: Allowed override values are 0 or 100; use only after checking the described body's role.
A25: COUNTER Code of Practice | B25: Multi-board governance | D25: 100 | F25: =IF(ISNUMBER(E25),E25,D25) -> 100 | G25: No G3 review flagged | H25: Allowed override values are 0 or 100; use only after checking the described body's role.
A26: Creative Commons Licenses | B26: Advisory board or steering committee | D26: 100 | F26: =IF(ISNUMBER(E26),E26,D26) -> 100 | G26: No G3 review flagged | H26: Allowed override values are 0 or 100; use only after checking the described body's role.
A27: Crossref Metadata Retrieval | B27: Multi-board governance | D27: 100 | F27: =IF(ISNUMBER(E27),E27,D27) -> 100 | G27: No G3 review flagged | H27: Allowed override values are 0 or 100; use only after checking the described body's role.
A28: D4Science Infrastructure | D28: 0 | F28: =IF(ISNUMBER(E28),E28,D28) -> 0 | G28: No G3 review flagged | H28: Allowed override values are 0 or 100; use only after checking the described body's role.
A29: DART (Digital Archivist's Resource Tool) | B29: Advisory board or steering committee | D29: 100 | F29: =IF(ISNUMBER(E29),E29,D29) -> 100 | G29: No G3 review flagged | H29: Allowed override values are 0 or 100; use only after checking the described body's role.
A30: Database Information System | B30: Advisory board or steering committee | D30: 100 | F30: =IF(ISNUMBER(E30),E30,D30) -> 100 | G30: No G3 review flagged | H30: Allowed override values are 0 or 100; use only after checking the described body's role.
A31: Data Citation Corpus | B31: None | D31: 0 | F31: =IF(ISNUMBER(E31),E31,D31) -> 0 | G31: No G3 review flagged | H31: Allowed override values are 0 or 100; use only after checking the described body's role.
A32: DataCite | B32: Advisory board or steering committee | D32: 100 | F32: =IF(ISNUMBER(E32),E32,D32) -> 100 | G32: No G3 review flagged | H32: Allowed override values are 0 or 100; use only after checking the described body's role.
A33: Data Stewardship Wizard | B33: Advisory board or steering committee | D33: 100 | F33: =IF(ISNUMBER(E33),E33,D33) -> 100 | G33: No G3 review flagged | H33: Allowed override values are 0 or 100; use only after checking the described body's role.
A34: Dataverse | B34: None | D34: 0 | F34: =IF(ISNUMBER(E34),E34,D34) -> 0 | G34: No G3 review flagged | H34: Allowed override values are 0 or 100; use only after checking the described body's role.
A35: DLCM Backend | B35: Advisory board or steering committee | D35: 100 | F35: =IF(ISNUMBER(E35),E35,D35) -> 100 | G35: No G3 review flagged | H35: Allowed override values are 0 or 100; use only after checking the described body's role.
A36: DLCM Portal | B36: Advisory board or steering committee | D36: 100 | F36: =IF(ISNUMBER(E36),E36,D36) -> 100 | G36: No G3 review flagged | H36: Allowed override values are 0 or 100; use only after checking the described body's role.
A37: DMP Tool | B37: None | D37: 0 | F37: =IF(ISNUMBER(E37),E37,D37) -> 0 | G37: No G3 review flagged | H37: Allowed override values are 0 or 100; use only after checking the described body's role.
A38: DOAJ (Directory of Open Access Journals) | B38: Advisory board or steering committee | Other | C38: Foundation Board & Advisory Board | D38: 100 | F38: =IF(ISNUMBER(E38),E38,D38) -> 100 | G38: No G3 review flagged | H38: Allowed override values are 0 or 100; use only after checking the described body's role.
A39: dokieli | D39: 0 | F39: =IF(ISNUMBER(E39),E39,D39) -> 0 | G39: No G3 review flagged | H39: Allowed override values are 0 or 100; use only after checking the described body's role.
A40: Dryad | B40: Other | D40: 0 | F40: =IF(ISNUMBER(E40),E40,D40) -> 0 | G40: Review Other response | H40: Allowed override values are 0 or 100; use only after checking the described body's role.
...

Sheet Review Queue
A1: Service | B1: Metric / field | C1: Raw value | D1: Provisional treatment | E1: Review reason / action | F1: Reviewer notes
A2: Archipelago Commons | B2: G1: 024_governance_structure_status | C2: Implemented/available | D2: Status scored 100; no paired URL supplied | E2: Review official evidence where available; this is a documentation check, not an eligibility rule.
A3: COAR Notify | B3: G3: 050/950 | C3: Other | Editorial Board | D3: 0 | E3: Confirm the described body governs, oversees, or advises this infrastructure; then enter 0 or 100 on Verification.
A4: DMP Tool | B4: G4: 029_web_accessibility_status | C4: Implemented/available | D4: Status scored 100; no paired URL supplied | E4: Review official evidence where available; this is a documentation check, not an eligibility rule.
A5: DOAJ (Directory of Open Access Journals) | B5: G4: 029_web_accessibility_status | C5: Implemented/available | D5: Status scored 100; no paired URL supplied | E5: Review official evidence where available; this is a documentation check, not an eligibility rule.
A6: Dryad | B6: G3: 050/950 | C6: Other | | D6: 0 | E6: Confirm the described body governs, oversees, or advises this infrastructure; then enter 0 or 100 on Verification.
A7: Dryad | B7: G4: 029_web_accessibility_status | C7: Implemented/available | D7: Status scored 100; no paired URL supplied | E7: Review official evidence where available; this is a documentation check, not an eligibility rule.
A8: fido | B8: G7: 048/049 | C8: Formal | D8: Formal scored 100; no paired URL supplied | E8: Review official evidence where available; this is a documentation check, not an eligibility rule.
A9: Fulcrum | B9: G3: 050/950 | C9: Other | | D9: 0 | E9: Confirm the described body governs, oversees, or advises this infrastructure; then enter 0 or 100 on Verification.
A10: Janeway | B10: G4: 029_web_accessibility_status | C10: Implemented/available | D10: Status scored 100; no paired URL supplied | E10: Review official evidence where available; this is a documentation check, not an eligibility rule.
A11: LA Referencia | B11: G7: 048/049 | C11: Formal | D11: Formal scored 100; no paired URL supplied | E11: Review official evidence where available; this is a documentation check, not an eligibility rule.
A12: Manifold | B12: G4: 029_web_accessibility_status | C12: Implemented/available | D12: Status scored 100; no paired URL supplied | E12: Review official evidence where available; this is a documentation check, not an eligibility rule.
A13: Omeka | B13: G4: 029_web_accessibility_status | C13: Implemented/available | D13: Status scored 100; no paired URL supplied | E13: Review official evidence where available; this is a documentation check, not an eligibility rule.
A14: OpenAlex | B14: G7: 048/049 | C14: Formal | D14: Formal scored 100; no paired URL supplied | E14: Review official evidence where available; this is a documentation check, not an eligibility rule.
A15: O Portal Brasileiro de Publicações e Dados Científicos em Acesso Aberto (The Brazilian Open Access Publications and Scientific Data Portal) (Oasisbr) | B15: G3: 050/950 | C15: Other | | D15: 0 | E15: Confirm the described body governs, oversees, or advises this infrastructure; then enter 0 or 100 on Verification.
A16: Peer Community In | B16: G7: 048/049 | C16: Formal | D16: Formal scored 100; no paired URL supplied | E16: Review official evidence where available; this is a documentation check, not an eligibility rule.
A17: Public Access Submission System | B17: G3: 050/950 | C17: Other | | D17: 0 | E17: Confirm the described body governs, oversees, or advises this infrastructure; then enter 0 or 100 on Verification.
A18: Public Utility Data Liberation (PUDL) | B18: G3: 050/950 | C18: Other | Board of directors | D18: 100 | E18: Confirm the described body governs, oversees, or advises this infrastructure; then enter 0 or 100 on Verification.
A19: RSpace | B19: G3: 050/950 | C19: Other | Board of directors of UK limited company | D19: 100 | E19: Confirm the described body governs, oversees, or advises this infrastructure; then enter 0 or 100 on Verification.
A20: Sciety | B20: G7: 048/049 | C20: Formal | D20: Formal scored 100; no paired URL supplied | E20: Review official evidence where available; this is a documentation check, not an eligibility rule.
A21: Thoth Open Metadata | B21: G3: 050/950 | C21: Other | Board of Directors | D21: 100 | E21: Confirm the described body governs, oversees, or advises this infrastructure; then enter 0 or 100 on Verification.
A22: veraPDF | B22: G7: 048/049 | C22: Formal | D22: Formal scored 100; no paired URL supplied | E22: Review official evidence where available; this is a documentation check, not an eligibility rule.
A23: ViPER | B23: G7: 048/049 | C23: Formal | D23: Formal scored 100; no paired URL supplied | E23: Review official evidence where available; this is a documentation check, not an eligibility rule.

Sheet Calc
A1: Service | B1: G1 | C1: G2 | D1: G3 provisional | E1: G4 | F1: G5 | G1: G6 | H1: G7 | I1: G3 coding rationale | J1: G3 review flag | K1: Python-checked zero-filled score | L1: Available metrics | M1: Observed coverage | N1: Observed-only mean | O1: Data-quality flags
A2: 2i2c | B2: 67 | C2: 0 | D2: 100 | E2: 33 | F2: 33 | G2: 100 | H2: 0 | I2: Recognized board or steering-body category | J2: No | K2: 47.571429 | L2: 6 | M2: 0.85714286 | N2: 55.5 | O2: 108_bylaws_status unavailable/unknown scored 0; No independent verification recorded
A3: Academic Preservation Trust (APTrust) | B3: 100 | C3: 100 | D3: 100 | E3: 33 | F3: 100 | G3: 0 | H3: 100 | I3: Recognized board or steering-body category | J3: No | K3: 76.142857 | L3: 7 | M3: 1 | N3: 76.142857 | O3: No independent verification recorded
A4: AfricArXiv | B4: 100 | C4: 0 | D4: 100 | E4: 67 | F4: 67 | G4: 100 | H4: 50 | I4: Recognized board or steering-body category | J4: No | K4: 69.142857 | L4: 7 | M4: 1 | N4: 69.142857 | O4: No independent verification recorded
A5: Arches Heritage Data Management Platform | B5: 100 | C5: 100 | D5: 100 | E5: 100 | F5: 0 | G5: 0 | H5: 100 | I5: Recognized board or steering-body category | J5: No | K5: 71.428571 | L5: 7 | M5: 1 | N5: 71.428571 | O5: No independent verification recorded
A6: Archipelago Commons | B6: 100 | C6: 100 | D6: 100 | E6: 100 | F6: 100 | G6: 33 | H6: 100 | I6: Recognized board or steering-body category | J6: No | K6: 90.428571 | L6: 7 | M6: 1 | N6: 90.428571 | O6: No independent verification recorded
A7: Archival Resource Key | B7: 67 | C7: 0 | D7: 100 | E7: 67 | F7: 33 | G7: 0 | H7: 50 | I7: Recognized board or steering-body category | J7: No | K7: 45.285714 | L7: 5 | M7: 0.71428571 | N7: 63.4 | O7: 108_bylaws_status unavailable/unknown scored 0; 044_commitment_to_privacy_status unavailable/unknown scored 0; No independent verification recorded
A8: Archivematica | B8: 33 | C8: 33 | D8: 0 | E8: 33 | F8: 33 | G8: 100 | H8: 0 | I8: Explicitly reports no board/steering body | J8: No | K8: 33.142857 | L8: 7 | M8: 1 | N8: 33.142857 | O8: No independent verification recorded
A9: ArchivesSpace | B9: 100 | C9: 100 | D9: 100 | E9: 100 | F9: 100 | G9: 100 | H9: 100 | I9: Recognized board or steering-body category | J9: No | K9: 100 | L9: 7 | M9: 1 | N9: 100 | O9: No independent verification recorded
A10: ARGOS | B10: 100 | C10: 100 | D10: 100 | E10: 67 | F10: 100 | G10: 100 | H10: 100 | I10: Recognized board or steering-body category | J10: No | K10: 95.285714 | L10: 7 | M10: 1 | N10: 95.285714 | O10: No independent verification recorded
