Workbook

Sheet Summary
A1: Organizational Capacity: Final Equal-Weight Results
A2: Infrastructure entries | B2: 112
A3: Final metrics | B3: M1, M2, H1, I2, O1
A4: Weight per metric | B4: 20.00% (1/5)
A5: Coverage / eligibility gate | B5: None
A6: Missing, unknown, N/A | B6: Scored 0; denominator remains five
A7: Mean score | B7: =AVERAGE(Scoring!O2:O113) -> 57.269345
A8: Median score | B8: =MEDIAN(Scoring!O2:O113) -> 60
A9: Highest score | B9: =MAX(Scoring!O2:O113) -> 95
A10: Lowest score | B10: =MIN(Scoring!O2:O113) -> 20
A11: Important interpretation | B11: Zero-filled score reflects both reported capacity and missing information. Review metric-level scores and notes before interpreting rank differences.
A12: Affiliation review | B12: Field 058 is free text. Use Verification to enter a corrected I2 score of 0, 50, or 100; scoring formulas update when opened/recalculated in Excel.
A13: Mean observed coverage | B13: =AVERAGE(Coverage!J2:J113) -> 0.71428571
A14: Entries with all five metrics observed | B14: =COUNTIF(Coverage!I2:I113,5) -> 29

Sheet Scoring
A1: Service | B1: Provider | C1: Solution category | D1: 079 Readiness | E1: 080 Maintenance | F1: 054 Full-time staff | G1: 055 Volunteers | H1: 058 Affiliations | I1: 076 Service options | J1: M1 | K1: M2 | L1: H1 | M1: I2 | N1: O1 | O1: Final score / 100 | P1: Rank | Q1: Data-quality notes | R1: Available metrics (of 5) | S1: Observed coverage | T1: Observed-only mean
A2: 2i2c | B2: Code for Science and Society | C2: Authoring tool | D2: Actual system proven in operational environment | E2: Actively Maintained | I2: Not applicable | J2: =Calc!B2 -> 100 | K2: =Calc!C2 -> 100 | L2: =Calc!F2 -> 0 | M2: =Verification!E2 -> 0 | N2: =Calc!I2 -> 0 | O2: =AVERAGE(J2:N2) -> 40 | P2: =RANK.EQ(O2,$O$2:$O$113,0) -> 83 | Q2: Full-time staffing missing/unknown scored 0; Volunteer staffing missing/unknown scored 0; Service-delivery field not applicable/unknown scored 0 | R2: =Coverage!I2 -> 2 | S2: =Coverage!J2 -> 0.4 | T2: =Coverage!K2 -> 100
A3: Academic Preservation Trust (APTrust) | B3: Academic Preservation Trust (APTrust) | C3: Digital preservation service | D3: Actual system proven in operational environment | E3: Actively Maintained | F3: 1-5 | H3: University of Virginia | I3: Through solution provider only | J3: =Calc!B3 -> 100 | K3: =Calc!C3 -> 100 | L3: =Calc!F3 -> 12.5 | M3: =Verification!E3 -> 50 | N3: =Calc!I3 -> 100 | O3: =AVERAGE(J3:N3) -> 72.5 | P3: =RANK.EQ(O3,$O$2:$O$113,0) -> 13 | Q3: Volunteer staffing missing/unknown scored 0; Review affiliation coding; override available | R3: =Coverage!I3 -> 5 | S3: =Coverage!J3 -> 1 | T3: =Coverage!K3 -> 75
A4: AfricArXiv | B4: UbuntuNet Alliance | C4: Repository service | D4: Actual system proven in operational environment | E4: Actively Maintained | F4: 1-5 | G4: 1-5 | H4: Access 2 Perspectives coordinates AfricArXiv’s operations. This includes managing day-to-day activities, overseeing submission processes, ensuring quality control, and facilitating the integration of AfricArXiv with other scholarly services | I4: Not applicable | J4: =Calc!B4 -> 100 | K4: =Calc!C4 -> 100 | L4: =Calc!F4 -> 25 | M4: =Verification!E4 -> 100 | N4: =Calc!I4 -> 0 | O4: =AVERAGE(J4:N4) -> 65 | P4: =RANK.EQ(O4,$O$2:$O$113,0) -> 31 | Q4: Review affiliation coding; override available; Service-delivery field not applicable/unknown scored 0 | R4: =Coverage!I4 -> 4 | S4: =Coverage!J4 -> 0.8 | T4: =Coverage!K4 -> 81.25
A5: Arches Heritage Data Management Platform | B5: Getty Conservation Institute (GCI) | C5: Data management planning tool or service | D5: Actual system proven in operational environment | E5: Actively Maintained | H5: Getty Conservation Institute Farallon Geographics | I5: Through third party vendor only | J5: =Calc!B5 -> 100 | K5: =Calc!C5 -> 100 | L5: =Calc!F5 -> 0 | M5: =Verification!E5 -> 50 | N5: =Calc!I5 -> 100 | O5: =AVERAGE(J5:N5) -> 70 | P5: =RANK.EQ(O5,$O$2:$O$113,0) -> 19 | Q5: Full-time staffing missing/unknown scored 0; Volunteer staffing missing/unknown scored 0; Review affiliation coding; override available | R5: =Coverage!I5 -> 4 | S5: =Coverage!J5 -> 0.8 | T5: =Coverage!K5 -> 87.5
A6: Archipelago Commons | B6: Metropolitan New York Library Council | C6: Digital library, collection or exhibit platform | Repository software | D6: Actual system proven in operational environment | E6: Actively Maintained | I6: Through solution provider or third party vendor | J6: =Calc!B6 -> 100 | K6: =Calc!C6 -> 100 | L6: =Calc!F6 -> 0 | M6: =Verification!E6 -> 0 | N6: =Calc!I6 -> 100 | O6: =AVERAGE(J6:N6) -> 60 | P6: =RANK.EQ(O6,$O$2:$O$113,0) -> 43 | Q6: Full-time staffing missing/unknown scored 0; Volunteer staffing missing/unknown scored 0 | R6: =Coverage!I6 -> 3 | S6: =Coverage!J6 -> 0.6 | T6: =Coverage!K6 -> 100
A7: Archival Resource Key | B7: ARK Alliance | C7: Standard, specification or protocol | D7: Technology validated in relevant environment | E7: Actively Maintained | I7: Not applicable | J7: =Calc!B7 -> 55.555556 | K7: =Calc!C7 -> 100 | L7: =Calc!F7 -> 0 | M7: =Verification!E7 -> 0 | N7: =Calc!I7 -> 0 | O7: =AVERAGE(J7:N7) -> 31.111111 | P7: =RANK.EQ(O7,$O$2:$O$113,0) -> 110 | Q7: Full-time staffing missing/unknown scored 0; Volunteer staffing missing/unknown scored 0; Service-delivery field not applicable/unknown scored 0 | R7: =Coverage!I7 -> 2 | S7: =Coverage!J7 -> 0.4 | T7: =Coverage!K7 -> 77.777778
A8: Archivematica | B8: Artefactual | C8: Digital preservation system | D8: Actual system proven in operational environment | E8: Actively Maintained | F8: More than 20 | H8: No Affiliations | I8: Through solution provider or third party vendor | J8: =Calc!B8 -> 100 | K8: =Calc!C8 -> 100 | L8: =Calc!F8 -> 50 | M8: =Verification!E8 -> 0 | N8: =Calc!I8 -> 100 | O8: =AVERAGE(J8:N8) -> 70 | P8: =RANK.EQ(O8,$O$2:$O$113,0) -> 19 | Q8: Volunteer staffing missing/unknown scored 0; Review affiliation coding; override available | R8: =Coverage!I8 -> 5 | S8: =Coverage!J8 -> 1 | T8: =Coverage!K8 -> 80
A9: ArchivesSpace | B9: ArchivesSpace | C9: Archive information management system | Discovery system | D9: Actual system proven in operational environment | E9: Actively Maintained | F9: 6-10 | H9: New York University and the University of California San Diego are the founding partners and have permanent seats on the Board; Lyrasis is the organizational home | I9: Through third party vendor only | J9: =Calc!B9 -> 100 | K9: =Calc!C9 -> 100 | L9: =Calc!F9 -> 25 | M9: =Verification!E9 -> 100 | N9: =Calc!I9 -> 100 | O9: =AVERAGE(J9:N9) -> 85 | P9: =RANK.EQ(O9,$O$2:$O$113,0) -> 3 | Q9: Volunteer staffing missing/unknown scored 0; Review affiliation coding; override available | R9: =Coverage!I9 -> 5 | S9: =Coverage!J9 -> 1 | T9: =Coverage!K9 -> 90
A10: ARGOS | B10: OpenAIRE | C10: Data management planning tool or service | D10: Actual system proven in operational environment | E10: Actively Maintained | H10: Athena Research Center (ARC) Communication & Information Technologies Experts (CITE) | I10: Through solution provider only | J10: =Calc!B10 -> 100 | K10: =Calc!C10 -> 100 | L10: =Calc!F10 -> 0 | M10: =Verification!E10 -> 50 | N10: =Calc!I10 -> 100 | O10: =AVERAGE(J10:N10) -> 70 | P10: =RANK.EQ(O10,$O$2:$O$113,0) -> 19 | Q10: Full-time staffing missing/unknown scored 0; Volunteer staffing missing/unknown scored 0; Review affiliation coding; override available | R10: =Coverage!I10 -> 4 | S10: =Coverage!J10 -> 0.8 | T10: =Coverage!K10 -> 87.5
A11: arXiv | B11: Cornell University | C11: Repository service | D11: Actual system proven in operational environment | E11: Actively Maintained | I11: Not applicable | J11: =Calc!B11 -> 100 | K11: =Calc!C11 -> 100 | L11: =Calc!F11 -> 0 | M11: =Verification!E11 -> 0 | N11: =Calc!I11 -> 0 | O11: =AVERAGE(J11:N11) -> 40 | P11: =RANK.EQ(O11,$O$2:$O$113,0) -> 83 | Q11: Full-time staffing missing/unknown scored 0; Volunteer staffing missing/unknown scored 0; Service-delivery field not applicable/unknown scored 0 | R11: =Coverage!I11 -> 2 | S11: =Coverage!J11 -> 0.4 | T11: =Coverage!K11 -> 100
A12: AtoM | B12: Artefactual | C12: Archive information management system | D12: Actual system proven in operational environment | E12: Actively Maintained | F12: More than 20 | G12: Unknown | H12: No affiliations | I12: Through solution provider or third party vendor | J12: =Calc!B12 -> 100 | K12: =Calc!C12 -> 100 | L12: =Calc!F12 -> 50 | M12: =Verification!E12 -> 0 | N12: =Calc!I12 -> 100 | O12: =AVERAGE(J12:N12) -> 70 | P12: =RANK.EQ(O12,$O$2:$O$113,0) -> 19 | Q12: Review affiliation coding; override available | R12: =Coverage!I12 -> 5 | S12: =Coverage!J12 -> 1 | T12: =Coverage!K12 -> 80
A13: Avalon Media System | B13: Indiana University Libraries | C13: Digital library, collection or exhibit platform | Repository software | D13: Actual system proven in operational environment | E13: Actively Maintained | F13: 1-5 | H13: Indiana University Libraries | I13: No services available | J13: =Calc!B13 -> 100 | K13: =Calc!C13 -> 100 | L13: =Calc!F13 -> 12.5 | M13: =Verification!E13 -> 50 | N13: =Calc!I13 -> 0 | O13: =AVERAGE(J13:N13) -> 52.5 | P13: =RANK.EQ(O13,$O$2:$O$113,0) -> 69 | Q13: Volunteer staffing missing/unknown scored 0; Review affiliation coding; override available | R13: =Coverage!I13 -> 5 | S13: =Coverage!J13 -> 1 | T13: =Coverage!K13 -> 55
A14: Biodiversity Heritage Library | B14: BHL Consortium | C14: Digital library, collection or exhibit platform | Open scholarly dataset | Repository service | D14: Actual system proven in operational environment | E14: Actively Maintained | F14: 1-5 | H14: BHL’s fiscal sponsor is the Council on Library and Information Resources (CLIR). | I14: Not applicable | J14: =Calc!B14 -> 100 | K14: =Calc!C14 -> 100 | L14: =Calc!F14 -> 12.5 | M14: =Verification!E14 -> 100 | N14: =Calc!I14 -> 0 | O14: =AVERAGE(J14:N14) -> 62.5 | P14: =RANK.EQ(O14,$O$2:$O$113,0) -> 37 | Q14: Volunteer staffing missing/unknown scored 0; Review affiliation coding; override available; Service-delivery field not applicable/unknown scored 0 | R14: =Coverage!I14 -> 4 | S14: =Coverage!J14 -> 0.8 | T14: =Coverage!K14 -> 81.25
A15: bioRxiv | B15: Cold Spring Harbor Laboratory | C15: Repository service | D15: Actual system proven in operational environment | E15: Actively Maintained | I15: Not applicable | J15: =Calc!B15 -> 100 | K15: =Calc!C15 -> 100 | L15: =Calc!F15 -> 0 | M15: =Verification!E15 -> 0 | N15: =Calc!I15 -> 0 | O15: =AVERAGE(J15:N15) -> 40 | P15: =RANK.EQ(O15,$O$2:$O$113,0) -> 83 | Q15: Full-time staffing missing/unknown scored 0; Volunteer staffing missing/unknown scored 0; Service-delivery field not applicable/unknown scored 0 | R15: =Coverage!I15 -> 2 | S15: =Coverage!J15 -> 0.4 | T15: =Coverage!K15 -> 100
A16: BitCurator Environment | B16: BitCurator Consortium | C16: Digital preservation tool | D16: Actual system proven in operational environment | E16: Actively Maintained | F16: 0 | G16: 6-10 | H16: BitCurator Consortium is administratively hosted by the Open Library Foundation. | I16: No services available | J16: =Calc!B16 -> 100 | K16: =Calc!C16 -> 100 | L16: =Calc!F16 -> 25 | M16: =Verification!E16 -> 100 | N16: =Calc!I16 -> 0 | O16: =AVERAGE(J16:N16) -> 65 | P16: =RANK.EQ(O16,$O$2:$O$113,0) -> 31 | Q16: Review affiliation coding; override available | R16: =Coverage!I16 -> 5 | S16: =Coverage!J16 -> 1 | T16: =Coverage!K16 -> 65
A17: Blacklight | B17: Blacklight | C17: Discovery system | Integrated Library System (ILS) or Library Services Platform (LSP) | D17: Actual system proven in operational environment | E17: Actively Maintained | F17: 6-10 | H17: See website | I17: Through solution provider only | J17: =Calc!B17 -> 100 | K17: =Calc!C17 -> 100 | L17: =Calc!F17 -> 25 | M17: =Verification!E17 -> 0 | N17: =Calc!I17 -> 100 | O17: =AVERAGE(J17:N17) -> 65 | P17: =RANK.EQ(O17,$O$2:$O$113,0) -> 31 | Q17: Volunteer staffing missing/unknown scored 0; Review affiliation coding; override available | R17: =Coverage!I17 -> 4 | S17: =Coverage!J17 -> 0.8 | T17: =Coverage!K17 -> 87.5
A18: BrCRIS | B18: IBICT | C18: Discovery system | Research profiling system | D18: Actual system proven in operational environment | E18: Actively Maintained | I18: Not applicable | J18: =Calc!B18 -> 100 | K18: =Calc!C18 -> 100 | L18: =Calc!F18 -> 0 | M18: =Verification!E18 -> 0 | N18: =Calc!I18 -> 0 | O18: =AVERAGE(J18:N18) -> 40 | P18: =RANK.EQ(O18,$O$2:$O$113,0) -> 83 | Q18: Full-time staffing missing/unknown scored 0; Volunteer staffing missing/unknown scored 0; Service-delivery field not applicable/unknown scored 0 | R18: =Coverage!I18 -> 2 | S18: =Coverage!J18 -> 0.4 | T18: =Coverage!K18 -> 100
A19: Browsertrix | B19: Webrecorder | C19: Digital library, collection or exhibit platform | Web archiving system | D19: Actual system proven in operational environment | E19: Actively Maintained | F19: 1-5 | G19: 0 | H19: No affiliations have direct involvement in governing or running our products except us. We are members of the International Internet Preservation Consortium (IIPC). | I19: Through solution provider or third party vendor | J19: =Calc!B19 -> 100 | K19: =Calc!C19 -> 100 | L19: =Calc!F19 -> 12.5 | M19: =Verification!E19 -> 50 | N19: =Calc!I19 -> 100 | O19: =AVERAGE(J19:N19) -> 72.5 | P19: =RANK.EQ(O19,$O$2:$O$113,0) -> 13 | Q19: Review affiliation coding; override available | R19: =Coverage!I19 -> 5 | S19: =Coverage!J19 -> 1 | T19: =Coverage!K19 -> 72.5
A20: CLOCKSS | B20: CLOCKSS | C20: Digital preservation service | D20: Actual system proven in operational environment | E20: Actively Maintained | F20: 1-5 | G20: 0 | H20: n/a | I20: Through solution provider or third party vendor | J20: =Calc!B20 -> 100 | K20: =Calc!C20 -> 100 | L20: =Calc!F20 -> 12.5 | M20: =Verification!E20 -> 0 | N20: =Calc!I20 -> 100 | O20: =AVERAGE(J20:N20) -> 62.5 | P20: =RANK.EQ(O20,$O$2:$O$113,0) -> 37 | Q20: Review affiliation coding; override available | R20: =Coverage!I20 -> 4 | S20: =Coverage!J20 -> 0.8 | T20: =Coverage!K20 -> 78.125
A21: COAR International Repository Directory (IRD) | B21: COAR | C21: Index or directory | D21: Actual system proven in operational environment | E21: Actively Maintained | F21: 1-5 | H21: Responsible Organisations: https://ird.coar-repositories.org/about?lang=en | I21: Not applicable | J21: =Calc!B21 -> 100 | K21: =Calc!C21 -> 100 | L21: =Calc!F21 -> 12.5 | M21: =Verification!E21 -> 50 | N21: =Calc!I21 -> 0 | O21: =AVERAGE(J21:N21) -> 52.5 | P21: =RANK.EQ(O21,$O$2:$O$113,0) -> 69 | Q21: Volunteer staffing missing/unknown scored 0; Review affiliation coding; override available; Service-delivery field not applicable/unknown scored 0 | R21: =Coverage!I21 -> 4 | S21: =Coverage!J21 -> 0.8 | T21: =Coverage!K21 -> 68.75
A22: COAR Notify | B22: COAR | C22: Standard, specification or protocol | D22: Actual system proven in operational environment | E22: Actively Maintained | H22: No affiliations. | I22: Through solution provider or third party vendor | J22: =Calc!B22 -> 100 | K22: =Calc!C22 -> 100 | L22: =Calc!F22 -> 0 | M22: =Verification!E22 -> 0 | N22: =Calc!I22 -> 100 | O22: =AVERAGE(J22:N22) -> 60 | P22: =RANK.EQ(O22,$O$2:$O$113,0) -> 43 | Q22: Full-time staffing missing/unknown scored 0; Volunteer staffing missing/unknown scored 0; Review affiliation coding; override available | R22: =Coverage!I22 -> 4 | S22: =Coverage!J22 -> 0.8 | T22: =Coverage!K22 -> 75
A23: CollectiveAccess | B23: Whirl-i-Gig | C23: Archive information management system | Digital asset management system | Digital library, collection or exhibit platform | D23: Actual system proven in operational environment | E23: Actively Maintained | F23: 6-10 | G23: 0 | H23: No affiliations | I23: Through solution provider or third party vendor | J23: =Calc!B23 -> 100 | K23: =Calc!C23 -> 100 | L23: =Calc!F23 -> 25 | M23: =Verification!E23 -> 0 | N23: =Calc!I23 -> 100 | O23: =AVERAGE(J23:N23) -> 65 | P23: =RANK.EQ(O23,$O$2:$O$113,0) -> 31 | Q23: Review affiliation coding; override available | R23: =Coverage!I23 -> 5 | S23: =Coverage!J23 -> 1 | T23: =Coverage!K23 -> 65
A24: CORE | B24: The Open University | C24: Discovery system | D24: Actual system proven in operational environment | E24: Actively Maintained | I24: Not applicable | J24: =Calc!B24 -> 100 | K24: =Calc!C24 -> 100 | L24: =Calc!F24 -> 0 | M24: =Verification!E24 -> 0 | N24: =Calc!I24 -> 0 | O24: =AVERAGE(J24:N24) -> 40 | P24: =RANK.EQ(O24,$O$2:$O$113,0) -> 83 | Q24: Full-time staffing missing/unknown scored 0; Volunteer staffing missing/unknown scored 0; Service-delivery field not applicable/unknown scored 0 | R24: =Coverage!I24 -> 2 | S24: =Coverage!J24 -> 0.4 | T24: =Coverage!K24 -> 100
A25: COUNTER Code of Practice | B25: COUNTER Metrics | C25: Standard, specification or protocol | D25: Actual system proven in operational environment | E25: Actively Maintained | I25: Not applicable | J25: =Calc!B25 -> 100 | K25: =Calc!C25 -> 100 | L25: =Calc!F25 -> 0 | M25: =Verification!E25 -> 0 | N25: =Calc!I25 -> 0 | O25: =AVERAGE(J25:N25) -> 40 | P25: =RANK.EQ(O25,$O$2:$O$113,0) -> 83 | Q25: Full-time staffing missing/unknown scored 0; Volunteer staffing missing/unknown scored 0; Service-delivery field not applicable/unknown scored 0 | R25: =Coverage!I25 -> 2 | S25: =Coverage!J25 -> 0.4 | T25: =Coverage!K25 -> 100
A26: Creative Commons Licenses | B26: Creative Commons | C26: Standard, specification or protocol | D26: System complete and qualified | E26: Actively Maintained | I26: Not applicable | J26: =Calc!B26 -> 88.888889 | K26: =Calc!C26 -> 100 | L26: =Calc!F26 -> 0 | M26: =Verification!E26 -> 0 | N26: =Calc!I26 -> 0 | O26: =AVERAGE(J26:N26) -> 37.777778 | P26: =RANK.EQ(O26,$O$2:$O$113,0) -> 108 | Q26: Full-time staffing missing/unknown scored 0; Volunteer staffing missing/unknown scored 0; Service-delivery field not applicable/unknown scored 0 | R26: =Coverage!I26 -> 2 | S26: =Coverage!J26 -> 0.4 | T26: =Coverage!K26 -> 94.444444
A27: Crossref Metadata Retrieval | B27: Crossref | C27: Open scholarly dataset | D27: Actual system proven in operational environment | E27: Actively Maintained | I27: Not applicable | J27: =Calc!B27 -> 100 | K27: =Calc!C27 -> 100 | L27: =Calc!F27 -> 0 | M27: =Verification!E27 -> 0 | N27: =Calc!I27 -> 0 | O27: =AVERAGE(J27:N27) -> 40 | P27: =RANK.EQ(O27,$O$2:$O$113,0) -> 83 | Q27: Full-time staffing missing/unknown scored 0; Volunteer staffing missing/unknown scored 0; Service-delivery field not applicable/unknown scored 0 | R27: =Coverage!I27 -> 2 | S27: =Coverage!J27 -> 0.4 | T27: =Coverage!K27 -> 100
A28: D4Science Infrastructure | B28: National Research Council of Italy | C28: Computing framework | Informal scholarly communications | Repository service | D28: Actual system proven in operational environment | E28: Actively Maintained | F28: 6-10 | G28: More than 20 | H28: D4Science is managed by the Italian National Research Council (CNR). Its headquarters are hosted by CNR's Institute of Information Science and Technologies "A. Faedo" (CNR-ISTI) in Pisa, Tuscany, Italy. | I28: Through solution provider only | J28: =Calc!B28 -> 100 | K28: =Calc!C28 -> 100 | L28: =Calc!F28 -> 75 | M28: =Verification!E28 -> 100 | N28: =Calc!I28 -> 100 | O28: =AVERAGE(J28:N28) -> 95 | P28: =RANK.EQ(O28,$O$2:$O$113,0) -> 1 | Q28: Review affiliation coding; override available | R28: =Coverage!I28 -> 5 | S28: =Coverage!J28 -> 1 | T28: =Coverage!K28 -> 95
A29: DART (Digital Archivist's Resource Tool) | B29: Academic Preservation Trust (APTrust) | C29: Digital preservation tool | D29: Actual system proven in operational environment | E29: Actively Maintained | F29: 1-5 | H29: University of Virginia | I29: No services available | J29: =Calc!B29 -> 100 | K29: =Calc!C29 -> 100 | L29: =Calc!F29 -> 12.5 | M29: =Verification!E29 -> 50 | N29: =Calc!I29 -> 0 | O29: =AVERAGE(J29:N29) -> 52.5 | P29: =RANK.EQ(O29,$O$2:$O$113,0) -> 69 | Q29: Volunteer staffing missing/unknown scored 0; Review affiliation coding; override available | R29: =Coverage!I29 -> 5 | S29: =Coverage!J29 -> 1 | T29: =Coverage!K29 -> 55
A30: Database Information System | B30: University Library of Regensburg | C30: Discovery system | Index or directory | D30: Actual system proven in operational environment | E30: Actively Maintained | H30: DBIS is operated by the University Library of Regensburg. | I30: Through solution provider or third party vendor | J30: =Calc!B30 -> 100 | K30: =Calc!C30 -> 100 | L30: =Calc!F30 -> 0 | M30: =Verification!E30 -> 50 | N30: =Calc!I30 -> 100 | O30: =AVERAGE(J30:N30) -> 70 | P30: =RANK.EQ(O30,$O$2:$O$113,0) -> 19 | Q30: Full-time staffing missing/unknown scored 0; Volunteer staffing missing/unknown scored 0; Review affiliation coding; override available | R30: =Coverage!I30 -> 4 | S30: =Coverage!J30 -> 0.8 | T30: =Coverage!K30 -> 87.5
A31: Data Citation Corpus | B31: Make Data Count | C31: Discovery system | Open scholarly dataset | D31: Technology validated in relevant environment | E31: Actively Maintained | G31: 11-20 | H31: DataCite leads the development of the Data Citation Corpus as part of Make Data Count activities. | I31: Not applicable | J31: =Calc!B31 -> 55.555556 | K31: =Calc!C31 -> 100 | L31: =Calc!F31 -> 37.5 | M31: =Verification!E31 -> 50 | N31: =Calc!I31 -> 0 | O31: =AVERAGE(J31:N31) -> 48.611111 | P31: =RANK.EQ(O31,$O$2:$O$113,0) -> 80 | Q31: Full-time staffing missing/unknown scored 0; Review affiliation coding; override available; Service-delivery field not applicable/unknown scored 0 | R31: =Coverage!I31 -> 4 | S31: =Coverage!J31 -> 0.8 | T31: =Coverage!K31 -> 70.138889
A32: DataCite | B32: DataCite | C32: Discovery system | Persistent identifier service | D32: Actual system proven in operational environment | E32: Actively Maintained | I32: Not applicable | J32: =Calc!B32 -> 100 | K32: =Calc!C32 -> 100 | L32: =Calc!F32 -> 0 | M32: =Verification!E32 -> 0 | N32: =Calc!I32 -> 0 | O32: =AVERAGE(J32:N32) -> 40 | P32: =RANK.EQ(O32,$O$2:$O$113,0) -> 83 | Q32: Full-time staffing missing/unknown scored 0; Volunteer staffing missing/unknown scored 0; Service-delivery field not applicable/unknown scored 0 | R32: =Coverage!I32 -> 2 | S32: =Coverage!J32 -> 0.4 | T32: =Coverage!K32 -> 100
A33: Data Stewardship Wizard | B33: DSW Team | C33: Data management planning tool or service | D33: Actual system proven in operational environment | E33: Actively Maintained | H33: Czech Technical University in Prague / ELIXIR-CZ Codevence Solutions | I33: Through third party vendor only | J33: =Calc!B33 -> 100 | K33: =Calc!C33 -> 100 | L33: =Calc!F33 -> 0 | M33: =Verification!E33 -> 50 | N33: =Calc!I33 -> 100 | O33: =AVERAGE(J33:N33) -> 70 | P33: =RANK.EQ(O33,$O$2:$O$113,0) -> 19 | Q33: Full-time staffing missing/unknown scored 0; Volunteer staffing missing/unknown scored 0; Review affiliation coding; override available | R33: =Coverage!I33 -> 4 | S33: =Coverage!J33 -> 0.8 | T33: =Coverage!K33 -> 87.5
A34: Dataverse | B34: Harvard University Institute for Quantitative Social Science (IQSS) | C34: Repository software | D34: Actual system proven in operational environment | E34: Actively Maintained | I34: Through third party vendor only | J34: =Calc!B34 -> 100 | K34: =Calc!C34 -> 100 | L34: =Calc!F34 -> 0 | M34: =Verification!E34 -> 0 | N34: =Calc!I34 -> 100 | O34: =AVERAGE(J34:N34) -> 60 | P34: =RANK.EQ(O34,$O$2:$O$113,0) -> 43 | Q34: Full-time staffing missing/unknown scored 0; Volunteer staffing missing/unknown scored 0 | R34: =Coverage!I34 -> 3 | S34: =Coverage!J34 -> 0.6 | T34: =Coverage!K34 -> 100
A35: DLCM Backend | B35: DLCM Technology | C35: Archive information management system | Digital preservation system | D35: Actual system proven in operational environment | E35: Actively Maintained | F35: 1-5 | G35: 1-5 | H35: University of Geneva (https://www.unige.ch/) HEG, HES-SO (https://www.hesge.ch/heg/en) UNIFR (https://www.unifr.ch/home/en/) BFH (https://www.bfh.ch/en/) OLOS (https://olos.swiss/) | I35: Through third party vendor only | J35: =Calc!B35 -> 100 | K35: =Calc!C35 -> 100 | L35: =Calc!F35 -> 25 | M35: =Verification!E35 -> 50 | N35: =Calc!I35 -> 100 | O35: =AVERAGE(J35:N35) -> 75 | P35: =RANK.EQ(O35,$O$2:$O$113,0) -> 10 | Q35: Review affiliation coding; override available | R35: =Coverage!I35 -> 5 | S35: =Coverage!J35 -> 1 | T35: =Coverage!K35 -> 75
A36: DLCM Portal | B36: DLCM Technology | C36: Archive information management system | Digital preservation system | Software preservation service | D36: Actual system proven in operational environment | E36: Actively Maintained | F36: 1-5 | G36: 1-5 | H36: University of Geneva (https://www.unige.ch/)HEG, HES-SO (https://www.hesge.ch/heg/en)UNIFR (https://www.unifr.ch/home/en/)BFH (https://www.bfh.ch/en/)OLOS (https://olos.swiss/) | I36: Through third party vendor only | J36: =Calc!B36 -> 100 | K36: =Calc!C36 -> 100 | L36: =Calc!F36 -> 25 | M36: =Verification!E36 -> 50 | N36: =Calc!I36 -> 100 | O36: =AVERAGE(J36:N36) -> 75 | P36: =RANK.EQ(O36,$O$2:$O$113,0) -> 10 | Q36: Review affiliation coding; override available | R36: =Coverage!I36 -> 5 | S36: =Coverage!J36 -> 1 | T36: =Coverage!K36 -> 75
A37: DMP Tool | B37: California Digital Library | C37: Data management planning tool or service | D37: Actual system proven in operational environment | E37: Actively Maintained | F37: 1-5 | G37: 0 | I37: Through solution provider only | J37: =Calc!B37 -> 100 | K37: =Calc!C37 -> 100 | L37: =Calc!F37 -> 12.5 | M37: =Verification!E37 -> 0 | N37: =Calc!I37 -> 100 | O37: =AVERAGE(J37:N37) -> 62.5 | P37: =RANK.EQ(O37,$O$2:$O$113,0) -> 37 | R37: =Coverage!I37 -> 4 | S37: =Coverage!J37 -> 0.8 | T37: =Coverage!K37 -> 78.125
A38: DOAJ (Directory of Open Access Journals) | B38: DOAJ Foundation | C38: Discovery system | Index or directory | Open scholarly dataset | D38: Actual system proven in operational environment | E38: Actively Maintained | I38: Not applicable | J38: =Calc!B38 -> 100 | K38: =Calc!C38 -> 100 | L38: =Calc!F38 -> 0 | M38: =Verification!E38 -> 0 | N38: =Calc!I38 -> 0 | O38: =AVERAGE(J38:N38) -> 40 | P38: =RANK.EQ(O38,$O$2:$O$113,0) -> 83 | Q38: Full-time staffing missing/unknown scored 0; Volunteer staffing missing/unknown scored 0; Service-delivery field not applicable/unknown scored 0 | R38: =Coverage!I38 -> 2 | S38: =Coverage!J38 -> 0.4 | T38: =Coverage!K38 -> 100
A39: dokieli | B39: dokieli | C39: Annotations system | Authoring tool | Informal scholarly communications | D39: Technology validated in relevant environment | E39: Actively Maintained | I39: Unknown | J39: =Calc!B39 -> 55.555556 | K39: =Calc!C39 -> 100 | L39: =Calc!F39 -> 0 | M39: =Verification!E39 -> 0 | N39: =Calc!I39 -> 0 | O39: =AVERAGE(J39:N39) -> 31.111111 | P39: =RANK.EQ(O39,$O$2:$O$113,0) -> 110 | Q39: Full-time staffing missing/unknown scored 0; Volunteer staffing missing/unknown scored 0; Service-delivery field not applicable/unknown scored 0 | R39: =Coverage!I39 -> 2 | S39: =Coverage!J39 -> 0.4 | T39: =Coverage!K39 -> 77.777778
A40: Dryad | B40: Dryad | C40: Repository service | D40: Actual system proven in operational environment | E40: Actively Maintained | I40: Not applicable | J40: =Calc!B40 -> 100 | K40: =Calc!C40 -> 100 | L40: =Calc!F40 -> 0 | M40: =Verification!E40 -> 0 | N40: =Calc!I40 -> 0 | O40: =AVERAGE(J40:N40) -> 40 | P40: =RANK.EQ(O40,$O$2:$O$113,0) -> 83 | Q40: Full-time staffing missing/unknown scored 0; Volunteer staffing missing/unknown scored 0; Service-delivery field not applicable/unknown scored 0 | R40: =Coverage!I40 -> 2 | S40: =Coverage!J40 -> 0.4 | T40: =Coverage!K40 -> 100
...

Sheet Metric Rules
A1: Code | B1: Metric | C1: Source field(s) | D1: Weight | E1: Scoring criteria | F1: Unavailable-data treatment | G1: Interpretation / caution
A2: M1 | B2: Technology readiness | C2: 079 | D2: 0.2 | E2: Nine-stage source scale: score = level / 9 x 100. Observed: Actual system proven in operational environment=100; System complete and qualified=88.89; Technology validated in relevant environment=55.56. | F2: Unknown, blank, or unrecognized=0. | G2: Ordinal normalization on the source readiness scale; current data are concentrated at the highest level.
A3: M2 | B3: Maintenance status | C3: 080 | D3: 0.2 | E3: Actively Maintained=100; Minimally Maintained=50; Inactive/not maintained=0. | F3: Unknown or blank=0. | G3: Current responses are highly concentrated at actively maintained.
A4: H1 | B4: Human-resource capacity | C4: 054 + 055 | D4: 0.2 | E4: Score each field: 0 people=0; 1-5=25; 6-10=50; 11-20=75; >20=100. H1=(full-time score+volunteer score)/2. | F4: Unknown or blank in either field=0 for that field; H1 remains the average of both fields. | G4: Ordinal ranges, not exact headcounts. Paid and volunteer staffing each contribute half of H1.
A5: I2 | B5: Institutional affiliations and support | C5: 058 | D5: 0.2 | E5: Formal host or explicit operational/financial support=100; substantive affiliation/membership without stated operational support=50; explicit absence/placeholders=0. | F5: Blank or unknown=0. Free-text provisional coding can be overridden on Verification sheet with 0, 50, or 100. | G5: Narrative coding needs consistent review; an override changes the Scoring sheet formula after recalculation in Excel.
A6: O1 | B6: Hosted/service-delivery capacity | C6: 076 | D6: 0.2 | E6: Any 'Through ...' hosted/service route=100; No services available=0. | F6: Not applicable, unknown, or blank=0. | G6: Measures reported service availability, not quality, uptime, affordability, or control.

Sheet Methodology
A1: Methodology and interpretation | B1: Details
A2: Metric selection | B2: Five measures are retained: technology readiness, maintenance, combined staffing, institutional affiliations/support, and hosted/service-delivery capacity. M3 Infrastructure age and I1 Formal organizational host are excluded. Funding, legal form, SCOSS, and provider-list fields remain descriptive, not scored.
A3: Equal weighting | B3: Each of the five metrics receives 20%. Equal weighting is a transparent analytic choice; it is not estimated from the observed data or claimed to establish equal causal importance.
A4: Final formula | B4: Organizational Capacity Score = (M1 + M2 + H1 + I2 + O1) / 5. Each metric is first placed on a 0-100 scale.
A5: Missing-data rule | B5: No coverage or eligibility threshold is applied. Blank, unknown, not applicable, or unrecognized values score 0, as requested. The denominator remains five for every infrastructure.
A6: Observed coverage diagnostics | B6: Observed coverage is reported for transparency only; it is not an eligibility gate. A metric is observed when a valid source response exists. H1 is observed if at least one staffing subfield has a recognized category; its observed-only diagnostic averages only the staffing subfields actually reported, while the final H1 score assigns zero to a missing subfield.
A7: Observed-only mean | B7: The per-infrastructure observed-only mean averages available metric scores and excludes unavailable metrics. It uses a variable denominator and is descriptive; the final score remains the equal-weight zero-filled mean across all five metrics.
A8: Interpretation | B8: The zero-filled score reflects recorded capacity and data availability together. A zero for a missing field does not prove the underlying capacity is absent. Publish metric-level values and data-quality notes with the total.
A9: Human resources | B9: Full-time and volunteer staffing are subfields of one metric. Each is scored 0/25/50/75/100 by reported category; their two sub-scores are averaged. Missing/unknown subfields score zero. The category scale is ordinal.
A10: Affiliation coding | B10: Field 058 is free text. A provisional deterministic rule assigns 100 only where explicit hosting/support language is present; other substantive affiliation text receives 50; explicit absence/placeholders/blank receive 0. Review and numeric overrides (0, 50, 100) are available in Verification.
A11: Source data | B11: The workbook contains 112 source entries copied from the Organizational Capacity verification sheet and includes the source Field_Guide. The source data are preserved as a separate sheet.
A12: No performance bands | B12: No 70-point cutoff or high/medium/low categories are applied.
A13: Limitations | B13: Technology readiness and maintenance responses show little variation. Staffing and affiliation information is incomplete or narrative. Hosted/service delivery is not a direct measure of quality. These constraints should be stated when interpreting comparisons.

Sheet Parameters
A1: Code | B1: Metric | C1: Source field(s) | D1: Exact weight | E1: Displayed weight | F1: Scale
A2: M1 | B2: Technology readiness | C2: 079_technology_readiness | D2: 0.2 | E2: 20.00% | F2: 0-100
A3: M2 | B3: Maintenance status | C3: 080_maintenance_status | D3: 0.2 | E3: 20.00% | F3: 0-100
A4: H1 | B4: Human-resource capacity | C4: 054_staffing_full_time + 055_staffing_volunteer | D4: 0.2 | E4: 20.00% | F4: 0-100
A5: I2 | B5: Institutional affiliations and support | C5: 058_affiliations | D5: 0.2 | E5: 20.00% | F5: 0-100
A6: O1 | B6: Hosted/service-delivery capacity | C6: 076_saas_options | D6: 0.2 | E6: 20.00% | F6: 0-100
A7: Total | D7: 1 | E7: 100.00%
A9: Zero-fill policy | B9: All unavailable, unknown, not applicable, or unrecognized values score 0; denominator stays five.
A10: Coverage threshold | B10: None

Sheet Verification
A1: Service | B1: Raw 058 affiliation text | C1: Provisional I2 score | D1: Override I2 (0/50/100) | E1: Final I2 score | F1: Reviewer notes
A2: 2i2c | C2: 0 | E2: =IF(ISNUMBER(D2),D2,C2) -> 0 | F2: Enter 0, 50, or 100 only when correcting the provisional text coding.
A3: Academic Preservation Trust (APTrust) | B3: University of Virginia | C3: 50 | E3: =IF(ISNUMBER(D3),D3,C3) -> 50 | F3: Enter 0, 50, or 100 only when correcting the provisional text coding.
A4: AfricArXiv | B4: Access 2 Perspectives coordinates AfricArXiv’s operations. This includes managing day-to-day activities, overseeing submission processes, ensuring quality control, and facilitating the integration of AfricArXiv with other scholarly services | C4: 100 | E4: =IF(ISNUMBER(D4),D4,C4) -> 100 | F4: Enter 0, 50, or 100 only when correcting the provisional text coding.
A5: Arches Heritage Data Management Platform | B5: Getty Conservation Institute Farallon Geographics | C5: 50 | E5: =IF(ISNUMBER(D5),D5,C5) -> 50 | F5: Enter 0, 50, or 100 only when correcting the provisional text coding.
A6: Archipelago Commons | C6: 0 | E6: =IF(ISNUMBER(D6),D6,C6) -> 0 | F6: Enter 0, 50, or 100 only when correcting the provisional text coding.
A7: Archival Resource Key | C7: 0 | E7: =IF(ISNUMBER(D7),D7,C7) -> 0 | F7: Enter 0, 50, or 100 only when correcting the provisional text coding.
A8: Archivematica | B8: No Affiliations | C8: 0 | E8: =IF(ISNUMBER(D8),D8,C8) -> 0 | F8: Enter 0, 50, or 100 only when correcting the provisional text coding.
A9: ArchivesSpace | B9: New York University and the University of California San Diego are the founding partners and have permanent seats on the Board; Lyrasis is the organizational home | C9: 100 | E9: =IF(ISNUMBER(D9),D9,C9) -> 100 | F9: Enter 0, 50, or 100 only when correcting the provisional text coding.
A10: ARGOS | B10: Athena Research Center (ARC) Communication & Information Technologies Experts (CITE) | C10: 50 | E10: =IF(ISNUMBER(D10),D10,C10) -> 50 | F10: Enter 0, 50, or 100 only when correcting the provisional text coding.
A11: arXiv | C11: 0 | E11: =IF(ISNUMBER(D11),D11,C11) -> 0 | F11: Enter 0, 50, or 100 only when correcting the provisional text coding.
A12: AtoM | B12: No affiliations | C12: 0 | E12: =IF(ISNUMBER(D12),D12,C12) -> 0 | F12: Enter 0, 50, or 100 only when correcting the provisional text coding.
A13: Avalon Media System | B13: Indiana University Libraries | C13: 50 | E13: =IF(ISNUMBER(D13),D13,C13) -> 50 | F13: Enter 0, 50, or 100 only when correcting the provisional text coding.
A14: Biodiversity Heritage Library | B14: BHL’s fiscal sponsor is the Council on Library and Information Resources (CLIR). | C14: 100 | E14: =IF(ISNUMBER(D14),D14,C14) -> 100 | F14: Enter 0, 50, or 100 only when correcting the provisional text coding.
A15: bioRxiv | C15: 0 | E15: =IF(ISNUMBER(D15),D15,C15) -> 0 | F15: Enter 0, 50, or 100 only when correcting the provisional text coding.
A16: BitCurator Environment | B16: BitCurator Consortium is administratively hosted by the Open Library Foundation. | C16: 100 | E16: =IF(ISNUMBER(D16),D16,C16) -> 100 | F16: Enter 0, 50, or 100 only when correcting the provisional text coding.
A17: Blacklight | B17: See website | C17: 0 | E17: =IF(ISNUMBER(D17),D17,C17) -> 0 | F17: Enter 0, 50, or 100 only when correcting the provisional text coding.
A18: BrCRIS | C18: 0 | E18: =IF(ISNUMBER(D18),D18,C18) -> 0 | F18: Enter 0, 50, or 100 only when correcting the provisional text coding.
A19: Browsertrix | B19: No affiliations have direct involvement in governing or running our products except us. We are members of the International Internet Preservation Consortium (IIPC). | C19: 50 | E19: =IF(ISNUMBER(D19),D19,C19) -> 50 | F19: Enter 0, 50, or 100 only when correcting the provisional text coding.
A20: CLOCKSS | B20: n/a | C20: 0 | E20: =IF(ISNUMBER(D20),D20,C20) -> 0 | F20: Enter 0, 50, or 100 only when correcting the provisional text coding.
A21: COAR International Repository Directory (IRD) | B21: Responsible Organisations: https://ird.coar-repositories.org/about?lang=en | C21: 50 | E21: =IF(ISNUMBER(D21),D21,C21) -> 50 | F21: Enter 0, 50, or 100 only when correcting the provisional text coding.
A22: COAR Notify | B22: No affiliations. | C22: 0 | E22: =IF(ISNUMBER(D22),D22,C22) -> 0 | F22: Enter 0, 50, or 100 only when correcting the provisional text coding.
A23: CollectiveAccess | B23: No affiliations | C23: 0 | E23: =IF(ISNUMBER(D23),D23,C23) -> 0 | F23: Enter 0, 50, or 100 only when correcting the provisional text coding.
A24: CORE | C24: 0 | E24: =IF(ISNUMBER(D24),D24,C24) -> 0 | F24: Enter 0, 50, or 100 only when correcting the provisional text coding.
A25: COUNTER Code of Practice | C25: 0 | E25: =IF(ISNUMBER(D25),D25,C25) -> 0 | F25: Enter 0, 50, or 100 only when correcting the provisional text coding.
A26: Creative Commons Licenses | C26: 0 | E26: =IF(ISNUMBER(D26),D26,C26) -> 0 | F26: Enter 0, 50, or 100 only when correcting the provisional text coding.
A27: Crossref Metadata Retrieval | C27: 0 | E27: =IF(ISNUMBER(D27),D27,C27) -> 0 | F27: Enter 0, 50, or 100 only when correcting the provisional text coding.
A28: D4Science Infrastructure | B28: D4Science is managed by the Italian National Research Council (CNR). Its headquarters are hosted by CNR's Institute of Information Science and Technologies "A. Faedo" (CNR-ISTI) in Pisa, Tuscany, Italy. | C28: 100 | E28: =IF(ISNUMBER(D28),D28,C28) -> 100 | F28: Enter 0, 50, or 100 only when correcting the provisional text coding.
A29: DART (Digital Archivist's Resource Tool) | B29: University of Virginia | C29: 50 | E29: =IF(ISNUMBER(D29),D29,C29) -> 50 | F29: Enter 0, 50, or 100 only when correcting the provisional text coding.
A30: Database Information System | B30: DBIS is operated by the University Library of Regensburg. | C30: 50 | E30: =IF(ISNUMBER(D30),D30,C30) -> 50 | F30: Enter 0, 50, or 100 only when correcting the provisional text coding.
A31: Data Citation Corpus | B31: DataCite leads the development of the Data Citation Corpus as part of Make Data Count activities. | C31: 50 | E31: =IF(ISNUMBER(D31),D31,C31) -> 50 | F31: Enter 0, 50, or 100 only when correcting the provisional text coding.
A32: DataCite | C32: 0 | E32: =IF(ISNUMBER(D32),D32,C32) -> 0 | F32: Enter 0, 50, or 100 only when correcting the provisional text coding.
A33: Data Stewardship Wizard | B33: Czech Technical University in Prague / ELIXIR-CZ Codevence Solutions | C33: 50 | E33: =IF(ISNUMBER(D33),D33,C33) -> 50 | F33: Enter 0, 50, or 100 only when correcting the provisional text coding.
A34: Dataverse | C34: 0 | E34: =IF(ISNUMBER(D34),D34,C34) -> 0 | F34: Enter 0, 50, or 100 only when correcting the provisional text coding.
A35: DLCM Backend | B35: University of Geneva (https://www.unige.ch/) HEG, HES-SO (https://www.hesge.ch/heg/en) UNIFR (https://www.unifr.ch/home/en/) BFH (https://www.bfh.ch/en/) OLOS (https://olos.swiss/) | C35: 50 | E35: =IF(ISNUMBER(D35),D35,C35) -> 50 | F35: Enter 0, 50, or 100 only when correcting the provisional text coding.
A36: DLCM Portal | B36: University of Geneva (https://www.unige.ch/)HEG, HES-SO (https://www.hesge.ch/heg/en)UNIFR (https://www.unifr.ch/home/en/)BFH (https://www.bfh.ch/en/)OLOS (https://olos.swiss/) | C36: 50 | E36: =IF(ISNUMBER(D36),D36,C36) -> 50 | F36: Enter 0, 50, or 100 only when correcting the provisional text coding.
A37: DMP Tool | C37: 0 | E37: =IF(ISNUMBER(D37),D37,C37) -> 0 | F37: Enter 0, 50, or 100 only when correcting the provisional text coding.
A38: DOAJ (Directory of Open Access Journals) | C38: 0 | E38: =IF(ISNUMBER(D38),D38,C38) -> 0 | F38: Enter 0, 50, or 100 only when correcting the provisional text coding.
A39: dokieli | C39: 0 | E39: =IF(ISNUMBER(D39),D39,C39) -> 0 | F39: Enter 0, 50, or 100 only when correcting the provisional text coding.
A40: Dryad | C40: 0 | E40: =IF(ISNUMBER(D40),D40,C40) -> 0 | F40: Enter 0, 50, or 100 only when correcting the provisional text coding.
...

Sheet Affiliation Coding
A1: Service | B1: Raw 058 affiliation text | C1: Provisional score | D1: Coding rationale | E1: Override score | F1: Final score | G1: Review note
A2: 2i2c | C2: 0 | D2: Blank: zero under the agreed unavailable-data rule | F2: =Verification!E2 -> 0 | G2: Use the override in Verification; this sheet mirrors the active score.
A3: Academic Preservation Trust (APTrust) | B3: University of Virginia | C3: 50 | D3: Substantive affiliation or membership reported; level of operational support not established | F3: =Verification!E3 -> 50 | G3: Use the override in Verification; this sheet mirrors the active score.
A4: AfricArXiv | B4: Access 2 Perspectives coordinates AfricArXiv’s operations. This includes managing day-to-day activities, overseeing submission processes, ensuring quality control, and facilitating the integration of AfricArXiv with other scholarly services | C4: 100 | D4: Explicit host or operational/financial support language | F4: =Verification!E4 -> 100 | G4: Use the override in Verification; this sheet mirrors the active score.
A5: Arches Heritage Data Management Platform | B5: Getty Conservation Institute Farallon Geographics | C5: 50 | D5: Substantive affiliation or membership reported; level of operational support not established | F5: =Verification!E5 -> 50 | G5: Use the override in Verification; this sheet mirrors the active score.
A6: Archipelago Commons | C6: 0 | D6: Blank: zero under the agreed unavailable-data rule | F6: =Verification!E6 -> 0 | G6: Use the override in Verification; this sheet mirrors the active score.
A7: Archival Resource Key | C7: 0 | D7: Blank: zero under the agreed unavailable-data rule | F7: =Verification!E7 -> 0 | G7: Use the override in Verification; this sheet mirrors the active score.
A8: Archivematica | B8: No Affiliations | C8: 0 | D8: Explicit absence or placeholder | F8: =Verification!E8 -> 0 | G8: Use the override in Verification; this sheet mirrors the active score.
A9: ArchivesSpace | B9: New York University and the University of California San Diego are the founding partners and have permanent seats on the Board; Lyrasis is the organizational home | C9: 100 | D9: Explicit host or operational/financial support language | F9: =Verification!E9 -> 100 | G9: Use the override in Verification; this sheet mirrors the active score.
A10: ARGOS | B10: Athena Research Center (ARC) Communication & Information Technologies Experts (CITE) | C10: 50 | D10: Substantive affiliation or membership reported; level of operational support not established | F10: =Verification!E10 -> 50 | G10: Use the override in Verification; this sheet mirrors the active score.
A11: arXiv | C11: 0 | D11: Blank: zero under the agreed unavailable-data rule | F11: =Verification!E11 -> 0 | G11: Use the override in Verification; this sheet mirrors the active score.
A12: AtoM | B12: No affiliations | C12: 0 | D12: Explicit absence or placeholder | F12: =Verification!E12 -> 0 | G12: Use the override in Verification; this sheet mirrors the active score.
A13: Avalon Media System | B13: Indiana University Libraries | C13: 50 | D13: Substantive affiliation or membership reported; level of operational support not established | F13: =Verification!E13 -> 50 | G13: Use the override in Verification; this sheet mirrors the active score.
A14: Biodiversity Heritage Library | B14: BHL’s fiscal sponsor is the Council on Library and Information Resources (CLIR). | C14: 100 | D14: Explicit host or operational/financial support language | F14: =Verification!E14 -> 100 | G14: Use the override in Verification; this sheet mirrors the active score.
A15: bioRxiv | C15: 0 | D15: Blank: zero under the agreed unavailable-data rule | F15: =Verification!E15 -> 0 | G15: Use the override in Verification; this sheet mirrors the active score.
A16: BitCurator Environment | B16: BitCurator Consortium is administratively hosted by the Open Library Foundation. | C16: 100 | D16: Explicit host or operational/financial support language | F16: =Verification!E16 -> 100 | G16: Use the override in Verification; this sheet mirrors the active score.
A17: Blacklight | B17: See website | C17: 0 | D17: Explicit absence or placeholder | F17: =Verification!E17 -> 0 | G17: Use the override in Verification; this sheet mirrors the active score.
A18: BrCRIS | C18: 0 | D18: Blank: zero under the agreed unavailable-data rule | F18: =Verification!E18 -> 0 | G18: Use the override in Verification; this sheet mirrors the active score.
A19: Browsertrix | B19: No affiliations have direct involvement in governing or running our products except us. We are members of the International Internet Preservation Consortium (IIPC). | C19: 50 | D19: Substantive affiliation or membership reported; level of operational support not established | F19: =Verification!E19 -> 50 | G19: Use the override in Verification; this sheet mirrors the active score.
A20: CLOCKSS | B20: n/a | C20: 0 | D20: Explicit absence or placeholder | F20: =Verification!E20 -> 0 | G20: Use the override in Verification; this sheet mirrors the active score.
A21: COAR International Repository Directory (IRD) | B21: Responsible Organisations: https://ird.coar-repositories.org/about?lang=en | C21: 50 | D21: Substantive affiliation or membership reported; level of operational support not established | F21: =Verification!E21 -> 50 | G21: Use the override in Verification; this sheet mirrors the active score.
A22: COAR Notify | B22: No affiliations. | C22: 0 | D22: Explicit absence or placeholder | F22: =Verification!E22 -> 0 | G22: Use the override in Verification; this sheet mirrors the active score.
A23: CollectiveAccess | B23: No affiliations | C23: 0 | D23: Explicit absence or placeholder | F23: =Verification!E23 -> 0 | G23: Use the override in Verification; this sheet mirrors the active score.
A24: CORE | C24: 0 | D24: Blank: zero under the agreed unavailable-data rule | F24: =Verification!E24 -> 0 | G24: Use the override in Verification; this sheet mirrors the active score.
A25: COUNTER Code of Practice | C25: 0 | D25: Blank: zero under the agreed unavailable-data rule | F25: =Verification!E25 -> 0 | G25: Use the override in Verification; this sheet mirrors the active score.
A26: Creative Commons Licenses | C26: 0 | D26: Blank: zero under the agreed unavailable-data rule | F26: =Verification!E26 -> 0 | G26: Use the override in Verification; this sheet mirrors the active score.
A27: Crossref Metadata Retrieval | C27: 0 | D27: Blank: zero under the agreed unavailable-data rule | F27: =Verification!E27 -> 0 | G27: Use the override in Verification; this sheet mirrors the active score.
A28: D4Science Infrastructure | B28: D4Science is managed by the Italian National Research Council (CNR). Its headquarters are hosted by CNR's Institute of Information Science and Technologies "A. Faedo" (CNR-ISTI) in Pisa, Tuscany, Italy. | C28: 100 | D28: Explicit host or operational/financial support language | F28: =Verification!E28 -> 100 | G28: Use the override in Verification; this sheet mirrors the active score.
A29: DART (Digital Archivist's Resource Tool) | B29: University of Virginia | C29: 50 | D29: Substantive affiliation or membership reported; level of operational support not established | F29: =Verification!E29 -> 50 | G29: Use the override in Verification; this sheet mirrors the active score.
A30: Database Information System | B30: DBIS is operated by the University Library of Regensburg. | C30: 50 | D30: Substantive affiliation or membership reported; level of operational support not established | F30: =Verification!E30 -> 50 | G30: Use the override in Verification; this sheet mirrors the active score.
A31: Data Citation Corpus | B31: DataCite leads the development of the Data Citation Corpus as part of Make Data Count activities. | C31: 50 | D31: Substantive affiliation or membership reported; level of operational support not established | F31: =Verification!E31 -> 50 | G31: Use the override in Verification; this sheet mirrors the active score.
A32: DataCite | C32: 0 | D32: Blank: zero under the agreed unavailable-data rule | F32: =Verification!E32 -> 0 | G32: Use the override in Verification; this sheet mirrors the active score.
A33: Data Stewardship Wizard | B33: Czech Technical University in Prague / ELIXIR-CZ Codevence Solutions | C33: 50 | D33: Substantive affiliation or membership reported; level of operational support not established | F33: =Verification!E33 -> 50 | G33: Use the override in Verification; this sheet mirrors the active score.
A34: Dataverse | C34: 0 | D34: Blank: zero under the agreed unavailable-data rule | F34: =Verification!E34 -> 0 | G34: Use the override in Verification; this sheet mirrors the active score.
A35: DLCM Backend | B35: University of Geneva (https://www.unige.ch/) HEG, HES-SO (https://www.hesge.ch/heg/en) UNIFR (https://www.unifr.ch/home/en/) BFH (https://www.bfh.ch/en/) OLOS (https://olos.swiss/) | C35: 50 | D35: Substantive affiliation or membership reported; level of operational support not established | F35: =Verification!E35 -> 50 | G35: Use the override in Verification; this sheet mirrors the active score.
A36: DLCM Portal | B36: University of Geneva (https://www.unige.ch/)HEG, HES-SO (https://www.hesge.ch/heg/en)UNIFR (https://www.unifr.ch/home/en/)BFH (https://www.bfh.ch/en/)OLOS (https://olos.swiss/) | C36: 50 | D36: Substantive affiliation or membership reported; level of operational support not established | F36: =Verification!E36 -> 50 | G36: Use the override in Verification; this sheet mirrors the active score.
A37: DMP Tool | C37: 0 | D37: Blank: zero under the agreed unavailable-data rule | F37: =Verification!E37 -> 0 | G37: Use the override in Verification; this sheet mirrors the active score.
A38: DOAJ (Directory of Open Access Journals) | C38: 0 | D38: Blank: zero under the agreed unavailable-data rule | F38: =Verification!E38 -> 0 | G38: Use the override in Verification; this sheet mirrors the active score.
A39: dokieli | C39: 0 | D39: Blank: zero under the agreed unavailable-data rule | F39: =Verification!E39 -> 0 | G39: Use the override in Verification; this sheet mirrors the active score.
A40: Dryad | C40: 0 | D40: Blank: zero under the agreed unavailable-data rule | F40: =Verification!E40 -> 0 | G40: Use the override in Verification; this sheet mirrors the active score.
...

Sheet Coverage
A1: Service | B1: M1 observed | C1: M2 observed | D1: 054 staff observed | E1: 055 volunteer observed | F1: H1 observed (either field) | G1: I2 observed | H1: O1 observed | I1: Available metrics (of 5) | J1: Observed coverage | K1: Observed-only mean | L1: Zero-filled final score
A2: 2i2c | B2: 1 | C2: 1 | D2: 0 | E2: 0 | F2: 0 | G2: 0 | H2: 0 | I2: 2 | J2: 0.4 | K2: 100 | L2: 40
A3: Academic Preservation Trust (APTrust) | B3: 1 | C3: 1 | D3: 1 | E3: 0 | F3: 1 | G3: 1 | H3: 1 | I3: 5 | J3: 1 | K3: 75 | L3: 72.5
A4: AfricArXiv | B4: 1 | C4: 1 | D4: 1 | E4: 1 | F4: 1 | G4: 1 | H4: 0 | I4: 4 | J4: 0.8 | K4: 81.25 | L4: 65
A5: Arches Heritage Data Management Platform | B5: 1 | C5: 1 | D5: 0 | E5: 0 | F5: 0 | G5: 1 | H5: 1 | I5: 4 | J5: 0.8 | K5: 87.5 | L5: 70
A6: Archipelago Commons | B6: 1 | C6: 1 | D6: 0 | E6: 0 | F6: 0 | G6: 0 | H6: 1 | I6: 3 | J6: 0.6 | K6: 100 | L6: 60
A7: Archival Resource Key | B7: 1 | C7: 1 | D7: 0 | E7: 0 | F7: 0 | G7: 0 | H7: 0 | I7: 2 | J7: 0.4 | K7: 77.777778 | L7: 31.111111
A8: Archivematica | B8: 1 | C8: 1 | D8: 1 | E8: 0 | F8: 1 | G8: 1 | H8: 1 | I8: 5 | J8: 1 | K8: 80 | L8: 70
A9: ArchivesSpace | B9: 1 | C9: 1 | D9: 1 | E9: 0 | F9: 1 | G9: 1 | H9: 1 | I9: 5 | J9: 1 | K9: 90 | L9: 85
A10: ARGOS | B10: 1 | C10: 1 | D10: 0 | E10: 0 | F10: 0 | G10: 1 | H10: 1 | I10: 4 | J10: 0.8 | K10: 87.5 | L10: 70
A11: arXiv | B11: 1 | C11: 1 | D11: 0 | E11: 0 | F11: 0 | G11: 0 | H11: 0 | I11: 2 | J11: 0.4 | K11: 100 | L11: 40
A12: AtoM | B12: 1 | C12: 1 | D12: 1 | E12: 0 | F12: 1 | G12: 1 | H12: 1 | I12: 5 | J12: 1 | K12: 80 | L12: 70
A13: Avalon Media System | B13: 1 | C13: 1 | D13: 1 | E13: 0 | F13: 1 | G13: 1 | H13: 1 | I13: 5 | J13: 1 | K13: 55 | L13: 52.5
... A113: Zotero | B113: 1 | C113: 1 | D113: 0 | E113: 0 | F113: 0 | G113: 1 | H113: 1 | I113: 4 | J113: 0.8 | K113: 75 | L113: 60

Sheet Diagnostics
A1: Code | B1: Metric | C1: Source field(s) | D1: Observed n | E1: Observed coverage | F1: Mean among observed | G1: Mean under zero-fill | H1: SD among observed | I1: % zero among observed | J1: Coverage definition / reading
A2: M1 | B2: Technology readiness | C2: 079 | D2: 112 | E2: 1 | F2: 98.511905 | G2: 98.511905 | H2: 7.3486396 | I2: 0 | J2: A recognized readiness category is present.
A3: M2 | B3: Maintenance status | C3: 080 | D3: 111 | E3: 0.99107143 | F3: 99.099099 | G3: 98.214286 | H3: 6.6508212 | I3: 0 | J3: A recognized active/minimal/inactive/not-maintained response is present.
A4: H1 | B4: Human-resource capacity | C4: 054 + 055 | D4: 56 | E4: 0.5 | F4: 38.839286 | G4: 15.066964 | H4: 25.186644 | I4: 0.017857143 | J4: At least one staffing field has a recognized range; observed-only H1 averages only reported staffing fields.
A5: I2 | B5: Institutional affiliations and support | C5: 058 | D5: 59 | E5: 0.52678571 | F5: 48.305085 | G5: 25.446429 | H5: 27.56518 | I5: 0.16949153 | J5: A substantive affiliation or explicit no-affiliation response is present; blank, unknown, and placeholders are unavailable.
A6: O1 | B6: Hosted/service-delivery capacity | C6: 076 | D6: 62 | E6: 0.55357143 | F6: 88.709677 | G6: 49.107143 | H6: 31.647447 | I6: 0.11290323 | J6: A hosted route or explicit 'No services available' response is present; N/A and Unknown are unavailable.
A8: Interpretation | B8: Observed coverage is descriptive only and does not determine whether an entry receives a score.
A9: Zero-filled mean | B9: Mean under zero-fill uses the final scoring rule, including zero for unavailable values and a fixed denominator.
A10: Observed-only mean | B10: Excludes unavailable metrics and has a variable denominator; it is not the final equal-weight score.

Sheet Calc
A1: Service | B1: M1 Technology readiness | C1: M2 Maintenance | D1: Full-time staffing subscore | E1: Volunteer staffing subscore | F1: H1 Human resources | G1: I2 Provisional affiliations | H1: I2 rationale | I1: O1 Service delivery | J1: Python-checked total | K1: Scoring flags
A2: 2i2c | B2: 100 | C2: 100 | D2: 0 | E2: 0 | F2: 0 | G2: 0 | H2: Blank: zero under the agreed unavailable-data rule | I2: 0 | J2: 40 | K2: Full-time staffing missing/unknown scored 0; Volunteer staffing missing/unknown scored 0; Service-delivery field not applicable/unknown scored 0
A3: Academic Preservation Trust (APTrust) | B3: 100 | C3: 100 | D3: 25 | E3: 0 | F3: 12.5 | G3: 50 | H3: Substantive affiliation or membership reported; level of operational support not established | I3: 100 | J3: 72.5 | K3: Volunteer staffing missing/unknown scored 0; Review affiliation coding; override available
A4: AfricArXiv | B4: 100 | C4: 100 | D4: 25 | E4: 25 | F4: 25 | G4: 100 | H4: Explicit host or operational/financial support language | I4: 0 | J4: 65 | K4: Review affiliation coding; override available; Service-delivery field not applicable/unknown scored 0
A5: Arches Heritage Data Management Platform | B5: 100 | C5: 100 | D5: 0 | E5: 0 | F5: 0 | G5: 50 | H5: Substantive affiliation or membership reported; level of operational support not established | I5: 100 | J5: 70 | K5: Full-time staffing missing/unknown scored 0; Volunteer staffing missing/unknown scored 0; Review affiliation coding; override available
A6: Archipelago Commons | B6: 100 | C6: 100 | D6: 0 | E6: 0 | F6: 0 | G6: 0 | H6: Blank: zero under the agreed unavailable-data rule | I6: 100 | J6: 60 | K6: Full-time staffing missing/unknown scored 0; Volunteer staffing missing/unknown scored 0
A7: Archival Resource Key | B7: 55.555556 | C7: 100 | D7: 0 | E7: 0 | F7: 0 | G7: 0 | H7: Blank: zero under the agreed unavailable-data rule | I7: 0 | J7: 31.111111 | K7: Full-time staffing missing/unknown scored 0; Volunteer staffing missing/unknown scored 0; Service-delivery field not applicable/unknown scored 0
A8: Archivematica | B8: 100 | C8: 100 | D8: 100 | E8: 0 | F8: 50 | G8: 0 | H8: Explicit absence or placeholder | I8: 100 | J8: 70 | K8: Volunteer staffing missing/unknown scored 0; Review affiliation coding; override available
A9: ArchivesSpace | B9: 100 | C9: 100 | D9: 50 | E9: 0 | F9: 25 | G9: 100 | H9: Explicit host or operational/financial support language | I9: 100 | J9: 85 | K9: Volunteer staffing missing/unknown scored 0; Review affiliation coding; override available
A10: ARGOS | B10: 100 | C10: 100 | D10: 0 | E10: 0 | F10: 0 | G10: 50 | H10: Substantive affiliation or membership reported; level of operational support not established | I10: 100 | J10: 70 | K10: Full-time staffing missing/unknown scored 0; Volunteer staffing missing/unknown scored 0; Review affiliation coding; override available
A11: arXiv | B11: 100 | C11: 100 | D11: 0 | E11: 0 | F11: 0 | G11: 0 | H11: Blank: zero under the agreed unavailable-data rule | I11: 0 | J11: 40 | K11: Full-time staffing missing/unknown scored 0; Volunteer staffing missing/unknown scored 0; Service-delivery field not applicable/unknown scored 0
A12: AtoM | B12: 100 | C12: 100 | D12: 100 | E12: 0 | F12: 50 | G12: 0 | H12: Explicit absence or placeholder | I12: 100 | J12: 70 | K12: Review affiliation coding; override available
A13: Avalon Media System | B13: 100 | C13: 100 | D13: 25 | E13: 0 | F13: 12.5 | G13: 50 | H13: Substantive affiliation or membership reported; level of operational support not established | I13: 0 | J13: 52.5 | K13: Volunteer staffing missing/unknown scored 0; Review affiliation coding; override available
... A36: DLCM Portal | B36: 100 | C36: 100 | D36: 25 | E36: 25 | F36: 25 | G36: 50 | H36: Substantive affiliation or membership reported; level of operational support not established | I36: 100 | J36: 75 | K36: Review affiliation coding; override available
A37: DMP Tool | B37: 100 | C37: 100 | D37: 25 | E37: 0 | F37: 12.5 | G37: 0 | H37: Blank: zero under the agreed unavailable-data rule | I37: 100 | J37: 62.5
A38: DOAJ (Directory of Open Access Journals) | B38: 100 | C38: 100 | D38: 0 | E38: 0 | F38: 0 | G38: 0 | H38: Blank: zero under the agreed unavailable-data rule | I38: 0 | J38: 40 | K38: Full-time staffing missing/unknown scored 0; Volunteer staffing missing/unknown scored 0; Service-delivery field not applicable/unknown scored 0
