Workbook

Sheet Method
A1: OISI Component 3 - Organizational Capacity: scoring workbook
A2: Source: OISI_112_Organizational_Capacity_Verification.xlsx (112 services, Infra Finder v3) + 03_Organizational_Capacity_OISI.docx (specification).
A4: HOW A SCORE IS BUILT
A5: 1. 079 technology readiness: TRL ratio (TRL5 0.56, TRL8 0.89, TRL9 1.00). 080 maintenance: Active 1, Minimal 0.5, Unknown NA.
A6: 2. 056 age: (as-of year minus launch year), capped at 15 years and divided by the cap, so age gives a small bounded credit (5%).
A7: 3. 058 affiliations: manual code (column H) - 1 named affiliation/support, 0 explicit "No affiliations", blank if not provided or uninformative. Count of affiliations is not rewarded. 099 SCOSS: TRUE 1 / FALSE 0.
A8: 4. 076 SaaS: any hosted channel 1, none 0, Not applicable / Unknown NA. 077 providers: 1 if a provider list exists; 0 if 076 lists third-party vendors but no provider list; otherwise NA. 077 sits in ONE sub-component (Operational) to meet the no-double-counting rule.
A9: 5. Sub-component = weighted mean of observed metrics, but only if >= 50% of its applicable weight is observed. Component = 100 x weighted mean of available sub-components (Maturity 50, Institutional 30, Operational 20).
A10: 6. Published only if completeness (observed / applicable weight) >= 70% and at least 2 sub-components exist. "Sub-components used" shows each repo's basis (M, I, O). RESULT: 109 of 112 repos (97%) get a score (v1 spec design: 85). Withheld: Europe PMC, OpenEdition and ROR, which lack enough observed data across sub-components. Set Parameters!B37 = 1 to publish Maturity-only scores anyway.
A12: DECISIONS YOU SHOULD CONFIRM BEFORE PUBLISHING
A13: A. 077 placement. Spec lists 077 in both Institutional Support (10%) and Operational Capacity (10%) and requires one. I kept it in Operational. Parameters!F12 switches placement (rho 0.96 if moved).
A14: E. SPEC AMENDMENT - new metric 051 institutional host (10 pts, Institutional Support). Your spec lists business form as descriptive only. I scored it because it is the most complete (106/112 usable) variable describing institutional backing: non-profit or fiscal sponsorship 1, commercial 0.5, volunteer community 0, Other NA. 058 drops from 15 to 10 pts. Set Parameters!H10 = 0 to return to the original spec; Sensitivity compares both (rho 0.81).
... A23: - verification_status / verification_notes are empty, so every value is self-reported Infra Finder data, not independently verified.

Sheet Parameters
A1: OISI Component 3 - Organizational Capacity: scoring parameters
A2: Blue = editable input. Every score on the "Scores" sheet recalculates from these cells.
A4: Category label | B4: Score (0-1) | C4: Variable / rationale | E4: Variable | F4: Sub-component | G4: Weight (pts of 100) | H4: Column in data? (1/0) | I4: Effective weight | J4: Justification
A5: Actual system proven in operational environment | B5: =9/9 -> 1 | C5: 079: TRL 9 | E5: 079_technology_readiness | F5: Maturity | G5: 20 | H5: 1 | I5: =G5*H5 -> 20 | J5: Core. 95% of repos are at the top category: near-constant (see Diagnostics).
A6: System complete and qualified | B6: =8/9 -> 0.88888889 | C6: 079: TRL 8 | E6: 080_maintenance_status | F6: Maturity | G6: 25 | H6: 1 | I6: =G6*H6 -> 25 | J6: Core. 97% Actively Maintained: near-constant. Unknown = NA.
A7: Technology validated in relevant environment | B7: =5/9 -> 0.55555556 | C7: 079: TRL 5 (ratio TRL/9 keeps the ordinal spacing) | E7: 056_launch_date | F7: Maturity | G7: 5 | H7: 1 | I7: =G7*H7 -> 5 | J7: Age normalised and capped (Settings) so old age cannot dominate. Year-only precision.
A8: Actively Maintained | B8: 1 | C8: 080 | E8: 058_affiliations | F8: Institutional | G8: 10 | H8: 1 | I8: =G8*H8 -> 10 | J8: Presence of a named affiliation (manual code, column H); number of affiliations is NOT rewarded.
A9: Minimally Maintained | B9: 0.5 | C9: 080: intermediate score (spec); value is a judgement | E9: 099_scoss | F9: Institutional | G9: 5 | H9: 1 | I9: =G9*H9 -> 5 | J9: SCOSS TRUE=1, FALSE=0. Only 7 repos TRUE.
A10: TRUE | B10: 1 | C10: 099 SCOSS participation | E10: 051_business_form | F10: Institutional | G10: 10 | H10: 1 | I10: =G10*H10 -> 10 | J10: NEW (amends spec): institutional host = non-profit / fiscal sponsorship 1, commercial 0.5, volunteer 0, Other NA. 95% coverage (106/112; Other = NA), fixes the Institutional gap left by sparse 058.
A11: FALSE | B11: 0 | C11: 099 no participation | E11: 076_saas_options | F11: Operational | G11: 10 | H11: 1 | I11: =G11*H11 -> 10 | J11: Any hosted/SaaS channel = 1; none = 0; Not applicable / Unknown = NA.
A12: No services available | B12: 0 | C12: 076 | E12: 077_registered_service_providers | F12: Operational | G12: 10 | H12: 1 | I12: =G12*H12 -> 10 | J12: Single placement (spec requires no double counting). Operational: provider ecosystem is a service-delivery feature. Change here to test Institutional.
A13: Through solution provider only | B13: 1 | C13: 076: availability scored, not provider type
A14: Through solution provider or third party vendor | B14: 1 | C14: 076 | E14: Sub-component | F14: Weight
A15: Through third party vendor only | B15: 1 | C15: 076 | E15: Maturity | F15: 0.5
A16: Unknown | B16: NA | C16: missing | E16: Institutional | F16: 0.3
A17: Not applicable | B17: NA | C17: missing / structurally not applicable | E17: Operational | F17: 0.2
A18: Non-profit organization | B18: 1 | C18: 051 institutional host: formal non-profit | E18: Check: sum | F18: =SUM(F15:F17) -> 1
A19: Fiscal sponsorship (academic institution) | B19: 1 | C19: 051: hosted by an academic institution
A20: Fiscal sponsorship (non-profit) | B20: 1 | C20: 051: hosted by a non-profit
A21: Fiscal sponsorship (non-profit) | Non-profit organization | B21: 1 | C21: 051
A22: Commercial (for-profit) | B22: 0.5 | C22: 051: organisational backing, but not public/institutional host (judgement)
A23: Volunteer community | B23: 0 | C23: 051: no legal/institutional host
A26: Third-party service categories (077 applicable when 076 is one of these)
A27: Through solution provider or third party vendor
A28: Through third party vendor only
A31: Settings
A32: As-of year for infrastructure age | B32: 2026
A33: Age cap (years): full credit at or above this age | B33: 15
A34: Blank 058_affiliations scored as (0 or NA) | B34: NA
A35: Minimum completeness to publish a score | B35: 0.7
A36: Minimum share of a sub-component's applicable weight that must be observed | B36: 0.5
A37: Minimum number of sub-components needed | B37: 2
A39: Design notes. (1) Blank 058 stays NA (not 0) because the field has an explicit absence value ("No affiliations", 10 repos): blank therefore means not provided. This differs from the Governance component, where the blank-as-absent rule was used because no explicit absence value existed. (2) A sub-component is scored only if >= 50% of its applicable weight is observed (prevents scoring a sub-component on SCOSS alone). (3) 077 is scored 1 if a provider list exists; 0 if third-party vendors are listed in 076 but no provider list is given; NA otherwise (where no third-party ecosystem is expected).

Sheet Scores
A1: Service | B1: Provider | C1: Solution category | D1: 079 Technology readiness | E1: 080 Maintenance status | F1: 056 Launch date | G1: 058 Affiliations (text) | H1: 058 manual code (1 named / 0 none / blank n.a.) | I1: 099 SCOSS | J1: 076 SaaS options | K1: 077 Registered service providers | L1: 051 Business form (institutional host, scored) | M1: 061 Primary funding (descriptive) | N1: 054 Staffing FT (descriptive) | O1: 055 Staffing volunteer (descriptive) | P1: s079 | Q1: s080 | R1: s056 | S1: s058 | T1: s099 | U1: s051 | V1: s076 | W1: s077 | X1: app076 | Y1: app077 | Z1: Maturity (0-1) | AA1: Institutional (0-1) | AB1: Operational (0-1) | AC1: Weight observed | AD1: Weight applicable | AE1: Completeness | AF1: Sub-components used | AG1: Org capacity score (0-100) | AH1: Rank
A2: 2i2c | B2: Code for Science and Society | C2: Authoring tool | D2: Actual system proven in operational environment | E2: Actively Maintained | F2: 2020-01-01 | I2: FALSE | J2: Not applicable | L2: Fiscal sponsorship (non-profit) | M2: Contributions | P2: =IFERROR(IF(ISNUMBER(INDEX(Parameters!$B$5:$B$23,MATCH(D2,Parameters!$A$5:$A$23,0))),INDEX(Parameters!$B$5:$B$23,MATCH(D2,Parameters!$A$5:$A$23,0)),""),"") -> 1 | Q2: =IFERROR(IF(ISNUMBER(INDEX(Parameters!$B$5:$B$23,MATCH(E2,Parameters!$A$5:$A$23,0))),INDEX(Parameters!$B$5:$B$23,MATCH(E2,Parameters!$A$5:$A$23,0)),""),"") -> 1 | R2: =IF(F2="","",IFERROR(MIN(Parameters!$B$33,MAX(0,Parameters!$B$32-VALUE(LEFT(F2,4))))/Parameters!$B$33,"")) -> 0.4 | S2: =IF(ISNUMBER(H2),H2,IF(G2="",IF(ISNUMBER(Parameters!$B$34),Parameters!$B$34,""),"")) | T2: =IFERROR(IF(ISNUMBER(INDEX(Parameters!$B$5:$B$23,MATCH(I2,Parameters!$A$5:$A$23,0))),INDEX(Parameters!$B$5:$B$23,MATCH(I2,Parameters!$A$5:$A$23,0)),""),"") -> 0 | U2: =IFERROR(IF(ISNUMBER(INDEX(Parameters!$B$5:$B$23,MATCH(L2,Parameters!$A$5:$A$23,0))),INDEX(Parameters!$B$5:$B$23,MATCH(L2,Parameters!$A$5:$A$23,0)),""),"") -> 1 | V2: =IFERROR(IF(ISNUMBER(INDEX(Parameters!$B$5:$B$23,MATCH(J2,Parameters!$A$5:$A$23,0))),INDEX(Parameters!$B$5:$B$23,MATCH(J2,Parameters!$A$5:$A$23,0)),""),"") | W2: =IF(K2<>"",1,IF(COUNTIF(Parameters!$A$27:$A$28,J2)>0,0,"")) | X2: =IF(J2="Not applicable",0,1) -> 0 | Y2: =IF(OR(K2<>"",COUNTIF(Parameters!$A$27:$A$28,J2)>0),1,0) -> 0 | Z2: =IF(((Parameters!$F$5=Parameters!$E$15)*Parameters!$I$5*1+(Parameters!$F$6=Parameters!$E$15)*Parameters!$I$6*1+(Parameters!$F$7=Parameters!$E$15)*Parameters!$I$7*1+(Parameters!$F$8=Parameters!$E$15)*Parameters!$I$8*1+(Parameters!$F$9=Parameters!$E$15)*Parameters!$I$9*1+(Parameters!$F$10=Parameters!$E$15)*Parameters!$I$10*1+(Parameters!$F$11=Parameters!$E$15)*Parameters!$I$11*X2+(Parameters!$F$12=Parameters!$E$15)*Parameters!$I$12*Y2)=0,"",IF(AND(((Parameters!$F$5=Parameters!$E$15)*Parameters!$I$5*ISNUMBER(P2)+(Parameters!$F$6=Parameters!$E$15)*Parameters!$I$6*ISNUMBER(Q2)+(Parameters!$F$7=Parameters!$E$15)*Parameters!$I$7*ISNUMBER(R2)+(Parameters!$F$8=Parameters!$E$15)*Parameters!$I$8*ISNUMBER(S2)+(Parameters!$F$9=Parameters!$E$15)*Parameters!$I$9*ISNUMBER(T2)+(Parameters!$F$10=Parameters!$E$15)*Parameters!$I$10*ISNUMBER(U2)+(Parameters!$F$11=Parameters!$E$15)*Parameters!$I$11*ISNUMBER(V2)+(Parameters!$F$12=Parameters!$E$15)*Parameters!$I$12*ISNUMBER(W2))>0,((Parameters!$F$5=Parameters!$E$15)*Parameters!$I$5*ISNUMBER(P2)+(Parameters!$F$6=Parameters!$E$15)*Parameters!$I$6*ISNUMBER(Q2)+(Parameters!$F$7=Parameters!$E$15)*Parameters!$I$7*ISNUMBER(R2)+(Parameters!$F$8=Parameters!$E$15)*Parameters!$I$8*ISNUMBER(S2)+(Parameters!$F$9=Parameters!$E$15)*Parameters!$I$9*ISNUMBER(T2)+(Parameters!$F$10=Parameters!$E$15)*Parameters!$I$10*ISNUMBER(U2)+(Parameters!$F$11=Parameters!$E$15)*Parameters!$I$11*ISNUMBER(V2)+(Parameters!$F$12=Parameters!$E$15)*Parameters!$I$12*ISNUMBER(W2))/((Parameters!$F$5=Parameters!$E$15)*Parameters!$I$5*1+(Parameters!$F$6=Parameters!$E$15)*Parameters!$I$6*1+(Parameters!$F$7=Parameters!$E$15)*Parameters!$I$7*1+(Parameters!$F$8=Parameters!$E$15)*Parameters!$I$8*1+(Parameters!$F$9=Parameters!$E$15)*Parameters!$I$9*1+(Parameters!$F$10=Parameters!$E$15)*Parameters!$I$10*1+(Parameters!$F$11=Parameters!$E$15)*Parameters!$I$11*X2+(Parameters!$F$12=Parameters!$E$15)*Parameters!$I$12*Y2)>=Parameters!$B$36),((Parameters!$F$5=Parameters!$E$15)*Parameters!$I$5*N(P2)+(Parameters!$F$6=Parameters!$E$15)*Parameters!$I$6*N(Q2)+(Parameters!$F$7=Parameters!$E$15)*Parameters!$I$7*N(R2)+(Parameters!$F$8=Parameters!$E$15)*Parameters!$I$8*N(S2)+(Parameters!$F$9=Parameters!$E$15)*Parameters!$I$9*N(T2)+(Parameters!$F$10=Parameters!$E$15)*Parameters!$I$10*N(U2)+(Parameters!$F$11=Parameters!$E$15)*Parameters!$I$11*N(V2)+(Parameters!$F$12=Parameters!$E$15)*Parameters!$I$12*N(W2))/((Parameters!$F$5=Parameters!$E$15)*Parameters!$I$5*ISNUMBER(P2)+(Parameters!$F$6=Parameters!$E$15)*Parameters!$I$6*ISNUMBER(Q2)+(Parameters!$F$7=Parameters!$E$15)*Parameters!$I$7*ISNUMBER(R2)+(Parameters!$F$8=Parameters!$E$15)*Parameters!$I$8*ISNUMBER(S2)+(Parameters!$F$9=Parameters!$E$15)*Parameters!$I$9*ISNUMBER(T2)+(Parameters!$F$10=Parameters!$E$15)*Parameters!$I$10*ISNUMBER(U2)+(Parameters!$F$11=Parameters!$E$15)*Parameters!$I$11*ISNUMBER(V2)+(Parameters!$F$12=Parameters!$E$15)*Parameters!$I$12*ISNUMBER(W2)),"")) -> 0.94 | AA2: =IF(((Parameters!$F$5=Parameters!$E$16)*Parameters!$I$5*1+(Parameters!$F$6=Parameters!$E$16)*Parameters!$I$6*1+(Parameters!$F$7=Parameters!$E$16)*Parameters!$I$7*1+(Parameters!$F$8=Parameters!$E$16)*Parameters!$I$8*1+(Parameters!$F$9=Parameters!$E$16)*Parameters!$I$9*1+(Parameters!$F$10=Parameters!$E$16)*Parameters!$I$10*1+(Parameters!$F$11=Parameters!$E$16)*Parameters!$I$11*X2+(Parameters!$F$12=Parameters!$E$16)*Parameters!$I$12*Y2)=0,"",IF(AND(((Parameters!$F$5=Parameters!$E$16)*Parameters!$I$5*ISNUMBER(P2)+(Parameters!$F$6=Parameters!$E$16)*Parameters!$I$6*ISNUMBER(Q2)+(Parameters!$F$7=Parameters!$E$16)*Parameters!$I$7*ISNUMBER(R2)+(Parameters!$F$8=Parameters!$E$16)*Parameters!$I$8*ISNUMBER(S2)+(Parameters!$F$9=Parameters!$E$16)*Parameters!$I$9*ISNUMBER(T2)+(Parameters!$F$10=Parameters!$E$16)*Parameters!$I$10*ISNUMBER(U2)+(Parameters!$F$11=Parameters!$E$16)*Parameters!$I$11*ISNUMBER(V2)+(Parameters!$F$12=Parameters!$E$16)*Parameters!$I$12*ISNUMBER(W2))>0,((Parameters!$F$5=Parameters!$E$16)*Parameters!$I$5*ISNUMBER(P2)+(Parameters!$F$6=Parameters!$E$16)*Parameters!$I$6*ISNUMBER(Q2)+(Parameters!$F$7=Parameters!$E$16)*Parameters!$I$7*ISNUMBER(R2)+(Parameters!$F$8=Parameters!$E$16)*Parameters!$I$8*ISNUMBER(S2)+(Parameters!$F$9=Parameters!$E$16)*Parameters!$I$9*ISNUMBER(T2)+(Parameters!$F$10=Parameters!$E$16)*Parameters!$I$10*ISNUMBER(U2)+(Parameters!$F$11=Parameters!$E$16)*Parameters!$I$11*ISNUMBER(V2)+(Parameters!$F$12=Parameters!$E$16)*Parameters!$I$12*ISNUMBER(W2))/((Parameters!$F$5=Parameters!$E$16)*Parameters!$I$5*1+(Parameters!$F$6=Parameters!$E$16)*Parameters!$I$6*1+(Parameters!$F$7=Parameters!$E$16)*Parameters!$I$7*1+(Parameters!$F$8=Parameters!$E$16)*Parameters!$I$8*1+(Parameters!$F$9=Parameters!$E$16)*Parameters!$I$9*1+(Parameters!$F$10=Parameters!$E$16)*Parameters!$I$10*1+(Parameters!$F$11=Parameters!$E$16)*Parameters!$I$11*X2+(Parameters!$F$12=Parameters!$E$16)*Parameters!$I$12*Y2)>=Parameters!$B$36),((Parameters!$F$5=Parameters!$E$16)*Parameters!$I$5*N(P2)+(Parameters!$F$6=Parameters!$E$16)*Parameters!$I$6*N(Q2)+(Parameters!$F$7=Parameters!$E$16)*Parameters!$I$7*N(R2)+(Parameters!$F$8=Parameters!$E$16)*Parameters!$I$8*N(S2)+(Parameters!$F$9=Parameters!$E$16)*Parameters!$I$9*N(T2)+(Parameters!$F$10=Parameters!$E$16)*Parameters!$I$10*N(U2)+(Parameters!$F$11=Parameters!$E$16)*Parameters!$I$11*N(V2)+(Parameters!$F$12=Parameters!$E$16)*Parameters!$I$12*N(W2))/((Parameters!$F$5=Parameters!$E$16)*Parameters!$I$5*ISNUMBER(P2)+(Parameters!$F$6=Parameters!$E$16)*Parameters!$I$6*ISNUMBER(Q2)+(Parameters!$F$7=Parameters!$E$16)*Parameters!$I$7*ISNUMBER(R2)+(Parameters!$F$8=Parameters!$E$16)*Parameters!$I$8*ISNUMBER(S2)+(Parameters!$F$9=Parameters!$E$16)*Parameters!$I$9*ISNUMBER(T2)+(Parameters!$F$10=Parameters!$E$16)*Parameters!$I$10*ISNUMBER(U2)+(Parameters!$F$11=Parameters!$E$16)*Parameters!$I$11*ISNUMBER(V2)+(Parameters!$F$12=Parameters!$E$16)*Parameters!$I$12*ISNUMBER(W2)),"")) -> 0.66666667 | AB2: =IF(((Parameters!$F$5=Parameters!$E$17)*Parameters!$I$5*1+(Parameters!$F$6=Parameters!$E$17)*Parameters!$I$6*1+(Parameters!$F$7=Parameters!$E$17)*Parameters!$I$7*1+(Parameters!$F$8=Parameters!$E$17)*Parameters!$I$8*1+(Parameters!$F$9=Parameters!$E$17)*Parameters!$I$9*1+(Parameters!$F$10=Parameters!$E$17)*Parameters!$I$10*1+(Parameters!$F$11=Parameters!$E$17)*Parameters!$I$11*X2+(Parameters!$F$12=Parameters!$E$17)*Parameters!$I$12*Y2)=0,"",IF(AND(((Parameters!$F$5=Parameters!$E$17)*Parameters!$I$5*ISNUMBER(P2)+(Parameters!$F$6=Parameters!$E$17)*Parameters!$I$6*ISNUMBER(Q2)+(Parameters!$F$7=Parameters!$E$17)*Parameters!$I$7*ISNUMBER(R2)+(Parameters!$F$8=Parameters!$E$17)*Parameters!$I$8*ISNUMBER(S2)+(Parameters!$F$9=Parameters!$E$17)*Parameters!$I$9*ISNUMBER(T2)+(Parameters!$F$10=Parameters!$E$17)*Parameters!$I$10*ISNUMBER(U2)+(Parameters!$F$11=Parameters!$E$17)*Parameters!$I$11*ISNUMBER(V2)+(Parameters!$F$12=Parameters!$E$17)*Parameters!$I$12*ISNUMBER(W2))>0,((Parameters!$F$5=Parameters!$E$17)*Parameters!$I$5*ISNUMBER(P2)+(Parameters!$F$6=Parameters!$E$17)*Parameters!$I$6*ISNUMBER(Q2)+(Parameters!$F$7=Parameters!$E$17)*Parameters!$I$7*ISNUMBER(R2)+(Parameters!$F$8=Parameters!$E$17)*Parameters!$I$8*ISNUMBER(S2)+(Parameters!$F$9=Parameters!$E$17)*Parameters!$I$9*ISNUMBER(T2)+(Parameters!$F$10=Parameters!$E$17)*Parameters!$I$10*ISNUMBER(U2)+(Parameters!$F$11=Parameters!$E$17)*Parameters!$I$11*ISNUMBER(V2)+(Parameters!$F$12=Parameters!$E$17)*Parameters!$I$12*ISNUMBER(W2))/((Parameters!$F$5=Parameters!$E$17)*Parameters!$I$5*1+(Parameters!$F$6=Parameters!$E$17)*Parameters!$I$6*1+(Parameters!$F$7=Parameters!$E$17)*Parameters!$I$7*1+(Parameters!$F$8=Parameters!$E$17)*Parameters!$I$8*1+(Parameters!$F$9=Parameters!$E$17)*Parameters!$I$9*1+(Parameters!$F$10=Parameters!$E$17)*Parameters!$I$10*1+(Parameters!$F$11=Parameters!$E$17)*Parameters!$I$11*X2+(Parameters!$F$12=Parameters!$E$17)*Parameters!$I$12*Y2)>=Parameters!$B$36),((Parameters!$F$5=Parameters!$E$17)*Parameters!$I$5*N(P2)+(Parameters!$F$6=Parameters!$E$17)*Parameters!$I$6*N(Q2)+(Parameters!$F$7=Parameters!$E$17)*Parameters!$I$7*N(R2)+(Parameters!$F$8=Parameters!$E$17)*Parameters!$I$8*N(S2)+(Parameters!$F$9=Parameters!$E$17)*Parameters!$I$9*N(T2)+(Parameters!$F$10=Parameters!$E$17)*Parameters!$I$10*N(U2)+(Parameters!$F$11=Parameters!$E$17)*Parameters!$I$11*N(V2)+(Parameters!$F$12=Parameters!$E$17)*Parameters!$I$12*N(W2))/((Parameters!$F$5=Parameters!$E$17)*Parameters!$I$5*ISNUMBER(P2)+(Parameters!$F$6=Parameters!$E$17)*Parameters!$I$6*ISNUMBER(Q2)+(Parameters!$F$7=Parameters!$E$17)*Parameters!$I$7*ISNUMBER(R2)+(Parameters!$F$8=Parameters!$E$17)*Parameters!$I$8*ISNUMBER(S2)+(Parameters!$F$9=Parameters!$E$17)*Parameters!$I$9*ISNUMBER(T2)+(Parameters!$F$10=Parameters!$E$17)*Parameters!$I$10*ISNUMBER(U2)+(Parameters!$F$11=Parameters!$E$17)*Parameters!$I$11*ISNUMBER(V2)+(Parameters!$F$12=Parameters!$E$17)*Parameters!$I$12*ISNUMBER(W2)),"")) | AC2: =Parameters!$I$5*ISNUMBER(P2)+Parameters!$I$6*ISNUMBER(Q2)+Parameters!$I$7*ISNUMBER(R2)+Parameters!$I$8*ISNUMBER(S2)+Parameters!$I$9*ISNUMBER(T2)+Parameters!$I$10*ISNUMBER(U2)+Parameters!$I$11*ISNUMBER(V2)+Parameters!$I$12*ISNUMBER(W2) -> 65 | AD2: =Parameters!$I$5*1+Parameters!$I$6*1+Parameters!$I$7*1+Parameters!$I$8*1+Parameters!$I$9*1+Parameters!$I$10*1+Parameters!$I$11*X2+Parameters!$I$12*Y2 -> 75 | AE2: =IF(AD2=0,"",AC2/AD2) -> 0.86666667 | AF2: =IF(ISNUMBER(Z2),"M","")&IF(ISNUMBER(AA2),"I","")&IF(ISNUMBER(AB2),"O","") -> MI | AG2: =IF(AND(ISNUMBER(AE2),ISNUMBER(Z2)+ISNUMBER(AA2)+ISNUMBER(AB2)>=Parameters!$B$37),IF(AE2>=Parameters!$B$35,100*(Parameters!$F$15*N(Z2)+Parameters!$F$16*N(AA2)+Parameters!$F$17*N(AB2))/(Parameters!$F$15*ISNUMBER(Z2)+Parameters!$F$16*ISNUMBER(AA2)+Parameters!$F$17*ISNUMBER(AB2)),""),"") -> 83.75 | AH2: =IF(ISNUMBER(AG2),RANK(AG2,$AG$2:$AG$113),"") -> 65
A3: Academic Preservation Trust (APTrust) | B3: Academic Preservation Trust (APTrust) | C3: Digital preservation service | D3: Actual system proven in operational environment | E3: Actively Maintained | F3: 2014-01-01 | G3: University of Virginia | H3: 1 | I3: FALSE | J3: Through solution provider only | L3: Fiscal sponsorship (academic institution) | M3: Program service revenue | N3: 1-5 | P3: =IFERROR(IF(ISNUMBER(INDEX(Parameters!$B$5:$B$23,MATCH(D3,Parameters!$A$5:$A$23,0))),INDEX(Parameters!$B$5:$B$23,MATCH(D3,Parameters!$A$5:$A$23,0)),""),"") -> 1 | Q3: =IFERROR(IF(ISNUMBER(INDEX(Parameters!$B$5:$B$23,MATCH(E3,Parameters!$A$5:$A$23,0))),INDEX(Parameters!$B$5:$B$23,MATCH(E3,Parameters!$A$5:$A$23,0)),""),"") -> 1 | R3: =IF(F3="","",IFERROR(MIN(Parameters!$B$33,MAX(0,Parameters!$B$32-VALUE(LEFT(F3,4))))/Parameters!$B$33,"")) -> 0.8 | S3: =IF(ISNUMBER(H3),H3,IF(G3="",IF(ISNUMBER(Parameters!$B$34),Parameters!$B$34,""),"")) -> 1 | T3: =IFERROR(IF(ISNUMBER(INDEX(Parameters!$B$5:$B$23,MATCH(I3,Parameters!$A$5:$A$23,0))),INDEX(Parameters!$B$5:$B$23,MATCH(I3,Parameters!$A$5:$A$23,0)),""),"") -> 0 | U3: =IFERROR(IF(ISNUMBER(INDEX(Parameters!$B$5:$B$23,MATCH(L3,Parameters!$A$5:$A$23,0))),INDEX(Parameters!$B$5:$B$23,MATCH(L3,Parameters!$A$5:$A$23,0)),""),"") -> 1 | V3: =IFERROR(IF(ISNUMBER(INDEX(Parameters!$B$5:$B$23,MATCH(J3,Parameters!$A$5:$A$23,0))),INDEX(Parameters!$B$5:$B$23,MATCH(J3,Parameters!$A$5:$A$23,0)),""),"") -> 1 | W3: =IF(K3<>"",1,IF(COUNTIF(Parameters!$A$27:$A$28,J3)>0,0,"")) | X3: =IF(J3="Not applicable",0,1) -> 1 | Y3: =IF(OR(K3<>"",COUNTIF(Parameters!$A$27:$A$28,J3)>0),1,0) -> 0 | Z3: =IF(((Parameters!$F$5=Parameters!$E$15)*Parameters!$I$5*1+(Parameters!$F$6=Parameters!$E$15)*Parameters!$I$6*1+(Parameters!$F$7=Parameters!$E$15)*Parameters!$I$7*1+(Parameters!$F$8=Parameters!$E$15)*Parameters!$I$8*1+(Parameters!$F$9=Parameters!$E$15)*Parameters!$I$9*1+(Parameters!$F$10=Parameters!$E$15)*Parameters!$I$10*1+(Parameters!$F$11=Parameters!$E$15)*Parameters!$I$11*X3+(Parameters!$F$12=Parameters!$E$15)*Parameters!$I$12*Y3)=0,"",IF(AND(((Parameters!$F$5=Parameters!$E$15)*Parameters!$I$5*ISNUMBER(P3)+(Parameters!$F$6=Parameters!$E$15)*Parameters!$I$6*ISNUMBER(Q3)+(Parameters!$F$7=Parameters!$E$15)*Parameters!$I$7*ISNUMBER(R3)+(Parameters!$F$8=Parameters!$E$15)*Parameters!$I$8*ISNUMBER(S3)+(Parameters!$F$9=Parameters!$E$15)*Parameters!$I$9*ISNUMBER(T3)+(Parameters!$F$10=Parameters!$E$15)*Parameters!$I$10*ISNUMBER(U3)+(Parameters!$F$11=Parameters!$E$15)*Parameters!$I$11*ISNUMBER(V3)+(Parameters!$F$12=Parameters!$E$15)*Parameters!$I$12*ISNUMBER(W3))>0,((Parameters!$F$5=Parameters!$E$15)*Parameters!$I$5*ISNUMBER(P3)+(Parameters!$F$6=Parameters!$E$15)*Parameters!$I$6*ISNUMBER(Q3)+(Parameters!$F$7=Parameters!$E$15)*Parameters!$I$7*ISNUMBER(R3)+(Parameters!$F$8=Parameters!$E$15)*Parameters!$I$8*ISNUMBER(S3)+(Parameters!$F$9=Parameters!$E$15)*Parameters!$I$9*ISNUMBER(T3)+(Parameters!$F$10=Parameters!$E$15)*Parameters!$I$10*ISNUMBER(U3)+(Parameters!$F$11=Parameters!$E$15)*Parameters!$I$11*ISNUMBER(V3)+(Parameters!$F$12=Parameters!$E$15)*Parameters!$I$12*ISNUMBER(W3))/((Parameters!$F$5=Parameters!$E$15)*Parameters!$I$5*1+(Parameters!$F$6=Parameters!$E$15)*Parameters!$I$6*1+(Parameters!$F$7=Parameters!$E$15)*Parameters!$I$7*1+(Parameters!$F$8=Parameters!$E$15)*Parameters!$I$8*1+(Parameters!$F$9=Parameters!$E$15)*Parameters!$I$9*1+(Parameters!$F$10=Parameters!$E$15)*Parameters!$I$10*1+(Parameters!$F$11=Parameters!$E$15)*Parameters!$I$11*X3+(Parameters!$F$12=Parameters!$E$15)*Parameters!$I$12*Y3)>=Parameters!$B$36),((Parameters!$F$5=Parameters!$E$15)*Parameters!$I$5*N(P3)+(Parameters!$F$6=Parameters!$E$15)*Parameters!$I$6*N(Q3)+(Parameters!$F$7=Parameters!$E$15)*Parameters!$I$7*N(R3)+(Parameters!$F$8=Parameters!$E$15)*Parameters!$I$8*N(S3)+(Parameters!$F$9=Parameters!$E$15)*Parameters!$I$9*N(T3)+(Parameters!$F$10=Parameters!$E$15)*Parameters!$I$10*N(U3)+(Parameters!$F$11=Parameters!$E$15)*Parameters!$I$11*N(V3)+(Parameters!$F$12=Parameters!$E$15)*Parameters!$I$12*N(W3))/((Parameters!$F$5=Parameters!$E$15)*Parameters!$I$5*ISNUMBER(P3)+(Parameters!$F$6=Parameters!$E$15)*Parameters!$I$6*ISNUMBER(Q3)+(Parameters!$F$7=Parameters!$E$15)*Parameters!$I$7*ISNUMBER(R3)+(Parameters!$F$8=Parameters!$E$15)*Parameters!$I$8*ISNUMBER(S3)+(Parameters!$F$9=Parameters!$E$15)*Parameters!$I$9*ISNUMBER(T3)+(Parameters!$F$10=Parameters!$E$15)*Parameters!$I$10*ISNUMBER(U3)+(Parameters!$F$11=Parameters!$E$15)*Parameters!$I$11*ISNUMBER(V3)+(Parameters!$F$12=Parameters!$E$15)*Parameters!$I$12*ISNUMBER(W3)),"")) -> 0.98 | AA3: =IF(((Parameters!$F$5=Parameters!$E$16)*Parameters!$I$5*1+(Parameters!$F$6=Parameters!$E$16)*Parameters!$I$6*1+(Parameters!$F$7=Parameters!$E$16)*Parameters!$I$7*1+(Parameters!$F$8=Parameters!$E$16)*Parameters!$I$8*1+(Parameters!$F$9=Parameters!$E$16)*Parameters!$I$9*1+(Parameters!$F$10=Parameters!$E$16)*Parameters!$I$10*1+(Parameters!$F$11=Parameters!$E$16)*Parameters!$I$11*X3+(Parameters!$F$12=Parameters!$E$16)*Parameters!$I$12*Y3)=0,"",IF(AND(((Parameters!$F$5=Parameters!$E$16)*Parameters!$I$5*ISNUMBER(P3)+(Parameters!$F$6=Parameters!$E$16)*Parameters!$I$6*ISNUMBER(Q3)+(Parameters!$F$7=Parameters!$E$16)*Parameters!$I$7*ISNUMBER(R3)+(Parameters!$F$8=Parameters!$E$16)*Parameters!$I$8*ISNUMBER(S3)+(Parameters!$F$9=Parameters!$E$16)*Parameters!$I$9*ISNUMBER(T3)+(Parameters!$F$10=Parameters!$E$16)*Parameters!$I$10*ISNUMBER(U3)+(Parameters!$F$11=Parameters!$E$16)*Parameters!$I$11*ISNUMBER(V3)+(Parameters!$F$12=Parameters!$E$16)*Parameters!$I$12*ISNUMBER(W3))>0,((Parameters!$F$5=Parameters!$E$16)*Parameters!$I$5*ISNUMBER(P3)+(Parameters!$F$6=Parameters!$E$16)*Parameters!$I$6*ISNUMBER(Q3)+(Parameters!$F$7=Parameters!$E$16)*Parameters!$I$7*ISNUMBER(R3)+(Parameters!$F$8=Parameters!$E$16)*Parameters!$I$8*ISNUMBER(S3)+(Parameters!$F$9=Parameters!$E$16)*Parameters!$I$9*ISNUMBER(T3)+(Parameters!$F$10=Parameters!$E$16)*Parameters!$I$10*ISNUMBER(U3)+(Parameters!$F$11=Parameters!$E$16)*Parameters!$I$11*ISNUMBER(V3)+(Parameters!$F$12=Parameters!$E$16)*Parameters!$I$12*ISNUMBER(W3))/((Parameters!$F$5=Parameters!$E$16)*Parameters!$I$5*1+(Parameters!$F$6=Parameters!$E$16)*Parameters!$I$6*1+(Parameters!$F$7=Parameters!$E$16)*Parameters!$I$7*1+(Parameters!$F$8=Parameters!$E$16)*Parameters!$I$8*1+(Parameters!$F$9=Parameters!$E$16)*Parameters!$I$9*1+(Parameters!$F$10=Parameters!$E$16)*Parameters!$I$10*1+(Parameters!$F$11=Parameters!$E$16)*Parameters!$I$11*X3+(Parameters!$F$12=Parameters!$E$16)*Parameters!$I$12*Y3)>=Parameters!$B$36),((Parameters!$F$5=Parameters!$E$16)*Parameters!$I$5*N(P3)+(Parameters!$F$6=Parameters!$E$16)*Parameters!$I$6*N(Q3)+(Parameters!$F$7=Parameters!$E$16)*Parameters!$I$7*N(R3)+(Parameters!$F$8=Parameters!$E$16)*Parameters!$I$8*N(S3)+(Parameters!$F$9=Parameters!$E$16)*Parameters!$I$9*N(T3)+(Parameters!$F$10=Parameters!$E$16)*Parameters!$I$10*N(U3)+(Parameters!$F$11=Parameters!$E$16)*Parameters!$I$11*N(V3)+(Parameters!$F$12=Parameters!$E$16)*Parameters!$I$12*N(W3))/((Parameters!$F$5=Parameters!$E$16)*Parameters!$I$5*ISNUMBER(P3)+(Parameters!$F$6=Parameters!$E$16)*Parameters!$I$6*ISNUMBER(Q3)+(Parameters!$F$7=Parameters!$E$16)*Parameters!$I$7*ISNUMBER(R3)+(Parameters!$F$8=Parameters!$E$16)*Parameters!$I$8*ISNUMBER(S3)+(Parameters!$F$9=Parameters!$E$16)*Parameters!$I$9*ISNUMBER(T3)+(Parameters!$F$10=Parameters!$E$16)*Parameters!$I$10*ISNUMBER(U3)+(Parameters!$F$11=Parameters!$E$16)*Parameters!$I$11*ISNUMBER(V3)+(Parameters!$F$12=Parameters!$E$16)*Parameters!$I$12*ISNUMBER(W3)),"")) -> 0.8 | AB3: =IF(((Parameters!$F$5=Parameters!$E$17)*Parameters!$I$5*1+(Parameters!$F$6=Parameters!$E$17)*Parameters!$I$6*1+(Parameters!$F$7=Parameters!$E$17)*Parameters!$I$7*1+(Parameters!$F$8=Parameters!$E$17)*Parameters!$I$8*1+(Parameters!$F$9=Parameters!$E$17)*Parameters!$I$9*1+(Parameters!$F$10=Parameters!$E$17)*Parameters!$I$10*1+(Parameters!$F$11=Parameters!$E$17)*Parameters!$I$11*X3+(Parameters!$F$12=Parameters!$E$17)*Parameters!$I$12*Y3)=0,"",IF(AND(((Parameters!$F$5=Parameters!$E$17)*Parameters!$I$5*ISNUMBER(P3)+(Parameters!$F$6=Parameters!$E$17)*Parameters!$I$6*ISNUMBER(Q3)+(Parameters!$F$7=Parameters!$E$17)*Parameters!$I$7*ISNUMBER(R3)+(Parameters!$F$8=Parameters!$E$17)*Parameters!$I$8*ISNUMBER(S3)+(Parameters!$F$9=Parameters!$E$17)*Parameters!$I$9*ISNUMBER(T3)+(Parameters!$F$10=Parameters!$E$17)*Parameters!$I$10*ISNUMBER(U3)+(Parameters!$F$11=Parameters!$E$17)*Parameters!$I$11*ISNUMBER(V3)+(Parameters!$F$12=Parameters!$E$17)*Parameters!$I$12*ISNUMBER(W3))>0,((Parameters!$F$5=Parameters!$E$17)*Parameters!$I$5*ISNUMBER(P3)+(Parameters!$F$6=Parameters!$E$17)*Parameters!$I$6*ISNUMBER(Q3)+(Parameters!$F$7=Parameters!$E$17)*Parameters!$I$7*ISNUMBER(R3)+(Parameters!$F$8=Parameters!$E$17)*Parameters!$I$8*ISNUMBER(S3)+(Parameters!$F$9=Parameters!$E$17)*Parameters!$I$9*ISNUMBER(T3)+(Parameters!$F$10=Parameters!$E$17)*Parameters!$I$10*ISNUMBER(U3)+(Parameters!$F$11=Parameters!$E$17)*Parameters!$I$11*ISNUMBER(V3)+(Parameters!$F$12=Parameters!$E$17)*Parameters!$I$12*ISNUMBER(W3))/((Parameters!$F$5=Parameters!$E$17)*Parameters!$I$5*1+(Parameters!$F$6=Parameters!$E$17)*Parameters!$I$6*1+(Parameters!$F$7=Parameters!$E$17)*Parameters!$I$7*1+(Parameters!$F$8=Parameters!$E$17)*Parameters!$I$8*1+(Parameters!$F$9=Parameters!$E$17)*Parameters!$I$9*1+(Parameters!$F$10=Parameters!$E$17)*Parameters!$I$10*1+(Parameters!$F$11=Parameters!$E$17)*Parameters!$I$11*X3+(Parameters!$F$12=Parameters!$E$17)*Parameters!$I$12*Y3)>=Parameters!$B$36),((Parameters!$F$5=Parameters!$E$17)*Parameters!$I$5*N(P3)+(Parameters!$F$6=Parameters!$E$17)*Parameters!$I$6*N(Q3)+(Parameters!$F$7=Parameters!$E$17)*Parameters!$I$7*N(R3)+(Parameters!$F$8=Parameters!$E$17)*Parameters!$I$8*N(S3)+(Parameters!$F$9=Parameters!$E$17)*Parameters!$I$9*N(T3)+(Parameters!$F$10=Parameters!$E$17)*Parameters!$I$10*N(U3)+(Parameters!$F$11=Parameters!$E$17)*Parameters!$I$11*N(V3)+(Parameters!$F$12=Parameters!$E$17)*Parameters!$I$12*N(W3))/((Parameters!$F$5=Parameters!$E$17)*Parameters!$I$5*ISNUMBER(P3)+(Parameters!$F$6=Parameters!$E$17)*Parameters!$I$6*ISNUMBER(Q3)+(Parameters!$F$7=Parameters!$E$17)*Parameters!$I$7*ISNUMBER(R3)+(Parameters!$F$8=Parameters!$E$17)*Parameters!$I$8*ISNUMBER(S3)+(Parameters!$F$9=Parameters!$E$17)*Parameters!$I$9*ISNUMBER(T3)+(Parameters!$F$10=Parameters!$E$17)*Parameters!$I$10*ISNUMBER(U3)+(Parameters!$F$11=Parameters!$E$17)*Parameters!$I$11*ISNUMBER(V3)+(Parameters!$F$12=Parameters!$E$17)*Parameters!$I$12*ISNUMBER(W3)),"")) -> 1 | AC3: =Parameters!$I$5*ISNUMBER(P3)+Parameters!$I$6*ISNUMBER(Q3)+Parameters!$I$7*ISNUMBER(R3)+Parameters!$I$8*ISNUMBER(S3)+Parameters!$I$9*ISNUMBER(T3)+Parameters!$I$10*ISNUMBER(U3)+Parameters!$I$11*ISNUMBER(V3)+Parameters!$I$12*ISNUMBER(W3) -> 85 | AD3: =Parameters!$I$5*1+Parameters!$I$6*1+Parameters!$I$7*1+Parameters!$I$8*1+Parameters!$I$9*1+Parameters!$I$10*1+Parameters!$I$11*X3+Parameters!$I$12*Y3 -> 85 | AE3: =IF(AD3=0,"",AC3/AD3) -> 1 | AF3: =IF(ISNUMBER(Z3),"M","")&IF(ISNUMBER(AA3),"I","")&IF(ISNUMBER(AB3),"O","") -> MIO | AG3: =IF(AND(ISNUMBER(AE3),ISNUMBER(Z3)+ISNUMBER(AA3)+ISNUMBER(AB3)>=Parameters!$B$37),IF(AE3>=Parameters!$B$35,100*(Parameters!$F$15*N(Z3)+Parameters!$F$16*N(AA3)+Parameters!$F$17*N(AB3))/(Parameters!$F$15*ISNUMBER(Z3)+Parameters!$F$16*ISNUMBER(AA3)+Parameters!$F$17*ISNUMBER(AB3)),""),"") -> 93 | AH3: =IF(ISNUMBER(AG3),RANK(AG3,$AG$2:$AG$113),"") -> 13
A4: AfricArXiv | B4: UbuntuNet Alliance | C4: Repository service | D4: Actual system proven in operational environment | E4: Actively Maintained | F4: 2018-01-01 | G4: Access 2 Perspectives coordinates AfricArXiv’s operations. This includes managing day-to-day activities, overseeing submission processes, ensuring quality control, and facilitating the integration of AfricArXiv with other scholarly services | H4: 1 | I4: FALSE | J4: Not applicable | L4: Fiscal sponsorship (non-profit) | M4: Contributions | N4: 1-5 | O4: 1-5 | P4: =IFERROR(IF(ISNUMBER(INDEX(Parameters!$B$5:$B$23,MATCH(D4,Parameters!$A$5:$A$23,0))),INDEX(Parameters!$B$5:$B$23,MATCH(D4,Parameters!$A$5:$A$23,0)),""),"") -> 1 | Q4: =IFERROR(IF(ISNUMBER(INDEX(Parameters!$B$5:$B$23,MATCH(E4,Parameters!$A$5:$A$23,0))),INDEX(Parameters!$B$5:$B$23,MATCH(E4,Parameters!$A$5:$A$23,0)),""),"") -> 1 | R4: =IF(F4="","",IFERROR(MIN(Parameters!$B$33,MAX(0,Parameters!$B$32-VALUE(LEFT(F4,4))))/Parameters!$B$33,"")) -> 0.53333333 | S4: =IF(ISNUMBER(H4),H4,IF(G4="",IF(ISNUMBER(Parameters!$B$34),Parameters!$B$34,""),"")) -> 1 | T4: =IFERROR(IF(ISNUMBER(INDEX(Parameters!$B$5:$B$23,MATCH(I4,Parameters!$A$5:$A$23,0))),INDEX(Parameters!$B$5:$B$23,MATCH(I4,Parameters!$A$5:$A$23,0)),""),"") -> 0 | U4: =IFERROR(IF(ISNUMBER(INDEX(Parameters!$B$5:$B$23,MATCH(L4,Parameters!$A$5:$A$23,0))),INDEX(Parameters!$B$5:$B$23,MATCH(L4,Parameters!$A$5:$A$23,0)),""),"") -> 1 | V4: =IFERROR(IF(ISNUMBER(INDEX(Parameters!$B$5:$B$23,MATCH(J4,Parameters!$A$5:$A$23,0))),INDEX(Parameters!$B$5:$B$23,MATCH(J4,Parameters!$A$5:$A$23,0)),""),"") | W4: =IF(K4<>"",1,IF(COUNTIF(Parameters!$A$27:$A$28,J4)>0,0,"")) | X4: =IF(J4="Not applicable",0,1) -> 0 | Y4: =IF(OR(K4<>"",COUNTIF(Parameters!$A$27:$A$28,J4)>0),1,0) -> 0 | Z4: =IF(((Parameters!$F$5=Parameters!$E$15)*Parameters!$I$5*1+(Parameters!$F$6=Parameters!$E$15)*Parameters!$I$6*1+(Parameters!$F$7=Parameters!$E$15)*Parameters!$I$7*1+(Parameters!$F$8=Parameters!$E$15)*Parameters!$I$8*1+(Parameters!$F$9=Parameters!$E$15)*Parameters!$I$9*1+(Parameters!$F$10=Parameters!$E$15)*Parameters!$I$10*1+(Parameters!$F$11=Parameters!$E$15)*Parameters!$I$11*X4+(Parameters!$F$12=Parameters!$E$15)*Parameters!$I$12*Y4)=0,"",IF(AND(((Parameters!$F$5=Parameters!$E$15)*Parameters!$I$5*ISNUMBER(P4)+(Parameters!$F$6=Parameters!$E$15)*Parameters!$I$6*ISNUMBER(Q4)+(Parameters!$F$7=Parameters!$E$15)*Parameters!$I$7*ISNUMBER(R4)+(Parameters!$F$8=Parameters!$E$15)*Parameters!$I$8*ISNUMBER(S4)+(Parameters!$F$9=Parameters!$E$15)*Parameters!$I$9*ISNUMBER(T4)+(Parameters!$F$10=Parameters!$E$15)*Parameters!$I$10*ISNUMBER(U4)+(Parameters!$F$11=Parameters!$E$15)*Parameters!$I$11*ISNUMBER(V4)+(Parameters!$F$12=Parameters!$E$15)*Parameters!$I$12*ISNUMBER(W4))>0,((Parameters!$F$5=Parameters!$E$15)*Parameters!$I$5*ISNUMBER(P4)+(Parameters!$F$6=Parameters!$E$15)*Parameters!$I$6*ISNUMBER(Q4)+(Parameters!$F$7=Parameters!$E$15)*Parameters!$I$7*ISNUMBER(R4)+(Parameters!$F$8=Parameters!$E$15)*Parameters!$I$8*ISNUMBER(S4)+(Parameters!$F$9=Parameters!$E$15)*Parameters!$I$9*ISNUMBER(T4)+(Parameters!$F$10=Parameters!$E$15)*Parameters!$I$10*ISNUMBER(U4)+(Parameters!$F$11=Parameters!$E$15)*Parameters!$I$11*ISNUMBER(V4)+(Parameters!$F$12=Parameters!$E$15)*Parameters!$I$12*ISNUMBER(W4))/((Parameters!$F$5=Parameters!$E$15)*Parameters!$I$5*1+(Parameters!$F$6=Parameters!$E$15)*Parameters!$I$6*1+(Parameters!$F$7=Parameters!$E$15)*Parameters!$I$7*1+(Parameters!$F$8=Parameters!$E$15)*Parameters!$I$8*1+(Parameters!$F$9=Parameters!$E$15)*Parameters!$I$9*1+(Parameters!$F$10=Parameters!$E$15)*Parameters!$I$10*1+(Parameters!$F$11=Parameters!$E$15)*Parameters!$I$11*X4+(Parameters!$F$12=Parameters!$E$15)*Parameters!$I$12*Y4)>=Parameters!$B$36),((Parameters!$F$5=Parameters!$E$15)*Parameters!$I$5*N(P4)+(Parameters!$F$6=Parameters!$E$15)*Parameters!$I$6*N(Q4)+(Parameters!$F$7=Parameters!$E$15)*Parameters!$I$7*N(R4)+(Parameters!$F$8=Parameters!$E$15)*Parameters!$I$8*N(S4)+(Parameters!$F$9=Parameters!$E$15)*Parameters!$I$9*N(T4)+(Parameters!$F$10=Parameters!$E$15)*Parameters!$I$10*N(U4)+(Parameters!$F$11=Parameters!$E$15)*Parameters!$I$11*N(V4)+(Parameters!$F$12=Parameters!$E$15)*Parameters!$I$12*N(W4))/((Parameters!$F$5=Parameters!$E$15)*Parameters!$I$5*ISNUMBER(P4)+(Parameters!$F$6=Parameters!$E$15)*Parameters!$I$6*ISNUMBER(Q4)+(Parameters!$F$7=Parameters!$E$15)*Parameters!$I$7*ISNUMBER(R4)+(Parameters!$F$8=Parameters!$E$15)*Parameters!$I$8*ISNUMBER(S4)+(Parameters!$F$9=Parameters!$E$15)*Parameters!$I$9*ISNUMBER(T4)+(Parameters!$F$10=Parameters!$E$15)*Parameters!$I$10*ISNUMBER(U4)+(Parameters!$F$11=Parameters!$E$15)*Parameters!$I$11*ISNUMBER(V4)+(Parameters!$F$12=Parameters!$E$15)*Parameters!$I$12*ISNUMBER(W4)),"")) -> 0.95333333 | AA4: =IF(((Parameters!$F$5=Parameters!$E$16)*Parameters!$I$5*1+(Parameters!$F$6=Parameters!$E$16)*Parameters!$I$6*1+(Parameters!$F$7=Parameters!$E$16)*Parameters!$I$7*1+(Parameters!$F$8=Parameters!$E$16)*Parameters!$I$8*1+(Parameters!$F$9=Parameters!$E$16)*Parameters!$I$9*1+(Parameters!$F$10=Parameters!$E$16)*Parameters!$I$10*1+(Parameters!$F$11=Parameters!$E$16)*Parameters!$I$11*X4+(Parameters!$F$12=Parameters!$E$16)*Parameters!$I$12*Y4)=0,"",IF(AND(((Parameters!$F$5=Parameters!$E$16)*Parameters!$I$5*ISNUMBER(P4)+(Parameters!$F$6=Parameters!$E$16)*Parameters!$I$6*ISNUMBER(Q4)+(Parameters!$F$7=Parameters!$E$16)*Parameters!$I$7*ISNUMBER(R4)+(Parameters!$F$8=Parameters!$E$16)*Parameters!$I$8*ISNUMBER(S4)+(Parameters!$F$9=Parameters!$E$16)*Parameters!$I$9*ISNUMBER(T4)+(Parameters!$F$10=Parameters!$E$16)*Parameters!$I$10*ISNUMBER(U4)+(Parameters!$F$11=Parameters!$E$16)*Parameters!$I$11*ISNUMBER(V4)+(Parameters!$F$12=Parameters!$E$16)*Parameters!$I$12*ISNUMBER(W4))>0,((Parameters!$F$5=Parameters!$E$16)*Parameters!$I$5*ISNUMBER(P4)+(Parameters!$F$6=Parameters!$E$16)*Parameters!$I$6*ISNUMBER(Q4)+(Parameters!$F$7=Parameters!$E$16)*Parameters!$I$7*ISNUMBER(R4)+(Parameters!$F$8=Parameters!$E$16)*Parameters!$I$8*ISNUMBER(S4)+(Parameters!$F$9=Parameters!$E$16)*Parameters!$I$9*ISNUMBER(T4)+(Parameters!$F$10=Parameters!$E$16)*Parameters!$I$10*ISNUMBER(U4)+(Parameters!$F$11=Parameters!$E$16)*Parameters!$I$11*ISNUMBER(V4)+(Parameters!$F$12=Parameters!$E$16)*Parameters!$I$12*ISNUMBER(W4))/((Parameters!$F$5=Parameters!$E$16)*Parameters!$I$5*1+(Parameters!$F$6=Parameters!$E$16)*Parameters!$I$6*1+(Parameters!$F$7=Parameters!$E$16)*Parameters!$I$7*1+(Parameters!$F$8=Parameters!$E$16)*Parameters!$I$8*1+(Parameters!$F$9=Parameters!$E$16)*Parameters!$I$9*1+(Parameters!$F$10=Parameters!$E$16)*Parameters!$I$10*1+(Parameters!$F$11=Parameters!$E$16)*Parameters!$I$11*X4+(Parameters!$F$12=Parameters!$E$16)*Parameters!$I$12*Y4)>=Parameters!$B$36),((Parameters!$F$5=Parameters!$E$16)*Parameters!$I$5*N(P4)+(Parameters!$F$6=Parameters!$E$16)*Parameters!$I$6*N(Q4)+(Parameters!$F$7=Parameters!$E$16)*Parameters!$I$7*N(R4)+(Parameters!$F$8=Parameters!$E$16)*Parameters!$I$8*N(S4)+(Parameters!$F$9=Parameters!$E$16)*Parameters!$I$9*N(T4)+(Parameters!$F$10=Parameters!$E$16)*Parameters!$I$10*N(U4)+(Parameters!$F$11=Parameters!$E$16)*Parameters!$I$11*N(V4)+(Parameters!$F$12=Parameters!$E$16)*Parameters!$I$12*N(W4))/((Parameters!$F$5=Parameters!$E$16)*Parameters!$I$5*ISNUMBER(P4)+(Parameters!$F$6=Parameters!$E$16)*Parameters!$I$6*ISNUMBER(Q4)+(Parameters!$F$7=Parameters!$E$16)*Parameters!$I$7*ISNUMBER(R4)+(Parameters!$F$8=Parameters!$E$16)*Parameters!$I$8*ISNUMBER(S4)+(Parameters!$F$9=Parameters!$E$16)*Parameters!$I$9*ISNUMBER(T4)+(Parameters!$F$10=Parameters!$E$16)*Parameters!$I$10*ISNUMBER(U4)+(Parameters!$F$11=Parameters!$E$16)*Parameters!$I$11*ISNUMBER(V4)+(Parameters!$F$12=Parameters!$E$16)*Parameters!$I$12*ISNUMBER(W4)),"")) -> 0.8 | AB4: =IF(((Parameters!$F$5=Parameters!$E$17)*Parameters!$I$5*1+(Parameters!$F$6=Parameters!$E$17)*Parameters!$I$6*1+(Parameters!$F$7=Parameters!$E$17)*Parameters!$I$7*1+(Parameters!$F$8=Parameters!$E$17)*Parameters!$I$8*1+(Parameters!$F$9=Parameters!$E$17)*Parameters!$I$9*1+(Parameters!$F$10=Parameters!$E$17)*Parameters!$I$10*1+(Parameters!$F$11=Parameters!$E$17)*Parameters!$I$11*X4+(Parameters!$F$12=Parameters!$E$17)*Parameters!$I$12*Y4)=0,"",IF(AND(((Parameters!$F$5=Parameters!$E$17)*Parameters!$I$5*ISNUMBER(P4)+(Parameters!$F$6=Parameters!$E$17)*Parameters!$I$6*ISNUMBER(Q4)+(Parameters!$F$7=Parameters!$E$17)*Parameters!$I$7*ISNUMBER(R4)+(Parameters!$F$8=Parameters!$E$17)*Parameters!$I$8*ISNUMBER(S4)+(Parameters!$F$9=Parameters!$E$17)*Parameters!$I$9*ISNUMBER(T4)+(Parameters!$F$10=Parameters!$E$17)*Parameters!$I$10*ISNUMBER(U4)+(Parameters!$F$11=Parameters!$E$17)*Parameters!$I$11*ISNUMBER(V4)+(Parameters!$F$12=Parameters!$E$17)*Parameters!$I$12*ISNUMBER(W4))>0,((Parameters!$F$5=Parameters!$E$17)*Parameters!$I$5*ISNUMBER(P4)+(Parameters!$F$6=Parameters!$E$17)*Parameters!$I$6*ISNUMBER(Q4)+(Parameters!$F$7=Parameters!$E$17)*Parameters!$I$7*ISNUMBER(R4)+(Parameters!$F$8=Parameters!$E$17)*Parameters!$I$8*ISNUMBER(S4)+(Parameters!$F$9=Parameters!$E$17)*Parameters!$I$9*ISNUMBER(T4)+(Parameters!$F$10=Parameters!$E$17)*Parameters!$I$10*ISNUMBER(U4)+(Parameters!$F$11=Parameters!$E$17)*Parameters!$I$11*ISNUMBER(V4)+(Parameters!$F$12=Parameters!$E$17)*Parameters!$I$12*ISNUMBER(W4))/((Parameters!$F$5=Parameters!$E$17)*Parameters!$I$5*1+(Parameters!$F$6=Parameters!$E$17)*Parameters!$I$6*1+(Parameters!$F$7=Parameters!$E$17)*Parameters!$I$7*1+(Parameters!$F$8=Parameters!$E$17)*Parameters!$I$8*1+(Parameters!$F$9=Parameters!$E$17)*Parameters!$I$9*1+(Parameters!$F$10=Parameters!$E$17)*Parameters!$I$10*1+(Parameters!$F$11=Parameters!$E$17)*Parameters!$I$11*X4+(Parameters!$F$12=Parameters!$E$17)*Parameters!$I$12*Y4)>=Parameters!$B$36),((Parameters!$F$5=Parameters!$E$17)*Parameters!$I$5*N(P4)+(Parameters!$F$6=Parameters!$E$17)*Parameters!$I$6*N(Q4)+(Parameters!$F$7=Parameters!$E$17)*Parameters!$I$7*N(R4)+(Parameters!$F$8=Parameters!$E$17)*Parameters!$I$8*N(S4)+(Parameters!$F$9=Parameters!$E$17)*Parameters!$I$9*N(T4)+(Parameters!$F$10=Parameters!$E$17)*Parameters!$I$10*N(U4)+(Parameters!$F$11=Parameters!$E$17)*Parameters!$I$11*N(V4)+(Parameters!$F$12=Parameters!$E$17)*Parameters!$I$12*N(W4))/((Parameters!$F$5=Parameters!$E$17)*Parameters!$I$5*ISNUMBER(P4)+(Parameters!$F$6=Parameters!$E$17)*Parameters!$I$6*ISNUMBER(Q4)+(Parameters!$F$7=Parameters!$E$17)*Parameters!$I$7*ISNUMBER(R4)+(Parameters!$F$8=Parameters!$E$17)*Parameters!$I$8*ISNUMBER(S4)+(Parameters!$F$9=Parameters!$E$17)*Parameters!$I$9*ISNUMBER(T4)+(Parameters!$F$10=Parameters!$E$17)*Parameters!$I$10*ISNUMBER(U4)+(Parameters!$F$11=Parameters!$E$17)*Parameters!$I$11*ISNUMBER(V4)+(Parameters!$F$12=Parameters!$E$17)*Parameters!$I$12*ISNUMBER(W4)),"")) | AC4: =Parameters!$I$5*ISNUMBER(P4)+Parameters!$I$6*ISNUMBER(Q4)+Parameters!$I$7*ISNUMBER(R4)+Parameters!$I$8*ISNUMBER(S4)+Parameters!$I$9*ISNUMBER(T4)+Parameters!$I$10*ISNUMBER(U4)+Parameters!$I$11*ISNUMBER(V4)+Parameters!$I$12*ISNUMBER(W4) -> 75 | AD4: =Parameters!$I$5*1+Parameters!$I$6*1+Parameters!$I$7*1+Parameters!$I$8*1+Parameters!$I$9*1+Parameters!$I$10*1+Parameters!$I$11*X4+Parameters!$I$12*Y4 -> 75 | AE4: =IF(AD4=0,"",AC4/AD4) -> 1 | AF4: =IF(ISNUMBER(Z4),"M","")&IF(ISNUMBER(AA4),"I","")&IF(ISNUMBER(AB4),"O","") -> MI | AG4: =IF(AND(ISNUMBER(AE4),ISNUMBER(Z4)+ISNUMBER(AA4)+ISNUMBER(AB4)>=Parameters!$B$37),IF(AE4>=Parameters!$B$35,100*(Parameters!$F$15*N(Z4)+Parameters!$F$16*N(AA4)+Parameters!$F$17*N(AB4))/(Parameters!$F$15*ISNUMBER(Z4)+Parameters!$F$16*ISNUMBER(AA4)+Parameters!$F$17*ISNUMBER(AB4)),""),"") -> 89.583333 | AH4: =IF(ISNUMBER(AG4),RANK(AG4,$AG$2:$AG$113),"") -> 31
A5: Arches Heritage Data Management Platform | B5: Getty Conservation Institute (GCI) | C5: Data management planning tool or service | D5: Actual system proven in operational environment | E5: Actively Maintained | F5: 2013-01-01 | G5: Getty Conservation Institute Farallon Geographics | H5: 1 | I5: FALSE | J5: Through third party vendor only | K5: https://www.archesproject.org/service-providers/ | L5: Non-profit organization | M5: Contributions | P5: =IFERROR(IF(ISNUMBER(INDEX(Parameters!$B$5:$B$23,MATCH(D5,Parameters!$A$5:$A$23,0))),INDEX(Parameters!$B$5:$B$23,MATCH(D5,Parameters!$A$5:$A$23,0)),""),"") -> 1 | Q5: =IFERROR(IF(ISNUMBER(INDEX(Parameters!$B$5:$B$23,MATCH(E5,Parameters!$A$5:$A$23,0))),INDEX(Parameters!$B$5:$B$23,MATCH(E5,Parameters!$A$5:$A$23,0)),""),"") -> 1 | R5: =IF(F5="","",IFERROR(MIN(Parameters!$B$33,MAX(0,Parameters!$B$32-VALUE(LEFT(F5,4))))/Parameters!$B$33,"")) -> 0.86666667 | S5: =IF(ISNUMBER(H5),H5,IF(G5="",IF(ISNUMBER(Parameters!$B$34),Parameters!$B$34,""),"")) -> 1 | T5: =IFERROR(IF(ISNUMBER(INDEX(Parameters!$B$5:$B$23,MATCH(I5,Parameters!$A$5:$A$23,0))),INDEX(Parameters!$B$5:$B$23,MATCH(I5,Parameters!$A$5:$A$23,0)),""),"") -> 0 | U5: =IFERROR(IF(ISNUMBER(INDEX(Parameters!$B$5:$B$23,MATCH(L5,Parameters!$A$5:$A$23,0))),INDEX(Parameters!$B$5:$B$23,MATCH(L5,Parameters!$A$5:$A$23,0)),""),"") -> 1 | V5: =IFERROR(IF(ISNUMBER(INDEX(Parameters!$B$5:$B$23,MATCH(J5,Parameters!$A$5:$A$23,0))),INDEX(Parameters!$B$5:$B$23,MATCH(J5,Parameters!$A$5:$A$23,0)),""),"") -> 1 | W5: =IF(K5<>"",1,IF(COUNTIF(Parameters!$A$27:$A$28,J5)>0,0,"")) -> 1 | X5: =IF(J5="Not applicable",0,1) -> 1 | Y5: =IF(OR(K5<>"",COUNTIF(Parameters!$A$27:$A$28,J5)>0),1,0) -> 1 | Z5: =IF(((Parameters!$F$5=Parameters!$E$15)*Parameters!$I$5*1+(Parameters!$F$6=Parameters!$E$15)*Parameters!$I$6*1+(Parameters!$F$7=Parameters!$E$15)*Parameters!$I$7*1+(Parameters!$F$8=Parameters!$E$15)*Parameters!$I$8*1+(Parameters!$F$9=Parameters!$E$15)*Parameters!$I$9*1+(Parameters!$F$10=Parameters!$E$15)*Parameters!$I$10*1+(Parameters!$F$11=Parameters!$E$15)*Parameters!$I$11*X5+(Parameters!$F$12=Parameters!$E$15)*Parameters!$I$12*Y5)=0,"",IF(AND(((Parameters!$F$5=Parameters!$E$15)*Parameters!$I$5*ISNUMBER(P5)+(Parameters!$F$6=Parameters!$E$15)*Parameters!$I$6*ISNUMBER(Q5)+(Parameters!$F$7=Parameters!$E$15)*Parameters!$I$7*ISNUMBER(R5)+(Parameters!$F$8=Parameters!$E$15)*Parameters!$I$8*ISNUMBER(S5)+(Parameters!$F$9=Parameters!$E$15)*Parameters!$I$9*ISNUMBER(T5)+(Parameters!$F$10=Parameters!$E$15)*Parameters!$I$10*ISNUMBER(U5)+(Parameters!$F$11=Parameters!$E$15)*Parameters!$I$11*ISNUMBER(V5)+(Parameters!$F$12=Parameters!$E$15)*Parameters!$I$12*ISNUMBER(W5))>0,((Parameters!$F$5=Parameters!$E$15)*Parameters!$I$5*ISNUMBER(P5)+(Parameters!$F$6=Parameters!$E$15)*Parameters!$I$6*ISNUMBER(Q5)+(Parameters!$F$7=Parameters!$E$15)*Parameters!$I$7*ISNUMBER(R5)+(Parameters!$F$8=Parameters!$E$15)*Parameters!$I$8*ISNUMBER(S5)+(Parameters!$F$9=Parameters!$E$15)*Parameters!$I$9*ISNUMBER(T5)+(Parameters!$F$10=Parameters!$E$15)*Parameters!$I$10*ISNUMBER(U5)+(Parameters!$F$11=Parameters!$E$15)*Parameters!$I$11*ISNUMBER(V5)+(Parameters!$F$12=Parameters!$E$15)*Parameters!$I$12*ISNUMBER(W5))/((Parameters!$F$5=Parameters!$E$15)*Parameters!$I$5*1+(Parameters!$F$6=Parameters!$E$15)*Parameters!$I$6*1+(Parameters!$F$7=Parameters!$E$15)*Parameters!$I$7*1+(Parameters!$F$8=Parameters!$E$15)*Parameters!$I$8*1+(Parameters!$F$9=Parameters!$E$15)*Parameters!$I$9*1+(Parameters!$F$10=Parameters!$E$15)*Parameters!$I$10*1+(Parameters!$F$11=Parameters!$E$15)*Parameters!$I$11*X5+(Parameters!$F$12=Parameters!$E$15)*Parameters!$I$12*Y5)>=Parameters!$B$36),((Parameters!$F$5=Parameters!$E$15)*Parameters!$I$5*N(P5)+(Parameters!$F$6=Parameters!$E$15)*Parameters!$I$6*N(Q5)+(Parameters!$F$7=Parameters!$E$15)*Parameters!$I$7*N(R5)+(Parameters!$F$8=Parameters!$E$15)*Parameters!$I$8*N(S5)+(Parameters!$F$9=Parameters!$E$15)*Parameters!$I$9*N(T5)+(Parameters!$F$10=Parameters!$E$15)*Parameters!$I$10*N(U5)+(Parameters!$F$11=Parameters!$E$15)*Parameters!$I$11*N(V5)+(Parameters!$F$12=Parameters!$E$15)*Parameters!$I$12*N(W5))/((Parameters!$F$5=Parameters!$E$15)*Parameters!$I$5*ISNUMBER(P5)+(Parameters!$F$6=Parameters!$E$15)*Parameters!$I$6*ISNUMBER(Q5)+(Parameters!$F$7=Parameters!$E$15)*Parameters!$I$7*ISNUMBER(R5)+(Parameters!$F$8=Parameters!$E$15)*Parameters!$I$8*ISNUMBER(S5)+(Parameters!$F$9=Parameters!$E$15)*Parameters!$I$9*ISNUMBER(T5)+(Parameters!$F$10=Parameters!$E$15)*Parameters!$I$10*ISNUMBER(U5)+(Parameters!$F$11=Parameters!$E$15)*Parameters!$I$11*ISNUMBER(V5)+(Parameters!$F$12=Parameters!$E$15)*Parameters!$I$12*ISNUMBER(W5)),"")) -> 0.98666667 | AA5: =IF(((Parameters!$F$5=Parameters!$E$16)*Parameters!$I$5*1+(Parameters!$F$6=Parameters!$E$16)*Parameters!$I$6*1+(Parameters!$F$7=Parameters!$E$16)*Parameters!$I$7*1+(Parameters!$F$8=Parameters!$E$16)*Parameters!$I$8*1+(Parameters!$F$9=Parameters!$E$16)*Parameters!$I$9*1+(Parameters!$F$10=Parameters!$E$16)*Parameters!$I$10*1+(Parameters!$F$11=Parameters!$E$16)*Parameters!$I$11*X5+(Parameters!$F$12=Parameters!$E$16)*Parameters!$I$12*Y5)=0,"",IF(AND(((Parameters!$F$5=Parameters!$E$16)*Parameters!$I$5*ISNUMBER(P5)+(Parameters!$F$6=Parameters!$E$16)*Parameters!$I$6*ISNUMBER(Q5)+(Parameters!$F$7=Parameters!$E$16)*Parameters!$I$7*ISNUMBER(R5)+(Parameters!$F$8=Parameters!$E$16)*Parameters!$I$8*ISNUMBER(S5)+(Parameters!$F$9=Parameters!$E$16)*Parameters!$I$9*ISNUMBER(T5)+(Parameters!$F$10=Parameters!$E$16)*Parameters!$I$10*ISNUMBER(U5)+(Parameters!$F$11=Parameters!$E$16)*Parameters!$I$11*ISNUMBER(V5)+(Parameters!$F$12=Parameters!$E$16)*Parameters!$I$12*ISNUMBER(W5))>0,((Parameters!$F$5=Parameters!$E$16)*Parameters!$I$5*ISNUMBER(P5)+(Parameters!$F$6=Parameters!$E$16)*Parameters!$I$6*ISNUMBER(Q5)+(Parameters!$F$7=Parameters!$E$16)*Parameters!$I$7*ISNUMBER(R5)+(Parameters!$F$8=Parameters!$E$16)*Parameters!$I$8*ISNUMBER(S5)+(Parameters!$F$9=Parameters!$E$16)*Parameters!$I$9*ISNUMBER(T5)+(Parameters!$F$10=Parameters!$E$16)*Parameters!$I$10*ISNUMBER(U5)+(Parameters!$F$11=Parameters!$E$16)*Parameters!$I$11*ISNUMBER(V5)+(Parameters!$F$12=Parameters!$E$16)*Parameters!$I$12*ISNUMBER(W5))/((Parameters!$F$5=Parameters!$E$16)*Parameters!$I$5*1+(Parameters!$F$6=Parameters!$E$16)*Parameters!$I$6*1+(Parameters!$F$7=Parameters!$E$16)*Parameters!$I$7*1+(Parameters!$F$8=Parameters!$E$16)*Parameters!$I$8*1+(Parameters!$F$9=Parameters!$E$16)*Parameters!$I$9*1+(Parameters!$F$10=Parameters!$E$16)*Parameters!$I$10*1+(Parameters!$F$11=Parameters!$E$16)*Parameters!$I$11*X5+(Parameters!$F$12=Parameters!$E$16)*Parameters!$I$12*Y5)>=Parameters!$B$36),((Parameters!$F$5=Parameters!$E$16)*Parameters!$I$5*N(P5)+(Parameters!$F$6=Parameters!$E$16)*Parameters!$I$6*N(Q5)+(Parameters!$F$7=Parameters!$E$16)*Parameters!$I$7*N(R5)+(Parameters!$F$8=Parameters!$E$16)*Parameters!$I$8*N(S5)+(Parameters!$F$9=Parameters!$E$16)*Parameters!$I$9*N(T5)+(Parameters!$F$10=Parameters!$E$16)*Parameters!$I$10*N(U5)+(Parameters!$F$11=Parameters!$E$16)*Parameters!$I$11*N(V5)+(Parameters!$F$12=Parameters!$E$16)*Parameters!$I$12*N(W5))/((Parameters!$F$5=Parameters!$E$16)*Parameters!$I$5*ISNUMBER(P5)+(Parameters!$F$6=Parameters!$E$16)*Parameters!$I$6*ISNUMBER(Q5)+(Parameters!$F$7=Parameters!$E$16)*Parameters!$I$7*ISNUMBER(R5)+(Parameters!$F$8=Parameters!$E$16)*Parameters!$I$8*ISNUMBER(S5)+(Parameters!$F$9=Parameters!$E$16)*Parameters!$I$9*ISNUMBER(T5)+(Parameters!$F$10=Parameters!$E$16)*Parameters!$I$10*ISNUMBER(U5)+(Parameters!$F$11=Parameters!$E$16)*Parameters!$I$11*ISNUMBER(V5)+(Parameters!$F$12=Parameters!$E$16)*Parameters!$I$12*ISNUMBER(W5)),"")) -> 0.8 | AB5: =IF(((Parameters!$F$5=Parameters!$E$17)*Parameters!$I$5*1+(Parameters!$F$6=Parameters!$E$17)*Parameters!$I$6*1+(Parameters!$F$7=Parameters!$E$17)*Parameters!$I$7*1+(Parameters!$F$8=Parameters!$E$17)*Parameters!$I$8*1+(Parameters!$F$9=Parameters!$E$17)*Parameters!$I$9*1+(Parameters!$F$10=Parameters!$E$17)*Parameters!$I$10*1+(Parameters!$F$11=Parameters!$E$17)*Parameters!$I$11*X5+(Parameters!$F$12=Parameters!$E$17)*Parameters!$I$12*Y5)=0,"",IF(AND(((Parameters!$F$5=Parameters!$E$17)*Parameters!$I$5*ISNUMBER(P5)+(Parameters!$F$6=Parameters!$E$17)*Parameters!$I$6*ISNUMBER(Q5)+(Parameters!$F$7=Parameters!$E$17)*Parameters!$I$7*ISNUMBER(R5)+(Parameters!$F$8=Parameters!$E$17)*Parameters!$I$8*ISNUMBER(S5)+(Parameters!$F$9=Parameters!$E$17)*Parameters!$I$9*ISNUMBER(T5)+(Parameters!$F$10=Parameters!$E$17)*Parameters!$I$10*ISNUMBER(U5)+(Parameters!$F$11=Parameters!$E$17)*Parameters!$I$11*ISNUMBER(V5)+(Parameters!$F$12=Parameters!$E$17)*Parameters!$I$12*ISNUMBER(W5))>0,((Parameters!$F$5=Parameters!$E$17)*Parameters!$I$5*ISNUMBER(P5)+(Parameters!$F$6=Parameters!$E$17)*Parameters!$I$6*ISNUMBER(Q5)+(Parameters!$F$7=Parameters!$E$17)*Parameters!$I$7*ISNUMBER(R5)+(Parameters!$F$8=Parameters!$E$17)*Parameters!$I$8*ISNUMBER(S5)+(Parameters!$F$9=Parameters!$E$17)*Parameters!$I$9*ISNUMBER(T5)+(Parameters!$F$10=Parameters!$E$17)*Parameters!$I$10*ISNUMBER(U5)+(Parameters!$F$11=Parameters!$E$17)*Parameters!$I$11*ISNUMBER(V5)+(Parameters!$F$12=Parameters!$E$17)*Parameters!$I$12*ISNUMBER(W5))/((Parameters!$F$5=Parameters!$E$17)*Parameters!$I$5*1+(Parameters!$F$6=Parameters!$E$17)*Parameters!$I$6*1+(Parameters!$F$7=Parameters!$E$17)*Parameters!$I$7*1+(Parameters!$F$8=Parameters!$E$17)*Parameters!$I$8*1+(Parameters!$F$9=Parameters!$E$17)*Parameters!$I$9*1+(Parameters!$F$10=Parameters!$E$17)*Parameters!$I$10*1+(Parameters!$F$11=Parameters!$E$17)*Parameters!$I$11*X5+(Parameters!$F$12=Parameters!$E$17)*Parameters!$I$12*Y5)>=Parameters!$B$36),((Parameters!$F$5=Parameters!$E$17)*Parameters!$I$5*N(P5)+(Parameters!$F$6=Parameters!$E$17)*Parameters!$I$6*N(Q5)+(Parameters!$F$7=Parameters!$E$17)*Parameters!$I$7*N(R5)+(Parameters!$F$8=Parameters!$E$17)*Parameters!$I$8*N(S5)+(Parameters!$F$9=Parameters!$E$17)*Parameters!$I$9*N(T5)+(Parameters!$F$10=Parameters!$E$17)*Parameters!$I$10*N(U5)+(Parameters!$F$11=Parameters!$E$17)*Parameters!$I$11*N(V5)+(Parameters!$F$12=Parameters!$E$17)*Parameters!$I$12*N(W5))/((Parameters!$F$5=Parameters!$E$17)*Parameters!$I$5*ISNUMBER(P5)+(Parameters!$F$6=Parameters!$E$17)*Parameters!$I$6*ISNUMBER(Q5)+(Parameters!$F$7=Parameters!$E$17)*Parameters!$I$7*ISNUMBER(R5)+(Parameters!$F$8=Parameters!$E$17)*Parameters!$I$8*ISNUMBER(S5)+(Parameters!$F$9=Parameters!$E$17)*Parameters!$I$9*ISNUMBER(T5)+(Parameters!$F$10=Parameters!$E$17)*Parameters!$I$10*ISNUMBER(U5)+(Parameters!$F$11=Parameters!$E$17)*Parameters!$I$11*ISNUMBER(V5)+(Parameters!$F$12=Parameters!$E$17)*Parameters!$I$12*ISNUMBER(W5)),"")) -> 1 | AC5: =Parameters!$I$5*ISNUMBER(P5)+Parameters!$I$6*ISNUMBER(Q5)+Parameters!$I$7*ISNUMBER(R5)+Parameters!$I$8*ISNUMBER(S5)+Parameters!$I$9*ISNUMBER(T5)+Parameters!$I$10*ISNUMBER(U5)+Parameters!$I$11*ISNUMBER(V5)+Parameters!$I$12*ISNUMBER(W5) -> 95 | AD5: =Parameters!$I$5*1+Parameters!$I$6*1+Parameters!$I$7*1+Parameters!$I$8*1+Parameters!$I$9*1+Parameters!$I$10*1+Parameters!$I$11*X5+Parameters!$I$12*Y5 -> 95 | AE5: =IF(AD5=0,"",AC5/AD5) -> 1 | AF5: =IF(ISNUMBER(Z5),"M","")&IF(ISNUMBER(AA5),"I","")&IF(ISNUMBER(AB5),"O","") -> MIO | AG5: =IF(AND(ISNUMBER(AE5),ISNUMBER(Z5)+ISNUMBER(AA5)+ISNUMBER(AB5)>=Parameters!$B$37),IF(AE5>=Parameters!$B$35,100*(Parameters!$F$15*N(Z5)+Parameters!$F$16*N(AA5)+Parameters!$F$17*N(AB5))/(Parameters!$F$15*ISNUMBER(Z5)+Parameters!$F$16*ISNUMBER(AA5)+Parameters!$F$17*ISNUMBER(AB5)),""),"") -> 93.333333 | AH5: =IF(ISNUMBER(AG5),RANK(AG5,$AG$2:$AG$113),"") -> 12
