Workbook

Sheet Summary
A1: Organizational Capacity: Final Equal-Weight Results
A2: Infrastructure entries | B2: 112
A3: Final metrics | B3: M1, M2, H1, I2, O1
A4: Weight per metric | B4: 20.00% (1/5)
A5: Coverage / eligibility gate | B5: None
A6: Missing, unknown, N/A | B6: Scored 0; denominator remains five
A7: Mean score | B7: =AVERAGE(Scoring!O2:O113)
A8: Median score | B8: =MEDIAN(Scoring!O2:O113)
A9: Highest score | B9: =MAX(Scoring!O2:O113)
A10: Lowest score | B10: =MIN(Scoring!O2:O113)
A11: Important interpretation | B11: Zero-filled score reflects both reported capacity and missing information. Review metric-level scores and notes before interpreting rank differences.
A12: Affiliation review | B12: Field 058 is free text. Use Verification to enter a corrected I2 score of 0, 50, or 100; scoring formulas update when opened/recalculated in Excel.

Sheet Scoring
A1: Service | B1: Provider | C1: Solution category | D1: 079 Readiness | E1: 080 Maintenance | F1: 054 Full-time staff | G1: 055 Volunteers | H1: 058 Affiliations | I1: 076 Service options | J1: M1 | K1: M2 | L1: H1 | M1: I2 | N1: O1 | O1: Final score / 100 | P1: Rank | Q1: Data-quality notes
A2: 2i2c | B2: Code for Science and Society | C2: Authoring tool | D2: Actual system proven in operational environment | E2: Actively Maintained | I2: Not applicable | J2: =Calc!B2 | K2: =Calc!C2 | L2: =Calc!F2 | M2: =Verification!E2 | N2: =Calc!I2 | O2: =AVERAGE(J2:N2) | P2: =RANK.EQ(O2,$O$2:$O$113,0) | Q2: Full-time staffing missing/unknown scored 0; Volunteer staffing missing/unknown scored 0; Service-delivery field not applicable/unknown scored 0
A3: Academic Preservation Trust (APTrust) | B3: Academic Preservation Trust (APTrust) | C3: Digital preservation service | D3: Actual system proven in operational environment | E3: Actively Maintained | F3: 1-5 | H3: University of Virginia | I3: Through solution provider only | J3: =Calc!B3 | K3: =Calc!C3 | L3: =Calc!F3 | M3: =Verification!E3 | N3: =Calc!I3 | O3: =AVERAGE(J3:N3) | P3: =RANK.EQ(O3,$O$2:$O$113,0) | Q3: Volunteer staffing missing/unknown scored 0; Review affiliation coding; override available
A4: AfricArXiv | B4: UbuntuNet Alliance | C4: Repository service | D4: Actual system proven in operational environment | E4: Actively Maintained | F4: 1-5 | G4: 1-5 | H4: Access 2 Perspectives coordinates AfricArXiv’s operations. This includes managing day-to-day activities, overseeing submission processes, ensuring quality control, and facilitating the integration of AfricArXiv with other scholarly services | I4: Not applicable | J4: =Calc!B4 | K4: =Calc!C4 | L4: =Calc!F4 | M4: =Verification!E4 | N4: =Calc!I4 | O4: =AVERAGE(J4:N4) | P4: =RANK.EQ(O4,$O$2:$O$113,0) | Q4: Review affiliation coding; override available; Service-delivery field not applicable/unknown scored 0
A5: Arches Heritage Data Management Platform | B5: Getty Conservation Institute (GCI) | C5: Data management planning tool or service | D5: Actual system proven in operational environment | E5: Actively Maintained | H5: Getty Conservation Institute Farallon Geographics | I5: Through third party vendor only | J5: =Calc!B5 | K5: =Calc!C5 | L5: =Calc!F5 | M5: =Verification!E5 | N5: =Calc!I5 | O5: =AVERAGE(J5:N5) | P5: =RANK.EQ(O5,$O$2:$O$113,0) | Q5: Full-time staffing missing/unknown scored 0; Volunteer staffing missing/unknown scored 0; Review affiliation coding; override available
A6: Archipelago Commons | B6: Metropolitan New York Library Council | C6: Digital library, collection or exhibit platform | Repository software | D6: Actual system proven in operational environment | E6: Actively Maintained | I6: Through solution provider or third party vendor | J6: =Calc!B6 | K6: =Calc!C6 | L6: =Calc!F6 | M6: =Verification!E6 | N6: =Calc!I6 | O6: =AVERAGE(J6:N6) | P6: =RANK.EQ(O6,$O$2:$O$113,0) | Q6: Full-time staffing missing/unknown scored 0; Volunteer staffing missing/unknown scored 0
A7: Archival Resource Key | B7: ARK Alliance | C7: Standard, specification or protocol | D7: Technology validated in relevant environment | E7: Actively Maintained | I7: Not applicable | J7: =Calc!B7 | K7: =Calc!C7 | L7: =Calc!F7 | M7: =Verification!E7 | N7: =Calc!I7 | O7: =AVERAGE(J7:N7) | P7: =RANK.EQ(O7,$O$2:$O$113,0) | Q7: Full-time staffing missing/unknown scored 0; Volunteer staffing missing/unknown scored 0; Service-delivery field not applicable/unknown scored 0
A8: Archivematica | B8: Artefactual | C8: Digital preservation system | D8: Actual system proven in operational environment | E8: Actively Maintained | F8: More than 20 | H8: No Affiliations | I8: Through solution provider or third party vendor | J8: =Calc!B8 | K8: =Calc!C8 | L8: =Calc!F8 | M8: =Verification!E8 | N8: =Calc!I8 | O8: =AVERAGE(J8:N8) | P8: =RANK.EQ(O8,$O$2:$O$113,0) | Q8: Volunteer staffing missing/unknown scored 0; Review affiliation coding; override available
A9: ArchivesSpace | B9: ArchivesSpace | C9: Archive information management system | Discovery system | D9: Actual system proven in operational environment | E9: Actively Maintained | F9: 6-10 | H9: New York University and the University of California San Diego are the founding partners and have permanent seats on the Board; Lyrasis is the organizational home | I9: Through third party vendor only | J9: =Calc!B9 | K9: =Calc!C9 | L9: =Calc!F9 | M9: =Verification!E9 | N9: =Calc!I9 | O9: =AVERAGE(J9:N9) | P9: =RANK.EQ(O9,$O$2:$O$113,0) | Q9: Volunteer staffing missing/unknown scored 0; Review affiliation coding; override available
A10: ARGOS | B10: OpenAIRE | C10: Data management planning tool or service | D10: Actual system proven in operational environment | E10: Actively Maintained | H10: Athena Research Center (ARC) Communication & Information Technologies Experts (CITE) | I10: Through solution provider only | J10: =Calc!B10 | K10: =Calc!C10 | L10: =Calc!F10 | M10: =Verification!E10 | N10: =Calc!I10 | O10: =AVERAGE(J10:N10) | P10: =RANK.EQ(O10,$O$2:$O$113,0) | Q10: Full-time staffing missing/unknown scored 0; Volunteer staffing missing/unknown scored 0; Review affiliation coding; override available
A11: arXiv | B11: Cornell University | C11: Repository service | D11: Actual system proven in operational environment | E11: Actively Maintained | I11: Not applicable | J11: =Calc!B11 | K11: =Calc!C11 | L11: =Calc!F11 | M11: =Verification!E11 | N11: =Calc!I11 | O11: =AVERAGE(J11:N11) | P11: =RANK.EQ(O11,$O$2:$O$113,0) | Q11: Full-time staffing missing/unknown scored 0; Volunteer staffing missing/unknown scored 0; Service-delivery field not applicable/unknown scored 0
A12: AtoM | B12: Artefactual | C12: Archive information management system | D12: Actual system proven in operational environment | E12: Actively Maintained | F12: More than 20 | G12: Unknown | H12: No affiliations | I12: Through solution provider or third party vendor | J12: =Calc!B12 | K12: =Calc!C12 | L12: =Calc!F12 | M12: =Verification!E12 | N12: =Calc!I12 | O12: =AVERAGE(J12:N12) | P12: =RANK.EQ(O12,$O$2:$O$113,0) | Q12: Review affiliation coding; override available
A13: Avalon Media System | B13: Indiana University Libraries | C13: Digital library, collection or exhibit platform | Repository software | D13: Actual system proven in operational environment | E13: Actively Maintained | F13: 1-5 | H13: Indiana University Libraries | I13: No services available | J13: =Calc!B13 | K13: =Calc!C13 | L13: =Calc!F13 | M13: =Verification!E13 | N13: =Calc!I13 | O13: =AVERAGE(J13:N13) | P13: =RANK.EQ(O13,$O$2:$O$113,0) | Q13: Volunteer staffing missing/unknown scored 0; Review affiliation coding; override available
A14: Biodiversity Heritage Library | B14: BHL Consortium | C14: Digital library, collection or exhibit platform | Open scholarly dataset | Repository service | D14: Actual system proven in operational environment | E14: Actively Maintained | F14: 1-5 | H14: BHL’s fiscal sponsor is the Council on Library and Information Resources (CLIR). | I14: Not applicable | J14: =Calc!B14 | K14: =Calc!C14 | L14: =Calc!F14 | M14: =Verification!E14 | N14: =Calc!I14 | O14: =AVERAGE(J14:N14) | P14: =RANK.EQ(O14,$O$2:$O$113,0) | Q14: Volunteer staffing missing/unknown scored 0; Review affiliation coding; override available; Service-delivery field not applicable/unknown scored 0
A15: bioRxiv | B15: Cold Spring Harbor Laboratory | C15: Repository service | D15: Actual system proven in operational environment | E15: Actively Maintained | I15: Not applicable | J15: =Calc!B15 | K15: =Calc!C15 | L15: =Calc!F15 | M15: =Verification!E15 | N15: =Calc!I15 | O15: =AVERAGE(J15:N15) | P15: =RANK.EQ(O15,$O$2:$O$113,0) | Q15: Full-time staffing missing/unknown scored 0; Volunteer staffing missing/unknown scored 0; Service-delivery field not applicable/unknown scored 0
A16: BitCurator Environment | B16: BitCurator Consortium | C16: Digital preservation tool | D16: Actual system proven in operational environment | E16: Actively Maintained | F16: 0 | G16: 6-10 | H16: BitCurator Consortium is administratively hosted by the Open Library Foundation. | I16: No services available | J16: =Calc!B16 | K16: =Calc!C16 | L16: =Calc!F16 | M16: =Verification!E16 | N16: =Calc!I16 | O16: =AVERAGE(J16:N16) | P16: =RANK.EQ(O16,$O$2:$O$113,0) | Q16: Review affiliation coding; override available
A17: Blacklight | B17: Blacklight | C17: Discovery system | Integrated Library System (ILS) or Library Services Platform (LSP) | D17: Actual system proven in operational environment | E17: Actively Maintained | F17: 6-10 | H17: See website | I17: Through solution provider only | J17: =Calc!B17 | K17: =Calc!C17 | L17: =Calc!F17 | M17: =Verification!E17 | N17: =Calc!I17 | O17: =AVERAGE(J17:N17) | P17: =RANK.EQ(O17,$O$2:$O$113,0) | Q17: Volunteer staffing missing/unknown scored 0; Review affiliation coding; override available
A18: BrCRIS | B18: IBICT | C18: Discovery system | Research profiling system | D18: Actual system proven in operational environment | E18: Actively Maintained | I18: Not applicable | J18: =Calc!B18 | K18: =Calc!C18 | L18: =Calc!F18 | M18: =Verification!E18 | N18: =Calc!I18 | O18: =AVERAGE(J18:N18) | P18: =RANK.EQ(O18,$O$2:$O$113,0) | Q18: Full-time staffing missing/unknown scored 0; Volunteer staffing missing/unknown scored 0; Service-delivery field not applicable/unknown scored 0
A19: Browsertrix | B19: Webrecorder | C19: Digital library, collection or exhibit platform | Web archiving system | D19: Actual system proven in operational environment | E19: Actively Maintained | F19: 1-5 | G19: 0 | H19: No affiliations have direct involvement in governing or running our products except us. We are members of the International Internet Preservation Consortium (IIPC). | I19: Through solution provider or third party vendor | J19: =Calc!B19 | K19: =Calc!C19 | L19: =Calc!F19 | M19: =Verification!E19 | N19: =Calc!I19 | O19: =AVERAGE(J19:N19) | P19: =RANK.EQ(O19,$O$2:$O$113,0) | Q19: Review affiliation coding; override available
A20: CLOCKSS | B20: CLOCKSS | C20: Digital preservation service | D20: Actual system proven in operational environment | E20: Actively Maintained | F20: 1-5 | G20: 0 | H20: n/a | I20: Through solution provider or third party vendor | J20: =Calc!B20 | K20: =Calc!C20 | L20: =Calc!F20 | M20: =Verification!E20 | N20: =Calc!I20 | O20: =AVERAGE(J20:N20) | P20: =RANK.EQ(O20,$O$2:$O$113,0) | Q20: Review affiliation coding; override available
A21: COAR International Repository Directory (IRD) | B21: COAR | C21: Index or directory | D21: Actual system proven in operational environment | E21: Actively Maintained | F21: 1-5 | H21: Responsible Organisations: https://ird.coar-repositories.org/about?lang=en | I21: Not applicable | J21: =Calc!B21 | K21: =Calc!C21 | L21: =Calc!F21 | M21: =Verification!E21 | N21: =Calc!I21 | O21: =AVERAGE(J21:N21) | P21: =RANK.EQ(O21,$O$2:$O$113,0) | Q21: Volunteer staffing missing/unknown scored 0; Review affiliation coding; override available; Service-delivery field not applicable/unknown scored 0
A22: COAR Notify | B22: COAR | C22: Standard, specification or protocol | D22: Actual system proven in operational environment | E22: Actively Maintained | H22: No affiliations. | I22: Through solution provider or third party vendor | J22: =Calc!B22 | K22: =Calc!C22 | L22: =Calc!F22 | M22: =Verification!E22 | N22: =Calc!I22 | O22: =AVERAGE(J22:N22) | P22: =RANK.EQ(O22,$O$2:$O$113,0) | Q22: Full-time staffing missing/unknown scored 0; Volunteer staffing missing/unknown scored 0; Review affiliation coding; override available
A23: CollectiveAccess | B23: Whirl-i-Gig | C23: Archive information management system | Digital asset management system | Digital library, collection or exhibit platform | D23: Actual system proven in operational environment | E23: Actively Maintained | F23: 6-10 | G23: 0 | H23: No affiliations | I23: Through solution provider or third party vendor | J23: =Calc!B23 | K23: =Calc!C23 | L23: =Calc!F23 | M23: =Verification!E23 | N23: =Calc!I23 | O23: =AVERAGE(J23:N23) | P23: =RANK.EQ(O23,$O$2:$O$113,0) | Q23: Review affiliation coding; override available
A24: CORE | B24: The Open University | C24: Discovery system | D24: Actual system proven in operational environment | E24: Actively Maintained | I24: Not applicable | J24: =Calc!B24 | K24: =Calc!C24 | L24: =Calc!F24 | M24: =Verification!E24 | N24: =Calc!I24 | O24: =AVERAGE(J24:N24) | P24: =RANK.EQ(O24,$O$2:$O$113,0) | Q24: Full-time staffing missing/unknown scored 0; Volunteer staffing missing/unknown scored 0; Service-delivery field not applicable/unknown scored 0
A25: COUNTER Code of Practice | B25: COUNTER Metrics | C25: Standard, specification or protocol | D25: Actual system proven in operational environment | E25: Actively Maintained | I25: Not applicable | J25: =Calc!B25 | K25: =Calc!C25 | L25: =Calc!F25 | M25: =Verification!E25 | N25: =Calc!I25 | O25: =AVERAGE(J25:N25) | P25: =RANK.EQ(O25,$O$2:$O$113,0) | Q25: Full-time staffing missing/unknown scored 0; Volunteer staffing missing/unknown scored 0; Service-delivery field not applicable/unknown scored 0
A26: Creative Commons Licenses | B26: Creative Commons | C26: Standard, specification or protocol | D26: System complete and qualified | E26: Actively Maintained | I26: Not applicable | J26: =Calc!B26 | K26: =Calc!C26 | L26: =Calc!F26 | M26: =Verification!E26 | N26: =Calc!I26 | O26: =AVERAGE(J26:N26) | P26: =RANK.EQ(O26,$O$2:$O$113,0) | Q26: Full-time staffing missing/unknown scored 0; Volunteer staffing missing/unknown scored 0; Service-delivery field not applicable/unknown scored 0
A27: Crossref Metadata Retrieval | B27: Crossref | C27: Open scholarly dataset | D27: Actual system proven in operational environment | E27: Actively Maintained | I27: Not applicable | J27: =Calc!B27 | K27: =Calc!C27 | L27: =Calc!F27 | M27: =Verification!E27 | N27: =Calc!I27 | O27: =AVERAGE(J27:N27) | P27: =RANK.EQ(O27,$O$2:$O$113,0) | Q27: Full-time staffing missing/unknown scored 0; Volunteer staffing missing/unknown scored 0; Service-delivery field not applicable/unknown scored 0
A28: D4Science Infrastructure | B28: National Research Council of Italy | C28: Computing framework | Informal scholarly communications | Repository service | D28: Actual system proven in operational environment | E28: Actively Maintained | F28: 6-10 | G28: More than 20 | H28: D4Science is managed by the Italian National Research Council (CNR). Its headquarters are hosted by CNR's Institute of Information Science and Technologies "A. Faedo" (CNR-ISTI) in Pisa, Tuscany, Italy. | I28: Through solution provider only | J28: =Calc!B28 | K28: =Calc!C28 | L28: =Calc!F28 | M28: =Verification!E28 | N28: =Calc!I28 | O28: =AVERAGE(J28:N28) | P28: =RANK.EQ(O28,$O$2:$O$113,0) | Q28: Review affiliation coding; override available
A29: DART (Digital Archivist's Resource Tool) | B29: Academic Preservation Trust (APTrust) | C29: Digital preservation tool | D29: Actual system proven in operational environment | E29: Actively Maintained | F29: 1-5 | H29: University of Virginia | I29: No services available | J29: =Calc!B29 | K29: =Calc!C29 | L29: =Calc!F29 | M29: =Verification!E29 | N29: =Calc!I29 | O29: =AVERAGE(J29:N29) | P29: =RANK.EQ(O29,$O$2:$O$113,0) | Q29: Volunteer staffing missing/unknown scored 0; Review affiliation coding; override available
A30: Database Information System | B30: University Library of Regensburg | C30: Discovery system | Index or directory | D30: Actual system proven in operational environment | E30: Actively Maintained | H30: DBIS is operated by the University Library of Regensburg. | I30: Through solution provider or third party vendor | J30: =Calc!B30 | K30: =Calc!C30 | L30: =Calc!F30 | M30: =Verification!E30 | N30: =Calc!I30 | O30: =AVERAGE(J30:N30) | P30: =RANK.EQ(O30,$O$2:$O$113,0) | Q30: Full-time staffing missing/unknown scored 0; Volunteer staffing missing/unknown scored 0; Review affiliation coding; override available
A31: Data Citation Corpus | B31: Make Data Count | C31: Discovery system | Open scholarly dataset | D31: Technology validated in relevant environment | E31: Actively Maintained | G31: 11-20 | H31: DataCite leads the development of the Data Citation Corpus as part of Make Data Count activities. | I31: Not applicable | J31: =Calc!B31 | K31: =Calc!C31 | L31: =Calc!F31 | M31: =Verification!E31 | N31: =Calc!I31 | O31: =AVERAGE(J31:N31) | P31: =RANK.EQ(O31,$O$2:$O$113,0) | Q31: Full-time staffing missing/unknown scored 0; Review affiliation coding; override available; Service-delivery field not applicable/unknown scored 0
A32: DataCite | B32: DataCite | C32: Discovery system | Persistent identifier service | D32: Actual system proven in operational environment | E32: Actively Maintained | I32: Not applicable | J32: =Calc!B32 | K32: =Calc!C32 | L32: =Calc!F32 | M32: =Verification!E32 | N32: =Calc!I32 | O32: =AVERAGE(J32:N32) | P32: =RANK.EQ(O32,$O$2:$O$113,0) | Q32: Full-time staffing missing/unknown scored 0; Volunteer staffing missing/unknown scored 0; Service-delivery field not applicable/unknown scored 0
A33: Data Stewardship Wizard | B33: DSW Team | C33: Data management planning tool or service | D33: Actual system proven in operational environment | E33: Actively Maintained | H33: Czech Technical University in Prague / ELIXIR-CZ Codevence Solutions | I33: Through third party vendor only | J33: =Calc!B33 | K33: =Calc!C33 | L33: =Calc!F33 | M33: =Verification!E33 | N33: =Calc!I33 | O33: =AVERAGE(J33:N33) | P33: =RANK.EQ(O33,$O$2:$O$113,0) | Q33: Full-time staffing missing/unknown scored 0; Volunteer staffing missing/unknown scored 0; Review affiliation coding; override available
A34: Dataverse | B34: Harvard University Institute for Quantitative Social Science (IQSS) | C34: Repository software | D34: Actual system proven in operational environment | E34: Actively Maintained | I34: Through third party vendor only | J34: =Calc!B34 | K34: =Calc!C34 | L34: =Calc!F34 | M34: =Verification!E34 | N34: =Calc!I34 | O34: =AVERAGE(J34:N34) | P34: =RANK.EQ(O34,$O$2:$O$113,0) | Q34: Full-time staffing missing/unknown scored 0; Volunteer staffing missing/unknown scored 0
A35: DLCM Backend | B35: DLCM Technology | C35: Archive information management system | Digital preservation system | D35: Actual system proven in operational environment | E35: Actively Maintained | F35: 1-5 | G35: 1-5 | H35: University of Geneva (https://www.unige.ch/) HEG, HES-SO (https://www.hesge.ch/heg/en) UNIFR (https://www.unifr.ch/home/en/) BFH (https://www.bfh.ch/en/) OLOS (https://olos.swiss/) | I35: Through third party vendor only | J35: =Calc!B35 | K35: =Calc!C35 | L35: =Calc!F35 | M35: =Verification!E35 | N35: =Calc!I35 | O35: =AVERAGE(J35:N35) | P35: =RANK.EQ(O35,$O$2:$O$113,0) | Q35: Review affiliation coding; override available
A36: DLCM Portal | B36: DLCM Technology | C36: Archive information management system | Digital preservation system | Software preservation service | D36: Actual system proven in operational environment | E36: Actively Maintained | F36: 1-5 | G36: 1-5 | H36: University of Geneva (https://www.unige.ch/)HEG, HES-SO (https://www.hesge.ch/heg/en)UNIFR (https://www.unifr.ch/home/en/)BFH (https://www.bfh.ch/en/)OLOS (https://olos.swiss/) | I36: Through third party vendor only | J36: =Calc!B36 | K36: =Calc!C36 | L36: =Calc!F36 | M36: =Verification!E36 | N36: =Calc!I36 | O36: =AVERAGE(J36:N36) | P36: =RANK.EQ(O36,$O$2:$O$113,0) | Q36: Review affiliation coding; override available
A37: DMP Tool | B37: California Digital Library | C37: Data management planning tool or service | D37: Actual system proven in operational environment | E37: Actively Maintained | F37: 1-5 | G37: 0 | I37: Through solution provider only | J37: =Calc!B37 | K37: =Calc!C37 | L37: =Calc!F37 | M37: =Verification!E37 | N37: =Calc!I37 | O37: =AVERAGE(J37:N37) | P37: =RANK.EQ(O37,$O$2:$O$113,0)
A38: DOAJ (Directory of Open Access Journals) | B38: DOAJ Foundation | C38: Discovery system | Index or directory | Open scholarly dataset | D38: Actual system proven in operational environment | E38: Actively Maintained | I38: Not applicable | J38: =Calc!B38 | K38: =Calc!C38 | L38: =Calc!F38 | M38: =Verification!E38 | N38: =Calc!I38 | O38: =AVERAGE(J38:N38) | P38: =RANK.EQ(O38,$O$2:$O$113,0) | Q38: Full-time staffing missing/unknown scored 0; Volunteer staffing missing/unknown scored 0; Service-delivery field not applicable/unknown scored 0
A39: dokieli | B39: dokieli | C39: Annotations system | Authoring tool | Informal scholarly communications | D39: Technology validated in relevant environment | E39: Actively Maintained | I39: Unknown | J39: =Calc!B39 | K39: =Calc!C39 | L39: =Calc!F39 | M39: =Verification!E39 | N39: =Calc!I39 | O39: =AVERAGE(J39:N39) | P39: =RANK.EQ(O39,$O$2:$O$113,0) | Q39: Full-time staffing missing/unknown scored 0; Volunteer staffing missing/unknown scored 0; Service-delivery field not applicable/unknown scored 0
A40: Dryad | B40: Dryad | C40: Repository service | D40: Actual system proven in operational environment | E40: Actively Maintained | I40: Not applicable | J40: =Calc!B40 | K40: =Calc!C40 | L40: =Calc!F40 | M40: =Verification!E40 | N40: =Calc!I40 | O40: =AVERAGE(J40:N40) | P40: =RANK.EQ(O40,$O$2:$O$113,0) | Q40: Full-time staffing missing/unknown scored 0; Volunteer staffing missing/unknown scored 0; Service-delivery field not applicable/unknown scored 0
...

Sheet Metric Rules
A1: Code | B1: Metric | C1: Source field(s) | D1: Weight | E1: Scoring criteria | F1: Unavailable-data treatment | G1: Interpretation / caution
A2: M1 | B2: Technology readiness | C2: 079 | D2: 0.2 | E2: Nine-stage source scale: score = level / 9 x 100. Observed: Actual system proven in operational environment=100; System complete and qualified=88.89; Technology validated in relevant environment=55.56. | F2: Unknown, blank, or unrecognized=0. | G2: Ordinal normalization on the source readiness scale; current data are concentrated at the highest level.
A3: M2 | B3: Maintenance status | C3: 080 | D3: 0.2 | E3: Actively Maintained=100; Minimally Maintained=50; Inactive/not maintained=0. | F3: Unknown or blank=0. | G3: Current responses are highly concentrated at actively maintained.
A4: H1 | B4: Human-resource capacity | C4: 054 + 055 | D4: 0.2 | E4: Score each field: 0 people=0; 1-5=25; 6-10=50; 11-20=75; >20=100. H1=(full-time score+volunteer score)/2. | F4: Unknown or blank in either field=0 for that field; H1 remains the average of both fields. | G4: Ordinal ranges, not exact headcounts. Paid and volunteer staffing each contribute half of H1.
A5: I2 | B5: Institutional affiliations and support | C5: 058 | D5: 0.2 | E5: Formal host or explicit operational/financial support=100; substantive affiliation/membership without stated operational support=50; explicit absence/placeholders=0. | F5: Blank or unknown=0. Free-text provisional coding can be overridden on Verification sheet with 0, 50, or 100. | G5: Narrative coding needs consistent review; an override changes the Scoring sheet formula after recalculation in Excel.
A6: O1 | B6: Hosted/service-delivery capacity | C6: 076 | D6: 0.2 | E6: Any 'Through ...' hosted/service route=100; No services available=0. | F6: Not applicable, unknown, or blank=0. | G6: Measures reported service availability, not quality, uptime, affordability, or control.

Sheet Methodology
A1: Methodology and interpretation | B1: Details
A2: Metric selection | B2: Five measures are retained: technology readiness, maintenance, combined staffing, institutional affiliations/support, and hosted/service-delivery capacity. M3 Infrastructure age and I1 Formal organizational host are excluded. Funding, legal form, SCOSS, and provider-list fields remain descriptive, not scored.
A3: Equal weighting | B3: Each of the five metrics receives 20%. Equal weighting is a transparent analytic choice; it is not estimated from the observed data or claimed to establish equal causal importance.
A4: Final formula | B4: Organizational Capacity Score = (M1 + M2 + H1 + I2 + O1) / 5. Each metric is first placed on a 0-100 scale.
A5: Missing-data rule | B5: No coverage or eligibility threshold is applied. Blank, unknown, not applicable, or unrecognized values score 0, as requested. The denominator remains five for every infrastructure.
A6: Interpretation | B6: The zero-filled score reflects recorded capacity and data availability together. A zero for a missing field does not prove the underlying capacity is absent. Publish metric-level values and data-quality notes with the total.
A7: Human resources | B7: Full-time and volunteer staffing are subfields of one metric. Each is scored 0/25/50/75/100 by reported category; their two sub-scores are averaged. Missing/unknown subfields score zero. The category scale is ordinal.
A8: Affiliation coding | B8: Field 058 is free text. A provisional deterministic rule assigns 100 only where explicit hosting/support language is present; other substantive affiliation text receives 50; explicit absence/placeholders/blank receive 0. Review and numeric overrides (0, 50, 100) are available in Verification.
A9: Source data | B9: The workbook contains 112 source entries copied from the Organizational Capacity verification sheet and includes the source Field_Guide. The source data are preserved as a separate sheet.
A10: No performance bands | B10: No 70-point cutoff or high/medium/low categories are applied.
A11: Limitations | B11: Technology readiness and maintenance responses show little variation. Staffing and affiliation information is incomplete or narrative. Hosted/service delivery is not a direct measure of quality. These constraints should be stated when interpreting comparisons.

Sheet Parameters
A1: Code | B1: Metric | C1: Source field(s) | D1: Exact weight | E1: Displayed weight | F1: Scale
A2: M1 | B2: Technology readiness | C2: 079_technology_readiness | D2: 0.2 | E2: 20.00% | F2: 0-100
A3: M2 | B3: Maintenance status | C3: 080_maintenance_status | D3: 0.2 | E3: 20.00% | F3: 0-100
A4: H1 | B4: Human-resource capacity | C4: 054_staffing_full_time + 055_staffing_volunteer | D4: 0.2 | E4: 20.00% | F4: 0-100
A5: I2 | B5: Institutional affiliations and support | C5: 058_affiliations | D5: 0.2 | E5: 20.00% | F5: 0-100
A6: O1 | B6: Hosted/service-delivery capacity | C6: 076_saas_options | D6: 0.2 | E6: 20.00% | F6: 0-100
A7: Total | D7: 1 | E7: 100.00%
A9: Zero-fill policy | B9: All unavailable, unknown, not applicable, or unrecognized values score 0; denominator stays five.
A10: Coverage threshold | B10: None

Sheet Verification
A1: Service | B1: Raw 058 affiliation text | C1: Provisional I2 score | D1: Override I2 (0/50/100) | E1: Final I2 score | F1: Reviewer notes
A2: 2i2c | C2: 0 | E2: =IF(ISNUMBER(D2),D2,C2) | F2: Enter 0, 50, or 100 only when correcting the provisional text coding.
A3: Academic Preservation Trust (APTrust) | B3: University of Virginia | C3: 50 | E3: =IF(ISNUMBER(D3),D3,C3) | F3: Enter 0, 50, or 100 only when correcting the provisional text coding.
A4: AfricArXiv | B4: Access 2 Perspectives coordinates AfricArXiv’s operations. This includes managing day-to-day activities, overseeing submission processes, ensuring quality control, and facilitating the integration of AfricArXiv with other scholarly services | C4: 100 | E4: =IF(ISNUMBER(D4),D4,C4) | F4: Enter 0, 50, or 100 only when correcting the provisional text coding.
A5: Arches Heritage Data Management Platform | B5: Getty Conservation Institute Farallon Geographics | C5: 50 | E5: =IF(ISNUMBER(D5),D5,C5) | F5: Enter 0, 50, or 100 only when correcting the provisional text coding.
A6: Archipelago Commons | C6: 0 | E6: =IF(ISNUMBER(D6),D6,C6) | F6: Enter 0, 50, or 100 only when correcting the provisional text coding.
A7: Archival Resource Key | C7: 0 | E7: =IF(ISNUMBER(D7),D7,C7) | F7: Enter 0, 50, or 100 only when correcting the provisional text coding.
A8: Archivematica | B8: No Affiliations | C8: 0 | E8: =IF(ISNUMBER(D8),D8,C8) | F8: Enter 0, 50, or 100 only when correcting the provisional text coding.
A9: ArchivesSpace | B9: New York University and the University of California San Diego are the founding partners and have permanent seats on the Board; Lyrasis is the organizational home | C9: 100 | E9: =IF(ISNUMBER(D9),D9,C9) | F9: Enter 0, 50, or 100 only when correcting the provisional text coding.
A10: ARGOS | B10: Athena Research Center (ARC) Communication & Information Technologies Experts (CITE) | C10: 50 | E10: =IF(ISNUMBER(D10),D10,C10) | F10: Enter 0, 50, or 100 only when correcting the provisional text coding.
A11: arXiv | C11: 0 | E11: =IF(ISNUMBER(D11),D11,C11) | F11: Enter 0, 50, or 100 only when correcting the provisional text coding.
A12: AtoM | B12: No affiliations | C12: 0 | E12: =IF(ISNUMBER(D12),D12,C12) | F12: Enter 0, 50, or 100 only when correcting the provisional text coding.
A13: Avalon Media System | B13: Indiana University Libraries | C13: 50 | E13: =IF(ISNUMBER(D13),D13,C13) | F13: Enter 0, 50, or 100 only when correcting the provisional text coding.
A14: Biodiversity Heritage Library | B14: BHL’s fiscal sponsor is the Council on Library and Information Resources (CLIR). | C14: 100 | E14: =IF(ISNUMBER(D14),D14,C14) | F14: Enter 0, 50, or 100 only when correcting the provisional text coding.
A15: bioRxiv | C15: 0 | E15: =IF(ISNUMBER(D15),D15,C15) | F15: Enter 0, 50, or 100 only when correcting the provisional text coding.
A16: BitCurator Environment | B16: BitCurator Consortium is administratively hosted by the Open Library Foundation. | C16: 100 | E16: =IF(ISNUMBER(D16),D16,C16) | F16: Enter 0, 50, or 100 only when correcting the provisional text coding.
A17: Blacklight | B17: See website | C17: 0 | E17: =IF(ISNUMBER(D17),D17,C17) | F17: Enter 0, 50, or 100 only when correcting the provisional text coding.
A18: BrCRIS | C18: 0 | E18: =IF(ISNUMBER(D18),D18,C18) | F18: Enter 0, 50, or 100 only when correcting the provisional text coding.
A19: Browsertrix | B19: No affiliations have direct involvement in governing or running our products except us. We are members of the International Internet Preservation Consortium (IIPC). | C19: 50 | E19: =IF(ISNUMBER(D19),D19,C19) | F19: Enter 0, 50, or 100 only when correcting the provisional text coding.
A20: CLOCKSS | B20: n/a | C20: 0 | E20: =IF(ISNUMBER(D20),D20,C20) | F20: Enter 0, 50, or 100 only when correcting the provisional text coding.
A21: COAR International Repository Directory (IRD) | B21: Responsible Organisations: https://ird.coar-repositories.org/about?lang=en | C21: 50 | E21: =IF(ISNUMBER(D21),D21,C21) | F21: Enter 0, 50, or 100 only when correcting the provisional text coding.
A22: COAR Notify | B22: No affiliations. | C22: 0 | E22: =IF(ISNUMBER(D22),D22,C22) | F22: Enter 0, 50, or 100 only when correcting the provisional text coding.
A23: CollectiveAccess | B23: No affiliations | C23: 0 | E23: =IF(ISNUMBER(D23),D23,C23) | F23: Enter 0, 50, or 100 only when correcting the provisional text coding.
A24: CORE | C24: 0 | E24: =IF(ISNUMBER(D24),D24,C24) | F24: Enter 0, 50, or 100 only when correcting the provisional text coding.
A25: COUNTER Code of Practice | C25: 0 | E25: =IF(ISNUMBER(D25),D25,C25) | F25: Enter 0, 50, or 100 only when correcting the provisional text coding.
A26: Creative Commons Licenses | C26: 0 | E26: =IF(ISNUMBER(D26),D26,C26) | F26: Enter 0, 50, or 100 only when correcting the provisional text coding.
A27: Crossref Metadata Retrieval | C27: 0 | E27: =IF(ISNUMBER(D27),D27,C27) | F27: Enter 0, 50, or 100 only when correcting the provisional text coding.
A28: D4Science Infrastructure | B28: D4Science is managed by the Italian National Research Council (CNR). Its headquarters are hosted by CNR's Institute of Information Science and Technologies "A. Faedo" (CNR-ISTI) in Pisa, Tuscany, Italy. | C28: 100 | E28: =IF(ISNUMBER(D28),D28,C28) | F28: Enter 0, 50, or 100 only when correcting the provisional text coding.
A29: DART (Digital Archivist's Resource Tool) | B29: University of Virginia | C29: 50 | E29: =IF(ISNUMBER(D29),D29,C29) | F29: Enter 0, 50, or 100 only when correcting the provisional text coding.
A30: Database Information System | B30: DBIS is operated by the University Library of Regensburg. | C30: 50 | E30: =IF(ISNUMBER(D30),D30,C30) | F30: Enter 0, 50, or 100 only when correcting the provisional text coding.
A31: Data Citation Corpus | B31: DataCite leads the development of the Data Citation Corpus as part of Make Data Count activities. | C31: 50 | E31: =IF(ISNUMBER(D31),D31,C31) | F31: Enter 0, 50, or 100 only when correcting the provisional text coding.
A32: DataCite | C32: 0 | E32: =IF(ISNUMBER(D32),D32,C32) | F32: Enter 0, 50, or 100 only when correcting the provisional text coding.
A33: Data Stewardship Wizard | B33: Czech Technical University in Prague / ELIXIR-CZ Codevence Solutions | C33: 50 | E33: =IF(ISNUMBER(D33),D33,C33) | F33: Enter 0, 50, or 100 only when correcting the provisional text coding.
A34: Dataverse | C34: 0 | E34: =IF(ISNUMBER(D34),D34,C34) | F34: Enter 0, 50, or 100 only when correcting the provisional text coding.
A35: DLCM Backend | B35: University of Geneva (https://www.unige.ch/) HEG, HES-SO (https://www.hesge.ch/heg/en) UNIFR (https://www.unifr.ch/home/en/) BFH (https://www.bfh.ch/en/) OLOS (https://olos.swiss/) | C35: 50 | E35: =IF(ISNUMBER(D35),D35,C35) | F35: Enter 0, 50, or 100 only when correcting the provisional text coding.
A36: DLCM Portal | B36: University of Geneva (https://www.unige.ch/)HEG, HES-SO (https://www.hesge.ch/heg/en)UNIFR (https://www.unifr.ch/home/en/)BFH (https://www.bfh.ch/en/)OLOS (https://olos.swiss/) | C36: 50 | E36: =IF(ISNUMBER(D36),D36,C36) | F36: Enter 0, 50, or 100 only when correcting the provisional text coding.
A37: DMP Tool | C37: 0 | E37: =IF(ISNUMBER(D37),D37,C37) | F37: Enter 0, 50, or 100 only when correcting the provisional text coding.
A38: DOAJ (Directory of Open Access Journals) | C38: 0 | E38: =IF(ISNUMBER(D38),D38,C38) | F38: Enter 0, 50, or 100 only when correcting the provisional text coding.
A39: dokieli | C39: 0 | E39: =IF(ISNUMBER(D39),D39,C39) | F39: Enter 0, 50, or 100 only when correcting the provisional text coding.
A40: Dryad | C40: 0 | E40: =IF(ISNUMBER(D40),D40,C40) | F40: Enter 0, 50, or 100 only when correcting the provisional text coding.
...

Sheet Affiliation Coding
A1: Service | B1: Raw 058 affiliation text | C1: Provisional score | D1: Coding rationale | E1: Override score | F1: Final score | G1: Review note
A2: 2i2c | C2: 0 | D2: Blank: zero under the agreed unavailable-data rule | F2: =Verification!E2 | G2: Use the override in Verification; this sheet mirrors the active score.
A3: Academic Preservation Trust (APTrust) | B3: University of Virginia | C3: 50 | D3: Substantive affiliation or membership reported; level of operational support not established | F3: =Verification!E3 | G3: Use the override in Verification; this sheet mirrors the active score.
A4: AfricArXiv | B4: Access 2 Perspectives coordinates AfricArXiv’s operations. This includes managing day-to-day activities, overseeing submission processes, ensuring quality control, and facilitating the integration of AfricArXiv with other scholarly services | C4: 100 | D4: Explicit host or operational/financial support language | F4: =Verification!E4 | G4: Use the override in Verification; this sheet mirrors the active score.
A5: Arches Heritage Data Management Platform | B5: Getty Conservation Institute Farallon Geographics | C5: 50 | D5: Substantive affiliation or membership reported; level of operational support not established | F5: =Verification!E5 | G5: Use the override in Verification; this sheet mirrors the active score.
A6: Archipelago Commons | C6: 0 | D6: Blank: zero under the agreed unavailable-data rule | F6: =Verification!E6 | G6: Use the override in Verification; this sheet mirrors the active score.
A7: Archival Resource Key | C7: 0 | D7: Blank: zero under the agreed unavailable-data rule | F7: =Verification!E7 | G7: Use the override in Verification; this sheet mirrors the active score.
A8: Archivematica | B8: No Affiliations | C8: 0 | D8: Explicit absence or placeholder | F8: =Verification!E8 | G8: Use the override in Verification; this sheet mirrors the active score.
A9: ArchivesSpace | B9: New York University and the University of California San Diego are the founding partners and have permanent seats on the Board; Lyrasis is the organizational home | C9: 100 | D9: Explicit host or operational/financial support language | F9: =Verification!E9 | G9: Use the override in Verification; this sheet mirrors the active score.
A10: ARGOS | B10: Athena Research Center (ARC) Communication & Information Technologies Experts (CITE) | C10: 50 | D10: Substantive affiliation or membership reported; level of operational support not established | F10: =Verification!E10 | G10: Use the override in Verification; this sheet mirrors the active score.
A11: arXiv | C11: 0 | D11: Blank: zero under the agreed unavailable-data rule | F11: =Verification!E11 | G11: Use the override in Verification; this sheet mirrors the active score.
A12: AtoM | B12: No affiliations | C12: 0 | D12: Explicit absence or placeholder | F12: =Verification!E12 | G12: Use the override in Verification; this sheet mirrors the active score.
A13: Avalon Media System | B13: Indiana University Libraries | C13: 50 | D13: Substantive affiliation or membership reported; level of operational support not established | F13: =Verification!E13 | G13: Use the override in Verification; this sheet mirrors the active score.
A14: Biodiversity Heritage Library | B14: BHL’s fiscal sponsor is the Council on Library and Information Resources (CLIR). | C14: 100 | D14: Explicit host or operational/financial support language | F14: =Verification!E14 | G14: Use the override in Verification; this sheet mirrors the active score.
A15: bioRxiv | C15: 0 | D15: Blank: zero under the agreed unavailable-data rule | F15: =Verification!E15 | G15: Use the override in Verification; this sheet mirrors the active score.
A16: BitCurator Environment | B16: BitCurator Consortium is administratively hosted by the Open Library Foundation. | C16: 100 | D16: Explicit host or operational/financial support language | F16: =Verification!E16 | G16: Use the override in Verification; this sheet mirrors the active score.
A17: Blacklight | B17: See website | C17: 0 | D17: Explicit absence or placeholder | F17: =Verification!E17 | G17: Use the override in Verification; this sheet mirrors the active score.
A18: BrCRIS | C18: 0 | D18: Blank: zero under the agreed unavailable-data rule | F18: =Verification!E18 | G18: Use the override in Verification; this sheet mirrors the active score.
A19: Browsertrix | B19: No affiliations have direct involvement in governing or running our products except us. We are members of the International Internet Preservation Consortium (IIPC). | C19: 50 | D19: Substantive affiliation or membership reported; level of operational support not established | F19: =Verification!E19 | G19: Use the override in Verification; this sheet mirrors the active score.
A20: CLOCKSS | B20: n/a | C20: 0 | D20: Explicit absence or placeholder | F20: =Verification!E20 | G20: Use the override in Verification; this sheet mirrors the active score.
A21: COAR International Repository Directory (IRD) | B21: Responsible Organisations: https://ird.coar-repositories.org/about?lang=en | C21: 50 | D21: Substantive affiliation or membership reported; level of operational support not established | F21: =Verification!E21 | G21: Use the override in Verification; this sheet mirrors the active score.
A22: COAR Notify | B22: No affiliations. | C22: 0 | D22: Explicit absence or placeholder | F22: =Verification!E22 | G22: Use the override in Verification; this sheet mirrors the active score.
A23: CollectiveAccess | B23: No affiliations | C23: 0 | D23: Explicit absence or placeholder | F23: =Verification!E23 | G23: Use the override in Verification; this sheet mirrors the active score.
A24: CORE | C24: 0 | D24: Blank: zero under the agreed unavailable-data rule | F24: =Verification!E24 | G24: Use the override in Verification; this sheet mirrors the active score.
A25: COUNTER Code of Practice | C25: 0 | D25: Blank: zero under the agreed unavailable-data rule | F25: =Verification!E25 | G25: Use the override in Verification; this sheet mirrors the active score.
A26: Creative Commons Licenses | C26: 0 | D26: Blank: zero under the agreed unavailable-data rule | F26: =Verification!E26 | G26: Use the override in Verification; this sheet mirrors the active score.
A27: Crossref Metadata Retrieval | C27: 0 | D27: Blank: zero under the agreed unavailable-data rule | F27: =Verification!E27 | G27: Use the override in Verification; this sheet mirrors the active score.
A28: D4Science Infrastructure | B28: D4Science is managed by the Italian National Research Council (CNR). Its headquarters are hosted by CNR's Institute of Information Science and Technologies "A. Faedo" (CNR-ISTI) in Pisa, Tuscany, Italy. | C28: 100 | D28: Explicit host or operational/financial support language | F28: =Verification!E28 | G28: Use the override in Verification; this sheet mirrors the active score.
A29: DART (Digital Archivist's Resource Tool) | B29: University of Virginia | C29: 50 | D29: Substantive affiliation or membership reported; level of operational support not established | F29: =Verification!E29 | G29: Use the override in Verification; this sheet mirrors the active score.
A30: Database Information System | B30: DBIS is operated by the University Library of Regensburg. | C30: 50 | D30: Substantive affiliation or membership reported; level of operational support not established | F30: =Verification!E30 | G30: Use the override in Verification; this sheet mirrors the active score.
A31: Data Citation Corpus | B31: DataCite leads the development of the Data Citation Corpus as part of Make Data Count activities. | C31: 50 | D31: Substantive affiliation or membership reported; level of operational support not established | F31: =Verification!E31 | G31: Use the override in Verification; this sheet mirrors the active score.
A32: DataCite | C32: 0 | D32: Blank: zero under the agreed unavailable-data rule | F32: =Verification!E32 | G32: Use the override in Verification; this sheet mirrors the active score.
A33: Data Stewardship Wizard | B33: Czech Technical University in Prague / ELIXIR-CZ Codevence Solutions | C33: 50 | D33: Substantive affiliation or membership reported; level of operational support not established | F33: =Verification!E33 | G33: Use the override in Verification; this sheet mirrors the active score.
A34: Dataverse | C34: 0 | D34: Blank: zero under the agreed unavailable-data rule | F34: =Verification!E34 | G34: Use the override in Verification; this sheet mirrors the active score.
A35: DLCM Backend | B35: University of Geneva (https://www.unige.ch/) HEG, HES-SO (https://www.hesge.ch/heg/en) UNIFR (https://www.unifr.ch/home/en/) BFH (https://www.bfh.ch/en/) OLOS (https://olos.swiss/) | C35: 50 | D35: Substantive affiliation or membership reported; level of operational support not established | F35: =Verification!E35 | G35: Use the override in Verification; this sheet mirrors the active score.
A36: DLCM Portal | B36: University of Geneva (https://www.unige.ch/)HEG, HES-SO (https://www.hesge.ch/heg/en)UNIFR (https://www.unifr.ch/home/en/)BFH (https://www.bfh.ch/en/)OLOS (https://olos.swiss/) | C36: 50 | D36: Substantive affiliation or membership reported; level of operational support not established | F36: =Verification!E36 | G36: Use the override in Verification; this sheet mirrors the active score.
A37: DMP Tool | C37: 0 | D37: Blank: zero under the agreed unavailable-data rule | F37: =Verification!E37 | G37: Use the override in Verification; this sheet mirrors the active score.
A38: DOAJ (Directory of Open Access Journals) | C38: 0 | D38: Blank: zero under the agreed unavailable-data rule | F38: =Verification!E38 | G38: Use the override in Verification; this sheet mirrors the active score.
A39: dokieli | C39: 0 | D39: Blank: zero under the agreed unavailable-data rule | F39: =Verification!E39 | G39: Use the override in Verification; this sheet mirrors the active score.
A40: Dryad | C40: 0 | D40: Blank: zero under the agreed unavailable-data rule | F40: =Verification!E40 | G40: Use the override in Verification; this sheet mirrors the active score.
...

Sheet Calc
A1: Service | B1: M1 Technology readiness | C1: M2 Maintenance | D1: Full-time staffing subscore | E1: Volunteer staffing subscore | F1: H1 Human resources | G1: I2 Provisional affiliations | H1: I2 rationale | I1: O1 Service delivery | J1: Python-checked total | K1: Scoring flags
A2: 2i2c | B2: 100 | C2: 100 | D2: 0 | E2: 0 | F2: 0 | G2: 0 | H2: Blank: zero under the agreed unavailable-data rule | I2: 0 | J2: 40 | K2: Full-time staffing missing/unknown scored 0; Volunteer staffing missing/unknown scored 0; Service-delivery field not applicable/unknown scored 0
A3: Academic Preservation Trust (APTrust) | B3: 100 | C3: 100 | D3: 25 | E3: 0 | F3: 12.5 | G3: 50 | H3: Substantive affiliation or membership reported; level of operational support not established | I3: 100 | J3: 72.5 | K3: Volunteer staffing missing/unknown scored 0; Review affiliation coding; override available
A4: AfricArXiv | B4: 100 | C4: 100 | D4: 25 | E4: 25 | F4: 25 | G4: 100 | H4: Explicit host or operational/financial support language | I4: 0 | J4: 65 | K4: Review affiliation coding; override available; Service-delivery field not applicable/unknown scored 0
A5: Arches Heritage Data Management Platform | B5: 100 | C5: 100 | D5: 0 | E5: 0 | F5: 0 | G5: 50 | H5: Substantive affiliation or membership reported; level of operational support not established | I5: 100 | J5: 70 | K5: Full-time staffing missing/unknown scored 0; Volunteer staffing missing/unknown scored 0; Review affiliation coding; override available
A6: Archipelago Commons | B6: 100 | C6: 100 | D6: 0 | E6: 0 | F6: 0 | G6: 0 | H6: Blank: zero under the agreed unavailable-data rule | I6: 100 | J6: 60 | K6: Full-time staffing missing/unknown scored 0; Volunteer staffing missing/unknown scored 0
A7: Archival Resource Key | B7: 55.555556 | C7: 100 | D7: 0 | E7: 0 | F7: 0 | G7: 0 | H7: Blank: zero under the agreed unavailable-data rule | I7: 0 | J7: 31.111111 | K7: Full-time staffing missing/unknown scored 0; Volunteer staffing missing/unknown scored 0; Service-delivery field not applicable/unknown scored 0
A8: Archivematica | B8: 100 | C8: 100 | D8: 100 | E8: 0 | F8: 50 | G8: 0 | H8: Explicit absence or placeholder | I8: 100 | J8: 70 | K8: Volunteer staffing missing/unknown scored 0; Review affiliation coding; override available
A9: ArchivesSpace | B9: 100 | C9: 100 | D9: 50 | E9: 0 | F9: 25 | G9: 100 | H9: Explicit host or operational/financial support language | I9: 100 | J9: 85 | K9: Volunteer staffing missing/unknown scored 0; Review affiliation coding; override available
A10: ARGOS | B10: 100 | C10: 100 | D10: 0 | E10: 0 | F10: 0 | G10: 50 | H10: Substantive affiliation or membership reported; level of operational support not established | I10: 100 | J10: 70 | K10: Full-time staffing missing/unknown scored 0; Volunteer staffing missing/unknown scored 0; Review affiliation coding; override available
A11: arXiv | B11: 100 | C11: 100 | D11: 0 | E11: 0 | F11: 0 | G11: 0 | H11: Blank: zero under the agreed unavailable-data rule | I11: 0 | J11: 40 | K11: Full-time staffing missing/unknown scored 0; Volunteer staffing missing/unknown scored 0; Service-delivery field not applicable/unknown scored 0
A12: AtoM | B12: 100 | C12: 100 | D12: 100 | E12: 0 | F12: 50 | G12: 0 | H12: Explicit absence or placeholder | I12: 100 | J12: 70 | K12: Review affiliation coding; override available
A13: Avalon Media System | B13: 100 | C13: 100 | D13: 25 | E13: 0 | F13: 12.5 | G13: 50 | H13: Substantive affiliation or membership reported; level of operational support not established | I13: 0 | J13: 52.5 | K13: Volunteer staffing missing/unknown scored 0; Review affiliation coding; override available
... A36: DLCM Portal | B36: 100 | C36: 100 | D36: 25 | E36: 25 | F36: 25 | G36: 50 | H36: Substantive affiliation or membership reported; level of operational support not established | I36: 100 | J36: 75 | K36: Review affiliation coding; override available
A37: DMP Tool | B37: 100 | C37: 100 | D37: 25 | E37: 0 | F37: 12.5 | G37: 0 | H37: Blank: zero under the agreed unavailable-data rule | I37: 100 | J37: 62.5
A38: DOAJ (Directory of Open Access Journals) | B38: 100 | C38: 100 | D38: 0 | E38: 0 | F38: 0 | G38: 0 | H38: Blank: zero under the agreed unavailable-data rule | I38: 0 | J38: 40 | K38: Full-time staffing missing/unknown scored 0; Volunteer staffing missing/unknown scored 0; Service-delivery field not applicable/unknown scored 0
A39: dokieli | B39: 55.555556 | C39: 100 | D39: 0 | E39: 0 | F39: 0 | G39: 0 | H39: Blank: zero under the agreed unavailable-data rule | I39: 0 | J39: 31.111111 | K39: Full-time staffing missing/unknown scored 0; Volunteer staffing missing/unknown scored 0; Service-delivery field not applicable/unknown scored 0
A40: Dryad | B40: 100 | C40: 100 | D40: 0 | E40: 0 | F40: 0 | G40: 0 | H40: Blank: zero under the agreed unavailable-data rule | I40: 0 | J40: 40 | K40: Full-time staffing missing/unknown scored 0; Volunteer staffing missing/unknown scored 0; Service-delivery field not applicable/unknown scored 0
A41: DSpace | B41: 100 | C41: 100 | D41: 25 | E41: 0 | F41: 12.5 | G41: 0 | H41: Blank: zero under the agreed unavailable-data rule | I41: 100 | J41: 62.5
A42: DuraCloud | B42: 100 | C42: 100 | D42: 0 | E42: 0 | F42: 0 | G42: 0 | H42: Explicit absence or placeholder | I42: 100 | J42: 60 | K42: Full-time staffing missing/unknown scored 0; Volunteer staffing missing/unknown scored 0; Review affiliation coding; override available
A43: Episciences | B43: 100 | C43: 100 | D43: 25 | E43: 100 | F43: 62.5 | G43: 50 | H43: Substantive affiliation or membership reported; level of operational support not established | I43: 0 | J43: 62.5 | K43: Review affiliation coding; override available; Service-delivery field not applicable/unknown scored 0
A44: EPrints | B44: 100 | C44: 100 | D44: 0 | E44: 0 | F44: 0 | G44: 50 | H44: Substantive affiliation or membership reported; level of operational support not established | I44: 100 | J44: 70 | K44: Full-time staffing missing/unknown scored 0; Volunteer staffing missing/unknown scored 0; Review affiliation coding; override available
A45: Érudit | B45: 100 | C45: 100 | D45: 0 | E45: 0 | F45: 0 | G45: 0 | H45: Blank: zero under the agreed unavailable-data rule | I45: 0 | J45: 40 | K45: Full-time staffing missing/unknown scored 0; Volunteer staffing missing/unknown scored 0; Service-delivery field not applicable/unknown scored 0
A46: Europe PMC | B46: 100 | C46: 100 | D46: 75 | E46: 0 | F46: 37.5 | G46: 0 | H46: Blank: zero under the agreed unavailable-data rule | I46: 0 | J46: 47.5 | K46: Volunteer staffing missing/unknown scored 0; Service-delivery field not applicable/unknown scored 0
A47: FAIR Wizard | B47: 100 | C47: 100 | D47: 25 | E47: 0 | F47: 12.5 | G47: 50 | H47: Substantive affiliation or membership reported; level of operational support not established | I47: 100 | J47: 72.5 | K47: Volunteer staffing missing/unknown scored 0; Review affiliation coding; override available
A48: Fedora | B48: 100 | C48: 100 | D48: 25 | E48: 0 | F48: 12.5 | G48: 0 | H48: Blank: zero under the agreed unavailable-data rule | I48: 100 | J48: 62.5
A49: fido | B49: 100 | C49: 100 | D49: 50 | E49: 0 | F49: 25 | G49: 50 | H49: Substantive affiliation or membership reported; level of operational support not established | I49: 0 | J49: 55 | K49: Volunteer staffing missing/unknown scored 0; Review affiliation coding; override available; Service-delivery field not applicable/unknown scored 0
A50: Fulcrum | B50: 100 | C50: 100 | D50: 0 | E50: 0 | F50: 0 | G50: 0 | H50: Blank: zero under the agreed unavailable-data rule | I50: 100 | J50: 60 | K50: Full-time staffing missing/unknown scored 0; Volunteer staffing missing/unknown scored 0
A51: Galaxy | B51: 100 | C51: 100 | D51: 100 | E51: 100 | F51: 100 | G51: 50 | H51: Substantive affiliation or membership reported; level of operational support not established | I51: 100 | J51: 90 | K51: Review affiliation coding; override available
A52: GeoServer | B52: 100 | C52: 100 | D52: 0 | E52: 100 | F52: 50 | G52: 50 | H52: Substantive affiliation or membership reported; level of operational support not established | I52: 100 | J52: 80 | K52: Review affiliation coding; override available
A53: Hyku | B53: 100 | C53: 100 | D53: 25 | E53: 25 | F53: 25 | G53: 0 | H53: Blank: zero under the agreed unavailable-data rule | I53: 100 | J53: 65
A54: Hyrax | B54: 100 | C54: 100 | D54: 25 | E54: 25 | F54: 25 | G54: 0 | H54: Explicit absence or placeholder | I54: 100 | J54: 65 | K54: Review affiliation coding; override available
A55: IIIF | B55: 100 | C55: 100 | D55: 0 | E55: 0 | F55: 0 | G55: 0 | H55: Blank: zero under the agreed unavailable-data rule | I55: 0 | J55: 40 | K55: Full-time staffing missing/unknown scored 0; Volunteer staffing missing/unknown scored 0; Service-delivery field not applicable/unknown scored 0
A56: ImpactU | B56: 100 | C56: 100 | D56: 0 | E56: 0 | F56: 0 | G56: 50 | H56: Substantive affiliation or membership reported; level of operational support not established | I56: 100 | J56: 70 | K56: Full-time staffing missing/unknown scored 0; Volunteer staffing missing/unknown scored 0; Review affiliation coding; override available
A57: International Generic Sample Number (IGSN) | B57: 100 | C57: 100 | D57: 25 | E57: 75 | F57: 50 | G57: 50 | H57: Substantive affiliation or membership reported; level of operational support not established | I57: 100 | J57: 80 | K57: Review affiliation coding; override available
A58: InvenioRDM | B58: 88.888889 | C58: 100 | D58: 0 | E58: 0 | F58: 0 | G58: 0 | H58: Blank: zero under the agreed unavailable-data rule | I58: 0 | J58: 37.777778 | K58: Full-time staffing missing/unknown scored 0; Volunteer staffing missing/unknown scored 0
A59: iRODS | B59: 100 | C59: 100 | D59: 50 | E59: 0 | F59: 25 | G59: 50 | H59: Substantive affiliation or membership reported; level of operational support not established | I59: 100 | J59: 75 | K59: Review affiliation coding; override available
A60: Islandora | B60: 100 | C60: 100 | D60: 0 | E60: 0 | F60: 0 | G60: 0 | H60: Blank: zero under the agreed unavailable-data rule | I60: 100 | J60: 60 | K60: Full-time staffing missing/unknown scored 0; Volunteer staffing missing/unknown scored 0
A61: Janeway | B61: 100 | C61: 100 | D61: 0 | E61: 0 | F61: 0 | G61: 0 | H61: Blank: zero under the agreed unavailable-data rule | I61: 100 | J61: 60 | K61: Full-time staffing missing/unknown scored 0; Volunteer staffing missing/unknown scored 0
A62: JHOVE | B62: 100 | C62: 100 | D62: 25 | E62: 0 | F62: 12.5 | G62: 50 | H62: Substantive affiliation or membership reported; level of operational support not established | I62: 0 | J62: 52.5 | K62: Review affiliation coding; override available
...

Sheet Data
A1: 001_service_name | B1: 008_provider_name | C1: 010_website | D1: 013_location | E1: 014_solution_category | F1: 019_open_code_repository_url | G1: 017_funding_needs | H1: 051_business_form | I1: 951_business_form_other | J1: 052_nonprofit_status | K1: 053_shareholders | L1: 054_staffing_full_time | M1: 055_staffing_volunteer | N1: 056_launch_date | O1: 057_organizational_history | P1: 058_affiliations | Q1: 059_founders | R1: 061_primary_funding_source | S1: 961_primary_funding_source_other | T1: 076_saas_options | U1: 077_registered_service_providers | V1: 079_technology_readiness | W1: 080_maintenance_status | X1: 099_scoss | Y1: verification_status | Z1: verification_notes
A2: 2i2c | B2: Code for Science and Society | C2: https://2i2c.org/ | D2: US | E2: Authoring tool | F2: https://github.com/2i2c-org/infrastructure | G2: <p>2i2c aims to identify a self-sustaining cost recovery model with ongoing service fees for communities that it partners with in managing cloud infrastructure. We also pursue several other funding streams to advance our mission in open infrastructure for open science.</p> <p>Below are a few areas where we are actively seeking funding.</p> <p> <ul> <li> Cloud and service costs for one or more communities that cannot afford the full price of a monthly service. <li> Development projects to enhance open source technology that is critical for open science and education. <li> Broader community and technical support for the key open source communities in which we participate. <li> Organizational service development funding runway to explore and refine our model for sustainably serving infrastructure. </ul> </p> | H2: Fiscal sponsorship (non-profit) | K2: FALSE | N2: 2020-01-01 | O2: <p>2i2c was created by its current Steering Council, who also act as its founding partners. This group roughly came from three projects that similarly operated cloud infrastructure for interactive computing:</p> <p> <ul> <li> The Berkeley DataHub is an institution-wide JupyterHub that was led in-part by Yuvi Panda, Chris Holdgraf, Cathryn Carson, and Fernando Perez. <li> The Syzygy project (<a href="https://syzygy.ca">https://syzygy.ca</a>) is a network of JupyterHubs for Canadian universities that was led in-part by Jim Colliander. <li> The Pangeo project (<a href="https://pangeo.io">https://pangeo.io</a>) is a community platform for Big Data geoscience that is built on a JupyterHub and cloud computing, and is led in-part by Ryan Abernathey. </ul> </p> <p>Each of these projects demonstrated considerable value for the communities it served, but it was also clear that this model was unsustainable for most other communities of practice due to difficulties in hiring for cloud engineering skills.</p> <p>As a result, communities tended to use proprietary services that weren't aligned with the values many of us identified with (e.g., community-driven infrastructure, values-based organizations, non-profit structures, etc).</p> <p>We created 2i2c in order to have a mission-driven and community-focused organization that could design and manage cloud infrastructure on behalf of communities of practice, but that framed the partnership as a collaboration based around shared responsibility and transparency rather than a pure "consumer / producer relationship". We also wanted to ensure that 2i2c would commit to making upstream contributions and support as part of its key mission, in order to avoid the extractive relationship many organizations have with open source.</p> | R2: Contributions | T2: Not applicable | V2: Actual system proven in operational environment | W2: Actively Maintained | X2: FALSE
