Workbook

Sheet Method
A1: OISI Component 2 - Governance Practices: scoring workbook
A2: Source: OISI_112_Governance_Practices_Verification.xlsm (112 services from Infra Finder v3) + 02_Governance_Practices_OISI.docx (specification).
A4: HOW A SCORE IS BUILT
A5: 1. Each status variable -> 0-1 via the ladder on Parameters (Implemented 1, In progress 0.67, Considering 0.33, Not planning 0). Unknown / Not applicable = NA (missing, not zero).
A6: 2. Presence variables (050 board structure, 046 values frameworks) -> 1 if any value is listed, else the blank rule on Parameters (default 0).
A7: 3. Sub-component score = weighted mean of its metrics that are observed (weights renormalised over non-missing metrics).
A8: 4. Component score = 100 x weighted mean of sub-components that are observed (Formal 40%, Participatory 25%, Transparency 35%).
A9: 5. A score is published only if completeness (observed weight / total weight in the data) >= 70% AND Formal and Transparency both have a value.
A10: 6. Evidence confidence (0-100%) = share of a repo's "Implemented" claims that carry an evidence URL. It is a reliability flag, NOT part of the score.
A12: THREE ISSUES YOU SHOULD DECIDE BEFORE PUBLISHING
A13: A. 048_community_governance_status now comes from OISI_112_Community_Engagement_Verification.xlsx (rows matched by order and service name, 112/112). Values: Formal 52, Ad hoc 35, blank 25. The spec's explicit None never appears, so blank is treated as absent (0) by default - the strongest assumption in the model; switch on Parameters!B21.
A14: B. 100_board_level is only 13% complete (15/112), so it is reported descriptively and its 5 points go to 048 (Participatory = 048 alone), as your spec allows.
... A21: - The scale is ordinal and self-reported; treat score differences of a few points as ties.

Sheet Parameters
A1: OISI Component 2 - Governance Practices: scoring parameters
A2: Blue = editable input. Every score in the "Scores" sheet recalculates from these cells.
A4: Status label | B4: Score (0-1) | C4: Used by | E4: Variable | F4: Sub-component | G4: Weight (pts of 100) | H4: Column in data? (1/0) | I4: Effective weight | J4: Justification / status
A5: Implemented/available | B5: 1 | C5: status metrics | E5: 024_governance_structure_status | F5: Formal | G5: 12 | H5: 1 | I5: =G5*H5 -> 12 | J5: Core: documented governance structure. 100% coverage.
A6: No direct costs | B6: 1 | C6: 033 only (per working rule) | E6: 026_governance_records_status | F6: Formal | G6: 12 | H6: 1 | I6: =G6*H6 -> 12 | J6: Core: public decision records = accountability evidence. 100% coverage.
A7: In progress | B7: 0.67 | C7: status metrics | E7: 108_bylaws_status | F7: Formal | G7: 8 | H7: 1 | I7: =G7*H7 -> 8 | J7: Core: formal rules. 26% Unknown -> NA, renormalised.
A8: Considering | B8: 0.33 | C8: status metrics | E8: 050_board_structure | F8: Formal | G8: 8 | H8: 1 | I8: =G8*H8 -> 8 | J8: Presence of any board/steering body. Type kept descriptive (no ranking of types).
A9: Not planning | B9: 0 | C9: status metrics | E9: 048_community_governance_status | F9: Participatory | G9: 20 | H9: 1 | I9: =G9*H9 -> 20 | J9: From OISI_112_Community_Engagement_Verification.xlsx (matched by row and service name). Formal 1 / Ad hoc 0.5 / blank = setting B21.
A10: Unknown | B10: NA | C10: treated as missing | E10: 100_board_level | F10: Participatory | G10: 5 | H10: 0 | I10: =G10*H10 -> 0 | J10: Descriptive only: 15/112 complete (13%). Its 5 pts go to 048 per working rule.
A11: Not applicable | B11: NA | C11: treated as missing | E11: 029_web_accessibility_status | F11: Transparency | G11: 7 | H11: 1 | I11: =G11*H11 -> 7 | J11: Core. 031 applicability retained as context.
A12: Formal | B12: 1 | C12: 048 (not in current file) | E12: 033_transparent_pricing_status | F12: Transparency | G12: 7 | H12: 1 | I12: =G12*H12 -> 7 | J12: Core, but 95% at ceiling: low discrimination (see Diagnostics).
A13: Ad hoc | B13: 0.5 | C13: 048 (not in current file) | E13: 035_commitment_to_equity_status | F13: Transparency | G13: 7 | H13: 1 | I13: =G13*H13 -> 7 | J13: Core.
A14: None | B14: 0 | C14: 048 (not in current file) | E14: 044_commitment_to_privacy_status | F14: Transparency | G14: 7 | H14: 1 | I14: =G14*H14 -> 7 | J14: Core.
E15: 046_values_frameworks | F15: Transparency | G15: 7 | H15: 1 | I15: =G15*H15 -> 7 | J15: Presence of >=1 named framework. Blank treated as absent (see setting below).
A17: Settings | E17: Sub-component | F17: Weight
A18: Blank 050_board_structure scored as (0 or NA) | B18: 0 | E18: Formal | F18: 0.4
A19: Blank 046_values_frameworks scored as (0 or NA) | B19: 0 | E19: Participatory | F19: 0.25
A20: Minimum completeness to publish a score | B20: 0.7 | E20: Transparency | F20: 0.35
A21: Blank 048_community_governance_status scored as (0 or NA) | B21: 0 | E21: Check: sum | F21: =SUM(F18:F20) -> 1
A22: Why blank = 0 for 050, 046 and 048 (deviation from the working "blank = NA" rule): these fields have no explicit absent option. For 050 and 046 every observed value would be 1 (zero variance). For 048 the file has only Formal (52) and Ad hoc (35) plus 25 blanks; the spec's None category never appears, so blank is the only way absence is recorded. Evidence: 76% of blank-048 repos have a governance structure that is not Implemented (vs 21% of the rest), only 1 of 25 gives a 048 URL (vs 55 of 87), and 54% of blank-050 repos report Not planning bylaws vs 9%. Switch B18/B19/B21 to NA to see the effect (Sensitivity sheet).

Sheet Scores
A1: Service | B1: Provider | C1: Solution category | D1: 024 Governance structure | E1: 026 Governance records | F1: 108 Bylaws | G1: 050 Board structure | H1: 100 Board level (descriptive) | I1: 048 Community governance | J1: 029 Web accessibility | K1: 033 Transparent pricing | L1: 035 Equity commitment | M1: 044 Privacy commitment | N1: 046 Values frameworks | O1: 025 URL | P1: 028 URL | Q1: 030 URL | R1: 034 URL | S1: 036 URL | T1: 045 URL | U1: 049 URL | V1: s024 | W1: s026 | X1: s108 | Y1: s050 | Z1: s048 | AA1: s029 | AB1: s033 | AC1: s035 | AD1: s044 | AE1: s046 | AF1: Formal (0-1) | AG1: Participatory (0-1) | AH1: Transparency (0-1) | AI1: Weight observed | AJ1: Completeness | AK1: Governance score (0-100) | AL1: Rank | AM1: Evidence confidence
A2: ArchivesSpace | B2: ArchivesSpace | C2: Archive information management system | Discovery system | D2: Implemented/available | E2: Implemented/available | F2: Implemented/available | G2: Advisory board or steering committee | I2: Formal | J2: Implemented/available | K2: Implemented/available | L2: Implemented/available | M2: Implemented/available | N2: It Takes a Village Open Source Software Sustainability toolkit | O2: https://archivesspace.org/governance-board-and-councils | P2: https://archivesspace.atlassian.net/wiki/spaces/AC/overview | Q2: https://archivesspace.org/application/accessibility-vpat | R2: https://archivesspace.org/membership/member-benefits | S2: https://archivesspace.org/about/anti-racism-inclusion-initiatives | T2: https://archivesspace.org/about/lyrasis-privacy-policy | U2: https://archivesspace.org/governance-board-and-councils | V2: =IFERROR(IF(ISNUMBER(INDEX(Parameters!$B$5:$B$14,MATCH(D2,Parameters!$A$5:$A$14,0))),INDEX(Parameters!$B$5:$B$14,MATCH(D2,Parameters!$A$5:$A$14,0)),""),"") -> 1 | W2: =IFERROR(IF(ISNUMBER(INDEX(Parameters!$B$5:$B$14,MATCH(E2,Parameters!$A$5:$A$14,0))),INDEX(Parameters!$B$5:$B$14,MATCH(E2,Parameters!$A$5:$A$14,0)),""),"") -> 1 | X2: =IFERROR(IF(ISNUMBER(INDEX(Parameters!$B$5:$B$14,MATCH(F2,Parameters!$A$5:$A$14,0))),INDEX(Parameters!$B$5:$B$14,MATCH(F2,Parameters!$A$5:$A$14,0)),""),"") -> 1 | Y2: =IF(G2<>"",1,IF(ISNUMBER(Parameters!$B$18),Parameters!$B$18,"")) -> 1 | Z2: =IF(I2<>"",IFERROR(IF(ISNUMBER(INDEX(Parameters!$B$5:$B$14,MATCH(I2,Parameters!$A$5:$A$14,0))),INDEX(Parameters!$B$5:$B$14,MATCH(I2,Parameters!$A$5:$A$14,0)),""),""),IF(ISNUMBER(Parameters!$B$21),Parameters!$B$21,"")) -> 1 | AA2: =IFERROR(IF(ISNUMBER(INDEX(Parameters!$B$5:$B$14,MATCH(J2,Parameters!$A$5:$A$14,0))),INDEX(Parameters!$B$5:$B$14,MATCH(J2,Parameters!$A$5:$A$14,0)),""),"") -> 1 | AB2: =IFERROR(IF(ISNUMBER(INDEX(Parameters!$B$5:$B$14,MATCH(K2,Parameters!$A$5:$A$14,0))),INDEX(Parameters!$B$5:$B$14,MATCH(K2,Parameters!$A$5:$A$14,0)),""),"") -> 1 | AC2: =IFERROR(IF(ISNUMBER(INDEX(Parameters!$B$5:$B$14,MATCH(L2,Parameters!$A$5:$A$14,0))),INDEX(Parameters!$B$5:$B$14,MATCH(L2,Parameters!$A$5:$A$14,0)),""),"") -> 1 | AD2: =IFERROR(IF(ISNUMBER(INDEX(Parameters!$B$5:$B$14,MATCH(M2,Parameters!$A$5:$A$14,0))),INDEX(Parameters!$B$5:$B$14,MATCH(M2,Parameters!$A$5:$A$14,0)),""),"") -> 1 | AE2: =IF(N2<>"",1,IF(ISNUMBER(Parameters!$B$19),Parameters!$B$19,"")) -> 1 | AF2: =IF((Parameters!$I$5*ISNUMBER(V2)+Parameters!$I$6*ISNUMBER(W2)+Parameters!$I$7*ISNUMBER(X2)+Parameters!$I$8*ISNUMBER(Y2))=0,"",(Parameters!$I$5*N(V2)+Parameters!$I$6*N(W2)+Parameters!$I$7*N(X2)+Parameters!$I$8*N(Y2))/(Parameters!$I$5*ISNUMBER(V2)+Parameters!$I$6*ISNUMBER(W2)+Parameters!$I$7*ISNUMBER(X2)+Parameters!$I$8*ISNUMBER(Y2))) -> 1 | AG2: =IF((Parameters!$I$9*ISNUMBER(Z2))=0,"",(Parameters!$I$9*N(Z2))/(Parameters!$I$9*ISNUMBER(Z2))) -> 1 | AH2: =IF((Parameters!$I$11*ISNUMBER(AA2)+Parameters!$I$12*ISNUMBER(AB2)+Parameters!$I$13*ISNUMBER(AC2)+Parameters!$I$14*ISNUMBER(AD2)+Parameters!$I$15*ISNUMBER(AE2))=0,"",(Parameters!$I$11*N(AA2)+Parameters!$I$12*N(AB2)+Parameters!$I$13*N(AC2)+Parameters!$I$14*N(AD2)+Parameters!$I$15*N(AE2))/(Parameters!$I$11*ISNUMBER(AA2)+Parameters!$I$12*ISNUMBER(AB2)+Parameters!$I$13*ISNUMBER(AC2)+Parameters!$I$14*ISNUMBER(AD2)+Parameters!$I$15*ISNUMBER(AE2))) -> 1 | AI2: =Parameters!$I$5*ISNUMBER(V2)+Parameters!$I$6*ISNUMBER(W2)+Parameters!$I$7*ISNUMBER(X2)+Parameters!$I$8*ISNUMBER(Y2)+Parameters!$I$9*ISNUMBER(Z2)+Parameters!$I$11*ISNUMBER(AA2)+Parameters!$I$12*ISNUMBER(AB2)+Parameters!$I$13*ISNUMBER(AC2)+Parameters!$I$14*ISNUMBER(AD2)+Parameters!$I$15*ISNUMBER(AE2) -> 95 | AJ2: =IF((Parameters!$I$5+Parameters!$I$6+Parameters!$I$7+Parameters!$I$8+Parameters!$I$9+Parameters!$I$11+Parameters!$I$12+Parameters!$I$13+Parameters!$I$14+Parameters!$I$15)=0,"",AI2/(Parameters!$I$5+Parameters!$I$6+Parameters!$I$7+Parameters!$I$8+Parameters!$I$9+Parameters!$I$11+Parameters!$I$12+Parameters!$I$13+Parameters!$I$14+Parameters!$I$15)) -> 1 | AK2: =IF(AND(ISNUMBER(AF2),ISNUMBER(AH2),OR(NOT((Parameters!$I$9)>0),ISNUMBER(AG2)),AJ2>=Parameters!$B$20),100*(Parameters!$F$18*N(AF2)+Parameters!$F$19*N(AG2)+Parameters!$F$20*N(AH2))/(Parameters!$F$18*ISNUMBER(AF2)+Parameters!$F$19*ISNUMBER(AG2)+Parameters!$F$20*ISNUMBER(AH2)),"") -> 100 | AL2: =IF(ISNUMBER(AK2),RANK(AK2,$AK$2:$AK$113),"") -> 1 | AM2: =IF(((D2="Implemented/available")+(E2="Implemented/available")+(J2="Implemented/available")+(K2="Implemented/available")+(L2="Implemented/available")+(M2="Implemented/available"))=0,"",(AND(D2="Implemented/available",O2<>"")+AND(E2="Implemented/available",P2<>"")+AND(J2="Implemented/available",Q2<>"")+AND(K2="Implemented/available",R2<>"")+AND(L2="Implemented/available",S2<>"")+AND(M2="Implemented/available",T2<>""))/((D2="Implemented/available")+(E2="Implemented/available")+(J2="Implemented/available")+(K2="Implemented/available")+(L2="Implemented/available")+(M2="Implemented/available"))) -> 1
A3: DOAJ (Directory of Open Access Journals) | B3: DOAJ Foundation | C3: Discovery system | Index or directory | Open scholarly dataset | D3: Implemented/available | E3: Implemented/available | F3: Implemented/available | G3: Advisory board or steering committee | Other | I3: Formal | J3: Implemented/available | K3: Implemented/available | L3: Implemented/available | M3: Implemented/available | N3: FOREST Framework for Values-Driven Scholarly Communication | Helsinki Initiative on Multilingualism | Joint Statement of Principles of the Coalition for Diversity and Inclusion in Scholarly Communication (C4DISC) | Principles for Open Scholarly Infrastructure (POSI) | San Francisco Declaration on Research Assessment (DORA) | O3: https://doaj.org/about/advisory-board-council/ | P3: https://doaj.org/about/advisory-board-council/ | R3: https://doaj.org/support/ | S3: https://doaj.org/about/#diversity-equity-and-inclusion | T3: https://doaj.org/privacy/ | U3: https://doaj.org/about/advisory-board-council/ | V3: =IFERROR(IF(ISNUMBER(INDEX(Parameters!$B$5:$B$14,MATCH(D3,Parameters!$A$5:$A$14,0))),INDEX(Parameters!$B$5:$B$14,MATCH(D3,Parameters!$A$5:$A$14,0)),""),"") -> 1 | W3: =IFERROR(IF(ISNUMBER(INDEX(Parameters!$B$5:$B$14,MATCH(E3,Parameters!$A$5:$A$14,0))),INDEX(Parameters!$B$5:$B$14,MATCH(E3,Parameters!$A$5:$A$14,0)),""),"") -> 1 | X3: =IFERROR(IF(ISNUMBER(INDEX(Parameters!$B$5:$B$14,MATCH(F3,Parameters!$A$5:$A$14,0))),INDEX(Parameters!$B$5:$B$14,MATCH(F3,Parameters!$A$5:$A$14,0)),""),"") -> 1 | Y3: =IF(G3<>"",1,IF(ISNUMBER(Parameters!$B$18),Parameters!$B$18,"")) -> 1 | Z3: =IF(I3<>"",IFERROR(IF(ISNUMBER(INDEX(Parameters!$B$5:$B$14,MATCH(I3,Parameters!$A$5:$A$14,0))),INDEX(Parameters!$B$5:$B$14,MATCH(I3,Parameters!$A$5:$A$14,0)),""),""),IF(ISNUMBER(Parameters!$B$21),Parameters!$B$21,"")) -> 1 | AA3: =IFERROR(IF(ISNUMBER(INDEX(Parameters!$B$5:$B$14,MATCH(J3,Parameters!$A$5:$A$14,0))),INDEX(Parameters!$B$5:$B$14,MATCH(J3,Parameters!$A$5:$A$14,0)),""),"") -> 1 | AB3: =IFERROR(IF(ISNUMBER(INDEX(Parameters!$B$5:$B$14,MATCH(K3,Parameters!$A$5:$A$14,0))),INDEX(Parameters!$B$5:$B$14,MATCH(K3,Parameters!$A$5:$A$14,0)),""),"") -> 1 | AC3: =IFERROR(IF(ISNUMBER(INDEX(Parameters!$B$5:$B$14,MATCH(L3,Parameters!$A$5:$A$14,0))),INDEX(Parameters!$B$5:$B$14,MATCH(L3,Parameters!$A$5:$A$14,0)),""),"") -> 1 | AD3: =IFERROR(IF(ISNUMBER(INDEX(Parameters!$B$5:$B$14,MATCH(M3,Parameters!$A$5:$A$14,0))),INDEX(Parameters!$B$5:$B$14,MATCH(M3,Parameters!$A$5:$A$14,0)),""),"") -> 1 | AE3: =IF(N3<>"",1,IF(ISNUMBER(Parameters!$B$19),Parameters!$B$19,"")) -> 1 | AF3: =IF((Parameters!$I$5*ISNUMBER(V3)+Parameters!$I$6*ISNUMBER(W3)+Parameters!$I$7*ISNUMBER(X3)+Parameters!$I$8*ISNUMBER(Y3))=0,"",(Parameters!$I$5*N(V3)+Parameters!$I$6*N(W3)+Parameters!$I$7*N(X3)+Parameters!$I$8*N(Y3))/(Parameters!$I$5*ISNUMBER(V3)+Parameters!$I$6*ISNUMBER(W3)+Parameters!$I$7*ISNUMBER(X3)+Parameters!$I$8*ISNUMBER(Y3))) -> 1 | AG3: =IF((Parameters!$I$9*ISNUMBER(Z3))=0,"",(Parameters!$I$9*N(Z3))/(Parameters!$I$9*ISNUMBER(Z3))) -> 1 | AH3: =IF((Parameters!$I$11*ISNUMBER(AA3)+Parameters!$I$12*ISNUMBER(AB3)+Parameters!$I$13*ISNUMBER(AC3)+Parameters!$I$14*ISNUMBER(AD3)+Parameters!$I$15*ISNUMBER(AE3))=0,"",(Parameters!$I$11*N(AA3)+Parameters!$I$12*N(AB3)+Parameters!$I$13*N(AC3)+Parameters!$I$14*N(AD3)+Parameters!$I$15*N(AE3))/(Parameters!$I$11*ISNUMBER(AA3)+Parameters!$I$12*ISNUMBER(AB3)+Parameters!$I$13*ISNUMBER(AC3)+Parameters!$I$14*ISNUMBER(AD3)+Parameters!$I$15*ISNUMBER(AE3))) -> 1 | AI3: =Parameters!$I$5*ISNUMBER(V3)+Parameters!$I$6*ISNUMBER(W3)+Parameters!$I$7*ISNUMBER(X3)+Parameters!$I$8*ISNUMBER(Y3)+Parameters!$I$9*ISNUMBER(Z3)+Parameters!$I$11*ISNUMBER(AA3)+Parameters!$I$12*ISNUMBER(AB3)+Parameters!$I$13*ISNUMBER(AC3)+Parameters!$I$14*ISNUMBER(AD3)+Parameters!$I$15*ISNUMBER(AE3) -> 95 | AJ3: =IF((Parameters!$I$5+Parameters!$I$6+Parameters!$I$7+Parameters!$I$8+Parameters!$I$9+Parameters!$I$11+Parameters!$I$12+Parameters!$I$13+Parameters!$I$14+Parameters!$I$15)=0,"",AI3/(Parameters!$I$5+Parameters!$I$6+Parameters!$I$7+Parameters!$I$8+Parameters!$I$9+Parameters!$I$11+Parameters!$I$12+Parameters!$I$13+Parameters!$I$14+Parameters!$I$15)) -> 1 | AK3: =IF(AND(ISNUMBER(AF3),ISNUMBER(AH3),OR(NOT((Parameters!$I$9)>0),ISNUMBER(AG3)),AJ3>=Parameters!$B$20),100*(Parameters!$F$18*N(AF3)+Parameters!$F$19*N(AG3)+Parameters!$F$20*N(AH3))/(Parameters!$F$18*ISNUMBER(AF3)+Parameters!$F$19*ISNUMBER(AG3)+Parameters!$F$20*ISNUMBER(AH3)),"") -> 100 | AL3: =IF(ISNUMBER(AK3),RANK(AK3,$AK$2:$AK$113),"") -> 1 | AM3: =IF(((D3="Implemented/available")+(E3="Implemented/available")+(J3="Implemented/available")+(K3="Implemented/available")+(L3="Implemented/available")+(M3="Implemented/available"))=0,"",(AND(D3="Implemented/available",O3<>"")+AND(E3="Implemented/available",P3<>"")+AND(J3="Implemented/available",Q3<>"")+AND(K3="Implemented/available",R3<>"")+AND(L3="Implemented/available",S3<>"")+AND(M3="Implemented/available",T3<>""))/((D3="Implemented/available")+(E3="Implemented/available")+(J3="Implemented/available")+(K3="Implemented/available")+(L3="Implemented/available")+(M3="Implemented/available"))) -> 0.83333333
A4: DSpace | B4: Lyrasis | C4: Repository software | D4: Implemented/available | E4: Implemented/available | F4: Implemented/available | G4: Advisory board or steering committee | I4: Formal | J4: Implemented/available | K4: Implemented/available | L4: Implemented/available | M4: Implemented/available | N4: It Takes a Village Open Source Software Sustainability toolkit | O4: https://dspace.org/governance/ | P4: https://wiki.lyrasis.org/display/DSPACE/Leadership+Group | Q4: https://dspace.org/accessibility/ | R4: https://dspace.org/membership/ | S4: https://lyrasis.org/job-bank/ | T4: https://demo.dspace.org/info/privacy | U4: https://dspace.org/governance | V4: =IFERROR(IF(ISNUMBER(INDEX(Parameters!$B$5:$B$14,MATCH(D4,Parameters!$A$5:$A$14,0))),INDEX(Parameters!$B$5:$B$14,MATCH(D4,Parameters!$A$5:$A$14,0)),""),"") -> 1 | W4: =IFERROR(IF(ISNUMBER(INDEX(Parameters!$B$5:$B$14,MATCH(E4,Parameters!$A$5:$A$14,0))),INDEX(Parameters!$B$5:$B$14,MATCH(E4,Parameters!$A$5:$A$14,0)),""),"") -> 1 | X4: =IFERROR(IF(ISNUMBER(INDEX(Parameters!$B$5:$B$14,MATCH(F4,Parameters!$A$5:$A$14,0))),INDEX(Parameters!$B$5:$B$14,MATCH(F4,Parameters!$A$5:$A$14,0)),""),"") -> 1 | Y4: =IF(G4<>"",1,IF(ISNUMBER(Parameters!$B$18),Parameters!$B$18,"")) -> 1 | Z4: =IF(I4<>"",IFERROR(IF(ISNUMBER(INDEX(Parameters!$B$5:$B$14,MATCH(I4,Parameters!$A$5:$A$14,0))),INDEX(Parameters!$B$5:$B$14,MATCH(I4,Parameters!$A$5:$A$14,0)),""),""),IF(ISNUMBER(Parameters!$B$21),Parameters!$B$21,"")) -> 1 | AA4: =IFERROR(IF(ISNUMBER(INDEX(Parameters!$B$5:$B$14,MATCH(J4,Parameters!$A$5:$A$14,0))),INDEX(Parameters!$B$5:$B$14,MATCH(J4,Parameters!$A$5:$A$14,0)),""),"") -> 1 | AB4: =IFERROR(IF(ISNUMBER(INDEX(Parameters!$B$5:$B$14,MATCH(K4,Parameters!$A$5:$A$14,0))),INDEX(Parameters!$B$5:$B$14,MATCH(K4,Parameters!$A$5:$A$14,0)),""),"") -> 1 | AC4: =IFERROR(IF(ISNUMBER(INDEX(Parameters!$B$5:$B$14,MATCH(L4,Parameters!$A$5:$A$14,0))),INDEX(Parameters!$B$5:$B$14,MATCH(L4,Parameters!$A$5:$A$14,0)),""),"") -> 1 | AD4: =IFERROR(IF(ISNUMBER(INDEX(Parameters!$B$5:$B$14,MATCH(M4,Parameters!$A$5:$A$14,0))),INDEX(Parameters!$B$5:$B$14,MATCH(M4,Parameters!$A$5:$A$14,0)),""),"") -> 1 | AE4: =IF(N4<>"",1,IF(ISNUMBER(Parameters!$B$19),Parameters!$B$19,"")) -> 1 | AF4: =IF((Parameters!$I$5*ISNUMBER(V4)+Parameters!$I$6*ISNUMBER(W4)+Parameters!$I$7*ISNUMBER(X4)+Parameters!$I$8*ISNUMBER(Y4))=0,"",(Parameters!$I$5*N(V4)+Parameters!$I$6*N(W4)+Parameters!$I$7*N(X4)+Parameters!$I$8*N(Y4))/(Parameters!$I$5*ISNUMBER(V4)+Parameters!$I$6*ISNUMBER(W4)+Parameters!$I$7*ISNUMBER(X4)+Parameters!$I$8*ISNUMBER(Y4))) -> 1 | AG4: =IF((Parameters!$I$9*ISNUMBER(Z4))=0,"",(Parameters!$I$9*N(Z4))/(Parameters!$I$9*ISNUMBER(Z4))) -> 1 | AH4: =IF((Parameters!$I$11*ISNUMBER(AA4)+Parameters!$I$12*ISNUMBER(AB4)+Parameters!$I$13*ISNUMBER(AC4)+Parameters!$I$14*ISNUMBER(AD4)+Parameters!$I$15*ISNUMBER(AE4))=0,"",(Parameters!$I$11*N(AA4)+Parameters!$I$12*N(AB4)+Parameters!$I$13*N(AC4)+Parameters!$I$14*N(AD4)+Parameters!$I$15*N(AE4))/(Parameters!$I$11*ISNUMBER(AA4)+Parameters!$I$12*ISNUMBER(AB4)+Parameters!$I$13*ISNUMBER(AC4)+Parameters!$I$14*ISNUMBER(AD4)+Parameters!$I$15*ISNUMBER(AE4))) -> 1 | AI4: =Parameters!$I$5*ISNUMBER(V4)+Parameters!$I$6*ISNUMBER(W4)+Parameters!$I$7*ISNUMBER(X4)+Parameters!$I$8*ISNUMBER(Y4)+Parameters!$I$9*ISNUMBER(Z4)+Parameters!$I$11*ISNUMBER(AA4)+Parameters!$I$12*ISNUMBER(AB4)+Parameters!$I$13*ISNUMBER(AC4)+Parameters!$I$14*ISNUMBER(AD4)+Parameters!$I$15*ISNUMBER(AE4) -> 95 | AJ4: =IF((Parameters!$I$5+Parameters!$I$6+Parameters!$I$7+Parameters!$I$8+Parameters!$I$9+Parameters!$I$11+Parameters!$I$12+Parameters!$I$13+Parameters!$I$14+Parameters!$I$15)=0,"",AI4/(Parameters!$I$5+Parameters!$I$6+Parameters!$I$7+Parameters!$I$8+Parameters!$I$9+Parameters!$I$11+Parameters!$I$12+Parameters!$I$13+Parameters!$I$14+Parameters!$I$15)) -> 1 | AK4: =IF(AND(ISNUMBER(AF4),ISNUMBER(AH4),OR(NOT((Parameters!$I$9)>0),ISNUMBER(AG4)),AJ4>=Parameters!$B$20),100*(Parameters!$F$18*N(AF4)+Parameters!$F$19*N(AG4)+Parameters!$F$20*N(AH4))/(Parameters!$F$18*ISNUMBER(AF4)+Parameters!$F$19*ISNUMBER(AG4)+Parameters!$F$20*ISNUMBER(AH4)),"") -> 100 | AL4: =IF(ISNUMBER(AK4),RANK(AK4,$AK$2:$AK$113),"") -> 1 | AM4: =IF(((D4="Implemented/available")+(E4="Implemented/available")+(J4="Implemented/available")+(K4="Implemented/available")+(L4="Implemented/available")+(M4="Implemented/available"))=0,"",(AND(D4="Implemented/available",O4<>"")+AND(E4="Implemented/available",P4<>"")+AND(J4="Implemented/available",Q4<>"")+AND(K4="Implemented/available",R4<>"")+AND(L4="Implemented/available",S4<>"")+AND(M4="Implemented/available",T4<>""))/((D4="Implemented/available")+(E4="Implemented/available")+(J4="Implemented/available")+(K4="Implemented/available")+(L4="Implemented/available")+(M4="Implemented/available"))) -> 1
A5: VuFind® | B5: Open Library Foundation | C5: Discovery system | D5: Implemented/available | E5: Implemented/available | F5: Implemented/available | G5: Advisory board or steering committee | I5: Formal | J5: Implemented/available | K5: No direct costs | L5: Implemented/available | M5: Implemented/available | N5: It Takes a Village Open Source Software Sustainability toolkit | O5: https://github.com/vufind-org/vufind/blob/dev/GOVERNANCE.md | P5: https://vufind.org/wiki/community:pmc_meetings | Q5: https://vufind.org/wiki/accessibility | S5: https://github.com/vufind-org/vufind/blob/dev/CODE_OF_CONDUCT.md | T5: https://vufind.org/wiki/configuration:user_privacy | U5: https://github.com/vufind-org/vufind/blob/dev/GOVERNANCE.md | V5: =IFERROR(IF(ISNUMBER(INDEX(Parameters!$B$5:$B$14,MATCH(D5,Parameters!$A$5:$A$14,0))),INDEX(Parameters!$B$5:$B$14,MATCH(D5,Parameters!$A$5:$A$14,0)),""),"") -> 1 | W5: =IFERROR(IF(ISNUMBER(INDEX(Parameters!$B$5:$B$14,MATCH(E5,Parameters!$A$5:$A$14,0))),INDEX(Parameters!$B$5:$B$14,MATCH(E5,Parameters!$A$5:$A$14,0)),""),"") -> 1 | X5: =IFERROR(IF(ISNUMBER(INDEX(Parameters!$B$5:$B$14,MATCH(F5,Parameters!$A$5:$A$14,0))),INDEX(Parameters!$B$5:$B$14,MATCH(F5,Parameters!$A$5:$A$14,0)),""),"") -> 1 | Y5: =IF(G5<>"",1,IF(ISNUMBER(Parameters!$B$18),Parameters!$B$18,"")) -> 1 | Z5: =IF(I5<>"",IFERROR(IF(ISNUMBER(INDEX(Parameters!$B$5:$B$14,MATCH(I5,Parameters!$A$5:$A$14,0))),INDEX(Parameters!$B$5:$B$14,MATCH(I5,Parameters!$A$5:$A$14,0)),""),""),IF(ISNUMBER(Parameters!$B$21),Parameters!$B$21,"")) -> 1 | AA5: =IFERROR(IF(ISNUMBER(INDEX(Parameters!$B$5:$B$14,MATCH(J5,Parameters!$A$5:$A$14,0))),INDEX(Parameters!$B$5:$B$14,MATCH(J5,Parameters!$A$5:$A$14,0)),""),"") -> 1 | AB5: =IFERROR(IF(ISNUMBER(INDEX(Parameters!$B$5:$B$14,MATCH(K5,Parameters!$A$5:$A$14,0))),INDEX(Parameters!$B$5:$B$14,MATCH(K5,Parameters!$A$5:$A$14,0)),""),"") -> 1 | AC5: =IFERROR(IF(ISNUMBER(INDEX(Parameters!$B$5:$B$14,MATCH(L5,Parameters!$A$5:$A$14,0))),INDEX(Parameters!$B$5:$B$14,MATCH(L5,Parameters!$A$5:$A$14,0)),""),"") -> 1 | AD5: =IFERROR(IF(ISNUMBER(INDEX(Parameters!$B$5:$B$14,MATCH(M5,Parameters!$A$5:$A$14,0))),INDEX(Parameters!$B$5:$B$14,MATCH(M5,Parameters!$A$5:$A$14,0)),""),"") -> 1 | AE5: =IF(N5<>"",1,IF(ISNUMBER(Parameters!$B$19),Parameters!$B$19,"")) -> 1 | AF5: =IF((Parameters!$I$5*ISNUMBER(V5)+Parameters!$I$6*ISNUMBER(W5)+Parameters!$I$7*ISNUMBER(X5)+Parameters!$I$8*ISNUMBER(Y5))=0,"",(Parameters!$I$5*N(V5)+Parameters!$I$6*N(W5)+Parameters!$I$7*N(X5)+Parameters!$I$8*N(Y5))/(Parameters!$I$5*ISNUMBER(V5)+Parameters!$I$6*ISNUMBER(W5)+Parameters!$I$7*ISNUMBER(X5)+Parameters!$I$8*ISNUMBER(Y5))) -> 1 | AG5: =IF((Parameters!$I$9*ISNUMBER(Z5))=0,"",(Parameters!$I$9*N(Z5))/(Parameters!$I$9*ISNUMBER(Z5))) -> 1 | AH5: =IF((Parameters!$I$11*ISNUMBER(AA5)+Parameters!$I$12*ISNUMBER(AB5)+Parameters!$I$13*ISNUMBER(AC5)+Parameters!$I$14*ISNUMBER(AD5)+Parameters!$I$15*ISNUMBER(AE5))=0,"",(Parameters!$I$11*N(AA5)+Parameters!$I$12*N(AB5)+Parameters!$I$13*N(AC5)+Parameters!$I$14*N(AD5)+Parameters!$I$15*N(AE5))/(Parameters!$I$11*ISNUMBER(AA5)+Parameters!$I$12*ISNUMBER(AB5)+Parameters!$I$13*ISNUMBER(AC5)+Parameters!$I$14*ISNUMBER(AD5)+Parameters!$I$15*ISNUMBER(AE5))) -> 1 | AI5: =Parameters!$I$5*ISNUMBER(V5)+Parameters!$I$6*ISNUMBER(W5)+Parameters!$I$7*ISNUMBER(X5)+Parameters!$I$8*ISNUMBER(Y5)+Parameters!$I$9*ISNUMBER(Z5)+Parameters!$I$11*ISNUMBER(AA5)+Parameters!$I$12*ISNUMBER(AB5)+Parameters!$I$13*ISNUMBER(AC5)+Parameters!$I$14*ISNUMBER(AD5)+Parameters!$I$15*ISNUMBER(AE5) -> 95 | AJ5: =IF((Parameters!$I$5+Parameters!$I$6+Parameters!$I$7+Parameters!$I$8+Parameters!$I$9+Parameters!$I$11+Parameters!$I$12+Parameters!$I$13+Parameters!$I$14+Parameters!$I$15)=0,"",AI5/(Parameters!$I$5+Parameters!$I$6+Parameters!$I$7+Parameters!$I$8+Parameters!$I$9+Parameters!$I$11+Parameters!$I$12+Parameters!$I$13+Parameters!$I$14+Parameters!$I$15)) -> 1 | AK5: =IF(AND(ISNUMBER(AF5),ISNUMBER(AH5),OR(NOT((Parameters!$I$9)>0),ISNUMBER(AG5)),AJ5>=Parameters!$B$20),100*(Parameters!$F$18*N(AF5)+Parameters!$F$19*N(AG5)+Parameters!$F$20*N(AH5))/(Parameters!$F$18*ISNUMBER(AF5)+Parameters!$F$19*ISNUMBER(AG5)+Parameters!$F$20*ISNUMBER(AH5)),"") -> 100 | AL5: =IF(ISNUMBER(AK5),RANK(AK5,$AK$2:$AK$113),"") -> 1 | AM5: =IF(((D5="Implemented/available")+(E5="Implemented/available")+(J5="Implemented/available")+(K5="Implemented/available")+(L5="Implemented/available")+(M5="Implemented/available"))=0,"",(AND(D5="Implemented/available",O5<>"")+AND(E5="Implemented/available",P5<>"")+AND(J5="Implemented/available",Q5<>"")+AND(K5="Implemented/available",R5<>"")+AND(L5="Implemented/available",S5<>"")+AND(M5="Implemented/available",T5<>""))/((D5="Implemented/available")+(E5="Implemented/available")+(J5="Implemented/available")+(K5="Implemented/available")+(L5="Implemented/available")+(M5="Implemented/available"))) -> 1
A6: COUNTER Code of Practice | B6: COUNTER Metrics | C6: Standard, specification or protocol | D6: Implemented/available | E6: Implemented/available | F6: Implemented/available | G6: Multi-board governance | I6: Formal | J6: Implemented/available | K6: Implemented/available | L6: In progress | M6: Implemented/available | N6: Principles for Open Scholarly Infrastructure (POSI) | O6: https://www.countermetrics.org/about/people/ | P6: https://www.countermetrics.org/category/agm-minutes/ | Q6: https://www.countermetrics.org/accessibility/ | R6: https://www.countermetrics.org/members/ | T6: https://www.countermetrics.org/privacy-data-protection/ | U6: https://find-and-update.company-information.service.gov.uk/company/04865179/filing-history | V6: =IFERROR(IF(ISNUMBER(INDEX(Parameters!$B$5:$B$14,MATCH(D6,Parameters!$A$5:$A$14,0))),INDEX(Parameters!$B$5:$B$14,MATCH(D6,Parameters!$A$5:$A$14,0)),""),"") -> 1 | W6: =IFERROR(IF(ISNUMBER(INDEX(Parameters!$B$5:$B$14,MATCH(E6,Parameters!$A$5:$A$14,0))),INDEX(Parameters!$B$5:$B$14,MATCH(E6,Parameters!$A$5:$A$14,0)),""),"") -> 1 | X6: =IFERROR(IF(ISNUMBER(INDEX(Parameters!$B$5:$B$14,MATCH(F6,Parameters!$A$5:$A$14,0))),INDEX(Parameters!$B$5:$B$14,MATCH(F6,Parameters!$A$5:$A$14,0)),""),"") -> 1 | Y6: =IF(G6<>"",1,IF(ISNUMBER(Parameters!$B$18),Parameters!$B$18,"")) -> 1 | Z6: =IF(I6<>"",IFERROR(IF(ISNUMBER(INDEX(Parameters!$B$5:$B$14,MATCH(I6,Parameters!$A$5:$A$14,0))),INDEX(Parameters!$B$5:$B$14,MATCH(I6,Parameters!$A$5:$A$14,0)),""),""),IF(ISNUMBER(Parameters!$B$21),Parameters!$B$21,"")) -> 1 | AA6: =IFERROR(IF(ISNUMBER(INDEX(Parameters!$B$5:$B$14,MATCH(J6,Parameters!$A$5:$A$14,0))),INDEX(Parameters!$B$5:$B$14,MATCH(J6,Parameters!$A$5:$A$14,0)),""),"") -> 1 | AB6: =IFERROR(IF(ISNUMBER(INDEX(Parameters!$B$5:$B$14,MATCH(K6,Parameters!$A$5:$A$14,0))),INDEX(Parameters!$B$5:$B$14,MATCH(K6,Parameters!$A$5:$A$14,0)),""),"") -> 1 | AC6: =IFERROR(IF(ISNUMBER(INDEX(Parameters!$B$5:$B$14,MATCH(L6,Parameters!$A$5:$A$14,0))),INDEX(Parameters!$B$5:$B$14,MATCH(L6,Parameters!$A$5:$A$14,0)),""),"") -> 0.67 | AD6: =IFERROR(IF(ISNUMBER(INDEX(Parameters!$B$5:$B$14,MATCH(M6,Parameters!$A$5:$A$14,0))),INDEX(Parameters!$B$5:$B$14,MATCH(M6,Parameters!$A$5:$A$14,0)),""),"") -> 1 | AE6: =IF(N6<>"",1,IF(ISNUMBER(Parameters!$B$19),Parameters!$B$19,"")) -> 1 | AF6: =IF((Parameters!$I$5*ISNUMBER(V6)+Parameters!$I$6*ISNUMBER(W6)+Parameters!$I$7*ISNUMBER(X6)+Parameters!$I$8*ISNUMBER(Y6))=0,"",(Parameters!$I$5*N(V6)+Parameters!$I$6*N(W6)+Parameters!$I$7*N(X6)+Parameters!$I$8*N(Y6))/(Parameters!$I$5*ISNUMBER(V6)+Parameters!$I$6*ISNUMBER(W6)+Parameters!$I$7*ISNUMBER(X6)+Parameters!$I$8*ISNUMBER(Y6))) -> 1 | AG6: =IF((Parameters!$I$9*ISNUMBER(Z6))=0,"",(Parameters!$I$9*N(Z6))/(Parameters!$I$9*ISNUMBER(Z6))) -> 1 | AH6: =IF((Parameters!$I$11*ISNUMBER(AA6)+Parameters!$I$12*ISNUMBER(AB6)+Parameters!$I$13*ISNUMBER(AC6)+Parameters!$I$14*ISNUMBER(AD6)+Parameters!$I$15*ISNUMBER(AE6))=0,"",(Parameters!$I$11*N(AA6)+Parameters!$I$12*N(AB6)+Parameters!$I$13*N(AC6)+Parameters!$I$14*N(AD6)+Parameters!$I$15*N(AE6))/(Parameters!$I$11*ISNUMBER(AA6)+Parameters!$I$12*ISNUMBER(AB6)+Parameters!$I$13*ISNUMBER(AC6)+Parameters!$I$14*ISNUMBER(AD6)+Parameters!$I$15*ISNUMBER(AE6))) -> 0.934 | AI6: =Parameters!$I$5*ISNUMBER(V6)+Parameters!$I$6*ISNUMBER(W6)+Parameters!$I$7*ISNUMBER(X6)+Parameters!$I$8*ISNUMBER(Y6)+Parameters!$I$9*ISNUMBER(Z6)+Parameters!$I$11*ISNUMBER(AA6)+Parameters!$I$12*ISNUMBER(AB6)+Parameters!$I$13*ISNUMBER(AC6)+Parameters!$I$14*ISNUMBER(AD6)+Parameters!$I$15*ISNUMBER(AE6) -> 95 | AJ6: =IF((Parameters!$I$5+Parameters!$I$6+Parameters!$I$7+Parameters!$I$8+Parameters!$I$9+Parameters!$I$11+Parameters!$I$12+Parameters!$I$13+Parameters!$I$14+Parameters!$I$15)=0,"",AI6/(Parameters!$I$5+Parameters!$I$6+Parameters!$I$7+Parameters!$I$8+Parameters!$I$9+Parameters!$I$11+Parameters!$I$12+Parameters!$I$13+Parameters!$I$14+Parameters!$I$15)) -> 1 | AK6: =IF(AND(ISNUMBER(AF6),ISNUMBER(AH6),OR(NOT((Parameters!$I$9)>0),ISNUMBER(AG6)),AJ6>=Parameters!$B$20),100*(Parameters!$F$18*N(AF6)+Parameters!$F$19*N(AG6)+Parameters!$F$20*N(AH6))/(Parameters!$F$18*ISNUMBER(AF6)+Parameters!$F$19*ISNUMBER(AG6)+Parameters!$F$20*ISNUMBER(AH6)),"") -> 97.69 | AL6: =IF(ISNUMBER(AK6),RANK(AK6,$AK$2:$AK$113),"") -> 5 | AM6: =IF(((D6="Implemented/available")+(E6="Implemented/available")+(J6="Implemented/available")+(K6="Implemented/available")+(L6="Implemented/available")+(M6="Implemented/available"))=0,"",(AND(D6="Implemented/available",O6<>"")+AND(E6="Implemented/available",P6<>"")+AND(J6="Implemented/available",Q6<>"")+AND(K6="Implemented/available",R6<>"")+AND(L6="Implemented/available",S6<>"")+AND(M6="Implemented/available",T6<>""))/((D6="Implemented/available")+(E6="Implemented/available")+(J6="Implemented/available")+(K6="Implemented/available")+(L6="Implemented/available")+(M6="Implemented/available"))) -> 1
A7: Crossref Metadata Retrieval | B7: Crossref | C7: Open scholarly dataset | D7: Implemented/available | E7: Implemented/available | F7: Implemented/available | G7: Multi-board governance | I7: Formal | J7: In progress | K7: Implemented/available | L7: Implemented/available | M7: Implemented/available | N7: Principles for Open Scholarly Infrastructure (POSI) | O7: https://www.crossref.org/board-and-governance/ | P7: https://www.crossref.org/board-and-governance/ | R7: https://www.crossref.org/fees/ | S7: https://www.crossref.org/gem/ | T7: https://www.crossref.org/operations-and-sustainability/privacy/ | U7: https://www.crossref.org/board-and-governance/bylaws/ | V7: =IFERROR(IF(ISNUMBER(INDEX(Parameters!$B$5:$B$14,MATCH(D7,Parameters!$A$5:$A$14,0))),INDEX(Parameters!$B$5:$B$14,MATCH(D7,Parameters!$A$5:$A$14,0)),""),"") -> 1 | W7: =IFERROR(IF(ISNUMBER(INDEX(Parameters!$B$5:$B$14,MATCH(E7,Parameters!$A$5:$A$14,0))),INDEX(Parameters!$B$5:$B$14,MATCH(E7,Parameters!$A$5:$A$14,0)),""),"") -> 1 | X7: =IFERROR(IF(ISNUMBER(INDEX(Parameters!$B$5:$B$14,MATCH(F7,Parameters!$A$5:$A$14,0))),INDEX(Parameters!$B$5:$B$14,MATCH(F7,Parameters!$A$5:$A$14,0)),""),"") -> 1 | Y7: =IF(G7<>"",1,IF(ISNUMBER(Parameters!$B$18),Parameters!$B$18,"")) -> 1 | Z7: =IF(I7<>"",IFERROR(IF(ISNUMBER(INDEX(Parameters!$B$5:$B$14,MATCH(I7,Parameters!$A$5:$A$14,0))),INDEX(Parameters!$B$5:$B$14,MATCH(I7,Parameters!$A$5:$A$14,0)),""),""),IF(ISNUMBER(Parameters!$B$21),Parameters!$B$21,"")) -> 1 | AA7: =IFERROR(IF(ISNUMBER(INDEX(Parameters!$B$5:$B$14,MATCH(J7,Parameters!$A$5:$A$14,0))),INDEX(Parameters!$B$5:$B$14,MATCH(J7,Parameters!$A$5:$A$14,0)),""),"") -> 0.67 | AB7: =IFERROR(IF(ISNUMBER(INDEX(Parameters!$B$5:$B$14,MATCH(K7,Parameters!$A$5:$A$14,0))),INDEX(Parameters!$B$5:$B$14,MATCH(K7,Parameters!$A$5:$A$14,0)),""),"") -> 1 | AC7: =IFERROR(IF(ISNUMBER(INDEX(Parameters!$B$5:$B$14,MATCH(L7,Parameters!$A$5:$A$14,0))),INDEX(Parameters!$B$5:$B$14,MATCH(L7,Parameters!$A$5:$A$14,0)),""),"") -> 1 | AD7: =IFERROR(IF(ISNUMBER(INDEX(Parameters!$B$5:$B$14,MATCH(M7,Parameters!$A$5:$A$14,0))),INDEX(Parameters!$B$5:$B$14,MATCH(M7,Parameters!$A$5:$A$14,0)),""),"") -> 1 | AE7: =IF(N7<>"",1,IF(ISNUMBER(Parameters!$B$19),Parameters!$B$19,"")) -> 1 | AF7: =IF((Parameters!$I$5*ISNUMBER(V7)+Parameters!$I$6*ISNUMBER(W7)+Parameters!$I$7*ISNUMBER(X7)+Parameters!$I$8*ISNUMBER(Y7))=0,"",(Parameters!$I$5*N(V7)+Parameters!$I$6*N(W7)+Parameters!$I$7*N(X7)+Parameters!$I$8*N(Y7))/(Parameters!$I$5*ISNUMBER(V7)+Parameters!$I$6*ISNUMBER(W7)+Parameters!$I$7*ISNUMBER(X7)+Parameters!$I$8*ISNUMBER(Y7))) -> 1 | AG7: =IF((Parameters!$I$9*ISNUMBER(Z7))=0,"",(Parameters!$I$9*N(Z7))/(Parameters!$I$9*ISNUMBER(Z7))) -> 1 | AH7: =IF((Parameters!$I$11*ISNUMBER(AA7)+Parameters!$I$12*ISNUMBER(AB7)+Parameters!$I$13*ISNUMBER(AC7)+Parameters!$I$14*ISNUMBER(AD7)+Parameters!$I$15*ISNUMBER(AE7))=0,"",(Parameters!$I$11*N(AA7)+Parameters!$I$12*N(AB7)+Parameters!$I$13*N(AC7)+Parameters!$I$14*N(AD7)+Parameters!$I$15*N(AE7))/(Parameters!$I$11*ISNUMBER(AA7)+Parameters!$I$12*ISNUMBER(AB7)+Parameters!$I$13*ISNUMBER(AC7)+Parameters!$I$14*ISNUMBER(AD7)+Parameters!$I$15*ISNUMBER(AE7))) -> 0.934 | AI7: =Parameters!$I$5*ISNUMBER(V7)+Parameters!$I$6*ISNUMBER(W7)+Parameters!$I$7*ISNUMBER(X7)+Parameters!$I$8*ISNUMBER(Y7)+Parameters!$I$9*ISNUMBER(Z7)+Parameters!$I$11*ISNUMBER(AA7)+Parameters!$I$12*ISNUMBER(AB7)+Parameters!$I$13*ISNUMBER(AC7)+Parameters!$I$14*ISNUMBER(AD7)+Parameters!$I$15*ISNUMBER(AE7) -> 95 | AJ7: =IF((Parameters!$I$5+Parameters!$I$6+Parameters!$I$7+Parameters!$I$8+Parameters!$I$9+Parameters!$I$11+Parameters!$I$12+Parameters!$I$13+Parameters!$I$14+Parameters!$I$15)=0,"",AI7/(Parameters!$I$5+Parameters!$I$6+Parameters!$I$7+Parameters!$I$8+Parameters!$I$9+Parameters!$I$11+Parameters!$I$12+Parameters!$I$13+Parameters!$I$14+Parameters!$I$15)) -> 1 | AK7: =IF(AND(ISNUMBER(AF7),ISNUMBER(AH7),OR(NOT((Parameters!$I$9)>0),ISNUMBER(AG7)),AJ7>=Parameters!$B$20),100*(Parameters!$F$18*N(AF7)+Parameters!$F$19*N(AG7)+Parameters!$F$20*N(AH7))/(Parameters!$F$18*ISNUMBER(AF7)+Parameters!$F$19*ISNUMBER(AG7)+Parameters!$F$20*ISNUMBER(AH7)),"") -> 97.69 | AL7: =IF(ISNUMBER(AK7),RANK(AK7,$AK$2:$AK$113),"") -> 5 | AM7: =IF(((D7="Implemented/available")+(E7="Implemented/available")+(J7="Implemented/available")+(K7="Implemented/available")+(L7="Implemented/available")+(M7="Implemented/available"))=0,"",(AND(D7="Implemented/available",O7<>"")+AND(E7="Implemented/available",P7<>"")+AND(J7="Implemented/available",Q7<>"")+AND(K7="Implemented/available",R7<>"")+AND(L7="Implemented/available",S7<>"")+AND(M7="Implemented/available",T7<>""))/((D7="Implemented/available")+(E7="Implemented/available")+(J7="Implemented/available")+(K7="Implemented/available")+(L7="Implemented/available")+(M7="Implemented/available"))) -> 1
A8: PKP Preservation Network | B8: Public Knowledge Project (PKP) | C8: Digital preservation service | D8: Implemented/available | E8: Implemented/available | F8: Implemented/available | G8: Multi-board governance | I8: Formal | J8: Implemented/available | K8: No direct costs | L8: In progress | M8: Implemented/available | N8: Principles for Open Scholarly Infrastructure (POSI) | O8: https://pkp.sfu.ca/about/governance/ | P8: https://pkp.sfu.ca/interest-groups/ | Q8: https://pkp.sfu.ca/general-accessibility-statement/ | T8: https://pkp.sfu.ca/privacy-policy/ | U8: http://www.sfu.ca/policies/gazette/board.html | V8: =IFERROR(IF(ISNUMBER(INDEX(Parameters!$B$5:$B$14,MATCH(D8,Parameters!$A$5:$A$14,0))),INDEX(Parameters!$B$5:$B$14,MATCH(D8,Parameters!$A$5:$A$14,0)),""),"") -> 1 | W8: =IFERROR(IF(ISNUMBER(INDEX(Parameters!$B$5:$B$14,MATCH(E8,Parameters!$A$5:$A$14,0))),INDEX(Parameters!$B$5:$B$14,MATCH(E8,Parameters!$A$5:$A$14,0)),""),"") -> 1 | X8: =IFERROR(IF(ISNUMBER(INDEX(Parameters!$B$5:$B$14,MATCH(F8,Parameters!$A$5:$A$14,0))),INDEX(Parameters!$B$5:$B$14,MATCH(F8,Parameters!$A$5:$A$14,0)),""),"") -> 1 | Y8: =IF(G8<>"",1,IF(ISNUMBER(Parameters!$B$18),Parameters!$B$18,"")) -> 1 | Z8: =IF(I8<>"",IFERROR(IF(ISNUMBER(INDEX(Parameters!$B$5:$B$14,MATCH(I8,Parameters!$A$5:$A$14,0))),INDEX(Parameters!$B$5:$B$14,MATCH(I8,Parameters!$A$5:$A$14,0)),""),""),IF(ISNUMBER(Parameters!$B$21),Parameters!$B$21,"")) -> 1 | AA8: =IFERROR(IF(ISNUMBER(INDEX(Parameters!$B$5:$B$14,MATCH(J8,Parameters!$A$5:$A$14,0))),INDEX(Parameters!$B$5:$B$14,MATCH(J8,Parameters!$A$5:$A$14,0)),""),"") -> 1 | AB8: =IFERROR(IF(ISNUMBER(INDEX(Parameters!$B$5:$B$14,MATCH(K8,Parameters!$A$5:$A$14,0))),INDEX(Parameters!$B$5:$B$14,MATCH(K8,Parameters!$A$5:$A$14,0)),""),"") -> 1 | AC8: =IFERROR(IF(ISNUMBER(INDEX(Parameters!$B$5:$B$14,MATCH(L8,Parameters!$A$5:$A$14,0))),INDEX(Parameters!$B$5:$B$14,MATCH(L8,Parameters!$A$5:$A$14,0)),""),"") -> 0.67 | AD8: =IFERROR(IF(ISNUMBER(INDEX(Parameters!$B$5:$B$14,MATCH(M8,Parameters!$A$5:$A$14,0))),INDEX(Parameters!$B$5:$B$14,MATCH(M8,Parameters!$A$5:$A$14,0)),""),"") -> 1 | AE8: =IF(N8<>"",1,IF(ISNUMBER(Parameters!$B$19),Parameters!$B$19,"")) -> 1 | AF8: =IF((Parameters!$I$5*ISNUMBER(V8)+Parameters!$I$6*ISNUMBER(W8)+Parameters!$I$7*ISNUMBER(X8)+Parameters!$I$8*ISNUMBER(Y8))=0,"",(Parameters!$I$5*N(V8)+Parameters!$I$6*N(W8)+Parameters!$I$7*N(X8)+Parameters!$I$8*N(Y8))/(Parameters!$I$5*ISNUMBER(V8)+Parameters!$I$6*ISNUMBER(W8)+Parameters!$I$7*ISNUMBER(X8)+Parameters!$I$8*ISNUMBER(Y8))) -> 1 | AG8: =IF((Parameters!$I$9*ISNUMBER(Z8))=0,"",(Parameters!$I$9*N(Z8))/(Parameters!$I$9*ISNUMBER(Z8))) -> 1 | AH8: =IF((Parameters!$I$11*ISNUMBER(AA8)+Parameters!$I$12*ISNUMBER(AB8)+Parameters!$I$13*ISNUMBER(AC8)+Parameters!$I$14*ISNUMBER(AD8)+Parameters!$I$15*ISNUMBER(AE8))=0,"",(Parameters!$I$11*N(AA8)+Parameters!$I$12*N(AB8)+Parameters!$I$13*N(AC8)+Parameters!$I$14*N(AD8)+Parameters!$I$15*N(AE8))/(Parameters!$I$11*ISNUMBER(AA8)+Parameters!$I$12*ISNUMBER(AB8)+Parameters!$I$13*ISNUMBER(AC8)+Parameters!$I$14*ISNUMBER(AD8)+Parameters!$I$15*ISNUMBER(AE8))) -> 0.934 | AI8: =Parameters!$I$5*ISNUMBER(V8)+Parameters!$I$6*ISNUMBER(W8)+Parameters!$I$7*ISNUMBER(X8)+Parameters!$I$8*ISNUMBER(Y8)+Parameters!$I$9*ISNUMBER(Z8)+Parameters!$I$11*ISNUMBER(AA8)+Parameters!$I$12*ISNUMBER(AB8)+Parameters!$I$13*ISNUMBER(AC8)+Parameters!$I$14*ISNUMBER(AD8)+Parameters!$I$15*ISNUMBER(AE8) -> 95 | AJ8: =IF((Parameters!$I$5+Parameters!$I$6+Parameters!$I$7+Parameters!$I$8+Parameters!$I$9+Parameters!$I$11+Parameters!$I$12+Parameters!$I$13+Parameters!$I$14+Parameters!$I$15)=0,"",AI8/(Parameters!$I$5+Parameters!$I$6+Parameters!$I$7+Parameters!$I$8+Parameters!$I$9+Parameters!$I$11+Parameters!$I$12+Parameters!$I$13+Parameters!$I$14+Parameters!$I$15)) -> 1 | AK8: =IF(AND(ISNUMBER(AF8),ISNUMBER(AH8),OR(NOT((Parameters!$I$9)>0),ISNUMBER(AG8)),AJ8>=Parameters!$B$20),100*(Parameters!$F$18*N(AF8)+Parameters!$F$19*N(AG8)+Parameters!$F$20*N(AH8))/(Parameters!$F$18*ISNUMBER(AF8)+Parameters!$F$19*ISNUMBER(AG8)+Parameters!$F$20*ISNUMBER(AH8)),"") -> 97.69 | AL8: =IF(ISNUMBER(AK8),RANK(AK8,$AK$2:$AK$113),"") -> 5 | AM8: =IF(((D8="Implemented/available")+(E8="Implemented/available")+(J8="Implemented/available")+(K8="Implemented/available")+(L8="Implemented/available")+(M8="Implemented/available"))=0,"",(AND(D8="Implemented/available",O8<>"")+AND(E8="Implemented/available",P8<>"")+AND(J8="Implemented/available",Q8<>"")+AND(K8="Implemented/available",R8<>"")+AND(L8="Implemented/available",S8<>"")+AND(M8="Implemented/available",T8<>""))/((D8="Implemented/available")+(E8="Implemented/available")+(J8="Implemented/available")+(K8="Implemented/available")+(L8="Implemented/available")+(M8="Implemented/available"))) -> 1
A9: Fedora | B9: Lyrasis | C9: Repository software | D9: Implemented/available | E9: Implemented/available | F9: Implemented/available | G9: Advisory board or steering committee | H9: Other | I9: Formal | J9: Considering | K9: Implemented/available | L9: Implemented/available | M9: Implemented/available | N9: It Takes a Village Open Source Software Sustainability toolkit | O9: https://wiki.lyrasis.org/display/FF/Project+Governance | P9: https://wiki.lyrasis.org/display/FF/Meetings | R9: https://fedorarepository.org/membership | S9: https://lyrasis.org/job-bank/ | T9: https://fedorarepository.org/privacy-policy/ | U9: https://wiki.lyrasis.org/display/FF/Project+Governance | V9: =IFERROR(IF(ISNUMBER(INDEX(Parameters!$B$5:$B$14,MATCH(D9,Parameters!$A$5:$A$14,0))),INDEX(Parameters!$B$5:$B$14,MATCH(D9,Parameters!$A$5:$A$14,0)),""),"") -> 1 | W9: =IFERROR(IF(ISNUMBER(INDEX(Parameters!$B$5:$B$14,MATCH(E9,Parameters!$A$5:$A$14,0))),INDEX(Parameters!$B$5:$B$14,MATCH(E9,Parameters!$A$5:$A$14,0)),""),"") -> 1 | X9: =IFERROR(IF(ISNUMBER(INDEX(Parameters!$B$5:$B$14,MATCH(F9,Parameters!$A$5:$A$14,0))),INDEX(Parameters!$B$5:$B$14,MATCH(F9,Parameters!$A$5:$A$14,0)),""),"") -> 1 | Y9: =IF(G9<>"",1,IF(ISNUMBER(Parameters!$B$18),Parameters!$B$18,"")) -> 1 | Z9: =IF(I9<>"",IFERROR(IF(ISNUMBER(INDEX(Parameters!$B$5:$B$14,MATCH(I9,Parameters!$A$5:$A$14,0))),INDEX(Parameters!$B$5:$B$14,MATCH(I9,Parameters!$A$5:$A$14,0)),""),""),IF(ISNUMBER(Parameters!$B$21),Parameters!$B$21,"")) -> 1 | AA9: =IFERROR(IF(ISNUMBER(INDEX(Parameters!$B$5:$B$14,MATCH(J9,Parameters!$A$5:$A$14,0))),INDEX(Parameters!$B$5:$B$14,MATCH(J9,Parameters!$A$5:$A$14,0)),""),"") -> 0.33 | AB9: =IFERROR(IF(ISNUMBER(INDEX(Parameters!$B$5:$B$14,MATCH(K9,Parameters!$A$5:$A$14,0))),INDEX(Parameters!$B$5:$B$14,MATCH(K9,Parameters!$A$5:$A$14,0)),""),"") -> 1 | AC9: =IFERROR(IF(ISNUMBER(INDEX(Parameters!$B$5:$B$14,MATCH(L9,Parameters!$A$5:$A$14,0))),INDEX(Parameters!$B$5:$B$14,MATCH(L9,Parameters!$A$5:$A$14,0)),""),"") -> 1 | AD9: =IFERROR(IF(ISNUMBER(INDEX(Parameters!$B$5:$B$14,MATCH(M9,Parameters!$A$5:$A$14,0))),INDEX(Parameters!$B$5:$B$14,MATCH(M9,Parameters!$A$5:$A$14,0)),""),"") -> 1 | AE9: =IF(N9<>"",1,IF(ISNUMBER(Parameters!$B$19),Parameters!$B$19,"")) -> 1 | AF9: =IF((Parameters!$I$5*ISNUMBER(V9)+Parameters!$I$6*ISNUMBER(W9)+Parameters!$I$7*ISNUMBER(X9)+Parameters!$I$8*ISNUMBER(Y9))=0,"",(Parameters!$I$5*N(V9)+Parameters!$I$6*N(W9)+Parameters!$I$7*N(X9)+Parameters!$I$8*N(Y9))/(Parameters!$I$5*ISNUMBER(V9)+Parameters!$I$6*ISNUMBER(W9)+Parameters!$I$7*ISNUMBER(X9)+Parameters!$I$8*ISNUMBER(Y9))) -> 1 | AG9: =IF((Parameters!$I$9*ISNUMBER(Z9))=0,"",(Parameters!$I$9*N(Z9))/(Parameters!$I$9*ISNUMBER(Z9))) -> 1 | AH9: =IF((Parameters!$I$11*ISNUMBER(AA9)+Parameters!$I$12*ISNUMBER(AB9)+Parameters!$I$13*ISNUMBER(AC9)+Parameters!$I$14*ISNUMBER(AD9)+Parameters!$I$15*ISNUMBER(AE9))=0,"",(Parameters!$I$11*N(AA9)+Parameters!$I$12*N(AB9)+Parameters!$I$13*N(AC9)+Parameters!$I$14*N(AD9)+Parameters!$I$15*N(AE9))/(Parameters!$I$11*ISNUMBER(AA9)+Parameters!$I$12*ISNUMBER(AB9)+Parameters!$I$13*ISNUMBER(AC9)+Parameters!$I$14*ISNUMBER(AD9)+Parameters!$I$15*ISNUMBER(AE9))) -> 0.866 | AI9: =Parameters!$I$5*ISNUMBER(V9)+Parameters!$I$6*ISNUMBER(W9)+Parameters!$I$7*ISNUMBER(X9)+Parameters!$I$8*ISNUMBER(Y9)+Parameters!$I$9*ISNUMBER(Z9)+Parameters!$I$11*ISNUMBER(AA9)+Parameters!$I$12*ISNUMBER(AB9)+Parameters!$I$13*ISNUMBER(AC9)+Parameters!$I$14*ISNUMBER(AD9)+Parameters!$I$15*ISNUMBER(AE9) -> 95 | AJ9: =IF((Parameters!$I$5+Parameters!$I$6+Parameters!$I$7+Parameters!$I$8+Parameters!$I$9+Parameters!$I$11+Parameters!$I$12+Parameters!$I$13+Parameters!$I$14+Parameters!$I$15)=0,"",AI9/(Parameters!$I$5+Parameters!$I$6+Parameters!$I$7+Parameters!$I$8+Parameters!$I$9+Parameters!$I$11+Parameters!$I$12+Parameters!$I$13+Parameters!$I$14+Parameters!$I$15)) -> 1 | AK9: =IF(AND(ISNUMBER(AF9),ISNUMBER(AH9),OR(NOT((Parameters!$I$9)>0),ISNUMBER(AG9)),AJ9>=Parameters!$B$20),100*(Parameters!$F$18*N(AF9)+Parameters!$F$19*N(AG9)+Parameters!$F$20*N(AH9))/(Parameters!$F$18*ISNUMBER(AF9)+Parameters!$F$19*ISNUMBER(AG9)+Parameters!$F$20*ISNUMBER(AH9)),"") -> 95.31 | AL9: =IF(ISNUMBER(AK9),RANK(AK9,$AK$2:$AK$113),"") -> 8 | AM9: =IF(((D9="Implemented/available")+(E9="Implemented/available")+(J9="Implemented/available")+(K9="Implemented/available")+(L9="Implemented/available")+(M9="Implemented/available"))=0,"",(AND(D9="Implemented/available",O9<>"")+AND(E9="Implemented/available",P9<>"")+AND(J9="Implemented/available",Q9<>"")+AND(K9="Implemented/available",R9<>"")+AND(L9="Implemented/available",S9<>"")+AND(M9="Implemented/available",T9<>""))/((D9="Implemented/available")+(E9="Implemented/available")+(J9="Implemented/available")+(K9="Implemented/available")+(L9="Implemented/available")+(M9="Implemented/available"))) -> 1
A10: Hyku | B10: Samvera | C10: Repository software | D10: Implemented/available | E10: Implemented/available | F10: Implemented/available | G10: Advisory board or steering committee | I10: Formal | J10: Implemented/available | K10: No direct costs | L10: Considering | M10: Implemented/available | N10: COAR Next Generation Repositories Principles | It Takes a Village Open Source Software Sustainability toolkit | O10: https://samvera.atlassian.net/wiki/spaces/samvera/pages/1387986974/Samvera+Bylaws | P10: https://samvera.atlassian.net/wiki/spaces/samvera/pages/426512038/Notes+from+Samvera+Board+meetings+and+calls | Q10: https://repo.samvera.org/concern/generic_works/19cc96b4-6e98-4dba-b908-91e3439cad44 | T10: https://repo.samvera.org/concern/generic_works/66c8c363-ac35-4e65-bb3d-2631b7c80ff6?locale=en | U10: https://samvera.atlassian.net/wiki/spaces/samvera/pages/1387986974/Samvera+Bylaws | V10: =IFERROR(IF(ISNUMBER(INDEX(Parameters!$B$5:$B$14,MATCH(D10,Parameters!$A$5:$A$14,0))),INDEX(Parameters!$B$5:$B$14,MATCH(D10,Parameters!$A$5:$A$14,0)),""),"") -> 1 | W10: =IFERROR(IF(ISNUMBER(INDEX(Parameters!$B$5:$B$14,MATCH(E10,Parameters!$A$5:$A$14,0))),INDEX(Parameters!$B$5:$B$14,MATCH(E10,Parameters!$A$5:$A$14,0)),""),"") -> 1 | X10: =IFERROR(IF(ISNUMBER(INDEX(Parameters!$B$5:$B$14,MATCH(F10,Parameters!$A$5:$A$14,0))),INDEX(Parameters!$B$5:$B$14,MATCH(F10,Parameters!$A$5:$A$14,0)),""),"") -> 1 | Y10: =IF(G10<>"",1,IF(ISNUMBER(Parameters!$B$18),Parameters!$B$18,"")) -> 1 | Z10: =IF(I10<>"",IFERROR(IF(ISNUMBER(INDEX(Parameters!$B$5:$B$14,MATCH(I10,Parameters!$A$5:$A$14,0))),INDEX(Parameters!$B$5:$B$14,MATCH(I10,Parameters!$A$5:$A$14,0)),""),""),IF(ISNUMBER(Parameters!$B$21),Parameters!$B$21,"")) -> 1 | AA10: =IFERROR(IF(ISNUMBER(INDEX(Parameters!$B$5:$B$14,MATCH(J10,Parameters!$A$5:$A$14,0))),INDEX(Parameters!$B$5:$B$14,MATCH(J10,Parameters!$A$5:$A$14,0)),""),"") -> 1 | AB10: =IFERROR(IF(ISNUMBER(INDEX(Parameters!$B$5:$B$14,MATCH(K10,Parameters!$A$5:$A$14,0))),INDEX(Parameters!$B$5:$B$14,MATCH(K10,Parameters!$A$5:$A$14,0)),""),"") -> 1 | AC10: =IFERROR(IF(ISNUMBER(INDEX(Parameters!$B$5:$B$14,MATCH(L10,Parameters!$A$5:$A$14,0))),INDEX(Parameters!$B$5:$B$14,MATCH(L10,Parameters!$A$5:$A$14,0)),""),"") -> 0.33 | AD10: =IFERROR(IF(ISNUMBER(INDEX(Parameters!$B$5:$B$14,MATCH(M10,Parameters!$A$5:$A$14,0))),INDEX(Parameters!$B$5:$B$14,MATCH(M10,Parameters!$A$5:$A$14,0)),""),"") -> 1 | AE10: =IF(N10<>"",1,IF(ISNUMBER(Parameters!$B$19),Parameters!$B$19,"")) -> 1 | AF10: =IF((Parameters!$I$5*ISNUMBER(V10)+Parameters!$I$6*ISNUMBER(W10)+Parameters!$I$7*ISNUMBER(X10)+Parameters!$I$8*ISNUMBER(Y10))=0,"",(Parameters!$I$5*N(V10)+Parameters!$I$6*N(W10)+Parameters!$I$7*N(X10)+Parameters!$I$8*N(Y10))/(Parameters!$I$5*ISNUMBER(V10)+Parameters!$I$6*ISNUMBER(W10)+Parameters!$I$7*ISNUMBER(X10)+Parameters!$I$8*ISNUMBER(Y10))) -> 1 | AG10: =IF((Parameters!$I$9*ISNUMBER(Z10))=0,"",(Parameters!$I$9*N(Z10))/(Parameters!$I$9*ISNUMBER(Z10))) -> 1 | AH10: =IF((Parameters!$I$11*ISNUMBER(AA10)+Parameters!$I$12*ISNUMBER(AB10)+Parameters!$I$13*ISNUMBER(AC10)+Parameters!$I$14*ISNUMBER(AD10)+Parameters!$I$15*ISNUMBER(AE10))=0,"",(Parameters!$I$11*N(AA10)+Parameters!$I$12*N(AB10)+Parameters!$I$13*N(AC10)+Parameters!$I$14*N(AD10)+Parameters!$I$15*N(AE10))/(Parameters!$I$11*ISNUMBER(AA10)+Parameters!$I$12*ISNUMBER(AB10)+Parameters!$I$13*ISNUMBER(AC10)+Parameters!$I$14*ISNUMBER(AD10)+Parameters!$I$15*ISNUMBER(AE10))) -> 0.866 | AI10: =Parameters!$I$5*ISNUMBER(V10)+Parameters!$I$6*ISNUMBER(W10)+Parameters!$I$7*ISNUMBER(X10)+Parameters!$I$8*ISNUMBER(Y10)+Parameters!$I$9*ISNUMBER(Z10)+Parameters!$I$11*ISNUMBER(AA10)+Parameters!$I$12*ISNUMBER(AB10)+Parameters!$I$13*ISNUMBER(AC10)+Parameters!$I$14*ISNUMBER(AD10)+Parameters!$I$15*ISNUMBER(AE10) -> 95 | AJ10: =IF((Parameters!$I$5+Parameters!$I$6+Parameters!$I$7+Parameters!$I$8+Parameters!$I$9+Parameters!$I$11+Parameters!$I$12+Parameters!$I$13+Parameters!$I$14+Parameters!$I$15)=0,"",AI10/(Parameters!$I$5+Parameters!$I$6+Parameters!$I$7+Parameters!$I$8+Parameters!$I$9+Parameters!$I$11+Parameters!$I$12+Parameters!$I$13+Parameters!$I$14+Parameters!$I$15)) -> 1 | AK10: =IF(AND(ISNUMBER(AF10),ISNUMBER(AH10),OR(NOT((Parameters!$I$9)>0),ISNUMBER(AG10)),AJ10>=Parameters!$B$20),100*(Parameters!$F$18*N(AF10)+Parameters!$F$19*N(AG10)+Parameters!$F$20*N(AH10))/(Parameters!$F$18*ISNUMBER(AF10)+Parameters!$F$19*ISNUMBER(AG10)+Parameters!$F$20*ISNUMBER(AH10)),"") -> 95.31 | AL10: =IF(ISNUMBER(AK10),RANK(AK10,$AK$2:$AK$113),"") -> 8 | AM10: =IF(((D10="Implemented/available")+(E10="Implemented/available")+(J10="Implemented/available")+(K10="Implemented/available")+(L10="Implemented/available")+(M10="Implemented/available"))=0,"",(AND(D10="Implemented/available",O10<>"")+AND(E10="Implemented/available",P10<>"")+AND(J10="Implemented/available",Q10<>"")+AND(K10="Implemented/available",R10<>"")+AND(L10="Implemented/available",S10<>"")+AND(M10="Implemented/available",T10<>""))/((D10="Implemented/available")+(E10="Implemented/available")+(J10="Implemented/available")+(K10="Implemented/available")+(L10="Implemented/available")+(M10="Implemented/available"))) -> 1
A11: OpenAIRE Graph | B11: OpenAIRE | C11: Discovery system | Open scholarly dataset | D11: Implemented/available | E11: Unknown | F11: Implemented/available | G11: Advisory board or steering committee | I11: Formal | J11: Considering | K11: No direct costs | L11: Implemented/available | M11: Implemented/available | N11: Principles for Open Scholarly Infrastructure (POSI) | O11: https://www.openaire.eu/organisation-2 | S11: https://www.openaire.eu/openaire-gep | T11: https://www.openaire.eu/privacy-policy | U11: https://www.openaire.eu/organisation-2 | V11: =IFERROR(IF(ISNUMBER(INDEX(Parameters!$B$5:$B$14,MATCH(D11,Parameters!$A$5:$A$14,0))),INDEX(Parameters!$B$5:$B$14,MATCH(D11,Parameters!$A$5:$A$14,0)),""),"") -> 1 | W11: =IFERROR(IF(ISNUMBER(INDEX(Parameters!$B$5:$B$14,MATCH(E11,Parameters!$A$5:$A$14,0))),INDEX(Parameters!$B$5:$B$14,MATCH(E11,Parameters!$A$5:$A$14,0)),""),"") | X11: =IFERROR(IF(ISNUMBER(INDEX(Parameters!$B$5:$B$14,MATCH(F11,Parameters!$A$5:$A$14,0))),INDEX(Parameters!$B$5:$B$14,MATCH(F11,Parameters!$A$5:$A$14,0)),""),"") -> 1 | Y11: =IF(G11<>"",1,IF(ISNUMBER(Parameters!$B$18),Parameters!$B$18,"")) -> 1 | Z11: =IF(I11<>"",IFERROR(IF(ISNUMBER(INDEX(Parameters!$B$5:$B$14,MATCH(I11,Parameters!$A$5:$A$14,0))),INDEX(Parameters!$B$5:$B$14,MATCH(I11,Parameters!$A$5:$A$14,0)),""),""),IF(ISNUMBER(Parameters!$B$21),Parameters!$B$21,"")) -> 1 | AA11: =IFERROR(IF(ISNUMBER(INDEX(Parameters!$B$5:$B$14,MATCH(J11,Parameters!$A$5:$A$14,0))),INDEX(Parameters!$B$5:$B$14,MATCH(J11,Parameters!$A$5:$A$14,0)),""),"") -> 0.33 | AB11: =IFERROR(IF(ISNUMBER(INDEX(Parameters!$B$5:$B$14,MATCH(K11,Parameters!$A$5:$A$14,0))),INDEX(Parameters!$B$5:$B$14,MATCH(K11,Parameters!$A$5:$A$14,0)),""),"") -> 1 | AC11: =IFERROR(IF(ISNUMBER(INDEX(Parameters!$B$5:$B$14,MATCH(L11,Parameters!$A$5:$A$14,0))),INDEX(Parameters!$B$5:$B$14,MATCH(L11,Parameters!$A$5:$A$14,0)),""),"") -> 1 | AD11: =IFERROR(IF(ISNUMBER(INDEX(Parameters!$B$5:$B$14,MATCH(M11,Parameters!$A$5:$A$14,0))),INDEX(Parameters!$B$5:$B$14,MATCH(M11,Parameters!$A$5:$A$14,0)),""),"") -> 1 | AE11: =IF(N11<>"",1,IF(ISNUMBER(Parameters!$B$19),Parameters!$B$19,"")) -> 1 | AF11: =IF((Parameters!$I$5*ISNUMBER(V11)+Parameters!$I$6*ISNUMBER(W11)+Parameters!$I$7*ISNUMBER(X11)+Parameters!$I$8*ISNUMBER(Y11))=0,"",(Parameters!$I$5*N(V11)+Parameters!$I$6*N(W11)+Parameters!$I$7*N(X11)+Parameters!$I$8*N(Y11))/(Parameters!$I$5*ISNUMBER(V11)+Parameters!$I$6*ISNUMBER(W11)+Parameters!$I$7*ISNUMBER(X11)+Parameters!$I$8*ISNUMBER(Y11))) -> 1 | AG11: =IF((Parameters!$I$9*ISNUMBER(Z11))=0,"",(Parameters!$I$9*N(Z11))/(Parameters!$I$9*ISNUMBER(Z11))) -> 1 | AH11: =IF((Parameters!$I$11*ISNUMBER(AA11)+Parameters!$I$12*ISNUMBER(AB11)+Parameters!$I$13*ISNUMBER(AC11)+Parameters!$I$14*ISNUMBER(AD11)+Parameters!$I$15*ISNUMBER(AE11))=0,"",(Parameters!$I$11*N(AA11)+Parameters!$I$12*N(AB11)+Parameters!$I$13*N(AC11)+Parameters!$I$14*N(AD11)+Parameters!$I$15*N(AE11))/(Parameters!$I$11*ISNUMBER(AA11)+Parameters!$I$12*ISNUMBER(AB11)+Parameters!$I$13*ISNUMBER(AC11)+Parameters!$I$14*ISNUMBER(AD11)+Parameters!$I$15*ISNUMBER(AE11))) -> 0.866 | AI11: =Parameters!$I$5*ISNUMBER(V11)+Parameters!$I$6*ISNUMBER(W11)+Parameters!$I$7*ISNUMBER(X11)+Parameters!$I$8*ISNUMBER(Y11)+Parameters!$I$9*ISNUMBER(Z11)+Parameters!$I$11*ISNUMBER(AA11)+Parameters!$I$12*ISNUMBER(AB11)+Parameters!$I$13*ISNUMBER(AC11)+Parameters!$I$14*ISNUMBER(AD11)+Parameters!$I$15*ISNUMBER(AE11) -> 83 | AJ11: =IF((Parameters!$I$5+Parameters!$I$6+Parameters!$I$7+Parameters!$I$8+Parameters!$I$9+Parameters!$I$11+Parameters!$I$12+Parameters!$I$13+Parameters!$I$14+Parameters!$I$15)=0,"",AI11/(Parameters!$I$5+Parameters!$I$6+Parameters!$I$7+Parameters!$I$8+Parameters!$I$9+Parameters!$I$11+Parameters!$I$12+Parameters!$I$13+Parameters!$I$14+Parameters!$I$15)) -> 0.87368421 | AK11: =IF(AND(ISNUMBER(AF11),ISNUMBER(AH11),OR(NOT((Parameters!$I$9)>0),ISNUMBER(AG11)),AJ11>=Parameters!$B$20),100*(Parameters!$F$18*N(AF11)+Parameters!$F$19*N(AG11)+Parameters!$F$20*N(AH11))/(Parameters!$F$18*ISNUMBER(AF11)+Parameters!$F$19*ISNUMBER(AG11)+Parameters!$F$20*ISNUMBER(AH11)),"") -> 95.31 | AL11: =IF(ISNUMBER(AK11),RANK(AK11,$AK$2:$AK$113),"") -> 8 | AM11: =IF(((D11="Implemented/available")+(E11="Implemented/available")+(J11="Implemented/available")+(K11="Implemented/available")+(L11="Implemented/available")+(M11="Implemented/available"))=0,"",(AND(D11="Implemented/available",O11<>"")+AND(E11="Implemented/available",P11<>"")+AND(J11="Implemented/available",Q11<>"")+AND(K11="Implemented/available",R11<>"")+AND(L11="Implemented/available",S11<>"")+AND(M11="Implemented/available",T11<>""))/((D11="Implemented/available")+(E11="Implemented/available")+(J11="Implemented/available")+(K11="Implemented/available")+(L11="Implemented/available")+(M11="Implemented/available"))) -> 1
A12: Hyrax | B12: Samvera | C12: Repository software | D12: Implemented/available | E12: Implemented/available | F12: Implemented/available | G12: Advisory board or steering committee | H12: Provider | I12: Formal | J12: In progress | K12: No direct costs | L12: In progress | M12: In progress | N12: It Takes a Village Open Source Software Sustainability toolkit | O12: https://samvera.atlassian.net/wiki/spaces/samvera/pages/1387986974/Samvera+Bylaws | P12: https://samvera.atlassian.net/wiki/spaces/samvera/pages/426512038/Notes+from+Samvera+Board+meetings+and+calls | U12: https://samvera.atlassian.net/wiki/spaces/samvera/pages/1387986974/Samvera+Bylaws | V12: =IFERROR(IF(ISNUMBER(INDEX(Parameters!$B$5:$B$14,MATCH(D12,Parameters!$A$5:$A$14,0))),INDEX(Parameters!$B$5:$B$14,MATCH(D12,Parameters!$A$5:$A$14,0)),""),"") -> 1 | W12: =IFERROR(IF(ISNUMBER(INDEX(Parameters!$B$5:$B$14,MATCH(E12,Parameters!$A$5:$A$14,0))),INDEX(Parameters!$B$5:$B$14,MATCH(E12,Parameters!$A$5:$A$14,0)),""),"") -> 1 | X12: =IFERROR(IF(ISNUMBER(INDEX(Parameters!$B$5:$B$14,MATCH(F12,Parameters!$A$5:$A$14,0))),INDEX(Parameters!$B$5:$B$14,MATCH(F12,Parameters!$A$5:$A$14,0)),""),"") -> 1 | Y12: =IF(G12<>"",1,IF(ISNUMBER(Parameters!$B$18),Parameters!$B$18,"")) -> 1 | Z12: =IF(I12<>"",IFERROR(IF(ISNUMBER(INDEX(Parameters!$B$5:$B$14,MATCH(I12,Parameters!$A$5:$A$14,0))),INDEX(Parameters!$B$5:$B$14,MATCH(I12,Parameters!$A$5:$A$14,0)),""),""),IF(ISNUMBER(Parameters!$B$21),Parameters!$B$21,"")) -> 1 | AA12: =IFERROR(IF(ISNUMBER(INDEX(Parameters!$B$5:$B$14,MATCH(J12,Parameters!$A$5:$A$14,0))),INDEX(Parameters!$B$5:$B$14,MATCH(J12,Parameters!$A$5:$A$14,0)),""),"") -> 0.67 | AB12: =IFERROR(IF(ISNUMBER(INDEX(Parameters!$B$5:$B$14,MATCH(K12,Parameters!$A$5:$A$14,0))),INDEX(Parameters!$B$5:$B$14,MATCH(K12,Parameters!$A$5:$A$14,0)),""),"") -> 1 | AC12: =IFERROR(IF(ISNUMBER(INDEX(Parameters!$B$5:$B$14,MATCH(L12,Parameters!$A$5:$A$14,0))),INDEX(Parameters!$B$5:$B$14,MATCH(L12,Parameters!$A$5:$A$14,0)),""),"") -> 0.67 | AD12: =IFERROR(IF(ISNUMBER(INDEX(Parameters!$B$5:$B$14,MATCH(M12,Parameters!$A$5:$A$14,0))),INDEX(Parameters!$B$5:$B$14,MATCH(M12,Parameters!$A$5:$A$14,0)),""),"") -> 0.67 | AE12: =IF(N12<>"",1,IF(ISNUMBER(Parameters!$B$19),Parameters!$B$19,"")) -> 1 | AF12: =IF((Parameters!$I$5*ISNUMBER(V12)+Parameters!$I$6*ISNUMBER(W12)+Parameters!$I$7*ISNUMBER(X12)+Parameters!$I$8*ISNUMBER(Y12))=0,"",(Parameters!$I$5*N(V12)+Parameters!$I$6*N(W12)+Parameters!$I$7*N(X12)+Parameters!$I$8*N(Y12))/(Parameters!$I$5*ISNUMBER(V12)+Parameters!$I$6*ISNUMBER(W12)+Parameters!$I$7*ISNUMBER(X12)+Parameters!$I$8*ISNUMBER(Y12))) -> 1 | AG12: =IF((Parameters!$I$9*ISNUMBER(Z12))=0,"",(Parameters!$I$9*N(Z12))/(Parameters!$I$9*ISNUMBER(Z12))) -> 1 | AH12: =IF((Parameters!$I$11*ISNUMBER(AA12)+Parameters!$I$12*ISNUMBER(AB12)+Parameters!$I$13*ISNUMBER(AC12)+Parameters!$I$14*ISNUMBER(AD12)+Parameters!$I$15*ISNUMBER(AE12))=0,"",(Parameters!$I$11*N(AA12)+Parameters!$I$12*N(AB12)+Parameters!$I$13*N(AC12)+Parameters!$I$14*N(AD12)+Parameters!$I$15*N(AE12))/(Parameters!$I$11*ISNUMBER(AA12)+Parameters!$I$12*ISNUMBER(AB12)+Parameters!$I$13*ISNUMBER(AC12)+Parameters!$I$14*ISNUMBER(AD12)+Parameters!$I$15*ISNUMBER(AE12))) -> 0.802 | AI12: =Parameters!$I$5*ISNUMBER(V12)+Parameters!$I$6*ISNUMBER(W12)+Parameters!$I$7*ISNUMBER(X12)+Parameters!$I$8*ISNUMBER(Y12)+Parameters!$I$9*ISNUMBER(Z12)+Parameters!$I$11*ISNUMBER(AA12)+Parameters!$I$12*ISNUMBER(AB12)+Parameters!$I$13*ISNUMBER(AC12)+Parameters!$I$14*ISNUMBER(AD12)+Parameters!$I$15*ISNUMBER(AE12) -> 95 | AJ12: =IF((Parameters!$I$5+Parameters!$I$6+Parameters!$I$7+Parameters!$I$8+Parameters!$I$9+Parameters!$I$11+Parameters!$I$12+Parameters!$I$13+Parameters!$I$14+Parameters!$I$15)=0,"",AI12/(Parameters!$I$5+Parameters!$I$6+Parameters!$I$7+Parameters!$I$8+Parameters!$I$9+Parameters!$I$11+Parameters!$I$12+Parameters!$I$13+Parameters!$I$14+Parameters!$I$15)) -> 1 | AK12: =IF(AND(ISNUMBER(AF12),ISNUMBER(AH12),OR(NOT((Parameters!$I$9)>0),ISNUMBER(AG12)),AJ12>=Parameters!$B$20),100*(Parameters!$F$18*N(AF12)+Parameters!$F$19*N(AG12)+Parameters!$F$20*N(AH12))/(Parameters!$F$18*ISNUMBER(AF12)+Parameters!$F$19*ISNUMBER(AG12)+Parameters!$F$20*ISNUMBER(AH12)),"") -> 93.07 | AL12: =IF(ISNUMBER(AK12),RANK(AK12,$AK$2:$AK$113),"") -> 11 | AM12: =IF(((D12="Implemented/available")+(E12="Implemented/available")+(J12="Implemented/available")+(K12="Implemented/available")+(L12="Implemented/available")+(M12="Implemented/available"))=0,"",(AND(D12="Implemented/available",O12<>"")+AND(E12="Implemented/available",P12<>"")+AND(J12="Implemented/available",Q12<>"")+AND(K12="Implemented/available",R12<>"")+AND(L12="Implemented/available",S12<>"")+AND(M12="Implemented/available",T12<>""))/((D12="Implemented/available")+(E12="Implemented/available")+(J12="Implemented/available")+(K12="Implemented/available")+(L12="Implemented/available")+(M12="Implemented/available"))) -> 1
