Workbook

Sheet Summary
A1: Development Activity: Equal-Metric Results | B1: Value
A2: Main-list entries | B2: 112
A3: Metrics | B3: 13
A4: Exact weight per metric | B4: 0.076923077
A5: Displayed weight per metric | B5: 7.69%
A6: Final score denominator | B6: 13
A7: Overall coverage eligibility rule | B7: None
A8: Unavailable metric treatment | B8: 0 in final score
A9: Mean zero-filled score | B9: =AVERAGE(Scoring!U2:U113) -> 45.672273
A10: Median zero-filled score | B10: =MEDIAN(Scoring!U2:U113) -> 51.658462
A11: Minimum score | B11: =MIN(Scoring!U2:U113) -> 0
A12: Maximum score | B12: =MAX(Scoring!U2:U113) -> 93.395385
A13: Mean observed coverage | B13: =AVERAGE(Coverage!Q2:Q113) -> 0.77129121
A14: Entries with all 13 metrics observed | B14: 45
A15: Register assessable=yes | B15: 102
A16: Register assessable=no | B16: 10
A17: Mean final score (Python check) | B17: 45.672273
A18: Repository register input | B18: repos.csv
A19: Git metrics input | B19: git_metrics.csv
A20: GitHub/API input | B20: gh_metrics.csv
A21: Manual metrics input | B21: manual_metrics.csv
A22: Interpretation | B22: Zero-filled results include missingness/platform availability; review status and metric-level diagnostics before comparing.

Sheet Scoring
A1: OISI ID | B1: Infrastructure | C1: Classification | D1: Repository status | E1: Primary repo(s) | F1: Git status | G1: GitHub/API status | H1: m1_commits | I1: m2_active_weeks | J1: m3_recency | K1: m4_releases | L1: m5_contributors | M1: m6_effective_contributors | N1: m7_retention | O1: m8_issue_response | P1: m9_pr_response | Q1: m10_issue_close90 | R1: m11_pr_decision30 | S1: m12_stars | T1: m13_forks | U1: Final score / 100 | V1: Rank (average ties) | W1: Available metrics (of 13) | X1: Observed coverage | Y1: Observed-only mean | Z1: Assessment interpretation | AA1: Data-quality notes
A2: C4-001 | B2: 2i2c | C2: software | D2: Ready | E2: 2i2c-org/infrastructure | F2: complete | G2: complete | H2: =Calc!H2 -> 100 | I2: =Calc!I2 -> 100 | J2: =Calc!J2 -> 100 | K2: =Calc!K2 -> 0 | L2: =Calc!L2 -> 100 | M2: =Calc!M2 -> 76.91 | N2: =Calc!N2 -> 100 | O2: =Calc!O2 -> 40.74 | ... T2: =Calc!T2 -> 67.94 | U2: =AVERAGE(H2:T2) -> 70.273846 | V2: =RANK(U2,$U$2:$U$113,0)+(COUNTIF($U$2:$U$113,U2)-1)/2 -> 25 | W2: =Coverage!P2 -> 13 | X2: =Coverage!Q2 -> 1 | Y2: =Coverage!R2 -> 70.273846 | Z2: Repository marked assessable in register | AA2: No missing metric inputs flagged by pipeline availability checks
A3: C4-002 | B3: Academic Preservation Trust (APTrust) | C3: software | D3: Ready | E3: APTrust/registry | F3: complete | G3: complete | H3: =Calc!H3 -> 73.19 | I3: =Calc!I3 -> 53.85 | J3: =Calc!J3 -> 100 | K3: =Calc!K3 -> 0 | L3: =Calc!L3 -> 40 | M3: =Calc!M3 -> 43.48 | N3: =Calc!N3 -> 75 | O3: =Calc!O3 -> 0 | ... T3: =Calc!T3 -> 0 | U3: =AVERAGE(H3:T3) -> 39.270769 | V3: =RANK(U3,$U$2:$U$113,0)+(COUNTIF($U$2:$U$113,U3)-1)/2 -> 71 | W3: =Coverage!P3 -> 13 | X3: =Coverage!Q3 -> 1 | Y3: =Coverage!R3 -> 39.270769 | Z3: Repository marked assessable in register | AA3: No missing metric inputs flagged by pipeline availability checks
A4: C4-003 | B4: AfricArXiv | C4: not-assessable | D4: Not assessable | H4: =Calc!H4 -> 0 | I4: =Calc!I4 -> 0 | J4: =Calc!J4 -> 0 | K4: =Calc!K4 -> 0 | L4: =Calc!L4 -> 0 | M4: =Calc!M4 -> 0 | N4: =Calc!N4 -> 0 | O4: =Calc!O4 -> 0 | ... T4: =Calc!T4 -> 0 | U4: =AVERAGE(H4:T4) -> 0 | V4: =RANK(U4,$U$2:$U$113,0)+(COUNTIF($U$2:$U$113,U4)-1)/2 -> 106 | W4: =Coverage!P4 -> 0 | X4: =Coverage!Q4 -> 0 | Y4: =Coverage!R4 -> 0 | Z4: NOT ASSESSABLE / EXCLUDED: numeric zero is a policy zero-fill, not measured inactivity | AA4: Repository register marks entry not assessable/excluded; zero-filled score is not evidence of inactivity; Git extraction incomplete or unavailable; GitHub/API extraction incomplete or no GitHub source; m8_issue_response unavailable; scored 0; m9_pr_response unavailable; scored 0; m10_issue_close90 unavailable; scored 0; m11_pr_decision30 unavailable; scored 0; GitHub adoption fields unavailable where no supported GitHub source exists; scored 0
A5: C4-004 | B5: Arches Heritage Data Management Platform | C5: software | D5: Ready | E5: archesproject/arches | F5: complete | G5: complete | H5: =Calc!H5 -> 94.95 | I5: =Calc!I5 -> 98.08 | J5: =Calc!J5 -> 100 | K5: =Calc!K5 -> 100 | L5: =Calc!L5 -> 95.1 | M5: =Calc!M5 -> 92.4 | N5: =Calc!N5 -> 100 | O5: =Calc!O5 -> 30.3 | ... T5: =Calc!T5 -> 61.39 | U5: =AVERAGE(H5:T5) -> 79.62 | V5: =RANK(U5,$U$2:$U$113,0)+(COUNTIF($U$2:$U$113,U5)-1)/2 -> 9 | W5: =Coverage!P5 -> 13 | X5: =Coverage!Q5 -> 1 | Y5: =Coverage!R5 -> 79.62 | Z5: Repository marked assessable in register | AA5: No missing metric inputs flagged by pipeline availability checks
A6: C4-005 | B6: Archipelago Commons | C6: software | D6: Org URL -> core module set | E6: esmero/strawberryfield;esmero/format_strawberryfield;esmero/webform_strawberryfield;esmero/strawberry_runners;esmero/ami;esmero/archipelago-deployment | F6: complete | G6: complete | H6: =Calc!H6 -> 75.64 | I6: =Calc!I6 -> 34.62 | J6: =Calc!J6 -> 100 | K6: =Calc!K6 -> 100 | L6: =Calc!L6 -> 31.7 | M6: =Calc!M6 -> 1.89 | N6: =Calc!N6 -> 25 | O6: =Calc!O6 -> 0 | ... T6: =Calc!T6 -> 34.87 | U6: =AVERAGE(H6:T6) -> 40.056154 | V6: =RANK(U6,$U$2:$U$113,0)+(COUNTIF($U$2:$U$113,U6)-1)/2 -> 69 | W6: =Coverage!P6 -> 11 | X6: =Coverage!Q6 -> 0.84615385 | Y6: =Coverage!R6 -> 47.339091 | Z6: Repository marked assessable in register | AA6: m8_issue_response below minimum eligible sample (n=8); scored 0; m10_issue_close90 below minimum eligible sample (n=6); scored 0
A7: C4-006 | B7: Archival Resource Key | C7: standard | D7: Resolved URL -> scoreable standard repo | E7: arks-org/arks.github.io | F7: complete | H7: =Calc!H7 -> 51.04 | I7: =Calc!I7 -> 23.08 | J7: =Calc!J7 -> 100 | K7: =Calc!K7 -> 50 | L7: =Calc!L7 -> 46.44 | M7: =Calc!M7 -> 34.75 | N7: =Calc!N7 -> 0 | O7: =Calc!O7 -> 0 | ... T7: =Calc!T7 -> 0 | U7: =AVERAGE(H7:T7) -> 23.485385 | V7: =RANK(U7,$U$2:$U$113,0)+(COUNTIF($U$2:$U$113,U7)-1)/2 -> 83 | W7: =Coverage!P7 -> 7 | X7: =Coverage!Q7 -> 0.53846154 | Y7: =Coverage!R7 -> 43.615714 | Z7: Repository marked assessable in register | AA7: GitHub/API extraction incomplete or no GitHub source; m8_issue_response unavailable; scored 0; m9_pr_response unavailable; scored 0; m10_issue_close90 unavailable; scored 0; m11_pr_decision30 unavailable; scored 0; GitHub adoption fields unavailable where no supported GitHub source exists; scored 0
A8: C4-007 | B8: Archivematica | C8: software | D8: Ready | E8: artefactual/archivematica | F8: complete | G8: complete | H8: =Calc!H8 -> 73.82 | I8: =Calc!I8 -> 73.08 | J8: =Calc!J8 -> 100 | K8: =Calc!K8 -> 75 | L8: =Calc!L8 -> 46.44 | M8: =Calc!M8 -> 41.9 | N8: =Calc!N8 -> 50 | O8: =Calc!O8 -> 47.5 | ... T8: =Calc!T8 -> 60.08 | U8: =AVERAGE(H8:T8) -> 61.393846 | V8: =RANK(U8,$U$2:$U$113,0)+(COUNTIF($U$2:$U$113,U8)-1)/2 -> 40 | W8: =Coverage!P8 -> 13 | X8: =Coverage!Q8 -> 1 | Y8: =Coverage!R8 -> 61.393846 | Z8: Repository marked assessable in register | AA8: No missing metric inputs flagged by pipeline availability checks
A9: C4-008 | B9: ArchivesSpace | C9: software | D9: Ready | E9: archivesspace/archivesspace | F9: complete | G9: complete | H9: =Calc!H9 -> 92.66 | I9: =Calc!I9 -> 98.08 | J9: =Calc!J9 -> 100 | K9: =Calc!K9 -> 100 | L9: =Calc!L9 -> 100 | M9: =Calc!M9 -> 92.4 | N9: =Calc!N9 -> 100 | O9: =Calc!O9 -> 41.18 | ... T9: =Calc!T9 -> 63.8 | U9: =AVERAGE(H9:T9) -> 81 | V9: =RANK(U9,$U$2:$U$113,0)+(COUNTIF($U$2:$U$113,U9)-1)/2 -> 8 | W9: =Coverage!P9 -> 13 | X9: =Coverage!Q9 -> 1 | Y9: =Coverage!R9 -> 81 | Z9: Repository marked assessable in register | AA9: No missing metric inputs flagged by pipeline availability checks
A10: C4-009 | B10: ARGOS | C10: software | D10: Keep (flag) | E10: OpenCDMP/OpenCDMP | F10: complete | G10: complete | H10: =Calc!H10 -> 23.3 | I10: =Calc!I10 -> 7.69 | J10: =Calc!J10 -> 52.13 | K10: =Calc!K10 -> 75 | L10: =Calc!L10 -> 0 | M10: =Calc!M10 -> 0 | N10: =Calc!N10 -> 0 | O10: =Calc!O10 -> 0 | ... T10: =Calc!T10 -> 23.8 | U10: =AVERAGE(H10:T10) -> 15.216923 | V10: =RANK(U10,$U$2:$U$113,0)+(COUNTIF($U$2:$U$113,U10)-1)/2 -> 93 | W10: =Coverage!P10 -> 9 | X10: =Coverage!Q10 -> 0.69230769 | Y10: =Coverage!R10 -> 21.98 | Z10: Repository marked assessable in register | AA10: m8_issue_response below minimum eligible sample (n=2); scored 0; m9_pr_response below minimum eligible sample (n=2); scored 0; m10_issue_close90 below minimum eligible sample (n=2); scored 0; m11_pr_decision30 below minimum eligible sample (n=2); scored 0
A11: C4-010 | B11: arXiv | C11: software | D11: Org URL -> primary repo | E11: arXiv/arxiv-browse | F11: complete | G11: complete | H11: =Calc!H11 -> 72.62 | I11: =Calc!I11 -> 65.38 | J11: =Calc!J11 -> 100 | K11: =Calc!K11 -> 0 | L11: =Calc!L11 -> 76.15 | M11: =Calc!M11 -> 63.31 | N11: =Calc!N11 -> 75 | O11: =Calc!O11 -> 0 | ... T11: =Calc!T11 -> 64.91 | U11: =AVERAGE(H11:T11) -> 57.309231 | V11: =RANK(U11,$U$2:$U$113,0)+(COUNTIF($U$2:$U$113,U11)-1)/2 -> 49 | W11: =Coverage!P11 -> 11 | X11: =Coverage!Q11 -> 0.84615385 | Y11: =Coverage!R11 -> 67.729091 | Z11: Repository marked assessable in register | AA11: m8_issue_response below minimum eligible sample (n=5); scored 0; m10_issue_close90 below minimum eligible sample (n=5); scored 0
A12: C4-011 | B12: AtoM | C12: software | D12: Ready | E12: artefactual/atom | F12: complete | G12: complete | H12: =Calc!H12 -> 68.17 | I12: =Calc!I12 -> 61.54 | J12: =Calc!J12 -> 100 | K12: =Calc!K12 -> 100 | L12: =Calc!L12 -> 71.7 | M12: =Calc!M12 -> 76.03 | N12: =Calc!N12 -> 100 | O12: =Calc!O12 -> 50.53 | ... T12: =Calc!T12 -> 62.63 | U12: =AVERAGE(H12:T12) -> 69.098462 | V12: =RANK(U12,$U$2:$U$113,0)+(COUNTIF($U$2:$U$113,U12)-1)/2 -> 27 | W12: =Coverage!P12 -> 13 | X12: =Coverage!Q12 -> 1 | Y12: =Coverage!R12 -> 69.098462 | Z12: Repository marked assessable in register | AA12: No missing metric inputs flagged by pipeline availability checks
A13: C4-012 | B13: Avalon Media System | C13: software | D13: Ready | E13: avalonmediasystem/avalon | F13: complete | G13: complete | H13: =Calc!H13 -> 82.27 | I13: =Calc!I13 -> 76.92 | J13: =Calc!J13 -> 100 | K13: =Calc!K13 -> 75 | L13: =Calc!L13 -> 60 | M13: =Calc!M13 -> 59.55 | N13: =Calc!N13 -> 75 | O13: =Calc!O13 -> 42.74 | ... T13: =Calc!T13 -> 0 | U13: =AVERAGE(H13:T13) -> 63.426923 | V13: =RANK(U13,$U$2:$U$113,0)+(COUNTIF($U$2:$U$113,U13)-1)/2 -> 36 | W13: =Coverage!P13 -> 13 | X13: =Coverage!Q13 -> 1 | Y13: =Coverage!R13 -> 63.426923 | Z13: Repository marked assessable in register | AA13: No missing metric inputs flagged by pipeline availability checks
A14: C4-013 | B14: Biodiversity Heritage Library | C14: software | D14: Ready | E14: gbhl/bhl-us | F14: complete | G14: complete | H14: =Calc!H14 -> 69.65 | I14: =Calc!I14 -> 88.46 | J14: =Calc!J14 -> 100 | K14: =Calc!K14 -> 0 | L14: =Calc!L14 -> 20 | M14: =Calc!M14 -> 16.86 | N14: =Calc!N14 -> 25 | O14: =Calc!O14 -> 0 | ... T14: =Calc!T14 -> 0 | U14: =AVERAGE(H14:T14) -> 26.405385 | V14: =RANK(U14,$U$2:$U$113,0)+(COUNTIF($U$2:$U$113,U14)-1)/2 -> 79 | W14: =Coverage!P14 -> 9 | X14: =Coverage!Q14 -> 0.69230769 | Y14: =Coverage!R14 -> 38.141111 | Z14: Repository marked assessable in register | AA14: m8_issue_response unavailable; scored 0; m9_pr_response below minimum eligible sample (n=0); scored 0; m10_issue_close90 unavailable; scored 0; m11_pr_decision30 below minimum eligible sample (n=0); scored 0
A15: C4-014 | B15: bioRxiv | C15: not-assessable | D15: Not assessable | H15: =Calc!H15 -> 0 | I15: =Calc!I15 -> 0 | J15: =Calc!J15 -> 0 | K15: =Calc!K15 -> 0 | L15: =Calc!L15 -> 0 | M15: =Calc!M15 -> 0 | N15: =Calc!N15 -> 0 | O15: =Calc!O15 -> 0 | ... T15: =Calc!T15 -> 0 | U15: =AVERAGE(H15:T15) -> 0 | V15: =RANK(U15,$U$2:$U$113,0)+(COUNTIF($U$2:$U$113,U15)-1)/2 -> 106 | W15: =Coverage!P15 -> 0 | X15: =Coverage!Q15 -> 0 | Y15: =Coverage!R15 -> 0 | Z15: NOT ASSESSABLE / EXCLUDED: numeric zero is a policy zero-fill, not measured inactivity | AA15: Repository register marks entry not assessable/excluded; zero-filled score is not evidence of inactivity; Git extraction incomplete or unavailable; GitHub/API extraction incomplete or no GitHub source; m8_issue_response unavailable; scored 0; m9_pr_response unavailable; scored 0; m10_issue_close90 unavailable; scored 0; m11_pr_decision30 unavailable; scored 0; GitHub adoption fields unavailable where no supported GitHub source exists; scored 0
A16: C4-015 | B16: BitCurator Environment | C16: software | D16: Ready | E16: bitcurator/bitcurator-salt | F16: complete | G16: complete | H16: =Calc!H16 -> 10.03 | I16: =Calc!I16 -> 1.92 | J16: =Calc!J16 -> 18.55 | K16: =Calc!K16 -> 0 | L16: =Calc!L16 -> 0 | M16: =Calc!M16 -> 0 | N16: =Calc!N16 -> 0 | O16: =Calc!O16 -> 0 | ... T16: =Calc!T16 -> 0 | U16: =AVERAGE(H16:T16) -> 2.3461538 | V16: =RANK(U16,$U$2:$U$113,0)+(COUNTIF($U$2:$U$113,U16)-1)/2 -> 98 | W16: =Coverage!P16 -> 9 | X16: =Coverage!Q16 -> 0.69230769 | Y16: =Coverage!R16 -> 3.3888889 | Z16: Repository marked assessable in register | AA16: m8_issue_response unavailable; scored 0; m9_pr_response below minimum eligible sample (n=1); scored 0; m10_issue_close90 unavailable; scored 0; m11_pr_decision30 below minimum eligible sample (n=1); scored 0
A17: C4-016 | B17: Blacklight | C17: software | D17: Org URL -> primary repo | E17: projectblacklight/blacklight | F17: complete | G17: complete | H17: =Calc!H17 -> 68.93 | I17: =Calc!I17 -> 57.69 | J17: =Calc!J17 -> 100 | K17: =Calc!K17 -> 100 | L17: =Calc!L17 -> 71.7 | M17: =Calc!M17 -> 64.07 | N17: =Calc!N17 -> 75 | O17: =Calc!O17 -> 58.33 | ... T17: =Calc!T17 -> 34.87 | U17: =AVERAGE(H17:T17) -> 65.488462 | V17: =RANK(U17,$U$2:$U$113,0)+(COUNTIF($U$2:$U$113,U17)-1)/2 -> 32 | W17: =Coverage!P17 -> 13 | X17: =Coverage!Q17 -> 1 | Y17: =Coverage!R17 -> 65.488462 | Z17: Repository marked assessable in register | AA17: No missing metric inputs flagged by pipeline availability checks
A18: C4-017 | B18: BrCRIS | C18: software | D18: Resolved URL | E18: brcris-ibict/brcris-interface-busca | F18: complete | H18: =Calc!H18 -> 78.07 | I18: =Calc!I18 -> 90.38 | J18: =Calc!J18 -> 100 | K18: =Calc!K18 -> 75 | L18: =Calc!L18 -> 40 | M18: =Calc!M18 -> 29.06 | N18: =Calc!N18 -> 50 | O18: =Calc!O18 -> 0 | ... T18: =Calc!T18 -> 0 | U18: =AVERAGE(H18:T18) -> 35.577692 | V18: =RANK(U18,$U$2:$U$113,0)+(COUNTIF($U$2:$U$113,U18)-1)/2 -> 76 | W18: =Coverage!P18 -> 7 | X18: =Coverage!Q18 -> 0.53846154 | Y18: =Coverage!R18 -> 66.072857 | Z18: Repository marked assessable in register | AA18: GitHub/API extraction incomplete or no GitHub source; m8_issue_response unavailable; scored 0; m9_pr_response unavailable; scored 0; m10_issue_close90 unavailable; scored 0; m11_pr_decision30 unavailable; scored 0; GitHub adoption fields unavailable where no supported GitHub source exists; scored 0
A19: C4-018 | B19: Browsertrix | C19: software | D19: Ready | E19: webrecorder/browsertrix | F19: complete | G19: complete | H19: =Calc!H19 -> 87.67 | I19: =Calc!I19 -> 100 | J19: =Calc!J19 -> 100 | K19: =Calc!K19 -> 100 | L19: =Calc!L19 -> 63.4 | M19: =Calc!M19 -> 64.07 | N19: =Calc!N19 -> 75 | O19: =Calc!O19 -> 45.59 | ... T19: =Calc!T19 -> 65.97 | U19: =AVERAGE(H19:T19) -> 78.180769 | V19: =RANK(U19,$U$2:$U$113,0)+(COUNTIF($U$2:$U$113,U19)-1)/2 -> 12 | W19: =Coverage!P19 -> 13 | X19: =Coverage!Q19 -> 1 | Y19: =Coverage!R19 -> 78.180769 | Z19: Repository marked assessable in register | AA19: No missing metric inputs flagged by pipeline availability checks
A20: C4-019 | B20: CLOCKSS | C20: software | D20: Org URL -> primary repo | E20: lockss/lockss-daemon | F20: complete | G20: complete | H20: =Calc!H20 -> 100 | I20: =Calc!I20 -> 98.08 | J20: =Calc!J20 -> 100 | K20: =Calc!K20 -> 100 | L20: =Calc!L20 -> 63.4 | M20: =Calc!M20 -> 59.27 | N20: =Calc!N20 -> 100 | O20: =Calc!O20 -> 0 | ... T20: =Calc!T20 -> 15.02 | U20: =AVERAGE(H20:T20) -> 50.697692 | V20: =RANK(U20,$U$2:$U$113,0)+(COUNTIF($U$2:$U$113,U20)-1)/2 -> 57 | W20: =Coverage!P20 -> 9 | X20: =Coverage!Q20 -> 0.69230769 | Y20: =Coverage!R20 -> 73.23 | Z20: Repository marked assessable in register | AA20: m8_issue_response below minimum eligible sample (n=0); scored 0; m9_pr_response below minimum eligible sample (n=1); scored 0; m10_issue_close90 below minimum eligible sample (n=0); scored 0; m11_pr_decision30 below minimum eligible sample (n=1); scored 0
A21: C4-020 | B21: COAR International Repository Directory (IRD) | C21: software | D21: Ready | E21: antleaf/IRD | F21: complete | G21: complete | H21: =Calc!H21 -> 59.97 | I21: =Calc!I21 -> 46.15 | J21: =Calc!J21 -> 100 | K21: =Calc!K21 -> 100 | L21: =Calc!L21 -> 31.7 | M21: =Calc!M21 -> 19.82 | N21: =Calc!N21 -> 25 | O21: =Calc!O21 -> 50 | ... T21: =Calc!T21 -> 15.02 | U21: =AVERAGE(H21:T21) -> 40.102308 | V21: =RANK(U21,$U$2:$U$113,0)+(COUNTIF($U$2:$U$113,U21)-1)/2 -> 68 | W21: =Coverage!P21 -> 11 | X21: =Coverage!Q21 -> 0.84615385 | Y21: =Coverage!R21 -> 47.393636 | Z21: Repository marked assessable in register | AA21: m9_pr_response below minimum eligible sample (n=6); scored 0; m11_pr_decision30 below minimum eligible sample (n=6); scored 0
A22: C4-021 | B22: COAR Notify | C22: software | D22: Ready | E22: coar-notify/coar-notify.net | F22: complete | G22: complete | H22: =Calc!H22 -> 33.33 | I22: =Calc!I22 -> 7.69 | J22: =Calc!J22 -> 77.73 | K22: =Calc!K22 -> 0 | L22: =Calc!L22 -> 31.7 | M22: =Calc!M22 -> 22.3 | N22: =Calc!N22 -> 25 | O22: =Calc!O22 -> 0 | ... T22: =Calc!T22 -> 23.8 | U22: =AVERAGE(H22:T22) -> 17.813846 | V22: =RANK(U22,$U$2:$U$113,0)+(COUNTIF($U$2:$U$113,U22)-1)/2 -> 91 | W22: =Coverage!P22 -> 9 | X22: =Coverage!Q22 -> 0.69230769 | Y22: =Coverage!R22 -> 25.731111 | Z22: Repository marked assessable in register | AA22: m8_issue_response below minimum eligible sample (n=3); scored 0; m9_pr_response below minimum eligible sample (n=3); scored 0; m10_issue_close90 below minimum eligible sample (n=3); scored 0; m11_pr_decision30 below minimum eligible sample (n=3); scored 0
A23: C4-022 | B23: CollectiveAccess | C23: software | D23: Org URL -> primary repo | E23: collectiveaccess/providence | F23: complete | G23: complete | H23: =Calc!H23 -> 97.46 | I23: =Calc!I23 -> 100 | J23: =Calc!J23 -> 100 | K23: =Calc!K23 -> 75 | L23: =Calc!L23 -> 71.7 | M23: =Calc!M23 -> 50.53 | N23: =Calc!N23 -> 100 | O23: =Calc!O23 -> 59.35 | ... T23: =Calc!T23 -> 58.68 | U23: =AVERAGE(H23:T23) -> 75.153846 | V23: =RANK(U23,$U$2:$U$113,0)+(COUNTIF($U$2:$U$113,U23)-1)/2 -> 18 | W23: =Coverage!P23 -> 13 | X23: =Coverage!Q23 -> 1 | Y23: =Coverage!R23 -> 75.153846 | Z23: Repository marked assessable in register | AA23: No missing metric inputs flagged by pipeline availability checks
A24: C4-023 | B24: CORE | C24: software | D24: Resolved URL | E24: oacore/dashboard | F24: complete | H24: =Calc!H24 -> 77.94 | I24: =Calc!I24 -> 75 | J24: =Calc!J24 -> 100 | K24: =Calc!K24 -> 0 | L24: =Calc!L24 -> 71.7 | M24: =Calc!M24 -> 67.5 | N24: =Calc!N24 -> 100 | O24: =Calc!O24 -> 0 | ... T24: =Calc!T24 -> 0 | U24: =AVERAGE(H24:T24) -> 37.856923 | V24: =RANK(U24,$U$2:$U$113,0)+(COUNTIF($U$2:$U$113,U24)-1)/2 -> 74 | W24: =Coverage!P24 -> 7 | X24: =Coverage!Q24 -> 0.53846154 | Y24: =Coverage!R24 -> 70.305714 | Z24: Repository marked assessable in register | AA24: GitHub/API extraction incomplete or no GitHub source; m8_issue_response unavailable; scored 0; m9_pr_response unavailable; scored 0; m10_issue_close90 unavailable; scored 0; m11_pr_decision30 unavailable; scored 0; GitHub adoption fields unavailable where no supported GitHub source exists; scored 0
A25: C4-024 | B25: COUNTER Code of Practice | C25: standard | D25: Resolved URL -> scoreable standard repo | E25: Project-Counter/cop5 | F25: complete | H25: =Calc!H25 -> 53.03 | I25: =Calc!I25 -> 19.23 | J25: =Calc!J25 -> 92.36 | K25: =Calc!K25 -> 0 | L25: =Calc!L25 -> 46.44 | M25: =Calc!M25 -> 58.99 | N25: =Calc!N25 -> 25 | O25: =Calc!O25 -> 0 | ... T25: =Calc!T25 -> 0 | U25: =AVERAGE(H25:T25) -> 22.696154 | V25: =RANK(U25,$U$2:$U$113,0)+(COUNTIF($U$2:$U$113,U25)-1)/2 -> 85 | W25: =Coverage!P25 -> 7 | X25: =Coverage!Q25 -> 0.53846154 | Y25: =Coverage!R25 -> 42.15 | Z25: Repository marked assessable in register | AA25: GitHub/API extraction incomplete or no GitHub source; m8_issue_response unavailable; scored 0; m9_pr_response unavailable; scored 0; m10_issue_close90 unavailable; scored 0; m11_pr_decision30 unavailable; scored 0; GitHub adoption fields unavailable where no supported GitHub source exists; scored 0
A26: C4-025 | B26: Creative Commons Licenses | C26: software | D26: Org URL -> primary repo | E26: creativecommons/cc-legal-tools-app | F26: complete | G26: complete | H26: =Calc!H26 -> 62.68 | I26: =Calc!I26 -> 30.77 | J26: =Calc!J26 -> 100 | K26: =Calc!K26 -> 0 | L26: =Calc!L26 -> 46.44 | M26: =Calc!M26 -> 32.61 | N26: =Calc!N26 -> 25 | O26: =Calc!O26 -> 63.64 | ... T26: =Calc!T26 -> 95.48 | U26: =AVERAGE(H26:T26) -> 57.923077 | V26: =RANK(U26,$U$2:$U$113,0)+(COUNTIF($U$2:$U$113,U26)-1)/2 -> 48 | W26: =Coverage!P26 -> 13 | X26: =Coverage!Q26 -> 1 | Y26: =Coverage!R26 -> 57.923077 | Z26: Repository marked assessable in register | AA26: No missing metric inputs flagged by pipeline availability checks
A27: C4-026 | B27: Crossref Metadata Retrieval | C27: software | D27: Non-GitHub (verify repo) | E27: https://gitlab.com/crossref/rest_api | F27: complete | G27: no GitHub source | H27: =Calc!H27 -> 55.1 | I27: =Calc!I27 -> 46.15 | J27: =Calc!J27 -> 100 | K27: =Calc!K27 -> 100 | L27: =Calc!L27 -> 51.7 | M27: =Calc!M27 -> 50.53 | N27: =Calc!N27 -> 75 | O27: =Calc!O27 -> 0 | ... T27: =Calc!T27 -> 0 | U27: =AVERAGE(H27:T27) -> 36.806154 | V27: =RANK(U27,$U$2:$U$113,0)+(COUNTIF($U$2:$U$113,U27)-1)/2 -> 75 | W27: =Coverage!P27 -> 7 | X27: =Coverage!Q27 -> 0.53846154 | Y27: =Coverage!R27 -> 68.354286 | Z27: Repository marked assessable in register | AA27: GitHub/API extraction incomplete or no GitHub source; m8_issue_response unavailable; scored 0; m9_pr_response unavailable; scored 0; m10_issue_close90 unavailable; scored 0; m11_pr_decision30 unavailable; scored 0; GitHub adoption fields unavailable where no supported GitHub source exists; scored 0
A28: C4-027 | B28: D4Science Infrastructure | C28: needs-decision | D28: Non-GitHub: choose repo | H28: =Calc!H28 -> 0 | I28: =Calc!I28 -> 0 | J28: =Calc!J28 -> 0 | K28: =Calc!K28 -> 0 | L28: =Calc!L28 -> 0 | M28: =Calc!M28 -> 0 | N28: =Calc!N28 -> 0 | O28: =Calc!O28 -> 0 | ... T28: =Calc!T28 -> 0 | U28: =AVERAGE(H28:T28) -> 0 | V28: =RANK(U28,$U$2:$U$113,0)+(COUNTIF($U$2:$U$113,U28)-1)/2 -> 106 | W28: =Coverage!P28 -> 0 | X28: =Coverage!Q28 -> 0 | Y28: =Coverage!R28 -> 0 | Z28: NOT ASSESSABLE / EXCLUDED: numeric zero is a policy zero-fill, not measured inactivity | AA28: Repository register marks entry not assessable/excluded; zero-filled score is not evidence of inactivity; Git extraction incomplete or unavailable; GitHub/API extraction incomplete or no GitHub source; m8_issue_response unavailable; scored 0; m9_pr_response unavailable; scored 0; m10_issue_close90 unavailable; scored 0; m11_pr_decision30 unavailable; scored 0; GitHub adoption fields unavailable where no supported GitHub source exists; scored 0
A29: C4-028 | B29: DART (Digital Archivist's Resource Tool) | C29: software | D29: Ready | E29: aptrust/dart | F29: complete | G29: complete | H29: =Calc!H29 -> 76.54 | I29: =Calc!I29 -> 44.23 | J29: =Calc!J29 -> 100 | K29: =Calc!K29 -> 100 | L29: =Calc!L29 -> 31.7 | M29: =Calc!M29 -> 37.48 | N29: =Calc!N29 -> 25 | O29: =Calc!O29 -> 100 | ... T29: =Calc!T29 -> 0 | U29: =AVERAGE(H29:T29) -> 42.708462 | V29: =RANK(U29,$U$2:$U$113,0)+(COUNTIF($U$2:$U$113,U29)-1)/2 -> 66 | W29: =Coverage!P29 -> 11 | X29: =Coverage!Q29 -> 0.84615385 | Y29: =Coverage!R29 -> 50.473636 | Z29: Repository marked assessable in register | AA29: m9_pr_response below minimum eligible sample (n=6); scored 0; m11_pr_decision30 below minimum eligible sample (n=5); scored 0
A30: C4-029 | B30: Database Information System | C30: software | D30: Keep (dormant/new) | E30: ub-regensburg/dbis | F30: complete | G30: complete | H30: =Calc!H30 -> 0 | I30: =Calc!I30 -> 0 | J30: =Calc!J30 -> 0 | K30: =Calc!K30 -> 0 | L30: =Calc!L30 -> 0 | M30: =Calc!M30 -> 0 | N30: =Calc!N30 -> 0 | O30: =Calc!O30 -> 0 | ... T30: =Calc!T30 -> 0 | U30: =AVERAGE(H30:T30) -> 0 | V30: =RANK(U30,$U$2:$U$113,0)+(COUNTIF($U$2:$U$113,U30)-1)/2 -> 106 | W30: =Coverage!P30 -> 9 | X30: =Coverage!Q30 -> 0.69230769 | Y30: =Coverage!R30 -> 0 | Z30: Repository marked assessable in register | AA30: m8_issue_response below minimum eligible sample (n=0); scored 0; m9_pr_response below minimum eligible sample (n=0); scored 0; m10_issue_close90 below minimum eligible sample (n=0); scored 0; m11_pr_decision30 below minimum eligible sample (n=0); scored 0
A31: C4-030 | B31: Data Citation Corpus | C31: software | D31: Keep | E31: Make-Data-Count-Community/corpus-data-file | F31: complete | G31: complete | H31: =Calc!H31 -> 10.03 | I31: =Calc!I31 -> 1.92 | J31: =Calc!J31 -> 80.72 | K31: =Calc!K31 -> 0 | L31: =Calc!L31 -> 0 | M31: =Calc!M31 -> 0 | N31: =Calc!N31 -> 0 | O31: =Calc!O31 -> 0 | ... T31: =Calc!T31 -> 0 | U31: =AVERAGE(H31:T31) -> 7.9 | V31: =RANK(U31,$U$2:$U$113,0)+(COUNTIF($U$2:$U$113,U31)-1)/2 -> 95 | W31: =Coverage!P31 -> 9 | X31: =Coverage!Q31 -> 0.69230769 | Y31: =Coverage!R31 -> 11.411111 | Z31: Repository marked assessable in register | AA31: m8_issue_response below minimum eligible sample (n=0); scored 0; m9_pr_response below minimum eligible sample (n=0); scored 0; m10_issue_close90 below minimum eligible sample (n=0); scored 0; m11_pr_decision30 below minimum eligible sample (n=0); scored 0
A32: C4-031 | B32: DataCite | C32: software | D32: Org URL -> primary repo | E32: datacite/lupo | F32: complete | G32: complete | H32: =Calc!H32 -> 97.95 | I32: =Calc!I32 -> 96.15 | J32: =Calc!J32 -> 100 | K32: =Calc!K32 -> 100 | L32: =Calc!L32 -> 69.19 | M32: =Calc!M32 -> 67.26 | N32: =Calc!N32 -> 100 | O32: =Calc!O32 -> 40 | ... T32: =Calc!T32 -> 0 | U32: =AVERAGE(H32:T32) -> 70.750769 | V32: =RANK(U32,$U$2:$U$113,0)+(COUNTIF($U$2:$U$113,U32)-1)/2 -> 24 | W32: =Coverage!P32 -> 13 | X32: =Coverage!Q32 -> 1 | Y32: =Coverage!R32 -> 70.750769 | Z32: Repository marked assessable in register | AA32: No missing metric inputs flagged by pipeline availability checks
A33: C4-032 | B33: Data Stewardship Wizard | C33: software | D33: Org URL -> product set | E33: ds-wizard/engine-backend;ds-wizard/engine-frontend | F33: complete | G33: complete | H33: =Calc!H33 -> 85.94 | I33: =Calc!I33 -> 94.23 | J33: =Calc!J33 -> 100 | K33: =Calc!K33 -> 100 | L33: =Calc!L33 -> 40 | M33: =Calc!M33 -> 31.62 | N33: =Calc!N33 -> 75 | O33: =Calc!O33 -> 60 | ... T33: =Calc!T33 -> 42.16 | U33: =AVERAGE(H33:T33) -> 58.443846 | V33: =RANK(U33,$U$2:$U$113,0)+(COUNTIF($U$2:$U$113,U33)-1)/2 -> 46 | W33: =Coverage!P33 -> 12 | X33: =Coverage!Q33 -> 0.92307692 | Y33: =Coverage!R33 -> 63.314167 | Z33: Repository marked assessable in register | AA33: m10_issue_close90 below minimum eligible sample (n=8); scored 0
A34: C4-033 | B34: Dataverse | C34: software | D34: Ready | E34: IQSS/dataverse | F34: complete | G34: complete | H34: =Calc!H34 -> 100 | I34: =Calc!I34 -> 98.08 | J34: =Calc!J34 -> 100 | K34: =Calc!K34 -> 100 | L34: =Calc!L34 -> 100 | M34: =Calc!M34 -> 93.78 | N34: =Calc!N34 -> 100 | O34: =Calc!O34 -> 55.95 | ... T34: =Calc!T34 -> 84.33 | U34: =AVERAGE(H34:T34) -> 83.001538 | V34: =RANK(U34,$U$2:$U$113,0)+(COUNTIF($U$2:$U$113,U34)-1)/2 -> 5 | W34: =Coverage!P34 -> 13 | X34: =Coverage!Q34 -> 1 | Y34: =Coverage!R34 -> 83.001538 | Z34: Repository marked assessable in register | AA34: No missing metric inputs flagged by pipeline availability checks
A35: C4-034 | B35: DLCM Backend | C35: software | D35: Non-GitHub | E35: https://gitlab.unige.ch/dlcm/community/dlcm-backend | F35: complete | G35: no GitHub source | H35: =Calc!H35 -> 68.43 | I35: =Calc!I35 -> 71.15 | J35: =Calc!J35 -> 100 | K35: =Calc!K35 -> 100 | L35: =Calc!L35 -> 66.44 | M35: =Calc!M35 -> 85.44 | N35: =Calc!N35 -> 100 | O35: =Calc!O35 -> 0 | ... T35: =Calc!T35 -> 0 | U35: =AVERAGE(H35:T35) -> 45.496923 | V35: =RANK(U35,$U$2:$U$113,0)+(COUNTIF($U$2:$U$113,U35)-1)/2 -> 62 | W35: =Coverage!P35 -> 7 | X35: =Coverage!Q35 -> 0.53846154 | Y35: =Coverage!R35 -> 84.494286 | Z35: Repository marked assessable in register | AA35: GitHub/API extraction incomplete or no GitHub source; m8_issue_response unavailable; scored 0; m9_pr_response unavailable; scored 0; m10_issue_close90 unavailable; scored 0; m11_pr_decision30 unavailable; scored 0; GitHub adoption fields unavailable where no supported GitHub source exists; scored 0
A36: C4-035 | B36: DLCM Portal | C36: software | D36: Non-GitHub | E36: https://gitlab.unige.ch/dlcm/ui/dlcm-portal | F36: complete | G36: no GitHub source | H36: =Calc!H36 -> 74.67 | I36: =Calc!I36 -> 63.46 | J36: =Calc!J36 -> 100 | K36: =Calc!K36 -> 100 | L36: =Calc!L36 -> 56.15 | M36: =Calc!M36 -> 31.87 | N36: =Calc!N36 -> 75 | O36: =Calc!O36 -> 0 | ... T36: =Calc!T36 -> 0 | U36: =AVERAGE(H36:T36) -> 38.55 | V36: =RANK(U36,$U$2:$U$113,0)+(COUNTIF($U$2:$U$113,U36)-1)/2 -> 72 | W36: =Coverage!P36 -> 7 | X36: =Coverage!Q36 -> 0.53846154 | Y36: =Coverage!R36 -> 71.592857 | Z36: Repository marked assessable in register | AA36: GitHub/API extraction incomplete or no GitHub source; m8_issue_response unavailable; scored 0; m9_pr_response unavailable; scored 0; m10_issue_close90 unavailable; scored 0; m11_pr_decision30 unavailable; scored 0; GitHub adoption fields unavailable where no supported GitHub source exists; scored 0
A37: C4-036 | B37: DMP Tool | C37: software | D37: Replace URL (verify) | E37: CDLUC3/dmsp_frontend_prototype;CDLUC3/dmsp_backend_prototype | F37: complete | G37: complete | H37: =Calc!H37 -> 100 | I37: =Calc!I37 -> 94.23 | J37: =Calc!J37 -> 100 | K37: =Calc!K37 -> 50 | L37: =Calc!L37 -> 63.4 | M37: =Calc!M37 -> 41.29 | N37: =Calc!N37 -> 75 | O37: =Calc!O37 -> 38.36 | ... T37: =Calc!T37 -> 15.02 | U37: =AVERAGE(H37:T37) -> 63.221538 | V37: =RANK(U37,$U$2:$U$113,0)+(COUNTIF($U$2:$U$113,U37)-1)/2 -> 37 | W37: =Coverage!P37 -> 13 | X37: =Coverage!Q37 -> 1 | Y37: =Coverage!R37 -> 63.221538 | Z37: Repository marked assessable in register | AA37: No missing metric inputs flagged by pipeline availability checks
A38: C4-037 | B38: DOAJ (Directory of Open Access Journals) | C38: software | D38: Org URL -> primary repo | E38: DOAJ/doaj | F38: complete | G38: complete | H38: =Calc!H38 -> 95.61 | I38: =Calc!I38 -> 98.08 | J38: =Calc!J38 -> 100 | K38: =Calc!K38 -> 100 | L38: =Calc!L38 -> 80 | M38: =Calc!M38 -> 100 | N38: =Calc!N38 -> 100 | O38: =Calc!O38 -> 0 | ... T38: =Calc!T38 -> 15.02 | U38: =AVERAGE(H38:T38) -> 62.024615 | V38: =RANK(U38,$U$2:$U$113,0)+(COUNTIF($U$2:$U$113,U38)-1)/2 -> 39 | W38: =Coverage!P38 -> 11 | X38: =Coverage!Q38 -> 0.84615385 | Y38: =Coverage!R38 -> 73.301818 | Z38: Repository marked assessable in register | AA38: m8_issue_response below minimum eligible sample (n=8); scored 0; m10_issue_close90 below minimum eligible sample (n=8); scored 0
A39: C4-038 | B39: dokieli | C39: software | D39: Ready | E39: linkeddata/dokieli | F39: complete | G39: complete | H39: =Calc!H39 -> 98.73 | I39: =Calc!I39 -> 86.54 | J39: =Calc!J39 -> 100 | K39: =Calc!K39 -> 0 | L39: =Calc!L39 -> 31.7 | M39: =Calc!M39 -> 31.37 | N39: =Calc!N39 -> 50 | O39: =Calc!O39 -> 11.76 | ... T39: =Calc!T39 -> 53.84 | U39: =AVERAGE(H39:T39) -> 52.619231 | V39: =RANK(U39,$U$2:$U$113,0)+(COUNTIF($U$2:$U$113,U39)-1)/2 -> 56 | W39: =Coverage!P39 -> 13 | X39: =Coverage!Q39 -> 1 | Y39: =Coverage!R39 -> 52.619231 | Z39: Repository marked assessable in register | AA39: No missing metric inputs flagged by pipeline availability checks
A40: C4-039 | B40: Dryad | C40: software | D40: Replace URL | E40: datadryad/dryad-app | F40: complete | G40: complete | H40: =Calc!H40 -> 100 | I40: =Calc!I40 -> 98.08 | J40: =Calc!J40 -> 100 | K40: =Calc!K40 -> 100 | L40: =Calc!L40 -> 31.7 | M40: =Calc!M40 -> 30.36 | N40: =Calc!N40 -> 75 | O40: =Calc!O40 -> 0 | ... T40: =Calc!T40 -> 15.02 | U40: =AVERAGE(H40:T40) -> 56.502308 | V40: =RANK(U40,$U$2:$U$113,0)+(COUNTIF($U$2:$U$113,U40)-1)/2 -> 52 | W40: =Coverage!P40 -> 11 | X40: =Coverage!Q40 -> 0.84615385 | Y40: =Coverage!R40 -> 66.775455 | Z40: Repository marked assessable in register | AA40: m8_issue_response below minimum eligible sample (n=0); scored 0; m10_issue_close90 below minimum eligible sample (n=0); scored 0
...

Sheet Metric Rules
A1: Code | B1: Metric | C1: Dimension label | D1: Source field | E1: Exact weight | F1: Displayed weight | G1: Definition | H1: Scoring rule | I1: Unavailable-data rule | J1: Why included / interpretation
A2: m1_commits | B2: Human commits | C2: Continuity | D2: git_metrics.csv::human_commits | E2: 0.076923077 | F2: 7.69% | G2: Non-merge, non-bot commits during the window. | H2: 100 * min(1, log10(1+c) / log10(1001)); 1,000 or more commits = 100. | I2: Scores 0 in the fixed-denominator final score; not counted as observed coverage. A valid observed zero remains observed. | J2: Measures recorded development volume. Log scaling limits domination by very large repositories.
A3: m2_active_weeks | B3: Active weeks | C3: Continuity | D3: git_metrics.csv::active_weeks | E3: 0.076923077 | F3: 7.69% | G3: Distinct weeks, out of 52, with at least one human non-merge commit. | H3: 100 * active_weeks / 52. | I3: Scores 0 in the fixed-denominator final score; not counted as observed coverage. A valid observed zero remains observed. | J3: Measures temporal spread of work rather than total volume.
A4: m3_recency | B4: Commit recency | C4: Continuity | D4: git_metrics.csv::days_since_last | E4: 0.076923077 | F4: 7.69% | G4: Days from the latest human non-merge commit in the window to the cutoff. | H4: 100 if d <= 30; otherwise max(0, 100 * (365-d)/335). No activity in a complete Git extract = 0. | I4: Scores 0 in the fixed-denominator final score; not counted as observed coverage. A valid observed zero remains observed. | J4: Distinguishes recent recorded development from activity that ended earlier in the window.
A5: m4_releases | B5: Release activity | C5: Continuity | D5: git_metrics.csv::tags_in_window | E5: 0.076923077 | F5: 7.69% | G5: Number of Git tags created during the window; tags are a proxy for releases. | H5: 0 tags = 0; 1 = 50; 2-3 = 75; 4+ = 100. | I5: Scores 0 in the fixed-denominator final score; not counted as observed coverage. A valid observed zero remains observed. | J5: Captures versioned outputs; projects that release without Git tags may be undercounted.
A6: m5_contributors | B6: Active contributors | C6: Contributors | D6: git_metrics.csv::contributors | E6: 0.076923077 | F6: 7.69% | G6: Resolved human identities with at least one non-merge commit in the window. | H6: 0-1 contributors = 0; otherwise 100 * min(1, log2(n)/5); 32+ = 100. | I6: Scores 0 in the fixed-denominator final score; not counted as observed coverage. A valid observed zero remains observed. | J6: Measures breadth of human participation, beyond commit volume alone.
A7: m6_effective_contributors | B7: Effective contributors | C7: Contributors | D7: git_metrics.csv::eff_contributors | E7: 0.076923077 | F7: 7.69% | G7: Inverse concentration of human commit shares: E = 1 / sum(p_i^2). | H7: 0 if E <= 1; otherwise 100 * min(1, log2(E)/3); E >= 8 = 100. | I7: Scores 0 in the fixed-denominator final score; not counted as observed coverage. A valid observed zero remains observed. | J7: Adjusts contributor count for whether work is concentrated in a small number of people.
A8: m7_retention | B8: Contributor retention | C8: Contributors | D8: git_metrics.csv::retained | E8: 0.076923077 | F8: 7.69% | G8: Number of contributors active in both halves of the observation window. | H8: 0 = 0; 1 = 25; 2 = 50; 3-4 = 75; 5+ = 100. | I8: Scores 0 in the fixed-denominator final score; not counted as observed coverage. A valid observed zero remains observed. | J8: Captures continued participation across the year rather than one-time contribution.
A9: m8_issue_response | B9: Issue response within 14 days | C9: Responsiveness | D9: gh_metrics.csv::m8_issue_response_rate; manual_metrics.csv override | E9: 0.076923077 | F9: 7.69% | G9: Share of eligible issues receiving a qualifying response within 14 days. | H9: 100 * response rate; at least 10 eligible issues required for an observed rate. | I9: Scores 0 in the fixed-denominator final score; not counted as observed coverage. A valid observed zero remains observed. Rate is unavailable below n >= 10; that does not exclude the infrastructure from scoring. | J9: Measures timely handling of reported issues. A response is not the same as resolution.
A10: m9_pr_response | B10: PR response within 7 days | C10: Responsiveness | D10: gh_metrics.csv::m9_pr_response_rate | E10: 0.076923077 | F10: 7.69% | G10: Share of eligible non-bot pull requests receiving a qualifying response within 7 days. | H10: 100 * response rate; at least 10 eligible PRs required for an observed rate. | I10: Scores 0 in the fixed-denominator final score; not counted as observed coverage. A valid observed zero remains observed. Rate is unavailable below n >= 10; that does not exclude the infrastructure from scoring. | J10: Measures timely engagement with proposed contributions.
A11: m10_issue_close90 | B11: Issue closure within 90 days | C11: Responsiveness | D11: gh_metrics.csv::m10_issue_close90_rate; manual_metrics.csv override | E11: 0.076923077 | F11: 7.69% | G11: Share of eligible human-authored issues closed within 90 days. | H11: 100 * closure rate; at least 10 eligible issues required for an observed rate. | I11: Scores 0 in the fixed-denominator final score; not counted as observed coverage. A valid observed zero remains observed. Rate is unavailable below n >= 10; that does not exclude the infrastructure from scoring. | J11: Measures follow-through on issues, distinct from an initial response.
A12: m11_pr_decision30 | B12: PR decision within 30 days | C12: Responsiveness | D12: gh_metrics.csv::m11_pr_decision30_rate | E12: 0.076923077 | F12: 7.69% | G12: Share of eligible non-bot PRs merged or closed within 30 days. | H12: 100 * decision rate; at least 10 eligible PRs required for an observed rate. | I12: Scores 0 in the fixed-denominator final score; not counted as observed coverage. A valid observed zero remains observed. Rate is unavailable below n >= 10; that does not exclude the infrastructure from scoring. | J12: Measures whether proposed changes reach a decision, not only an initial response.
A13: m12_stars | B13: Stars gained | C13: Adoption | D13: gh_metrics.csv::m12_stars_gained | E13: 0.076923077 | F13: 7.69% | G13: New GitHub stars recorded inside the window. | H13: 100 * min(1, log10(1+stars)/3); 999+ = 100. | I13: Scores 0 in the fixed-denominator final score; not counted as observed coverage. A valid observed zero remains observed. | J13: A window-specific attention/adoption signal, not a direct quality measure; GitHub-only coverage.
A14: m13_forks | B14: Forks created | C14: Adoption | D14: gh_metrics.csv::m13_forks_created | E14: 0.076923077 | F14: 7.69% | G14: GitHub forks created inside the window. | H14: 100 * min(1, log10(1+forks)/2); 99+ = 100. | I14: Scores 0 in the fixed-denominator final score; not counted as observed coverage. A valid observed zero remains observed. | J14: A possible code-reuse signal distinct from stars, but correlated with them and GitHub-specific.
A15: TOTAL | E15: 1 | F15: 100.00% | H15: All 13 normalized metric scores averaged with a fixed denominator of 13. | I15: No overall coverage or eligibility threshold. | J15: Equal metric weighting, not equal dimension weighting.

Sheet Methodology
A1: Methodology and interpretation | B1: Details
A2: Purpose | B2: Summarize recorded software-development activity and repository-level interaction/adoption signals for the OISI Development Activity component.
A3: Metric set | B3: The 13 established indicators m1-m13 are retained; no new metric is introduced in this workbook.
A4: Equal weighting | B4: Each metric contributes exactly 1/13 = 7.6923% (display 7.69%). This is an explicit transparent choice, not an empirical estimate of causal importance.
A5: Dimension labels | B5: Dimensions are descriptive only. Equal metric weights imply Continuity=4/13 (30.77%), Contributors=3/13 (23.08%), Responsiveness=4/13 (30.77%), Adoption=2/13 (15.38%). They are not separately reweighted.
A6: Final formula | B6: Development Activity Score = (m1 + m2 + ... + m13) / 13, where every metric is normalized to 0-100 before averaging.
A7: Missing data | B7: Unknown, unavailable, unsupported-platform, failed extraction, or insufficient sample-size values score 0 in the final score. The denominator remains 13 for every entry.
A8: No coverage gate | B8: No minimum observed-metric count, weight-coverage threshold, or dimension eligibility threshold is applied. Every one of the 112 register entries receives a numeric zero-filled result.
A9: Metric-level sample rule | B9: Responsiveness rates m8-m11 retain the pipeline's minimum of 10 eligible records to avoid highly unstable rates. Below that sample, the metric is unavailable and contributes 0; the infrastructure still receives a score.
A10: Observed coverage | B10: Available metric count / 13. A valid measured zero counts as observed; unavailable values are not observed. Coverage is descriptive only and never gates the score.
A11: Observed-only mean | B11: Mean of available metric scores for that entry. It is reported as a diagnostic with a variable denominator and is not the final score or ranking.
A12: Assessability status | B12: Ten entries are marked scored=no in the current repository register (non-assessable, standards, or unresolved repository choice). They still receive numeric 0 under the requested fixed-denominator zero-fill rule, but remain visibly flagged and should not be interpreted as measured low activity or compared as ordinary software repositories.
... A20: Interpretation | B20: The score summarizes these operational indicators only. It is not a direct measure of software quality, impact, security, user satisfaction, or long-term sustainability.

Sheet Parameters
A1: Parameter | B1: Value | C1: Explanation
A2: Number of metrics | B2: 13 | C2: m1 through m13
A3: Exact metric weight | B3: 0.076923077 | C3: Each metric contributes exactly 1/13; exact weights sum to 100%.
A4: Displayed metric weight | B4: 7.69% | C4: Rounded presentation of 7.6923%.
A5: Final score denominator | B5: 13 | C5: Fixed for every entry, including entries with missing fields.
A6: Overall coverage eligibility threshold | B6: None | C6: No entry is excluded for low observed coverage.
A7: Unavailable-data treatment | B7: 0 | C7: Unavailable or insufficient-sample metrics score zero in the final composite.
A8: Observed coverage denominator | B8: 13 | C8: Available metric count / 13; diagnostic only.
A9: Responsiveness minimum sample | B9: 10 | C9: Minimum eligible n for m8-m11 rates. Under-threshold indicators score zero; entry remains scored.
A10: Observation window start | B10: 2025-10-01T00:00:00+00:00 | C10: UTC inclusive.
A11: Observation window end | B11: 2026-10-01T00:00:00+00:00 | C11: UTC exclusive.
A12: Tie ranking | B12: Average rank | C12: Tied entries receive the average of their occupied ranks.

Sheet Diagnostics
A1: Code | B1: Metric | C1: Dimension | D1: Source field | E1: Observed n | F1: Observed coverage | G1: Mean among observed | H1: Mean under zero-fill | I1: SD among observed | J1: % zero among observed | K1: Availability note
A2: m1_commits | B2: Human commits | C2: Continuity | D2: git_metrics.csv::human_commits | E2: 101 | F2: 0.90178571 | G2: 70.322178 | H2: 63.415536 | I2: 27.830187 | J2: 0.03960396 | K2: 101 of 112 entries have a usable value.
A3: m2_active_weeks | B3: Active weeks | C3: Continuity | D3: git_metrics.csv::active_weeks | E3: 101 | F3: 0.90178571 | G3: 62.357228 | H3: 56.232857 | I3: 35.528326 | J3: 0.03960396 | K3: 101 of 112 entries have a usable value.
A4: m3_recency | B4: Commit recency | C4: Continuity | D4: git_metrics.csv::days_since_last | E4: 101 | F4: 0.90178571 | G4: 91.253366 | H4: 82.290982 | I4: 24.134627 | J4: 0.03960396 | K4: 101 of 112 entries have a usable value.
A5: m4_releases | B5: Release activity | C5: Continuity | D5: git_metrics.csv::tags_in_window | E5: 101 | F5: 0.90178571 | G5: 69.80198 | H5: 62.946429 | I5: 41.224577 | J5: 0.23762376 | K5: 101 of 112 entries have a usable value.
A6: m5_contributors | B6: Active contributors | C6: Contributors | D6: git_metrics.csv::contributors | E6: 101 | F6: 0.90178571 | G6: 52.435941 | H6: 47.285982 | I6: 30.107148 | J6: 0.13861386 | K6: 101 of 112 entries have a usable value.
A7: m6_effective_contributors | B7: Effective contributors | C7: Contributors | D7: git_metrics.csv::eff_contributors | E7: 101 | F7: 0.90178571 | G7: 47.334455 | H7: 42.685536 | I7: 32.115195 | J7: 0.13861386 | K7: 101 of 112 entries have a usable value.
A8: m7_retention | B8: Contributor retention | C8: Contributors | D8: git_metrics.csv::retained | E8: 101 | F8: 0.90178571 | G8: 61.881188 | H8: 55.803571 | I8: 37.16335 | J8: 0.14851485 | K8: 101 of 112 entries have a usable value.
A9: m8_issue_response | B9: Issue response within 14 days | C9: Responsiveness | D9: gh_metrics.csv::m8_issue_response_rate; manual_metrics.csv override | E9: 54 | F9: 0.48214286 | G9: 44.645185 | H9: 21.525357 | I9: 23.128007 | J9: 0.037037037 | K9: 54 of 112 entries have a usable value. Requires at least 10 eligible items.
A10: m9_pr_response | B10: PR response within 7 days | C10: Responsiveness | D10: gh_metrics.csv::m9_pr_response_rate | E10: 65 | F10: 0.58035714 | G10: 57.976923 | H10: 33.647321 | I10: 27.141484 | J10: 0 | K10: 65 of 112 entries have a usable value. Requires at least 10 eligible items.
A11: m10_issue_close90 | B11: Issue closure within 90 days | C11: Responsiveness | D11: gh_metrics.csv::m10_issue_close90_rate; manual_metrics.csv override | E11: 52 | F11: 0.46428571 | G11: 42.460769 | H11: 19.713929 | I11: 22.036705 | J11: 0.038461538 | K11: 52 of 112 entries have a usable value. Requires at least 10 eligible items.
A12: m11_pr_decision30 | B12: PR decision within 30 days | C12: Responsiveness | D12: gh_metrics.csv::m11_pr_decision30_rate | E12: 65 | F12: 0.58035714 | G12: 83.399385 | H12: 48.401429 | I12: 16.147695 | J12: 0 | K12: 65 of 112 entries have a usable value. Requires at least 10 eligible items.
A13: m12_stars | B13: Stars gained | C13: Adoption | D13: gh_metrics.csv::m12_stars_gained | E13: 90 | F13: 0.80357143 | G13: 35.148111 | H13: 28.244018 | I13: 24.79763 | J13: 0.14444444 | K13: 90 of 112 entries have a usable value. GitHub-derived; no-source entries are unavailable.
A14: m13_forks | B14: Forks created | C14: Adoption | D14: gh_metrics.csv::m13_forks_created | E14: 90 | F14: 0.80357143 | G14: 39.258 | H14: 31.546607 | I14: 29.897849 | J14: 0.15555556 | K14: 90 of 112 entries have a usable value. GitHub-derived; no-source entries are unavailable.
A16: Cohort statistic | B16: Value
A17: Entries | B17: 112
A18: Mean zero-filled Development Activity score | B18: 45.672273
A19: Median zero-filled Development Activity score | B19: 51.658462
A20: Mean observed metric coverage | B20: 0.77129121
A21: Entries with all 13 metrics observed | B21: 45
A22: Entries with zero observed metrics | B22: 11
A23: Register marked assessable | B23: 102
A24: Register marked not assessable/excluded | B24: 10

Sheet Sensitivity
A1: Scenario | B1: Metrics averaged | C1: Entries | D1: Spearman rho vs baseline | E1: Mean absolute score change | F1: Maximum absolute score change | G1: Mean absolute rank shift | H1: Maximum absolute rank shift | I1: Top-10 overlap | J1: Interpretation
A2: Baseline: 13 equal metrics, zero-filled | B2: 13 | C2: 112 | D2: 1 | E2: 0 | F2: 0 | G2: 0 | H2: 0 | I2: 10 | J2: Primary fixed-denominator result.
A3: Sensitivity: observed-only mean | B3: 0 | C3: 112 | D3: 0.92000753 | E3: 5.848561 | F3: 38.997363 | G3: 7.9107143 | H3: 56 | I3: 7 | J3: Variable-denominator diagnostic; not the primary score.
A4: Sensitivity: omit m1_commits | B4: 12 | C4: 112 | D4: 0.99875092 | E4: 1.5489211 | F4: 5.079359 | G4: 1.0535714 | H4: 6 | I4: 9 | J4: Leave-one-metric-out robustness check; not the primary score.
A5: Sensitivity: omit m2_active_weeks | B5: 12 | C5: 112 | D5: 0.99721951 | E5: 1.4290516 | F5: 5.1712179 | G5: 1.4107143 | H5: 10 | I5: 10 | J5: Leave-one-metric-out robustness check; not the primary score.
A6: Sensitivity: omit m3_recency | B6: 12 | C6: 112 | D6: 0.99976901 | E6: 3.064826 | F6: 7.0201923 | G6: 0.26785714 | H6: 3 | I6: 10 | J6: Leave-one-metric-out robustness check; not the primary score.
A7: Sensitivity: omit m4_releases | B7: 12 | C7: 112 | D7: 0.99195429 | E7: 2.5531164 | F7: 7.6923077 | G7: 2.6517857 | H7: 14 | I7: 10 | J7: Leave-one-metric-out robustness check; not the primary score.
A8: Sensitivity: omit m5_contributors | B8: 12 | C8: 112 | D8: 0.99865681 | E8: 0.83973901 | F8: 2.8202564 | G8: 1.0714286 | H8: 6 | I8: 9 | J8: Leave-one-metric-out robustness check; not the primary score.
A9: Sensitivity: omit m6_effective_contributors | B9: 12 | C9: 112 | D9: 0.99756173 | E9: 1.152132 | F9: 4.2203205 | G9: 1.4285714 | H9: 9 | I9: 9 | J9: Leave-one-metric-out robustness check; not the primary score.
A10: Sensitivity: omit m7_retention | B10: 12 | C10: 112 | D10: 0.99822049 | E10: 1.4371537 | F10: 5.1785897 | G10: 1.125 | H10: 9 | I10: 9 | J10: Leave-one-metric-out robustness check; not the primary score.
A11: Sensitivity: omit m8_issue_response | B11: 12 | C11: 112 | D11: 0.99593621 | E11: 2.3000715 | F11: 6.6321795 | G11: 2 | H11: 10 | I11: 10 | J11: Leave-one-metric-out robustness check; not the primary score.
A12: Sensitivity: omit m9_pr_response | B12: 12 | C12: 112 | D12: 0.99681741 | E12: 1.602931 | F12: 4.7514744 | G12: 1.5714286 | H12: 9 | I12: 9 | J12: Leave-one-metric-out robustness check; not the primary score.
A13: Sensitivity: omit m10_issue_close90 | B13: 12 | C13: 112 | D13: 0.99662064 | E13: 2.4251196 | F13: 6.6321795 | G13: 1.7321429 | H13: 9 | I13: 9 | J13: Leave-one-metric-out robustness check; not the primary score.
... A16: Sensitivity: omit m13_forks | B16: 12 | C16: 112 | D16: 0.99684308 | E16: 1.5833957 | F16: 5.8958974 | G16: 1.6607143 | H16: 10 | I16: 9 | J16: Leave-one-metric-out robustness check; not the primary score.

Sheet Sensitivity Ranks
A1: OISI ID | B1: Infrastructure | C1: Baseline score | D1: Baseline rank | E1: Observed-only score | F1: Observed-only rank | G1: Rank without m1_commits | H1: Rank without m2_active_weeks | I1: Rank without m3_recency | J1: Rank without m4_releases | K1: Rank without m5_contributors | L1: Rank without m6_effective_contributors | M1: Rank without m7_retention | N1: Rank without m8_issue_response | O1: Rank without m9_pr_response | P1: Rank without m10_issue_close90 | Q1: Rank without m11_pr_decision30 | R1: Rank without m12_stars | S1: Rank without m13_forks
A2: C4-001 | B2: 2i2c | C2: 70.273846 | D2: 25 | E2: 70.273846 | F2: 35 | G2: 28 | H2: 28 | I2: 25 | J2: 14 | K2: 30 | L2: 27 | M2: 27 | N2: 27 | O2: 19 | P2: 29 | Q2: 28 | R2: 25 | S2: 26
A3: C4-002 | B3: Academic Preservation Trust (APTrust) | C3: 39.270769 | D3: 71 | E3: 39.270769 | F3: 79 | G3: 71 | H3: 71 | I3: 71 | J3: 64 | K3: 72 | L3: 73 | M3: 72 | N3: 69 | O3: 76 | P3: 69 | Q3: 72 | R3: 68 | S3: 66
A4: C4-003 | B4: AfricArXiv | C4: 0 | D4: 106 | E4: 0 | F4: 106 | G4: 106 | H4: 106 | I4: 106 | J4: 105.5 | K4: 106 | L4: 106 | M4: 106 | N4: 106 | O4: 106 | P4: 106 | Q4: 106 | R4: 105.5 | S4: 106
A5: C4-004 | B5: Arches Heritage Data Management Platform | C5: 79.62 | D5: 9 | E5: 79.62 | F5: 14 | G5: 10 | H5: 9 | I5: 9 | J5: 9 | K5: 10 | L5: 10 | M5: 10 | N5: 8 | O5: 11 | P5: 11 | Q5: 10 | R5: 9 | S5: 8
A6: C4-005 | B6: Archipelago Commons | C6: 40.056154 | D6: 69 | E6: 47.339091 | F6: 70 | G6: 70 | H6: 67 | I6: 69 | J6: 72 | K6: 69 | L6: 63 | M6: 67 | N6: 67 | O6: 69 | P6: 67 | Q6: 73 | R6: 71 | S6: 73
A7: C4-006 | B7: Archival Resource Key | C7: 23.485385 | D7: 83 | E7: 43.615714 | F7: 77 | G7: 83 | H7: 82 | I7: 84 | J7: 84 | K7: 85 | L7: 84 | M7: 81 | N7: 81 | O7: 83 | P7: 83 | Q7: 83 | R7: 81 | S7: 81
A8: C4-007 | B8: Archivematica | C8: 61.393846 | D8: 40 | E8: 61.393846 | F8: 55 | G8: 37 | H8: 39 | I8: 40 | J8: 42 | K8: 37 | L8: 37 | M8: 36 | N8: 43 | O8: 42 | P8: 41 | Q8: 42 | R8: 43 | S8: 42
A9: C4-008 | B9: ArchivesSpace | C9: 81 | D9: 8 | E9: 81 | F9: 12 | G9: 8 | H9: 8 | I9: 8 | J9: 8 | K9: 8 | L9: 8 | M9: 8 | N9: 7 | O9: 10 | P9: 7 | Q9: 8 | R9: 7 | S9: 7
A10: C4-009 | B10: ARGOS | C10: 15.216923 | D10: 93 | E10: 21.98 | F10: 93 | G10: 92 | H10: 92 | I10: 91 | J10: 94 | K10: 93 | L10: 93 | M10: 92 | N10: 93 | O10: 93 | P10: 93 | Q10: 93 | R10: 93 | S10: 93
A11: C4-010 | B11: arXiv | C11: 57.309231 | D11: 49 | E11: 67.729091 | F11: 43 | G11: 50 | H11: 49 | I11: 49 | J11: 37 | K11: 53 | L11: 53 | M11: 49 | N11: 45 | O11: 52 | P11: 46 | Q11: 50 | R11: 51 | S11: 52
A12: C4-011 | B12: AtoM | C12: 69.098462 | D12: 27 | E12: 69.098462 | F12: 38 | G12: 26 | H12: 24 | I12: 27 | J12: 28 | K12: 28 | L12: 29 | M12: 30 | N12: 29 | O12: 25 | P12: 28 | Q12: 22 | R12: 27 | S12: 27
A13: C4-012 | B13: Avalon Media System | C13: 63.426923 | D13: 36 | E13: 63.426923 | F13: 52 | G13: 34 | H13: 33 | I13: 36 | J13: 36 | K13: 35 | L13: 36 | M13: 35 | N13: 39 | O13: 43 | P13: 40 | Q13: 38 | R13: 36 | S13: 32
... A113: C4-112 | B113: Zotero | C113: 84.213846 | D113: 4 | E113: 84.213846 | F113: 7 | G113: 4 | H113: 4 | I113: 4 | J113: 4 | K113: 3 | L113: 3 | M113: 4 | N113: 4 | O113: 5 | P113: 6 | Q113: 4 | R113: 6 | S113: 5

Sheet Correlations
A1: Metric A | B1: Metric B | C1: Pairwise observed n | D1: Spearman rho | E1: Interpretation
A2: m1_commits | B2: m2_active_weeks | C2: 101 | D2: 0.92891205 | E2: Strong association; interpret equal weights as indicator weights, not independent construct weights.
A3: m1_commits | B3: m3_recency | C3: 101 | D3: 0.5801017 | E3: Exploratory pairwise association; not evidence of causality.
A4: m1_commits | B4: m4_releases | C4: 101 | D4: 0.35523435 | E4: Exploratory pairwise association; not evidence of causality.
A5: m1_commits | B5: m5_contributors | C5: 101 | D5: 0.66869476 | E5: Exploratory pairwise association; not evidence of causality.
A6: m1_commits | B6: m6_effective_contributors | C6: 101 | D6: 0.58317124 | E6: Exploratory pairwise association; not evidence of causality.
A7: m1_commits | B7: m7_retention | C7: 101 | D7: 0.7661257 | E7: Strong association; interpret equal weights as indicator weights, not independent construct weights.
A8: m1_commits | B8: m8_issue_response | C8: 54 | D8: 0.1174181 | E8: Exploratory pairwise association; not evidence of causality.
A9: m1_commits | B9: m9_pr_response | C9: 65 | D9: 0.13738319 | E9: Exploratory pairwise association; not evidence of causality.
A10: m1_commits | B10: m10_issue_close90 | C10: 52 | D10: 0.25284728 | E10: Exploratory pairwise association; not evidence of causality.
A11: m1_commits | B11: m11_pr_decision30 | C11: 65 | D11: 0.2658889 | E11: Exploratory pairwise association; not evidence of causality.
A12: m1_commits | B12: m12_stars | C12: 90 | D12: 0.37874678 | E12: Exploratory pairwise association; not evidence of causality.
A13: m1_commits | B13: m13_forks | C13: 90 | D13: 0.38215758 | E13: Exploratory pairwise association; not evidence of causality.
... A79: m12_stars | B79: m13_forks | C79: 90 | D79: 0.85164952 | E79: Strong association; interpret equal weights as indicator weights, not independent construct weights.

Sheet Coverage
A1: OISI ID | B1: Infrastructure | C1: m1_commits observed | D1: m2_active_weeks observed | E1: m3_recency observed | F1: m4_releases observed | G1: m5_contributors observed | H1: m6_effective_contributors observed | I1: m7_retention observed | J1: m8_issue_response observed | K1: m9_pr_response observed | L1: m10_issue_close90 observed | M1: m11_pr_decision30 observed | N1: m12_stars observed | O1: m13_forks observed | P1: Available metrics (of 13) | Q1: Observed coverage | R1: Observed-only mean | S1: Zero-filled final score | T1: Coverage interpretation
A2: C4-001 | B2: 2i2c | C2: 1 | D2: 1 | E2: 1 | F2: 1 | G2: 1 | H2: 1 | I2: 1 | J2: 1 | K2: 1 | L2: 1 | M2: 1 | N2: 1 | O2: 1 | P2: =SUM(C2:O2) -> 13 | Q2: =P2/13 -> 1 | R2: =IFERROR(SUMPRODUCT(Calc!B2:N2,C2:O2)/P2,0) -> 70.273846 | S2: =Scoring!U2 -> 70.273846 | T2: Diagnostic only; never an eligibility rule.
A3: C4-002 | B3: Academic Preservation Trust (APTrust) | C3: 1 | D3: 1 | E3: 1 | F3: 1 | G3: 1 | H3: 1 | I3: 1 | J3: 1 | K3: 1 | L3: 1 | M3: 1 | N3: 1 | O3: 1 | P3: =SUM(C3:O3) -> 13 | Q3: =P3/13 -> 1 | R3: =IFERROR(SUMPRODUCT(Calc!B3:N3,C3:O3)/P3,0) -> 39.270769 | S3: =Scoring!U3 -> 39.270769 | T3: Diagnostic only; never an eligibility rule.
A4: C4-003 | B4: AfricArXiv | C4: 0 | D4: 0 | E4: 0 | F4: 0 | G4: 0 | H4: 0 | I4: 0 | J4: 0 | K4: 0 | L4: 0 | M4: 0 | N4: 0 | O4: 0 | P4: =SUM(C4:O4) -> 0 | Q4: =P4/13 -> 0 | R4: =IFERROR(SUMPRODUCT(Calc!B4:N4,C4:O4)/P4,0) -> 0 | S4: =Scoring!U4 -> 0 | T4: Diagnostic only; never an eligibility rule.
A5: C4-004 | B5: Arches Heritage Data Management Platform | C5: 1 | D5: 1 | E5: 1 | F5: 1 | G5: 1 | H5: 1 | I5: 1 | J5: 1 | K5: 1 | L5: 1 | M5: 1 | N5: 1 | O5: 1 | P5: =SUM(C5:O5) -> 13 | Q5: =P5/13 -> 1 | R5: =IFERROR(SUMPRODUCT(Calc!B5:N5,C5:O5)/P5,0) -> 79.62 | S5: =Scoring!U5 -> 79.62 | T5: Diagnostic only; never an eligibility rule.
A6: C4-005 | B6: Archipelago Commons | C6: 1 | D6: 1 | E6: 1 | F6: 1 | G6: 1 | H6: 1 | I6: 1 | J6: 0 | K6: 1 | L6: 0 | M6: 1 | N6: 1 | O6: 1 | P6: =SUM(C6:O6) -> 11 | Q6: =P6/13 -> 0.84615385 | R6: =IFERROR(SUMPRODUCT(Calc!B6:N6,C6:O6)/P6,0) -> 47.339091 | S6: =Scoring!U6 -> 40.056154 | T6: Diagnostic only; never an eligibility rule.
A7: C4-006 | B7: Archival Resource Key | C7: 1 | D7: 1 | E7: 1 | F7: 1 | G7: 1 | H7: 1 | I7: 1 | J7: 0 | K7: 0 | L7: 0 | M7: 0 | N7: 0 | O7: 0 | P7: =SUM(C7:O7) -> 7 | Q7: =P7/13 -> 0.53846154 | R7: =IFERROR(SUMPRODUCT(Calc!B7:N7,C7:O7)/P7,0) -> 43.615714 | S7: =Scoring!U7 -> 23.485385 | T7: Diagnostic only; never an eligibility rule.
A8: C4-007 | B8: Archivematica | C8: 1 | D8: 1 | E8: 1 | F8: 1 | G8: 1 | H8: 1 | I8: 1 | J8: 1 | K8: 1 | L8: 1 | M8: 1 | N8: 1 | O8: 1 | P8: =SUM(C8:O8) -> 13 | Q8: =P8/13 -> 1 | R8: =IFERROR(SUMPRODUCT(Calc!B8:N8,C8:O8)/P8,0) -> 61.393846 | S8: =Scoring!U8 -> 61.393846 | T8: Diagnostic only; never an eligibility rule.
A9: C4-008 | B9: ArchivesSpace | C9: 1 | D9: 1 | E9: 1 | F9: 1 | G9: 1 | H9: 1 | I9: 1 | J9: 1 | K9: 1 | L9: 1 | M9: 1 | N9: 1 | O9: 1 | P9: =SUM(C9:O9) -> 13 | Q9: =P9/13 -> 1 | R9: =IFERROR(SUMPRODUCT(Calc!B9:N9,C9:O9)/P9,0) -> 81 | S9: =Scoring!U9 -> 81 | T9: Diagnostic only; never an eligibility rule.
A10: C4-009 | B10: ARGOS | C10: 1 | D10: 1 | E10: 1 | F10: 1 | G10: 1 | H10: 1 | I10: 1 | J10: 0 | K10: 0 | L10: 0 | M10: 0 | N10: 1 | O10: 1 | P10: =SUM(C10:O10) -> 9 | Q10: =P10/13 -> 0.69230769 | R10: =IFERROR(SUMPRODUCT(Calc!B10:N10,C10:O10)/P10,0) -> 21.98 | S10: =Scoring!U10 -> 15.216923 | T10: Diagnostic only; never an eligibility rule.
A11: C4-010 | B11: arXiv | C11: 1 | D11: 1 | E11: 1 | F11: 1 | G11: 1 | H11: 1 | I11: 1 | J11: 0 | K11: 1 | L11: 0 | M11: 1 | N11: 1 | O11: 1 | P11: =SUM(C11:O11) -> 11 | Q11: =P11/13 -> 0.84615385 | R11: =IFERROR(SUMPRODUCT(Calc!B11:N11,C11:O11)/P11,0) -> 67.729091 | S11: =Scoring!U11 -> 57.309231 | T11: Diagnostic only; never an eligibility rule.
A12: C4-011 | B12: AtoM | C12: 1 | D12: 1 | E12: 1 | F12: 1 | G12: 1 | H12: 1 | I12: 1 | J12: 1 | K12: 1 | L12: 1 | M12: 1 | N12: 1 | O12: 1 | P12: =SUM(C12:O12) -> 13 | Q12: =P12/13 -> 1 | R12: =IFERROR(SUMPRODUCT(Calc!B12:N12,C12:O12)/P12,0) -> 69.098462 | S12: =Scoring!U12 -> 69.098462 | T12: Diagnostic only; never an eligibility rule.
