Workbook

Sheet Summary
A1: Community Analysis equal-metric scoring summary
A2: Services in source snapshot | B2: 112
A3: Metric set | B3: E1, E2, C1, C2, C3, N1; six equally weighted metrics
A4: Weight per metric | B4: 1/6 = 16.6667% (displayed 16.67%)
A5: Scored services | B5: =COUNT(Scoring!K2:K113)
A6: Mean score | B6: =IFERROR(AVERAGE(Scoring!K2:K113),"")
A7: Scoring rule | B7: Equal arithmetic mean of all six metrics; every unavailable metric is scored as 0. No coverage eligibility gate.
A8: Interpretation | B8: Zero-filled scores are conservative evidence-adjusted results; zero due to unavailable data does not establish zero underlying performance.

Sheet Scoring
A1: Service | B1: Provider | C1: Solution category | D1: E1 | E1: E2 | F1: C1 | G1: C2 | H1: C3 | I1: N1 | J1: Metrics with source data (of 6) | K1: Community Analysis score (0-100; missing=0) | L1: Missing metrics scored as 0 | M1: Review status | N1: Data-quality flags
A2: 2i2c | B2: Code for Science and Society | C2: Authoring tool | D2: =IF(ISNUMBER(Verification!B2),Verification!B2,IF(Calc!B2="",0,Calc!B2)) | E2: =IF(ISNUMBER(Verification!C2),Verification!C2,IF(Calc!C2="",0,Calc!C2)) | F2: =IF(ISNUMBER(Verification!D2),Verification!D2,IF(Calc!D2="",0,Calc!D2)) | G2: =IF(ISNUMBER(Verification!E2),Verification!E2,IF(Calc!E2="",0,Calc!E2)) | H2: =IF(ISNUMBER(Verification!F2),Verification!F2,IF(Calc!F2="",0,Calc!F2)) | I2: =IF(ISNUMBER(Verification!G2),Verification!G2,IF(Calc!G2="",0,Calc!G2)) | J2: =COUNT(Calc!B2:G2) | K2: =AVERAGE(D2:I2) | L2: =6-J2 | M2: =IF(COUNTIF(Verification!H2:L2,"Review*")>0,"Scored - coding review","Scored") | N2: 938 coding requires reviewer confirmation; 019 scored from populated repository field; 043 evidence URL should be checked; not scored separately; 116 retained as source evidence only; not scored; 2 unavailable metric(s) scored as 0
A3: Academic Preservation Trust (APTrust) | B3: Academic Preservation Trust (APTrust) | C3: Digital preservation service | D3: =IF(ISNUMBER(Verification!B3),Verification!B3,IF(Calc!B3="",0,Calc!B3)) | E3: =IF(ISNUMBER(Verification!C3),Verification!C3,IF(Calc!C3="",0,Calc!C3)) | F3: =IF(ISNUMBER(Verification!D3),Verification!D3,IF(Calc!D3="",0,Calc!D3)) | G3: =IF(ISNUMBER(Verification!E3),Verification!E3,IF(Calc!E3="",0,Calc!E3)) | H3: =IF(ISNUMBER(Verification!F3),Verification!F3,IF(Calc!F3="",0,Calc!F3)) | I3: =IF(ISNUMBER(Verification!G3),Verification!G3,IF(Calc!G3="",0,Calc!G3)) | J3: =COUNT(Calc!B3:G3) | K3: =AVERAGE(D3:I3) | L3: =6-J3 | M3: =IF(COUNTIF(Verification!H3:L3,"Review*")>0,"Scored - coding review","Scored") | N3: 041 scored from available URL tier; 019 scored from populated repository field; 043 evidence URL should be checked; not scored separately; 116 retained as source evidence only; not scored
A4: AfricArXiv | B4: UbuntuNet Alliance | C4: Repository service | D4: =IF(ISNUMBER(Verification!B4),Verification!B4,IF(Calc!B4="",0,Calc!B4)) | E4: =IF(ISNUMBER(Verification!C4),Verification!C4,IF(Calc!C4="",0,Calc!C4)) | F4: =IF(ISNUMBER(Verification!D4),Verification!D4,IF(Calc!D4="",0,Calc!D4)) | G4: =IF(ISNUMBER(Verification!E4),Verification!E4,IF(Calc!E4="",0,Calc!E4)) | H4: =IF(ISNUMBER(Verification!F4),Verification!F4,IF(Calc!F4="",0,Calc!F4)) | I4: =IF(ISNUMBER(Verification!G4),Verification!G4,IF(Calc!G4="",0,Calc!G4)) | J4: =COUNT(Calc!B4:G4) | K4: =AVERAGE(D4:I4) | L4: =6-J4 | M4: =IF(COUNTIF(Verification!H4:L4,"Review*")>0,"Scored - coding review","Scored") | N4: 043 evidence URL should be checked; not scored separately; 4 unavailable metric(s) scored as 0
A5: Arches Heritage Data Management Platform | B5: Getty Conservation Institute (GCI) | C5: Data management planning tool or service | D5: =IF(ISNUMBER(Verification!B5),Verification!B5,IF(Calc!B5="",0,Calc!B5)) | E5: =IF(ISNUMBER(Verification!C5),Verification!C5,IF(Calc!C5="",0,Calc!C5)) | F5: =IF(ISNUMBER(Verification!D5),Verification!D5,IF(Calc!D5="",0,Calc!D5)) | G5: =IF(ISNUMBER(Verification!E5),Verification!E5,IF(Calc!E5="",0,Calc!E5)) | H5: =IF(ISNUMBER(Verification!F5),Verification!F5,IF(Calc!F5="",0,Calc!F5)) | I5: =IF(ISNUMBER(Verification!G5),Verification!G5,IF(Calc!G5="",0,Calc!G5)) | J5: =COUNT(Calc!B5:G5) | K5: =AVERAGE(D5:I5) | L5: =6-J5 | M5: =IF(COUNTIF(Verification!H5:L5,"Review*")>0,"Scored - coding review","Scored") | N5: 041 scored from available URL tier; 019 scored from populated repository field; 043 evidence URL should be checked; not scored separately; 116 retained as source evidence only; not scored; 2 unavailable metric(s) scored as 0
A6: Archipelago Commons | B6: Metropolitan New York Library Council | C6: Digital library, collection or exhibit platform | Repository software | D6: =IF(ISNUMBER(Verification!B6),Verification!B6,IF(Calc!B6="",0,Calc!B6)) | E6: =IF(ISNUMBER(Verification!C6),Verification!C6,IF(Calc!C6="",0,Calc!C6)) | F6: =IF(ISNUMBER(Verification!D6),Verification!D6,IF(Calc!D6="",0,Calc!D6)) | G6: =IF(ISNUMBER(Verification!E6),Verification!E6,IF(Calc!E6="",0,Calc!E6)) | H6: =IF(ISNUMBER(Verification!F6),Verification!F6,IF(Calc!F6="",0,Calc!F6)) | I6: =IF(ISNUMBER(Verification!G6),Verification!G6,IF(Calc!G6="",0,Calc!G6)) | J6: =COUNT(Calc!B6:G6) | K6: =AVERAGE(D6:I6) | L6: =6-J6 | M6: =IF(COUNTIF(Verification!H6:L6,"Review*")>0,"Scored - coding review","Scored") | N6: 938 coding requires reviewer confirmation; 041 scored from available URL tier; 019 scored from populated repository field; 043 evidence URL should be checked; not scored separately; 116 retained as source evidence only; not scored
A7: Archival Resource Key | B7: ARK Alliance | C7: Standard, specification or protocol | D7: =IF(ISNUMBER(Verification!B7),Verification!B7,IF(Calc!B7="",0,Calc!B7)) | E7: =IF(ISNUMBER(Verification!C7),Verification!C7,IF(Calc!C7="",0,Calc!C7)) | F7: =IF(ISNUMBER(Verification!D7),Verification!D7,IF(Calc!D7="",0,Calc!D7)) | G7: =IF(ISNUMBER(Verification!E7),Verification!E7,IF(Calc!E7="",0,Calc!E7)) | H7: =IF(ISNUMBER(Verification!F7),Verification!F7,IF(Calc!F7="",0,Calc!F7)) | I7: =IF(ISNUMBER(Verification!G7),Verification!G7,IF(Calc!G7="",0,Calc!G7)) | J7: =COUNT(Calc!B7:G7) | K7: =AVERAGE(D7:I7) | L7: =6-J7 | M7: =IF(COUNTIF(Verification!H7:L7,"Review*")>0,"Scored - coding review","Scored") | N7: 041 scored from available URL tier; 019 scored from populated repository field; 043 evidence URL should be checked; not scored separately; 116 retained as source evidence only; not scored; 1 unavailable metric(s) scored as 0
A8: Archivematica | B8: Artefactual | C8: Digital preservation system | D8: =IF(ISNUMBER(Verification!B8),Verification!B8,IF(Calc!B8="",0,Calc!B8)) | E8: =IF(ISNUMBER(Verification!C8),Verification!C8,IF(Calc!C8="",0,Calc!C8)) | F8: =IF(ISNUMBER(Verification!D8),Verification!D8,IF(Calc!D8="",0,Calc!D8)) | G8: =IF(ISNUMBER(Verification!E8),Verification!E8,IF(Calc!E8="",0,Calc!E8)) | H8: =IF(ISNUMBER(Verification!F8),Verification!F8,IF(Calc!F8="",0,Calc!F8)) | I8: =IF(ISNUMBER(Verification!G8),Verification!G8,IF(Calc!G8="",0,Calc!G8)) | J8: =COUNT(Calc!B8:G8) | K8: =AVERAGE(D8:I8) | L8: =6-J8 | M8: =IF(COUNTIF(Verification!H8:L8,"Review*")>0,"Scored - coding review","Scored") | N8: 041 scored from available URL tier; 019 scored from populated repository field; 043 evidence URL should be checked; not scored separately; 116 retained as source evidence only; not scored; 3 unavailable metric(s) scored as 0
A9: ArchivesSpace | B9: ArchivesSpace | C9: Archive information management system | Discovery system | D9: =IF(ISNUMBER(Verification!B9),Verification!B9,IF(Calc!B9="",0,Calc!B9)) | E9: =IF(ISNUMBER(Verification!C9),Verification!C9,IF(Calc!C9="",0,Calc!C9)) | F9: =IF(ISNUMBER(Verification!D9),Verification!D9,IF(Calc!D9="",0,Calc!D9)) | G9: =IF(ISNUMBER(Verification!E9),Verification!E9,IF(Calc!E9="",0,Calc!E9)) | H9: =IF(ISNUMBER(Verification!F9),Verification!F9,IF(Calc!F9="",0,Calc!F9)) | I9: =IF(ISNUMBER(Verification!G9),Verification!G9,IF(Calc!G9="",0,Calc!G9)) | J9: =COUNT(Calc!B9:G9) | K9: =AVERAGE(D9:I9) | L9: =6-J9 | M9: =IF(COUNTIF(Verification!H9:L9,"Review*")>0,"Scored - coding review","Scored") | N9: 041 scored from available URL tier; 019 scored from populated repository field; 043 evidence URL should be checked; not scored separately; 116 retained as source evidence only; not scored; 1 unavailable metric(s) scored as 0
A10: ARGOS | B10: OpenAIRE | C10: Data management planning tool or service | D10: =IF(ISNUMBER(Verification!B10),Verification!B10,IF(Calc!B10="",0,Calc!B10)) | E10: =IF(ISNUMBER(Verification!C10),Verification!C10,IF(Calc!C10="",0,Calc!C10)) | F10: =IF(ISNUMBER(Verification!D10),Verification!D10,IF(Calc!D10="",0,Calc!D10)) | G10: =IF(ISNUMBER(Verification!E10),Verification!E10,IF(Calc!E10="",0,Calc!E10)) | H10: =IF(ISNUMBER(Verification!F10),Verification!F10,IF(Calc!F10="",0,Calc!F10)) | I10: =IF(ISNUMBER(Verification!G10),Verification!G10,IF(Calc!G10="",0,Calc!G10)) | J10: =COUNT(Calc!B10:G10) | K10: =AVERAGE(D10:I10) | L10: =6-J10 | M10: =IF(COUNTIF(Verification!H10:L10,"Review*")>0,"Scored - coding review","Scored") | N10: 019 scored from populated repository field; 043 evidence URL should be checked; not scored separately; 116 retained as source evidence only; not scored; 2 unavailable metric(s) scored as 0
A11: arXiv | B11: Cornell University | C11: Repository service | D11: =IF(ISNUMBER(Verification!B11),Verification!B11,IF(Calc!B11="",0,Calc!B11)) | E11: =IF(ISNUMBER(Verification!C11),Verification!C11,IF(Calc!C11="",0,Calc!C11)) | F11: =IF(ISNUMBER(Verification!D11),Verification!D11,IF(Calc!D11="",0,Calc!D11)) | G11: =IF(ISNUMBER(Verification!E11),Verification!E11,IF(Calc!E11="",0,Calc!E11)) | H11: =IF(ISNUMBER(Verification!F11),Verification!F11,IF(Calc!F11="",0,Calc!F11)) | I11: =IF(ISNUMBER(Verification!G11),Verification!G11,IF(Calc!G11="",0,Calc!G11)) | J11: =COUNT(Calc!B11:G11) | K11: =AVERAGE(D11:I11) | L11: =6-J11 | M11: =IF(COUNTIF(Verification!H11:L11,"Review*")>0,"Scored - coding review","Scored") | N11: 938 coding requires reviewer confirmation; 041 scored from available URL tier; 019 scored from populated repository field; 043 evidence URL should be checked; not scored separately
A12: AtoM | B12: Artefactual | C12: Archive information management system | D12: =IF(ISNUMBER(Verification!B12),Verification!B12,IF(Calc!B12="",0,Calc!B12)) | E12: =IF(ISNUMBER(Verification!C12),Verification!C12,IF(Calc!C12="",0,Calc!C12)) | F12: =IF(ISNUMBER(Verification!D12),Verification!D12,IF(Calc!D12="",0,Calc!D12)) | G12: =IF(ISNUMBER(Verification!E12),Verification!E12,IF(Calc!E12="",0,Calc!E12)) | H12: =IF(ISNUMBER(Verification!F12),Verification!F12,IF(Calc!F12="",0,Calc!F12)) | I12: =IF(ISNUMBER(Verification!G12),Verification!G12,IF(Calc!G12="",0,Calc!G12)) | J12: =COUNT(Calc!B12:G12) | K12: =AVERAGE(D12:I12) | L12: =6-J12 | M12: =IF(COUNTIF(Verification!H12:L12,"Review*")>0,"Scored - coding review","Scored") | N12: 041 scored from available URL tier; 019 scored from populated repository field; 043 evidence URL should be checked; not scored separately; 4 unavailable metric(s) scored as 0
A13: Avalon Media System | B13: Indiana University Libraries | C13: Digital library, collection or exhibit platform | Repository software | D13: =IF(ISNUMBER(Verification!B13),Verification!B13,IF(Calc!B13="",0,Calc!B13)) | E13: =IF(ISNUMBER(Verification!C13),Verification!C13,IF(Calc!C13="",0,Calc!C13)) | F13: =IF(ISNUMBER(Verification!D13),Verification!D13,IF(Calc!D13="",0,Calc!D13)) | G13: =IF(ISNUMBER(Verification!E13),Verification!E13,IF(Calc!E13="",0,Calc!E13)) | H13: =IF(ISNUMBER(Verification!F13),Verification!F13,IF(Calc!F13="",0,Calc!F13)) | I13: =IF(ISNUMBER(Verification!G13),Verification!G13,IF(Calc!G13="",0,Calc!G13)) | J13: =COUNT(Calc!B13:G13) | K13: =AVERAGE(D13:I13) | L13: =6-J13 | M13: =IF(COUNTIF(Verification!H13:L13,"Review*")>0,"Scored - coding review","Scored") | N13: 041 scored from available URL tier; 019 scored from populated repository field; 043 evidence URL should be checked; not scored separately; 116 retained as source evidence only; not scored
... A113: Zotero | B113: Digital Scholar | C113: Annotations system | D113: =IF(ISNUMBER(Verification!B113),Verification!B113,IF(Calc!B113="",0,Calc!B113)) | E113: =IF(ISNUMBER(Verification!C113),Verification!C113,IF(Calc!C113="",0,Calc!C113)) | F113: =IF(ISNUMBER(Verification!D113),Verification!D113,IF(Calc!D113="",0,Calc!D113)) | G113: =IF(ISNUMBER(Verification!E113),Verification!E113,IF(Calc!E113="",0,Calc!E113)) | H113: =IF(ISNUMBER(Verification!F113),Verification!F113,IF(Calc!F113="",0,Calc!F113)) | I113: =IF(ISNUMBER(Verification!G113),Verification!G113,IF(Calc!G113="",0,Calc!G113)) | J113: =COUNT(Calc!B113:G113) | K113: =AVERAGE(D113:I113) | L113: =6-J113 | M113: =IF(COUNTIF(Verification!H113:L113,"Review*")>0,"Scored - coding review","Scored") | N113: 041 scored from available URL tier; 019 scored from populated repository field; 043 evidence URL should be checked; not scored separately; 116 retained as source evidence only; not scored

Sheet Metric Rules
A1: OISI Community Analysis / Community Engagement: Equal-Weight Scoring Rules
A2: Scoring set | B2: Six metrics E1, E2, C1, C2, C3, N1. Each is equally weighted.
A3: Weights | B3: Each metric = 1/6 = 16.6667%; displayed as 16.67%. Calculations use the exact 1/6 fraction.
A4: Final score | B4: Arithmetic mean of all six metric scores on a 0-100 scale.
A5: Coverage rule | B5: No coverage eligibility gate. Every infrastructure receives a score.
A6: Missing values | B6: Unavailable, blank, Unknown, or ambiguous metric values are scored as 0. This zero-filled score is not proof of zero underlying performance.
A7: Performance bands | B7: None are used.
A8: 038 and 938 | B8: Twelve named 038 activity types plus a thirteenth Other category, only when Other is selected and 938 supports a distinct unlisted activity. Duplicate categories are counted once.
A9: 040 and 940 | B9: Eight named 040 contribution routes plus a ninth Other category, only when Other is selected and 940 supports a distinct unlisted route.
A10: 116 | B10: Evidence only; not a scored metric. It is not included in E2 counts.
A11: 042 and 043 | B11: 042 is one status metric. 043 is supporting evidence for reviewer verification and is not scored separately.
A12: Review status | B12: C2 and C3 are scored automatically when their source fields are populated. URL review notes are audit context, not a scoring prerequisite. Free-text coding and Other categories remain reviewable.
A14: Code | B14: Metric | C14: Source fields | D14: Equal weight | E14: Scoring rule | F14: Missing / verification treatment
A15: E1 | B15: Engagement status | C15: 037 | D15: 0.16666667 | E15: Implemented/available=100; In progress=67; Considering=33; Not planning=0. | F15: Unknown/blank=0.
A16: E2 | B16: Engagement activity breadth | C16: 038 + reviewed/coded 938 | D16: 0.16666667 | E16: 100 x distinct supported activity types / 13. Twelve named types plus valid Other; categories deduplicated. | F16: No supported type=0. Review 938 coding and Other where needed.
A17: C1 | B17: Contribution opportunity breadth | C17: 040 + reviewed 940 | D17: 0.16666667 | E17: 100 x distinct supported routes / 9. Eight named routes plus valid Other; categories deduplicated. | F17: No supported route=0. Review 940 Other where needed.
A18: C2 | B18: Contribution guidance | C18: 041 | D18: 0.16666667 | E18: Available dedicated contribution-guide URL=100; available relevant general participation URL=50. | F18: Blank or suspect URL=0.
A19: C3 | B19: Public contribution repository | C19: 019 | D19: 0.16666667 | E19: Available public-forge URL=100; populated URL on another/unspecified host=50. | F19: Blank field=0.
A20: N1 | B20: Code of Conduct status | C20: 042; 043 evidence only | D20: 0.16666667 | E20: Implemented/available=100; In progress=67; Considering=33; Not planning=0. | F20: Unknown/blank=0. Use 043 as evidence only; no separate URL bonus/penalty.

Sheet Parameters
A1: Code | B1: Metric | C1: Source fields | D1: Weight (exact) | E1: Weight (display) | F1: Dimension
A2: E1 | B2: Engagement status | C2: 037 | D2: 0.16666667 | E2: 16.67% | F2: Engagement & Participation
A3: E2 | B3: Engagement activity breadth | C3: 038 + reviewed/coded 938 | D3: 0.16666667 | E3: 16.67% | F3: Engagement & Participation
A4: C1 | B4: Contribution opportunity breadth | C4: 040 + reviewed 940 | D4: 0.16666667 | E4: 16.67% | F4: Contribution Mechanisms
A5: C2 | B5: Contribution guidance | C5: 041 | D5: 0.16666667 | E5: 16.67% | F5: Contribution Mechanisms
A6: C3 | B6: Public contribution repository | C6: 019 | D6: 0.16666667 | E6: 16.67% | F6: Contribution Mechanisms
A7: N1 | B7: Code of Conduct status | C7: 042; 043 evidence only | D7: 0.16666667 | E7: 16.67% | F7: Community Norms
A8: Total | D8: 1 | E8: 100.00%
A10: Breadth denominator | B10: Available indicators | C10: Count rule
A11: 038 | B11: 13 | C11: 12 named types + valid Other; no duplicate category count
A12: 040 | B12: 9 | C12: 8 named routes + valid Other; no duplicate route count
A13: Coverage eligibility gate | B13: None | C13: All infrastructures receive an equal-weight score; unavailable metrics contribute 0

Sheet Verification
A1: Service | B1: E1 override (0-100) | C1: E2 override (0-100) | D1: C1 override (0-100) | E1: C2 override (0-100) | F1: C3 override (0-100) | G1: N1 override (0-100) | H1: 938 reviewed? | I1: 940 reviewed? | J1: 041 verified? | K1: 019 verified public repo? | L1: 043 checked? | M1: Reviewer notes
A2: 2i2c | H2: Review coding | I2: N/A | J2: No score | K2: Scored from available field | L2: Evidence only
A3: Academic Preservation Trust (APTrust) | H3: N/A | I3: N/A | J3: Scored from available URL | K3: Scored from available field | L3: Evidence only
A4: AfricArXiv | H4: N/A | I4: N/A | J4: No score | K4: No score | L4: Evidence only
A5: Arches Heritage Data Management Platform | H5: N/A | I5: N/A | J5: Scored from available URL | K5: Scored from available field | L5: Evidence only
A6: Archipelago Commons | H6: Review coding | I6: N/A | J6: Scored from available URL | K6: Scored from available field | L6: Evidence only
A7: Archival Resource Key | H7: N/A | I7: N/A | J7: Scored from available URL | K7: Scored from available field | L7: Evidence only
A8: Archivematica | H8: N/A | I8: N/A | J8: Scored from available URL | K8: Scored from available field | L8: Evidence only
A9: ArchivesSpace | H9: N/A | I9: N/A | J9: Scored from available URL | K9: Scored from available field | L9: Evidence only
A10: ARGOS | H10: N/A | I10: N/A | J10: No score | K10: Scored from available field | L10: Evidence only
A11: arXiv | H11: Review coding | I11: N/A | J11: Scored from available URL | K11: Scored from available field | L11: Evidence only
A12: AtoM | H12: N/A | I12: N/A | J12: No score | K12: Scored from available field | L12: Evidence only
A13: Avalon Media System | H13: N/A | I13: N/A | J13: Scored from available URL | K13: Scored from available field | L13: Evidence only
... A113: Zotero | H113: N/A | I113: N/A | J113: Scored from available URL | K113: Scored from available field | L113: Evidence only

Sheet Activity Coding
A1: Service | B1: 038: Annual meetings | C1: 038: Blogs | D1: 038: Community calls | E1: 038: Conference participation | F1: 038: Development sprints | G1: 038: Interest, working, user, or advisory groups | H1: 038: Mailing lists and discussion forums (including Slack) | I1: 038: Social media | J1: 038: Staff roles with responsibility for community engagement | K1: 038: User research | L1: 038: Volunteer or ambassador network | M1: 038: Webinars and training | N1: 938 coded: Annual meetings | O1: 938 coded: Blogs | P1: 938 coded: Community calls | Q1: 938 coded: Conference participation | R1: 938 coded: Development sprints | S1: 938 coded: Interest, working, user, or advisory groups | T1: 938 coded: Mailing lists and discussion forums (including Slack) | U1: 938 coded: Social media | V1: 938 coded: Staff roles with responsibility for community engagement | W1: 938 coded: User research | X1: 938 coded: Volunteer or ambassador network | Y1: 938 coded: Webinars and training | Z1: 038 count | AA1: 938 coded count | AB1: Other supported | AC1: Union count / 13 | AD1: Coded union
A2: 2i2c | B2: 0 | C2: 0 | D2: 0 | E2: 0 | F2: 0 | G2: 0 | H2: 0 | I2: 0 | J2: 0 | K2: 0 | L2: 0 | M2: 0 | N2: 0 | O2: 0 | P2: 1 | Q2: 0 | R2: 0 | S2: 1 | T2: 0 | U2: 0 | V2: 0 | W2: 0 | X2: 0 | Y2: 0 | Z2: 0 | AA2: 2 | AB2: 0 | AC2: 2 | AD2: Community calls; Interest, working, user, or advisory groups
A3: Academic Preservation Trust (APTrust) | B3: 1 | C3: 1 | D3: 1 | E3: 1 | F3: 1 | G3: 1 | H3: 1 | I3: 0 | J3: 1 | K3: 1 | L3: 0 | M3: 1 | N3: 0 | O3: 0 | P3: 0 | Q3: 0 | R3: 0 | S3: 0 | T3: 0 | U3: 0 | V3: 0 | W3: 0 | X3: 0 | Y3: 0 | Z3: 10 | AA3: 0 | AB3: 0 | AC3: 10 | AD3: Annual meetings; Blogs; Community calls; Conference participation; Development sprints; Interest, working, user, or advisory groups; Mailing lists and discussion forums (including Slack); Staff roles with responsibility for community engagement; User research; Webinars and training
A4: AfricArXiv | B4: 0 | C4: 0 | D4: 0 | E4: 0 | F4: 0 | G4: 0 | H4: 0 | I4: 0 | J4: 0 | K4: 0 | L4: 0 | M4: 0 | N4: 0 | O4: 0 | P4: 0 | Q4: 0 | R4: 0 | S4: 0 | T4: 0 | U4: 0 | V4: 0 | W4: 0 | X4: 0 | Y4: 0 | Z4: 0 | AA4: 0 | AB4: 0 | AC4: 0
A5: Arches Heritage Data Management Platform | B5: 0 | C5: 0 | D5: 0 | E5: 0 | F5: 0 | G5: 0 | H5: 0 | I5: 0 | J5: 0 | K5: 0 | L5: 0 | M5: 0 | N5: 0 | O5: 0 | P5: 0 | Q5: 0 | R5: 0 | S5: 0 | T5: 0 | U5: 0 | V5: 0 | W5: 0 | X5: 0 | Y5: 0 | Z5: 0 | AA5: 0 | AB5: 0 | AC5: 0
A6: Archipelago Commons | B6: 0 | C6: 0 | D6: 1 | E6: 1 | F6: 0 | G6: 1 | H6: 1 | I6: 0 | J6: 1 | K6: 0 | L6: 1 | M6: 1 | N6: 0 | O6: 0 | P6: 0 | Q6: 0 | R6: 0 | S6: 1 | T6: 1 | U6: 0 | V6: 0 | W6: 0 | X6: 0 | Y6: 0 | Z6: 7 | AA6: 2 | AB6: 0 | AC6: 7 | AD6: Community calls; Conference participation; Interest, working, user, or advisory groups; Mailing lists and discussion forums (including Slack); Staff roles with responsibility for community engagement; Volunteer or ambassador network; Webinars and training
A7: Archival Resource Key | B7: 0 | C7: 0 | D7: 0 | E7: 0 | F7: 0 | G7: 0 | H7: 0 | I7: 0 | J7: 0 | K7: 0 | L7: 0 | M7: 0 | N7: 0 | O7: 0 | P7: 0 | Q7: 0 | R7: 0 | S7: 0 | T7: 0 | U7: 0 | V7: 0 | W7: 0 | X7: 0 | Y7: 0 | Z7: 0 | AA7: 0 | AB7: 0 | AC7: 0
A8: Archivematica | B8: 0 | C8: 0 | D8: 0 | E8: 0 | F8: 0 | G8: 0 | H8: 0 | I8: 0 | J8: 0 | K8: 0 | L8: 0 | M8: 0 | N8: 0 | O8: 0 | P8: 0 | Q8: 0 | R8: 0 | S8: 0 | T8: 0 | U8: 0 | V8: 0 | W8: 0 | X8: 0 | Y8: 0 | Z8: 0 | AA8: 0 | AB8: 0 | AC8: 0
A9: ArchivesSpace | B9: 1 | C9: 1 | D9: 1 | E9: 1 | F9: 0 | G9: 1 | H9: 1 | I9: 1 | J9: 1 | K9: 0 | L9: 0 | M9: 1 | N9: 0 | O9: 0 | P9: 0 | Q9: 0 | R9: 0 | S9: 0 | T9: 0 | U9: 0 | V9: 0 | W9: 0 | X9: 0 | Y9: 0 | Z9: 9 | AA9: 0 | AB9: 0 | AC9: 9 | AD9: Annual meetings; Blogs; Community calls; Conference participation; Interest, working, user, or advisory groups; Mailing lists and discussion forums (including Slack); Social media; Staff roles with responsibility for community engagement; Webinars and training
A10: ARGOS | B10: 0 | C10: 1 | D10: 1 | E10: 1 | F10: 1 | G10: 1 | H10: 0 | I10: 1 | J10: 1 | K10: 0 | L10: 0 | M10: 1 | N10: 0 | O10: 0 | P10: 0 | Q10: 0 | R10: 0 | S10: 0 | T10: 0 | U10: 0 | V10: 0 | W10: 0 | X10: 0 | Y10: 0 | Z10: 8 | AA10: 0 | AB10: 0 | AC10: 8 | AD10: Blogs; Community calls; Conference participation; Development sprints; Interest, working, user, or advisory groups; Social media; Staff roles with responsibility for community engagement; Webinars and training
A11: arXiv | B11: 0 | C11: 0 | D11: 0 | E11: 0 | F11: 0 | G11: 0 | H11: 0 | I11: 0 | J11: 0 | K11: 0 | L11: 0 | M11: 0 | N11: 0 | O11: 0 | P11: 0 | Q11: 0 | R11: 0 | S11: 1 | T11: 1 | U11: 0 | V11: 0 | W11: 1 | X11: 1 | Y11: 0 | Z11: 0 | AA11: 4 | AB11: 0 | AC11: 4 | AD11: Interest, working, user, or advisory groups; Mailing lists and discussion forums (including Slack); User research; Volunteer or ambassador network
A12: AtoM | B12: 0 | C12: 0 | D12: 0 | E12: 0 | F12: 0 | G12: 0 | H12: 0 | I12: 0 | J12: 0 | K12: 0 | L12: 0 | M12: 0 | N12: 0 | O12: 0 | P12: 0 | Q12: 0 | R12: 0 | S12: 0 | T12: 0 | U12: 0 | V12: 0 | W12: 0 | X12: 0 | Y12: 0 | Z12: 0 | AA12: 0 | AB12: 0 | AC12: 0
A13: Avalon Media System | B13: 1 | C13: 0 | D13: 1 | E13: 1 | F13: 0 | G13: 1 | H13: 1 | I13: 0 | J13: 0 | K13: 0 | L13: 0 | M13: 0 | N13: 0 | O13: 0 | P13: 0 | Q13: 0 | R13: 0 | S13: 0 | T13: 0 | U13: 0 | V13: 0 | W13: 0 | X13: 0 | Y13: 0 | Z13: 5 | AA13: 0 | AB13: 0 | AC13: 5 | AD13: Annual meetings; Community calls; Conference participation; Interest, working, user, or advisory groups; Mailing lists and discussion forums (including Slack)
A14: Biodiversity Heritage Library | B14: 1 | C14: 1 | D14: 0 | E14: 1 | F14: 0 | G14: 0 | H14: 1 | I14: 1 | J14: 0 | K14: 0 | L14: 1 | M14: 1 | N14: 0 | O14: 0 | P14: 0 | Q14: 0 | R14: 0 | S14: 0 | T14: 0 | U14: 0 | V14: 0 | W14: 0 | X14: 0 | Y14: 0 | Z14: 7 | AA14: 0 | AB14: 0 | AC14: 7 | AD14: Annual meetings; Blogs; Conference participation; Mailing lists and discussion forums (including Slack); Social media; Volunteer or ambassador network; Webinars and training
A15: bioRxiv | B15: 0 | C15: 0 | D15: 0 | E15: 0 | F15: 0 | G15: 0 | H15: 0 | I15: 0 | J15: 0 | K15: 0 | L15: 0 | M15: 0 | N15: 0 | O15: 0 | P15: 0 | Q15: 0 | R15: 0 | S15: 0 | T15: 0 | U15: 0 | V15: 0 | W15: 1 | X15: 1 | Y15: 0 | Z15: 0 | AA15: 2 | AB15: 0 | AC15: 2 | AD15: User research; Volunteer or ambassador network
A16: BitCurator Environment | B16: 1 | C16: 1 | D16: 1 | E16: 0 | F16: 0 | G16: 1 | H16: 1 | I16: 0 | J16: 1 | K16: 0 | L16: 0 | M16: 1 | N16: 0 | O16: 0 | P16: 0 | Q16: 0 | R16: 0 | S16: 0 | T16: 0 | U16: 0 | V16: 0 | W16: 0 | X16: 0 | Y16: 0 | Z16: 7 | AA16: 0 | AB16: 0 | AC16: 7 | AD16: Annual meetings; Blogs; Community calls; Interest, working, user, or advisory groups; Mailing lists and discussion forums (including Slack); Staff roles with responsibility for community engagement; Webinars and training
A17: Blacklight | B17: 0 | C17: 1 | D17: 1 | E17: 1 | F17: 1 | G17: 0 | H17: 1 | I17: 1 | J17: 0 | K17: 1 | L17: 1 | M17: 1 | N17: 0 | O17: 0 | P17: 0 | Q17: 0 | R17: 0 | S17: 0 | T17: 0 | U17: 0 | V17: 0 | W17: 0 | X17: 0 | Y17: 0 | Z17: 9 | AA17: 0 | AB17: 0 | AC17: 9 | AD17: Blogs; Community calls; Conference participation; Development sprints; Mailing lists and discussion forums (including Slack); Social media; User research; Volunteer or ambassador network; Webinars and training
A18: BrCRIS | B18: 0 | C18: 0 | D18: 0 | E18: 0 | F18: 0 | G18: 0 | H18: 0 | I18: 0 | J18: 0 | K18: 0 | L18: 0 | M18: 0 | N18: 0 | O18: 0 | P18: 0 | Q18: 0 | R18: 0 | S18: 0 | T18: 0 | U18: 0 | V18: 0 | W18: 0 | X18: 0 | Y18: 0 | Z18: 0 | AA18: 0 | AB18: 0 | AC18: 0
A19: Browsertrix | B19: 0 | C19: 0 | D19: 0 | E19: 0 | F19: 0 | G19: 0 | H19: 0 | I19: 1 | J19: 0 | K19: 0 | L19: 0 | M19: 0 | N19: 0 | O19: 0 | P19: 0 | Q19: 0 | R19: 0 | S19: 0 | T19: 0 | U19: 0 | V19: 0 | W19: 0 | X19: 0 | Y19: 0 | Z19: 1 | AA19: 0 | AB19: 0 | AC19: 1 | AD19: Social media
A20: CLOCKSS | B20: 0 | C20: 0 | D20: 0 | E20: 0 | F20: 0 | G20: 0 | H20: 0 | I20: 0 | J20: 0 | K20: 0 | L20: 0 | M20: 0 | N20: 0 | O20: 0 | P20: 0 | Q20: 0 | R20: 0 | S20: 0 | T20: 0 | U20: 0 | V20: 0 | W20: 0 | X20: 0 | Y20: 0 | Z20: 0 | AA20: 0 | AB20: 0 | AC20: 0
A21: COAR International Repository Directory (IRD) | B21: 0 | C21: 1 | D21: 1 | E21: 0 | F21: 1 | G21: 0 | H21: 0 | I21: 0 | J21: 0 | K21: 0 | L21: 1 | M21: 0 | N21: 0 | O21: 0 | P21: 0 | Q21: 0 | R21: 0 | S21: 0 | T21: 0 | U21: 0 | V21: 0 | W21: 0 | X21: 0 | Y21: 0 | Z21: 4 | AA21: 0 | AB21: 0 | AC21: 4 | AD21: Blogs; Community calls; Development sprints; Volunteer or ambassador network
A22: COAR Notify | B22: 0 | C22: 1 | D22: 0 | E22: 1 | F22: 0 | G22: 1 | H22: 1 | I22: 0 | J22: 0 | K22: 0 | L22: 0 | M22: 1 | N22: 0 | O22: 0 | P22: 0 | Q22: 0 | R22: 0 | S22: 0 | T22: 0 | U22: 0 | V22: 0 | W22: 0 | X22: 0 | Y22: 0 | Z22: 5 | AA22: 0 | AB22: 0 | AC22: 5 | AD22: Blogs; Conference participation; Interest, working, user, or advisory groups; Mailing lists and discussion forums (including Slack); Webinars and training
A23: CollectiveAccess | B23: 0 | C23: 0 | D23: 0 | E23: 0 | F23: 0 | G23: 0 | H23: 0 | I23: 0 | J23: 0 | K23: 0 | L23: 0 | M23: 0 | N23: 0 | O23: 0 | P23: 0 | Q23: 0 | R23: 0 | S23: 0 | T23: 0 | U23: 0 | V23: 0 | W23: 0 | X23: 0 | Y23: 0 | Z23: 0 | AA23: 0 | AB23: 0 | AC23: 0
A24: CORE | B24: 0 | C24: 0 | D24: 0 | E24: 0 | F24: 0 | G24: 0 | H24: 0 | I24: 0 | J24: 0 | K24: 0 | L24: 0 | M24: 0 | N24: 0 | O24: 1 | P24: 0 | Q24: 0 | R24: 0 | S24: 0 | T24: 0 | U24: 0 | V24: 0 | W24: 0 | X24: 0 | Y24: 0 | Z24: 0 | AA24: 1 | AB24: 0 | AC24: 1 | AD24: Blogs
A25: COUNTER Code of Practice | B25: 1 | C25: 1 | D25: 1 | E25: 1 | F25: 0 | G25: 1 | H25: 1 | I25: 1 | J25: 0 | K25: 0 | L25: 0 | M25: 1 | N25: 1 | O25: 1 | P25: 1 | Q25: 1 | R25: 0 | S25: 1 | T25: 0 | U25: 0 | V25: 0 | W25: 1 | X25: 0 | Y25: 1 | Z25: 8 | AA25: 7 | AB25: 0 | AC25: 9 | AD25: Annual meetings; Blogs; Community calls; Conference participation; Interest, working, user, or advisory groups; Mailing lists and discussion forums (including Slack); Social media; User research; Webinars and training
A26: Creative Commons Licenses | B26: 0 | C26: 0 | D26: 0 | E26: 0 | F26: 0 | G26: 0 | H26: 0 | I26: 0 | J26: 0 | K26: 0 | L26: 0 | M26: 0 | N26: 1 | O26: 1 | P26: 1 | Q26: 0 | R26: 0 | S26: 0 | T26: 0 | U26: 0 | V26: 1 | W26: 0 | X26: 0 | Y26: 0 | Z26: 0 | AA26: 4 | AB26: 0 | AC26: 4 | AD26: Annual meetings; Blogs; Community calls; Staff roles with responsibility for community engagement
A27: Crossref Metadata Retrieval | B27: 0 | C27: 0 | D27: 0 | E27: 0 | F27: 0 | G27: 0 | H27: 0 | I27: 0 | J27: 0 | K27: 0 | L27: 0 | M27: 0 | N27: 0 | O27: 1 | P27: 1 | Q27: 1 | R27: 0 | S27: 1 | T27: 1 | U27: 0 | V27: 1 | W27: 0 | X27: 1 | Y27: 1 | Z27: 0 | AA27: 8 | AB27: 0 | AC27: 8 | AD27: Blogs; Community calls; Conference participation; Interest, working, user, or advisory groups; Mailing lists and discussion forums (including Slack); Staff roles with responsibility for community engagement; Volunteer or ambassador network; Webinars and training
A28: D4Science Infrastructure | B28: 0 | C28: 0 | D28: 0 | E28: 0 | F28: 0 | G28: 0 | H28: 0 | I28: 0 | J28: 0 | K28: 0 | L28: 0 | M28: 0 | N28: 0 | O28: 0 | P28: 0 | Q28: 0 | R28: 0 | S28: 0 | T28: 0 | U28: 0 | V28: 0 | W28: 0 | X28: 0 | Y28: 0 | Z28: 0 | AA28: 0 | AB28: 0 | AC28: 0
A29: DART (Digital Archivist's Resource Tool) | B29: 0 | C29: 0 | D29: 0 | E29: 0 | F29: 0 | G29: 0 | H29: 0 | I29: 0 | J29: 0 | K29: 0 | L29: 0 | M29: 0 | N29: 0 | O29: 0 | P29: 0 | Q29: 0 | R29: 0 | S29: 0 | T29: 0 | U29: 0 | V29: 0 | W29: 0 | X29: 0 | Y29: 0 | Z29: 0 | AA29: 0 | AB29: 0 | AC29: 0
A30: Database Information System | B30: 1 | C30: 1 | D30: 0 | E30: 1 | F30: 0 | G30: 0 | H30: 1 | I30: 0 | J30: 1 | K30: 1 | L30: 0 | M30: 1 | N30: 0 | O30: 0 | P30: 0 | Q30: 0 | R30: 0 | S30: 0 | T30: 0 | U30: 0 | V30: 0 | W30: 0 | X30: 0 | Y30: 0 | Z30: 7 | AA30: 0 | AB30: 0 | AC30: 7 | AD30: Annual meetings; Blogs; Conference participation; Mailing lists and discussion forums (including Slack); Staff roles with responsibility for community engagement; User research; Webinars and training
A31: Data Citation Corpus | B31: 0 | C31: 1 | D31: 0 | E31: 1 | F31: 0 | G31: 1 | H31: 1 | I31: 1 | J31: 0 | K31: 0 | L31: 0 | M31: 1 | N31: 0 | O31: 0 | P31: 0 | Q31: 0 | R31: 0 | S31: 0 | T31: 0 | U31: 0 | V31: 0 | W31: 0 | X31: 0 | Y31: 0 | Z31: 6 | AA31: 0 | AB31: 0 | AC31: 6 | AD31: Blogs; Conference participation; Interest, working, user, or advisory groups; Mailing lists and discussion forums (including Slack); Social media; Webinars and training
A32: DataCite | B32: 0 | C32: 0 | D32: 0 | E32: 0 | F32: 0 | G32: 0 | H32: 0 | I32: 0 | J32: 0 | K32: 0 | L32: 0 | M32: 0 | N32: 0 | O32: 1 | P32: 0 | Q32: 0 | R32: 0 | S32: 0 | T32: 0 | U32: 0 | V32: 0 | W32: 0 | X32: 0 | Y32: 0 | Z32: 0 | AA32: 1 | AB32: 0 | AC32: 1 | AD32: Blogs
A33: Data Stewardship Wizard | B33: 1 | C33: 1 | D33: 1 | E33: 1 | F33: 0 | G33: 1 | H33: 1 | I33: 1 | J33: 0 | K33: 1 | L33: 1 | M33: 1 | N33: 0 | O33: 0 | P33: 0 | Q33: 0 | R33: 0 | S33: 0 | T33: 0 | U33: 0 | V33: 0 | W33: 0 | X33: 0 | Y33: 0 | Z33: 10 | AA33: 0 | AB33: 0 | AC33: 10 | AD33: Annual meetings; Blogs; Community calls; Conference participation; Interest, working, user, or advisory groups; Mailing lists and discussion forums (including Slack); Social media; User research; Volunteer or ambassador network; Webinars and training
A34: Dataverse | B34: 0 | C34: 0 | D34: 0 | E34: 0 | F34: 0 | G34: 0 | H34: 0 | I34: 0 | J34: 0 | K34: 0 | L34: 0 | M34: 0 | N34: 0 | O34: 0 | P34: 1 | Q34: 1 | R34: 0 | S34: 0 | T34: 1 | U34: 0 | V34: 0 | W34: 0 | X34: 0 | Y34: 0 | Z34: 0 | AA34: 3 | AB34: 0 | AC34: 3 | AD34: Community calls; Conference participation; Mailing lists and discussion forums (including Slack)
A35: DLCM Backend | B35: 0 | C35: 0 | D35: 1 | E35: 1 | F35: 0 | G35: 1 | H35: 0 | I35: 0 | J35: 0 | K35: 0 | L35: 0 | M35: 1 | N35: 0 | O35: 0 | P35: 0 | Q35: 0 | R35: 0 | S35: 0 | T35: 0 | U35: 0 | V35: 0 | W35: 0 | X35: 0 | Y35: 0 | Z35: 4 | AA35: 0 | AB35: 0 | AC35: 4 | AD35: Community calls; Conference participation; Interest, working, user, or advisory groups; Webinars and training
A36: DLCM Portal | B36: 0 | C36: 0 | D36: 1 | E36: 1 | F36: 0 | G36: 1 | H36: 0 | I36: 0 | J36: 0 | K36: 0 | L36: 0 | M36: 1 | N36: 0 | O36: 0 | P36: 0 | Q36: 0 | R36: 0 | S36: 0 | T36: 0 | U36: 0 | V36: 0 | W36: 0 | X36: 0 | Y36: 0 | Z36: 4 | AA36: 0 | AB36: 0 | AC36: 4 | AD36: Community calls; Conference participation; Interest, working, user, or advisory groups; Webinars and training
A37: DMP Tool | B37: 0 | C37: 1 | D37: 1 | E37: 1 | F37: 0 | G37: 0 | H37: 1 | I37: 1 | J37: 1 | K37: 1 | L37: 0 | M37: 1 | N37: 0 | O37: 0 | P37: 0 | Q37: 0 | R37: 0 | S37: 0 | T37: 0 | U37: 0 | V37: 0 | W37: 0 | X37: 0 | Y37: 0 | Z37: 8 | AA37: 0 | AB37: 0 | AC37: 8 | AD37: Blogs; Community calls; Conference participation; Mailing lists and discussion forums (including Slack); Social media; Staff roles with responsibility for community engagement; User research; Webinars and training
A38: DOAJ (Directory of Open Access Journals) | B38: 0 | C38: 1 | D38: 1 | E38: 1 | F38: 0 | G38: 1 | H38: 0 | I38: 1 | J38: 0 | K38: 1 | L38: 1 | M38: 1 | N38: 0 | O38: 1 | P38: 0 | Q38: 0 | R38: 0 | S38: 1 | T38: 0 | U38: 0 | V38: 0 | W38: 0 | X38: 0 | Y38: 0 | Z38: 8 | AA38: 2 | AB38: 0 | AC38: 9 | AD38: Blogs; Community calls; Conference participation; Interest, working, user, or advisory groups; Other; Social media; User research; Volunteer or ambassador network; Webinars and training
A39: dokieli | B39: 0 | C39: 0 | D39: 0 | E39: 0 | F39: 0 | G39: 0 | H39: 0 | I39: 0 | J39: 0 | K39: 0 | L39: 0 | M39: 0 | N39: 0 | O39: 0 | P39: 0 | Q39: 1 | R39: 0 | S39: 0 | T39: 1 | U39: 0 | V39: 0 | W39: 0 | X39: 0 | Y39: 0 | Z39: 0 | AA39: 2 | AB39: 0 | AC39: 2 | AD39: Conference participation; Mailing lists and discussion forums (including Slack)
A40: Dryad | B40: 0 | C40: 0 | D40: 0 | E40: 0 | F40: 0 | G40: 0 | H40: 0 | I40: 0 | J40: 0 | K40: 0 | L40: 0 | M40: 0 | N40: 0 | O40: 1 | P40: 0 | Q40: 1 | R40: 0 | S40: 1 | T40: 1 | U40: 0 | V40: 0 | W40: 0 | X40: 0 | Y40: 0 | Z40: 0 | AA40: 4 | AB40: 0 | AC40: 4 | AD40: Blogs; Conference participation; Interest, working, user, or advisory groups; Mailing lists and discussion forums (including Slack)
...

Sheet Contribution Coding
A1: Service | B1: 040: Contribute funds | C1: 040: Contribute to code | D1: 040: Contribute to documentation | E1: 040: Contribute to education or training | F1: 040: Contribute to governance | G1: 040: Contribute to peer reviews | H1: 040: Contribute to user research or user testing | I1: 040: Contribute to working groups or interest groups | J1: 940 text | K1: Other selected and described | L1: Route count / 9 | M1: Coded routes
A2: 2i2c | B2: 0 | C2: 0 | D2: 0 | E2: 0 | F2: 0 | G2: 0 | H2: 0 | I2: 0 | K2: 0 | L2: 0
A3: Academic Preservation Trust (APTrust) | B3: 1 | C3: 1 | D3: 1 | E3: 1 | F3: 1 | G3: 0 | H3: 1 | I3: 1 | K3: 0 | L3: 7 | M3: Contribute funds; Contribute to code; Contribute to documentation; Contribute to education or training; Contribute to governance; Contribute to user research or user testing; Contribute to working groups or interest groups
A4: AfricArXiv | B4: 0 | C4: 0 | D4: 0 | E4: 0 | F4: 0 | G4: 0 | H4: 0 | I4: 0 | K4: 0 | L4: 0
A5: Arches Heritage Data Management Platform | B5: 0 | C5: 0 | D5: 0 | E5: 0 | F5: 0 | G5: 0 | H5: 0 | I5: 0 | K5: 0 | L5: 0
A6: Archipelago Commons | B6: 0 | C6: 1 | D6: 1 | E6: 0 | F6: 0 | G6: 0 | H6: 0 | I6: 1 | K6: 0 | L6: 3 | M6: Contribute to code; Contribute to documentation; Contribute to working groups or interest groups
A7: Archival Resource Key | B7: 1 | C7: 1 | D7: 1 | E7: 1 | F7: 0 | G7: 0 | H7: 0 | I7: 1 | K7: 0 | L7: 5 | M7: Contribute funds; Contribute to code; Contribute to documentation; Contribute to education or training; Contribute to working groups or interest groups
A8: Archivematica | B8: 0 | C8: 0 | D8: 0 | E8: 0 | F8: 0 | G8: 0 | H8: 0 | I8: 0 | K8: 0 | L8: 0
A9: ArchivesSpace | B9: 0 | C9: 0 | D9: 0 | E9: 0 | F9: 0 | G9: 0 | H9: 0 | I9: 0 | K9: 0 | L9: 0
A10: ARGOS | B10: 0 | C10: 0 | D10: 0 | E10: 0 | F10: 0 | G10: 0 | H10: 0 | I10: 0 | K10: 0 | L10: 0
A11: arXiv | B11: 1 | C11: 1 | D11: 0 | E11: 0 | F11: 0 | G11: 0 | H11: 0 | I11: 1 | K11: 0 | L11: 3 | M11: Contribute funds; Contribute to code; Contribute to working groups or interest groups
A12: AtoM | B12: 0 | C12: 0 | D12: 0 | E12: 0 | F12: 0 | G12: 0 | H12: 0 | I12: 0 | K12: 0 | L12: 0
A13: Avalon Media System | B13: 1 | C13: 1 | D13: 1 | E13: 1 | F13: 1 | G13: 0 | H13: 1 | I13: 0 | K13: 0 | L13: 6 | M13: Contribute funds; Contribute to code; Contribute to documentation; Contribute to education or training; Contribute to governance; Contribute to user research or user testing
A14: Biodiversity Heritage Library | B14: 1 | C14: 0 | D14: 0 | E14: 0 | F14: 0 | G14: 0 | H14: 0 | I14: 0 | K14: 0 | L14: 1 | M14: Contribute funds
A15: bioRxiv | B15: 0 | C15: 0 | D15: 0 | E15: 0 | F15: 0 | G15: 0 | H15: 0 | I15: 0 | K15: 0 | L15: 0
A16: BitCurator Environment | B16: 0 | C16: 1 | D16: 1 | E16: 1 | F16: 1 | G16: 0 | H16: 0 | I16: 1 | K16: 0 | L16: 5 | M16: Contribute to code; Contribute to documentation; Contribute to education or training; Contribute to governance; Contribute to working groups or interest groups
A17: Blacklight | B17: 1 | C17: 1 | D17: 1 | E17: 1 | F17: 1 | G17: 0 | H17: 1 | I17: 1 | K17: 0 | L17: 7 | M17: Contribute funds; Contribute to code; Contribute to documentation; Contribute to education or training; Contribute to governance; Contribute to user research or user testing; Contribute to working groups or interest groups
A18: BrCRIS | B18: 0 | C18: 0 | D18: 0 | E18: 0 | F18: 0 | G18: 0 | H18: 0 | I18: 0 | K18: 0 | L18: 0
A19: Browsertrix | B19: 0 | C19: 1 | D19: 1 | E19: 0 | F19: 0 | G19: 0 | H19: 0 | I19: 0 | K19: 0 | L19: 2 | M19: Contribute to code; Contribute to documentation
A20: CLOCKSS | B20: 0 | C20: 0 | D20: 0 | E20: 0 | F20: 0 | G20: 0 | H20: 0 | I20: 0 | K20: 0 | L20: 0
A21: COAR International Repository Directory (IRD) | B21: 0 | C21: 0 | D21: 1 | E21: 0 | F21: 0 | G21: 0 | H21: 1 | I21: 0 | K21: 0 | L21: 2 | M21: Contribute to documentation; Contribute to user research or user testing
A22: COAR Notify | B22: 0 | C22: 1 | D22: 1 | E22: 1 | F22: 0 | G22: 0 | H22: 1 | I22: 1 | K22: 0 | L22: 5 | M22: Contribute to code; Contribute to documentation; Contribute to education or training; Contribute to user research or user testing; Contribute to working groups or interest groups
A23: CollectiveAccess | B23: 0 | C23: 0 | D23: 0 | E23: 0 | F23: 0 | G23: 0 | H23: 0 | I23: 0 | K23: 0 | L23: 0
A24: CORE | B24: 1 | C24: 1 | D24: 1 | E24: 0 | F24: 0 | G24: 0 | H24: 0 | I24: 0 | K24: 0 | L24: 3 | M24: Contribute funds; Contribute to code; Contribute to documentation
A25: COUNTER Code of Practice | B25: 1 | C25: 0 | D25: 1 | E25: 1 | F25: 1 | G25: 0 | H25: 0 | I25: 1 | K25: 0 | L25: 5 | M25: Contribute funds; Contribute to documentation; Contribute to education or training; Contribute to governance; Contribute to working groups or interest groups
A26: Creative Commons Licenses | B26: 1 | C26: 1 | D26: 0 | E26: 0 | F26: 0 | G26: 0 | H26: 0 | I26: 1 | K26: 0 | L26: 3 | M26: Contribute funds; Contribute to code; Contribute to working groups or interest groups
A27: Crossref Metadata Retrieval | B27: 1 | C27: 1 | D27: 1 | E27: 1 | F27: 0 | G27: 0 | H27: 0 | I27: 1 | K27: 0 | L27: 5 | M27: Contribute funds; Contribute to code; Contribute to documentation; Contribute to education or training; Contribute to working groups or interest groups
A28: D4Science Infrastructure | B28: 0 | C28: 0 | D28: 0 | E28: 0 | F28: 0 | G28: 0 | H28: 0 | I28: 0 | K28: 0 | L28: 0
A29: DART (Digital Archivist's Resource Tool) | B29: 1 | C29: 1 | D29: 1 | E29: 1 | F29: 1 | G29: 0 | H29: 1 | I29: 1 | K29: 0 | L29: 7 | M29: Contribute funds; Contribute to code; Contribute to documentation; Contribute to education or training; Contribute to governance; Contribute to user research or user testing; Contribute to working groups or interest groups
A30: Database Information System | B30: 0 | C30: 0 | D30: 0 | E30: 0 | F30: 0 | G30: 0 | H30: 0 | I30: 1 | K30: 0 | L30: 1 | M30: Contribute to working groups or interest groups
A31: Data Citation Corpus | B31: 0 | C31: 0 | D31: 0 | E31: 0 | F31: 0 | G31: 0 | H31: 0 | I31: 0 | J31: Groups can contribute citations to the Corpus | K31: 1 | L31: 1 | M31: Other
A32: DataCite | B32: 1 | C32: 0 | D32: 1 | E32: 0 | F32: 0 | G32: 0 | H32: 0 | I32: 1 | K32: 0 | L32: 3 | M32: Contribute funds; Contribute to documentation; Contribute to working groups or interest groups
A33: Data Stewardship Wizard | B33: 0 | C33: 1 | D33: 1 | E33: 1 | F33: 1 | G33: 0 | H33: 1 | I33: 0 | K33: 0 | L33: 5 | M33: Contribute to code; Contribute to documentation; Contribute to education or training; Contribute to governance; Contribute to user research or user testing
A34: Dataverse | B34: 0 | C34: 1 | D34: 1 | E34: 1 | F34: 0 | G34: 0 | H34: 0 | I34: 1 | K34: 0 | L34: 4 | M34: Contribute to code; Contribute to documentation; Contribute to education or training; Contribute to working groups or interest groups
A35: DLCM Backend | B35: 0 | C35: 0 | D35: 0 | E35: 0 | F35: 0 | G35: 0 | H35: 0 | I35: 0 | K35: 0 | L35: 0
A36: DLCM Portal | B36: 0 | C36: 0 | D36: 0 | E36: 0 | F36: 0 | G36: 0 | H36: 0 | I36: 0 | K36: 0 | L36: 0
A37: DMP Tool | B37: 0 | C37: 0 | D37: 0 | E37: 0 | F37: 0 | G37: 0 | H37: 0 | I37: 0 | K37: 0 | L37: 0
A38: DOAJ (Directory of Open Access Journals) | B38: 0 | C38: 1 | D38: 1 | E38: 1 | F38: 0 | G38: 0 | H38: 1 | I38: 1 | J38: <p>We have a network of over 100 volunteers who review applications. We have regional representation through our Ambassador network. Some of our volunteers and ambassadors have been with us for more than 10 years.</p> <p>We have a dedicated community engagement role to ensure that we are in touch with the large number of stakeholder groups that use and rely upon DOAJ. When we move to our new governance structure, we will establish a stakeholder council.</p> <p>Our strategy states we will advocate for equity and diversity in global open access journal publishing. To do that, we engage with journal platforms and representative groups from around the world, e.g., the Chinese Academy of Science, KISTI in South Korea, J-STAGE in Japan, Publicera in Sweden, Scielo in Latin America, ASSAf and AJOL in South Africa and more.</p> | K38: 0 | L38: 5 | M38: Contribute to code; Contribute to documentation; Contribute to education or training; Contribute to user research or user testing; Contribute to working groups or interest groups
A39: dokieli | B39: 1 | C39: 1 | D39: 1 | E39: 1 | F39: 0 | G39: 0 | H39: 0 | I39: 0 | K39: 0 | L39: 4 | M39: Contribute funds; Contribute to code; Contribute to documentation; Contribute to education or training
A40: Dryad | B40: 1 | C40: 0 | D40: 0 | E40: 1 | F40: 1 | G40: 0 | H40: 0 | I40: 1 | K40: 0 | L40: 4 | M40: Contribute funds; Contribute to education or training; Contribute to governance; Contribute to working groups or interest groups
...

Sheet Calc
A1: Service | B1: E1 default | C1: E2 preliminary | D1: C1 preliminary | E1: C2 URL score | F1: C3 repository-field score | G1: N1 default | H1: E2 count | I1: C1 count | J1: C2 scoring note | K1: C3 scoring note | L1: Data flags
A2: 2i2c | B2: 100 | C2: 15.3846 | F2: 100 | G2: 100 | H2: 2 | I2: 0 | J2: None: Blank or suspect URL; review required | K2: 100.0: Available public-forge repository URL | L2: 938 coding requires reviewer confirmation; 019 scored from populated repository field; 043 evidence URL should be checked; not scored separately; 116 retained as source evidence only; not scored; 2 unavailable metric(s) scored as 0
A3: Academic Preservation Trust (APTrust) | B3: 100 | C3: 76.9231 | D3: 77.7778 | E3: 50 | F3: 100 | G3: 100 | H3: 10 | I3: 7 | J3: 50.0: Candidate general participation page; verify URL | K3: 100.0: Available public-forge repository URL | L3: 041 scored from available URL tier; 019 scored from populated repository field; 043 evidence URL should be checked; not scored separately; 116 retained as source evidence only; not scored
A4: AfricArXiv | B4: 33 | G4: 100 | H4: 0 | I4: 0 | J4: None: Blank or suspect URL; review required | K4: None: No repository URL supplied | L4: 043 evidence URL should be checked; not scored separately; 4 unavailable metric(s) scored as 0
A5: Arches Heritage Data Management Platform | B5: 100 | E5: 100 | F5: 100 | G5: 100 | H5: 0 | I5: 0 | J5: 100.0: Candidate dedicated contribution guide; verify URL | K5: 100.0: Available public-forge repository URL | L5: 041 scored from available URL tier; 019 scored from populated repository field; 043 evidence URL should be checked; not scored separately; 116 retained as source evidence only; not scored; 2 unavailable metric(s) scored as 0
A6: Archipelago Commons | B6: 100 | C6: 53.8462 | D6: 33.3333 | E6: 100 | F6: 100 | G6: 100 | H6: 7 | I6: 3 | J6: 100.0: Candidate dedicated contribution guide; verify URL | K6: 100.0: Available public-forge repository URL | L6: 938 coding requires reviewer confirmation; 041 scored from available URL tier; 019 scored from populated repository field; 043 evidence URL should be checked; not scored separately; 116 retained as source evidence only; not scored
A7: Archival Resource Key | B7: 100 | D7: 55.5556 | E7: 50 | F7: 100 | G7: 100 | H7: 0 | I7: 5 | J7: 50.0: Candidate general participation page; verify URL | K7: 100.0: Available public-forge repository URL | L7: 041 scored from available URL tier; 019 scored from populated repository field; 043 evidence URL should be checked; not scored separately; 116 retained as source evidence only; not scored; 1 unavailable metric(s) scored as 0
A8: Archivematica | B8: 100 | E8: 100 | F8: 100 | H8: 0 | I8: 0 | J8: 100.0: Candidate dedicated contribution guide; verify URL | K8: 100.0: Available public-forge repository URL | L8: 041 scored from available URL tier; 019 scored from populated repository field; 043 evidence URL should be checked; not scored separately; 116 retained as source evidence only; not scored; 3 unavailable metric(s) scored as 0
A9: ArchivesSpace | B9: 100 | C9: 69.2308 | E9: 100 | F9: 100 | G9: 100 | H9: 9 | I9: 0 | J9: 100.0: Candidate dedicated contribution guide; verify URL | K9: 100.0: Available public-forge repository URL | L9: 041 scored from available URL tier; 019 scored from populated repository field; 043 evidence URL should be checked; not scored separately; 116 retained as source evidence only; not scored; 1 unavailable metric(s) scored as 0
A10: ARGOS | B10: 100 | C10: 61.5385 | F10: 100 | G10: 100 | H10: 8 | I10: 0 | J10: None: Blank or suspect URL; review required | K10: 100.0: Available public-forge repository URL | L10: 019 scored from populated repository field; 043 evidence URL should be checked; not scored separately; 116 retained as source evidence only; not scored; 2 unavailable metric(s) scored as 0
A11: arXiv | B11: 100 | C11: 30.7692 | D11: 33.3333 | E11: 50 | F11: 100 | G11: 100 | H11: 4 | I11: 3 | J11: 50.0: Candidate general participation page; verify URL | K11: 100.0: Available public-forge repository URL | L11: 938 coding requires reviewer confirmation; 041 scored from available URL tier; 019 scored from populated repository field; 043 evidence URL should be checked; not scored separately
A12: AtoM | B12: 67 | F12: 100 | H12: 0 | I12: 0 | J12: None: Blank or suspect URL; review required | K12: 100.0: Available public-forge repository URL | L12: 041 scored from available URL tier; 019 scored from populated repository field; 043 evidence URL should be checked; not scored separately; 4 unavailable metric(s) scored as 0
A13: Avalon Media System | B13: 100 | C13: 38.4615 | D13: 66.6667 | E13: 50 | F13: 100 | G13: 100 | H13: 5 | I13: 6 | J13: 50.0: Candidate general participation page; verify URL | K13: 100.0: Available public-forge repository URL | L13: 041 scored from available URL tier; 019 scored from populated repository field; 043 evidence URL should be checked; not scored separately; 116 retained as source evidence only; not scored
A14: Biodiversity Heritage Library | B14: 100 | C14: 53.8462 | D14: 11.1111 | E14: 100 | F14: 100 | G14: 100 | H14: 7 | I14: 1 | J14: 100.0: Candidate dedicated contribution guide; verify URL | K14: 100.0: Available public-forge repository URL | L14: 041 scored from available URL tier; 019 scored from populated repository field; 043 evidence URL should be checked; not scored separately; 116 retained as source evidence only; not scored
A15: bioRxiv | B15: 100 | C15: 15.3846 | G15: 33 | H15: 2 | I15: 0 | J15: None: Blank or suspect URL; review required | K15: None: No repository URL supplied | L15: 938 coding requires reviewer confirmation; 3 unavailable metric(s) scored as 0
A16: BitCurator Environment | B16: 100 | C16: 53.8462 | D16: 55.5556 | E16: 50 | F16: 100 | G16: 100 | H16: 7 | I16: 5 | J16: 50.0: Candidate general participation page; verify URL | K16: 100.0: Available public-forge repository URL | L16: 041 scored from available URL tier; 019 scored from populated repository field; 043 evidence URL should be checked; not scored separately; 116 retained as source evidence only; not scored
A17: Blacklight | B17: 100 | C17: 69.2308 | D17: 77.7778 | E17: 100 | F17: 100 | G17: 67 | H17: 9 | I17: 7 | J17: 100.0: Candidate dedicated contribution guide; verify URL | K17: 100.0: Available public-forge repository URL | L17: 041 scored from available URL tier; 019 scored from populated repository field; 116 retained as source evidence only; not scored
A18: BrCRIS | B18: 67 | F18: 100 | G18: 100 | H18: 0 | I18: 0 | J18: None: Blank or suspect URL; review required | K18: 100.0: Available public-forge repository URL | L18: 019 scored from populated repository field; 043 evidence URL should be checked; not scored separately; 3 unavailable metric(s) scored as 0
A19: Browsertrix | B19: 100 | C19: 7.6923 | D19: 22.2222 | F19: 100 | G19: 100 | H19: 1 | I19: 2 | J19: None: Blank or suspect URL; review required | K19: 100.0: Available public-forge repository URL | L19: 019 scored from populated repository field; 043 evidence URL should be checked; not scored separately; 116 retained as source evidence only; not scored; 1 unavailable metric(s) scored as 0
A20: CLOCKSS | B20: 100 | F20: 100 | G20: 33 | H20: 0 | I20: 0 | J20: None: Blank or suspect URL; review required | K20: 100.0: Available public-forge repository URL | L20: 019 scored from populated repository field; 116 retained as source evidence only; not scored; 3 unavailable metric(s) scored as 0
A21: COAR International Repository Directory (IRD) | B21: 100 | C21: 30.7692 | D21: 22.2222 | E21: 50 | F21: 100 | G21: 67 | H21: 4 | I21: 2 | J21: 50.0: Candidate general participation page; verify URL | K21: 100.0: Available public-forge repository URL | L21: 041 scored from available URL tier; 019 scored from populated repository field; 116 retained as source evidence only; not scored
A22: COAR Notify | B22: 100 | C22: 38.4615 | D22: 55.5556 | E22: 50 | F22: 100 | G22: 33 | H22: 5 | I22: 5 | J22: 50.0: Candidate general participation page; verify URL | K22: 100.0: Available public-forge repository URL | L22: 041 scored from available URL tier; 019 scored from populated repository field; 116 retained as source evidence only; not scored
A23: CollectiveAccess | B23: 100 | E23: 50 | F23: 100 | H23: 0 | I23: 0 | J23: 50.0: Candidate general participation page; verify URL | K23: 100.0: Available public-forge repository URL | L23: 041 scored from available URL tier; 019 scored from populated repository field; 043 evidence URL should be checked; not scored separately; 116 retained as source evidence only; not scored; 3 unavailable metric(s) scored as 0
A24: CORE | B24: 100 | C24: 7.6923 | D24: 33.3333 | E24: 50 | F24: 100 | G24: 100 | H24: 1 | I24: 3 | J24: 50.0: Candidate general participation page; verify URL | K24: 100.0: Available public-forge repository URL | L24: 938 coding requires reviewer confirmation; 041 scored from available URL tier; 019 scored from populated repository field; 043 evidence URL should be checked; not scored separately; 116 retained as source evidence only; not scored
A25: COUNTER Code of Practice | B25: 100 | C25: 69.2308 | D25: 55.5556 | E25: 50 | F25: 50 | G25: 100 | H25: 9 | I25: 5 | J25: 50.0: Candidate general participation page; verify URL | K25: 50.0: Repository field populated on another/unspecified host | L25: 938 coding requires reviewer confirmation; 041 scored from available URL tier; 019 scored from populated repository field; 043 evidence URL should be checked; not scored separately; 116 retained as source evidence only; not scored
A26: Creative Commons Licenses | B26: 100 | C26: 30.7692 | D26: 33.3333 | E26: 100 | F26: 100 | G26: 100 | H26: 4 | I26: 3 | J26: 100.0: Candidate dedicated contribution guide; verify URL | K26: 100.0: Available public-forge repository URL | L26: 938 coding requires reviewer confirmation; 041 scored from available URL tier; 019 scored from populated repository field; 043 evidence URL should be checked; not scored separately
A27: Crossref Metadata Retrieval | B27: 100 | C27: 61.5385 | D27: 55.5556 | E27: 50 | F27: 100 | G27: 100 | H27: 8 | I27: 5 | J27: 50.0: Candidate general participation page; verify URL | K27: 100.0: Available public-forge repository URL | L27: 938 coding requires reviewer confirmation; 041 scored from available URL tier; 019 scored from populated repository field; 043 evidence URL should be checked; not scored separately; 116 retained as source evidence only; not scored
A28: D4Science Infrastructure | B28: 33 | F28: 50 | G28: 33 | H28: 0 | I28: 0 | J28: None: Blank or suspect URL; review required | K28: 50.0: Repository field populated on another/unspecified host | L28: 019 scored from populated repository field; 3 unavailable metric(s) scored as 0
A29: DART (Digital Archivist's Resource Tool) | B29: 100 | D29: 77.7778 | E29: 50 | F29: 100 | G29: 33 | H29: 0 | I29: 7 | J29: 50.0: Candidate general participation page; verify URL | K29: 100.0: Available public-forge repository URL | L29: 041 scored from available URL tier; 019 scored from populated repository field; 116 retained as source evidence only; not scored; 1 unavailable metric(s) scored as 0
A30: Database Information System | B30: 100 | C30: 53.8462 | D30: 11.1111 | F30: 100 | G30: 33 | H30: 7 | I30: 1 | J30: None: Blank or suspect URL; review required | K30: 100.0: Available public-forge repository URL | L30: 019 scored from populated repository field; 1 unavailable metric(s) scored as 0
A31: Data Citation Corpus | B31: 100 | C31: 46.1538 | D31: 11.1111 | E31: 100 | F31: 100 | G31: 0 | H31: 6 | I31: 1 | J31: 100.0: Candidate dedicated contribution guide; verify URL | K31: 100.0: Available public-forge repository URL | L31: 940 Other route requires reviewer confirmation; 041 scored from available URL tier; 019 scored from populated repository field; 116 retained as source evidence only; not scored
A32: DataCite | B32: 100 | C32: 7.6923 | D32: 33.3333 | E32: 50 | F32: 100 | G32: 100 | H32: 1 | I32: 3 | J32: 50.0: Candidate general participation page; verify URL | K32: 100.0: Available public-forge repository URL | L32: 938 coding requires reviewer confirmation; 041 scored from available URL tier; 019 scored from populated repository field; 043 evidence URL should be checked; not scored separately; 116 retained as source evidence only; not scored
A33: Data Stewardship Wizard | B33: 100 | C33: 76.9231 | D33: 55.5556 | E33: 100 | F33: 100 | G33: 100 | H33: 10 | I33: 5 | J33: 100.0: Candidate dedicated contribution guide; verify URL | K33: 100.0: Available public-forge repository URL | L33: 041 scored from available URL tier; 019 scored from populated repository field; 043 evidence URL should be checked; not scored separately; 116 retained as source evidence only; not scored
A34: Dataverse | B34: 100 | C34: 23.0769 | D34: 44.4444 | E34: 50 | F34: 100 | G34: 100 | H34: 3 | I34: 4 | J34: 50.0: Candidate general participation page; verify URL | K34: 100.0: Available public-forge repository URL | L34: 938 coding requires reviewer confirmation; 041 scored from available URL tier; 019 scored from populated repository field; 043 evidence URL should be checked; not scored separately; 116 retained as source evidence only; not scored
A35: DLCM Backend | B35: 100 | C35: 30.7692 | E35: 100 | F35: 50 | G35: 100 | H35: 4 | I35: 0 | J35: 100.0: Candidate dedicated contribution guide; verify URL | K35: 50.0: Repository field populated on another/unspecified host | L35: 041 scored from available URL tier; 019 scored from populated repository field; 043 evidence URL should be checked; not scored separately; 116 retained as source evidence only; not scored; 1 unavailable metric(s) scored as 0
A36: DLCM Portal | B36: 100 | C36: 30.7692 | E36: 100 | F36: 50 | G36: 100 | H36: 4 | I36: 0 | J36: 100.0: Candidate dedicated contribution guide; verify URL | K36: 50.0: Repository field populated on another/unspecified host | L36: 041 scored from available URL tier; 019 scored from populated repository field; 043 evidence URL should be checked; not scored separately; 116 retained as source evidence only; not scored; 1 unavailable metric(s) scored as 0
A37: DMP Tool | B37: 100 | C37: 61.5385 | F37: 100 | G37: 0 | H37: 8 | I37: 0 | J37: None: Blank or suspect URL; review required | K37: 100.0: Available public-forge repository URL | L37: 019 scored from populated repository field; 2 unavailable metric(s) scored as 0
A38: DOAJ (Directory of Open Access Journals) | B38: 100 | C38: 69.2308 | D38: 55.5556 | F38: 100 | G38: 100 | H38: 9 | I38: 5 | J38: None: Blank or suspect URL; review required | K38: 100.0: Available public-forge repository URL | L38: 938 coding requires reviewer confirmation; 940 Other route requires reviewer confirmation; 019 scored from populated repository field; 043 evidence URL should be checked; not scored separately; 1 unavailable metric(s) scored as 0
A39: dokieli | B39: 100 | C39: 15.3846 | D39: 44.4444 | E39: 50 | F39: 100 | G39: 100 | H39: 2 | I39: 4 | J39: 50.0: Candidate general participation page; verify URL | K39: 100.0: Available public-forge repository URL | L39: 938 coding requires reviewer confirmation; 041 scored from available URL tier; 019 scored from populated repository field; 043 evidence URL should be checked; not scored separately; 116 retained as source evidence only; not scored
