Workbook

Sheet Codebook
A1: OISI Component 1 — Community Engagement: codebook and method
A2: Dataset: Infra Finder data, Invest in Open Infrastructure, v3.0 (Zenodo record 18225266, 13 Jan 2026). 112 infrastructures. Variable values are self-reported and only as current as the snapshot.
A4: 1. Score formula
A5: Community Engagement Score (0–100) = 100 × Σ(wᵢ × sᵢ) / Σ(wᵢ), summed only over metrics i that have a valid score sᵢ (0–1).
A6: Weights wᵢ are on the Parameters sheet (E1=8%, E2=22%, C1=18%, C2=12%, C3=5%, G1=15%, G2=20%). They sum to 100%, so the 30/35/35 sub-component weights are implied, not applied separately.
A7: Missing data rule: Unknown, blank and Not applicable are NA — excluded from both numerator and denominator, never counted as 0.
A8: Completeness rule: a repo is scored only if scored metrics carry ≥ 60% of the weight AND at least one metric is scored in each of the 3 sub-components. Otherwise the score is NA.
A9: Uncertainty rule: every score carries a range. Lower bound = score if all missing metrics were 0; upper bound = score if all missing metrics were 1. Result status: Reportable (≥85% of weight scored) can be ranked and cited; Provisional (60–85%) is cited only with its range.
A10: Overall OISI contribution: this component × 25% (OISI = 100 × [0.25 CE + 0.25 Governance + 0.25 Org. Capacity + 0.25 Dev. Activity]).
A12: 2. Metric definitions
A13: Code | B13: Metric | C13: Sub-component | D13: Weight | E13: Source field type | F13: Scoring rule (automatic) | G13: NA / missing rule | H13: Verification guidance (override on Verification sheet)
A14: E1 | B14: Engagement status (037) | C14: Engagement & Participation | D14: =Parameters!$E$6 -> 0.08 | E14: Status list | F14: Ladder: Implemented 1.00; In progress 0.67; Considering 0.33; Not planning 0. | G14: Unknown / blank → NA | H14: Open 116_community_engagement_url; confirm a real programme exists. About 85% of scored repos are "Implemented", so weight is only 8%.
A15: E2 | B15: Engagement breadth (038 + coded 938) | C15: Engagement & Participation | D15: =Parameters!$E$7 -> 0.22 | E15: Multi-select checklist + coded free text | F15: Score = min(n, 8) / 8, n = distinct categories in the UNION of the 038 checklist and categories coded from 938 text (Dictionary sheet). "Other" counts as 1 only with 938 text. Gate: if E1 ≤ Considering, E2 = 0 and flagged. | G15: No category from either source → NA (never 0) | H15: Coded text is strict (precision over recall) so it can understate breadth. Check the Audit sheet; override on Verification (E2 override) after reading the text. Sensitivity row "E2 checklist only" shows the effect of dropping 938.
A16: C1 | B16: Contribution routes (040 + 940) | C16: Contribution Mechanisms | D16: =Parameters!$E$8 -> 0.18 | E16: Multi-select (8 categories) + free text | F16: Score = min(n, 6) / 6. "Contribute funds" counts (OISI draft). "Other" counts as 1 only with 940 text. | G16: Blank / "Not applicable" → NA | H16: Check the listed routes against the website and repo.
A17: C2 | B17: Contribution guidance (041) | C17: Contribution Mechanisms | D17: =Parameters!$E$9 -> 0.12 | E17: URL (not a status) | F17: Tiers from the URL: dedicated guide 1.00; other get-involved page 0.50. Suspect URL → NA until verified. | G17: Blank → NA | H17: Open each URL. 1.00 = usable how-to; 0.50 = general invitation; 0 = verified absent. Check the repo for CONTRIBUTING.md.
A18: C3 | B18: Open contribution infrastructure (019) | C18: Contribution Mechanisms | D18: =Parameters!$E$10 -> 0.05 | E18: URL host | F18: Public forge (GitHub, GitLab.com, Bitbucket, Codeberg, SourceHut) 1.00; other host 0.50. Replaces 039. | G18: Blank → NA | H18: Low weight (5%): 103 of 108 repos score 1.00, so it separates little until live checks are added (CONTRIBUTING file, issue tracker, recent commits, external contributors).
A19: G1 | B19: Code of Conduct (042) | C19: Community Norms & Governance | D19: =Parameters!$E$11 -> 0.15 | E19: Status list | F19: Same ladder as E1. | G19: Unknown → NA | H19: Open 043 URL. An inherited parent-organisation Code counts only if it explicitly covers this community.
A20: G2 | B20: Community governance (048) | C20: Community Norms & Governance | D20: =Parameters!$E$12 -> 0.2 | E20: Status list | F20: Formal 1.00; Ad hoc 0.50; None 0. | G20: Blank → NA | H20: Open 049 URL: bylaws, charter or governance page = Formal. Enter 0 only when absence is verified.
A21: 039 (contribution pathways) is NOT scored: 68 of 112 values are Unknown. It is kept only as a consistency flag (Calc column R). 078, 107 are descriptive only. Supporting URLs (116, 043, 049) are evidence, not scored.
A23: 3. Decision log
A24: # | B24: Decision | C24: Rationale
A25: D1 | B25: Blank / Unknown / Not applicable = NA, never 0. | C25: Follows the OISI missing-data rule. The Zenodo dataset does not say whether a blank means "none" or "not answered", so assuming 0 would invent evidence and penalise skipped questions.
A26: D2 | B26: A blank becomes 0 only through verification. | C26: Record the evidence on the Verification sheet; verified overrides replace auto scores.
A27: D3 | B27: Flat weighted mean over available metrics, with a completeness threshold. | C27: Avoids inflating repos that were scored on one or two metrics. Threshold 60% of weight + all three sub-components; 50% and 70% shown in Sensitivity.
A28: D4 | B28: Inherited Code of Conduct counts only if explicitly applicable and verified. | C28: Keeps the rule consistent without crediting a generic organisational page.
A29: D5 | B29: "Contribute funds" counts in 040. | C29: The OISI draft lists funding as a contribution opportunity. Sensitivity sheet shows the effect of excluding it.
A30: D6 | B30: 041 is scored in tiers (1 / 0.5 / NA-or-0) from the URL. | C30: The field is a URL, not a status; only ~25 of 81 URLs are dedicated contribution documents and 6 are not guidance at all. Tiers are provisional until each URL is opened.
A31: D7 | B31: "Other" counts as one category only with a free-text description. | C31: Prevents unverifiable credit.
A32: D8 | B32: 039 is removed from the score; replaced by C3 (019). | C32: 68 of 112 are Unknown. Inferring a pathway from 040/041 would double-count the same evidence, so C3 uses a different, almost complete field (019). 039 stays only as a consistency flag.
A33: D9 | B33: Engagement gate (037 ≤ Considering → 038 = 0). | C33: Two repos list activities while reporting no implemented engagement; flagged for verification.
A34: D10 | B34: Every score is published with a lower and upper bound. | C34: Renormalising over available metrics lets a repo with 60% of the weight scored reach 100. The range (missing = 0 vs missing = 1) shows how much of the score rests on assumption; a repo is confidently high only if its lower bound is also high.
A35: D11 | B35: Only Reportable repos (≥85% of weight scored) are ranked in the top/bottom lists and headline claims. | C35: Provisional scores stay visible but are labelled; they should not be named best or worst.
... A38: D14 | B38: D14: 938 free text is coded onto the 12 categories and unioned with 038. | C38: 038 and 938 are complementary (only 11 repos have both, none identical). Coder is a published keyword dictionary, strict by design, audited on 20 repos (Audit sheet) with a checklist-only sensitivity scenario.
A39: 4. Verification workflow
A40: 1) Go to the Verification sheet. Filter "Open flags" > 0 first (flags are explained in the Action column).
A41: 2) Open the evidence URL, decide the verified value, and type it in the yellow override cell for that metric (a number 0–1, or NA). Leave blank to keep the automatic score.
A42: 3) Fill Verified by, Date, Evidence/notes, and set Verification status. Scoring, Summary and Sensitivity update automatically.
A43: Example row (illustrative format only): Service = Hyrax | 039 override = 1.00 | Verified by = initials | Date = 2026-02-01 | Notes = "Getting Started page lists code, docs and group routes" | Status = Verified.
A44: 4) Re-check Sensitivity and the score ranges after verification: as NA cells are resolved, ranges narrow and Provisional repos become Reportable.
A46: 5. Sheet guide and colour legend
...

Sheet Summary
A1: OISI Component 1 — Community Engagement: results summary
A2: All figures are live formulas. Scores use the strict missing-data rule (Unknown / blank / Not applicable = NA, never 0). Metric set v2: E1, E2 (038 + coded 938), C1, C2, C3 (019), G1, G2. Component = 25% of overall OISI.
A4: 1. Headline
A5: Repositories in dataset | B5: =COUNTA(Scoring!$A$2:$A$113) -> 112
A6: Primary completeness threshold | B6: =Parameters!$C$56 -> 0.6
A7: Repositories with a score | B7: =COUNT(Scoring!$S$2:$S$113) -> 87
A8: Share scored | B8: =B7/B5 -> 0.77678571
A9: Median score | B9: =IFERROR(MEDIAN(Scoring!$S$2:$S$113),"n/a") -> 78.225806
A10: Mean score | B10: =IFERROR(AVERAGE(Scoring!$S$2:$S$113),"n/a") -> 75.90664
A11: 25th percentile | B11: =IFERROR(QUARTILE(Scoring!$S$2:$S$113,1),"n/a") -> 62.683333
A12: 75th percentile | B12: =IFERROR(QUARTILE(Scoring!$S$2:$S$113,3),"n/a") -> 88.75
A13: Minimum | B13: =IFERROR(MIN(Scoring!$S$2:$S$113),"n/a") -> 37.705882
A14: Maximum | B14: =IFERROR(MAX(Scoring!$S$2:$S$113),"n/a") -> 100
A15: Std. deviation | B15: =IFERROR(STDEV(Scoring!$S$2:$S$113),"n/a") -> 16.223826
A16: Contribution to OISI (points) at median score | B16: =IFERROR(B9*Parameters!$C$21,"n/a") -> 19.556452
A17: Reportable repos (≥ 85% of weight scored) | B17: =COUNTIF(Scoring!$V$2:$V$113,"Reportable") -> 51
A19: 2. Metric coverage and level
A20: Metric | B20: Weight | C20: Scored (n) | D20: NA (n) | E20: NA % | F20: Mean (scored) | G20: Share at 1.00
A21: E1 Engagement status (037) | B21: =Parameters!$E$6 -> 0.08 | C21: =COUNT(Scoring!$D$2:$D$113) -> 111 | D21: =$B$5-C21 -> 1 | E21: =D21/$B$5 -> 0.0089285714 | F21: =IFERROR(AVERAGE(Scoring!$D$2:$D$113),"n/a") -> 0.91297297 | G21: =IFERROR(COUNTIF(Scoring!$D$2:$D$113,1)/C21,"n/a") -> 0.84684685
A22: E2 Engagement breadth (038 + coded 938) | B22: =Parameters!$E$7 -> 0.22 | C22: =COUNT(Scoring!$E$2:$E$113) -> 73 | D22: =$B$5-C22 -> 39 | E22: =D22/$B$5 -> 0.34821429 | F22: =IFERROR(AVERAGE(Scoring!$E$2:$E$113),"n/a") -> 0.65582192 | G22: =IFERROR(COUNTIF(Scoring!$E$2:$E$113,1)/C22,"n/a") -> 0.32876712
A23: C1 Contribution routes (040) | B23: =Parameters!$E$8 -> 0.18 | C23: =COUNT(Scoring!$F$2:$F$113) -> 73 | D23: =$B$5-C23 -> 39 | E23: =D23/$B$5 -> 0.34821429 | F23: =IFERROR(AVERAGE(Scoring!$F$2:$F$113),"n/a") -> 0.64611872 | G23: =IFERROR(COUNTIF(Scoring!$F$2:$F$113,1)/C23,"n/a") -> 0.21917808
A24: C2 Contribution guidance (041) | B24: =Parameters!$E$9 -> 0.12 | C24: =COUNT(Scoring!$G$2:$G$113) -> 75 | D24: =$B$5-C24 -> 37 | E24: =D24/$B$5 -> 0.33035714 | F24: =IFERROR(AVERAGE(Scoring!$G$2:$G$113),"n/a") -> 0.66666667 | G24: =IFERROR(COUNTIF(Scoring!$G$2:$G$113,1)/C24,"n/a") -> 0.33333333
A25: C3 Open contribution infrastructure (019) | B25: =Parameters!$E$10 -> 0.05 | C25: =COUNT(Scoring!$H$2:$H$113) -> 108 | D25: =$B$5-C25 -> 4 | E25: =D25/$B$5 -> 0.035714286 | F25: =IFERROR(AVERAGE(Scoring!$H$2:$H$113),"n/a") -> 0.97685185 | G25: =IFERROR(COUNTIF(Scoring!$H$2:$H$113,1)/C25,"n/a") -> 0.9537037
A26: G1 Code of Conduct (042) | B26: =Parameters!$E$11 -> 0.15 | C26: =COUNT(Scoring!$I$2:$I$113) -> 105 | D26: =$B$5-C26 -> 7 | E26: =D26/$B$5 -> 0.0625 | F26: =IFERROR(AVERAGE(Scoring!$I$2:$I$113),"n/a") -> 0.76152381 | G26: =IFERROR(COUNTIF(Scoring!$I$2:$I$113,1)/C26,"n/a") -> 0.64761905
A27: G2 Community governance (048) | B27: =Parameters!$E$12 -> 0.2 | C27: =COUNT(Scoring!$J$2:$J$113) -> 87 | D27: =$B$5-C27 -> 25 | E27: =D27/$B$5 -> 0.22321429 | F27: =IFERROR(AVERAGE(Scoring!$J$2:$J$113),"n/a") -> 0.79885057 | G27: =IFERROR(COUNTIF(Scoring!$J$2:$J$113,1)/C27,"n/a") -> 0.59770115
A30: 3. Sub-component medians (0–100, scored repos only)
A31: Engagement & Participation (30%) | B31: =IFERROR(MEDIAN(Scoring!$K$2:$K$113),"n/a") -> 81.666667
A32: Contribution Mechanisms (35%) | B32: =IFERROR(MEDIAN(Scoring!$L$2:$L$113),"n/a") -> 74.285714
A33: Community Norms & Governance (35%) | B33: =IFERROR(MEDIAN(Scoring!$M$2:$M$113),"n/a") -> 78.642857
A36: 4. Score distribution
A37: Band | B37: Repos
A38: 0 – <25 | B38: =COUNTIFS(Scoring!$S$2:$S$113,">=0",Scoring!$S$2:$S$113,"<25") -> 0
A39: 25 – <50 | B39: =COUNTIFS(Scoring!$S$2:$S$113,">=25",Scoring!$S$2:$S$113,"<50") -> 6
A40: 50 – <75 | B40: =COUNTIFS(Scoring!$S$2:$S$113,">=50",Scoring!$S$2:$S$113,"<75") -> 33
A41: 75 – 100 | B41: =COUNTIFS(Scoring!$S$2:$S$113,">=75",Scoring!$S$2:$S$113,"<100.0001") -> 48
A42: Not scored (below completeness threshold) | B42: =$B$5-$B$7 -> 25
A45: 5. Completeness bands
A46: High | B46: =COUNTIF(Scoring!$X$2:$X$113,"High") -> 51 | C46: High ≥ 85% of weight scored; Medium ≥ primary threshold; Low below it (not scored).
A47: Medium | B47: =COUNTIF(Scoring!$X$2:$X$113,"Medium") -> 36
A48: Low | B48: =COUNTIF(Scoring!$X$2:$X$113,"Low") -> 25
...

Sheet Scoring
A1: Service | B1: Provider | C1: Solution category | D1: E1 Engagement status (037) | E1: E2 Engagement breadth (038 + coded 938) | F1: C1 Contribution routes (040) | G1: C2 Contribution guidance (041) | H1: C3 Open contribution infrastructure (019) | I1: G1 Code of Conduct (042) | J1: G2 Governance (048) | K1: Engagement & Participation (0–100) | L1: Contribution Mechanisms (0–100) | M1: Norms & Governance (0–100) | N1: Weight scored (share) | O1: Weighted sum | P1: Metrics scored (of 7) | Q1: Sub-components covered (of 3) | R1: Eligible for score? | S1: COMMUNITY ENGAGEMENT SCORE (0–100) | T1: Lower bound (missing metrics = 0) | U1: Upper bound (missing metrics = 1) | V1: Result status | W1: Rank (all scored) | X1: Completeness band | Y1: Data-quality flags | Z1: Rank key – reportable only (helper) | AA1: Rank – reportable only (helper)
A2: =Data!$A2 -> 2i2c | B2: =Data!$B2 -> Code for Science and Society | C2: =Data!$E2 -> Authoring tool | D2: =IF(Verification!C2="",Calc!B2,Verification!C2) -> 1 | E2: =IF(Verification!D2="",Calc!D2,Verification!D2) -> NA | F2: =IF(Verification!E2="",Calc!G2,Verification!E2) -> NA | G2: =IF(Verification!F2="",Calc!I2,Verification!F2) -> NA | H2: =IF(Verification!G2="",Calc!E2,Verification!G2) -> 1 | I2: =IF(Verification!H2="",Calc!J2,Verification!H2) -> 1 | J2: =IF(Verification!I2="",Calc!K2,Verification!I2) -> NA | K2: =IF(COUNT(D2:E2)=0,"NA",(IF(ISNUMBER(D2),D2*Parameters!$E$6,0)+IF(ISNUMBER(E2),E2*Parameters!$E$7,0))/(IF(ISNUMBER(D2),Parameters!$E$6,0)+IF(ISNUMBER(E2),Parameters!$E$7,0))*100) -> 100 | L2: =IF(COUNT(F2:H2)=0,"NA",(IF(ISNUMBER(F2),F2*Parameters!$E$8,0)+IF(ISNUMBER(G2),G2*Parameters!$E$9,0)+IF(ISNUMBER(H2),H2*Parameters!$E$10,0))/(IF(ISNUMBER(F2),Parameters!$E$8,0)+IF(ISNUMBER(G2),Parameters!$E$9,0)+IF(ISNUMBER(H2),Parameters!$E$10,0))*100) -> 100 | M2: =IF(COUNT(I2:J2)=0,"NA",(IF(ISNUMBER(I2),I2*Parameters!$E$11,0)+IF(ISNUMBER(J2),J2*Parameters!$E$12,0))/(IF(ISNUMBER(I2),Parameters!$E$11,0)+IF(ISNUMBER(J2),Parameters!$E$12,0))*100) -> 100 | N2: =IF(ISNUMBER(D2),Parameters!$E$6,0)+IF(ISNUMBER(E2),Parameters!$E$7,0)+IF(ISNUMBER(F2),Parameters!$E$8,0)+IF(ISNUMBER(G2),Parameters!$E$9,0)+IF(ISNUMBER(H2),Parameters!$E$10,0)+IF(ISNUMBER(I2),Parameters!$E$11,0)+IF(ISNUMBER(J2),Parameters!$E$12,0) -> 0.28 | O2: =IF(ISNUMBER(D2),D2*Parameters!$E$6,0)+IF(ISNUMBER(E2),E2*Parameters!$E$7,0)+IF(ISNUMBER(F2),F2*Parameters!$E$8,0)+IF(ISNUMBER(G2),G2*Parameters!$E$9,0)+IF(ISNUMBER(H2),H2*Parameters!$E$10,0)+IF(ISNUMBER(I2),I2*Parameters!$E$11,0)+IF(ISNUMBER(J2),J2*Parameters!$E$12,0) -> 0.28 | P2: =COUNT(D2:J2) -> 3 | Q2: =(COUNT(D2:E2)>0)+(COUNT(F2:H2)>0)+(COUNT(I2:J2)>0) -> 3 | R2: =IF(AND(N2>=Parameters!$C$56,Q2>=Parameters!$C$59),"Yes","No") -> No | S2: =IF(R2="Yes",O2/N2*100,"NA") -> NA | T2: =IF(R2="Yes",O2/Parameters!$E$13*100,"NA") -> NA | U2: =IF(R2="Yes",(O2+(Parameters!$E$13-N2))/Parameters!$E$13*100,"NA") -> NA | V2: =IF(R2<>"Yes","Not scored",IF(N2>=Parameters!$C$60,"Reportable","Provisional")) -> Not scored | W2: =IF(ISNUMBER(S2),RANK(S2,$S$2:$S$113,0),"NA") -> NA | X2: =IF(N2>=Parameters!$C$60,"High",IF(N2>=Parameters!$C$56,"Medium","Low")) -> Low | Y2: =Calc!T2 -> 1 | Z2: =IF(V2="Reportable",S2-ROW()*0.000000001,"") | AA2: =IF(ISNUMBER(Z2),RANK(Z2,$Z$2:$Z$113,0),"NA") -> NA
A3: =Data!$A3 -> Academic Preservation Trust (APTrust) | B3: =Data!$B3 -> Academic Preservation Trust (APTrust) | C3: =Data!$E3 -> Digital preservation service | D3: =IF(Verification!C3="",Calc!B3,Verification!C3) -> 1 | E3: =IF(Verification!D3="",Calc!D3,Verification!D3) -> 1 | F3: =IF(Verification!E3="",Calc!G3,Verification!E3) -> 1 | G3: =IF(Verification!F3="",Calc!I3,Verification!F3) -> 0.5 | H3: =IF(Verification!G3="",Calc!E3,Verification!G3) -> 1 | I3: =IF(Verification!H3="",Calc!J3,Verification!H3) -> 1 | J3: =IF(Verification!I3="",Calc!K3,Verification!I3) -> 1 | K3: =IF(COUNT(D3:E3)=0,"NA",(IF(ISNUMBER(D3),D3*Parameters!$E$6,0)+IF(ISNUMBER(E3),E3*Parameters!$E$7,0))/(IF(ISNUMBER(D3),Parameters!$E$6,0)+IF(ISNUMBER(E3),Parameters!$E$7,0))*100) -> 100 | L3: =IF(COUNT(F3:H3)=0,"NA",(IF(ISNUMBER(F3),F3*Parameters!$E$8,0)+IF(ISNUMBER(G3),G3*Parameters!$E$9,0)+IF(ISNUMBER(H3),H3*Parameters!$E$10,0))/(IF(ISNUMBER(F3),Parameters!$E$8,0)+IF(ISNUMBER(G3),Parameters!$E$9,0)+IF(ISNUMBER(H3),Parameters!$E$10,0))*100) -> 82.857143 | M3: =IF(COUNT(I3:J3)=0,"NA",(IF(ISNUMBER(I3),I3*Parameters!$E$11,0)+IF(ISNUMBER(J3),J3*Parameters!$E$12,0))/(IF(ISNUMBER(I3),Parameters!$E$11,0)+IF(ISNUMBER(J3),Parameters!$E$12,0))*100) -> 100 | N3: =IF(ISNUMBER(D3),Parameters!$E$6,0)+IF(ISNUMBER(E3),Parameters!$E$7,0)+IF(ISNUMBER(F3),Parameters!$E$8,0)+IF(ISNUMBER(G3),Parameters!$E$9,0)+IF(ISNUMBER(H3),Parameters!$E$10,0)+IF(ISNUMBER(I3),Parameters!$E$11,0)+IF(ISNUMBER(J3),Parameters!$E$12,0) -> 1 | O3: =IF(ISNUMBER(D3),D3*Parameters!$E$6,0)+IF(ISNUMBER(E3),E3*Parameters!$E$7,0)+IF(ISNUMBER(F3),F3*Parameters!$E$8,0)+IF(ISNUMBER(G3),G3*Parameters!$E$9,0)+IF(ISNUMBER(H3),H3*Parameters!$E$10,0)+IF(ISNUMBER(I3),I3*Parameters!$E$11,0)+IF(ISNUMBER(J3),J3*Parameters!$E$12,0) -> 0.94 | P3: =COUNT(D3:J3) -> 7 | Q3: =(COUNT(D3:E3)>0)+(COUNT(F3:H3)>0)+(COUNT(I3:J3)>0) -> 3 | R3: =IF(AND(N3>=Parameters!$C$56,Q3>=Parameters!$C$59),"Yes","No") -> Yes | S3: =IF(R3="Yes",O3/N3*100,"NA") -> 94 | T3: =IF(R3="Yes",O3/Parameters!$E$13*100,"NA") -> 94 | U3: =IF(R3="Yes",(O3+(Parameters!$E$13-N3))/Parameters!$E$13*100,"NA") -> 94 | V3: =IF(R3<>"Yes","Not scored",IF(N3>=Parameters!$C$60,"Reportable","Provisional")) -> Reportable | W3: =IF(ISNUMBER(S3),RANK(S3,$S$2:$S$113,0),"NA") -> 13 | X3: =IF(N3>=Parameters!$C$60,"High",IF(N3>=Parameters!$C$56,"Medium","Low")) -> High | Y3: =Calc!T3 -> 0 | Z3: =IF(V3="Reportable",S3-ROW()*0.000000001,"") -> 94 | AA3: =IF(ISNUMBER(Z3),RANK(Z3,$Z$2:$Z$113,0),"NA") -> 5
A4: =Data!$A4 -> AfricArXiv | B4: =Data!$B4 -> UbuntuNet Alliance | C4: =Data!$E4 -> Repository service | D4: =IF(Verification!C4="",Calc!B4,Verification!C4) -> 0.33 | E4: =IF(Verification!D4="",Calc!D4,Verification!D4) -> NA | F4: =IF(Verification!E4="",Calc!G4,Verification!E4) -> NA | G4: =IF(Verification!F4="",Calc!I4,Verification!F4) -> NA | H4: =IF(Verification!G4="",Calc!E4,Verification!G4) -> NA | I4: =IF(Verification!H4="",Calc!J4,Verification!H4) -> 1 | J4: =IF(Verification!I4="",Calc!K4,Verification!I4) -> 0.5 | K4: =IF(COUNT(D4:E4)=0,"NA",(IF(ISNUMBER(D4),D4*Parameters!$E$6,0)+IF(ISNUMBER(E4),E4*Parameters!$E$7,0))/(IF(ISNUMBER(D4),Parameters!$E$6,0)+IF(ISNUMBER(E4),Parameters!$E$7,0))*100) -> 33 | L4: =IF(COUNT(F4:H4)=0,"NA",(IF(ISNUMBER(F4),F4*Parameters!$E$8,0)+IF(ISNUMBER(G4),G4*Parameters!$E$9,0)+IF(ISNUMBER(H4),H4*Parameters!$E$10,0))/(IF(ISNUMBER(F4),Parameters!$E$8,0)+IF(ISNUMBER(G4),Parameters!$E$9,0)+IF(ISNUMBER(H4),Parameters!$E$10,0))*100) -> NA | M4: =IF(COUNT(I4:J4)=0,"NA",(IF(ISNUMBER(I4),I4*Parameters!$E$11,0)+IF(ISNUMBER(J4),J4*Parameters!$E$12,0))/(IF(ISNUMBER(I4),Parameters!$E$11,0)+IF(ISNUMBER(J4),Parameters!$E$12,0))*100) -> 71.428571 | N4: =IF(ISNUMBER(D4),Parameters!$E$6,0)+IF(ISNUMBER(E4),Parameters!$E$7,0)+IF(ISNUMBER(F4),Parameters!$E$8,0)+IF(ISNUMBER(G4),Parameters!$E$9,0)+IF(ISNUMBER(H4),Parameters!$E$10,0)+IF(ISNUMBER(I4),Parameters!$E$11,0)+IF(ISNUMBER(J4),Parameters!$E$12,0) -> 0.43 | O4: =IF(ISNUMBER(D4),D4*Parameters!$E$6,0)+IF(ISNUMBER(E4),E4*Parameters!$E$7,0)+IF(ISNUMBER(F4),F4*Parameters!$E$8,0)+IF(ISNUMBER(G4),G4*Parameters!$E$9,0)+IF(ISNUMBER(H4),H4*Parameters!$E$10,0)+IF(ISNUMBER(I4),I4*Parameters!$E$11,0)+IF(ISNUMBER(J4),J4*Parameters!$E$12,0) -> 0.2764 | P4: =COUNT(D4:J4) -> 3 | Q4: =(COUNT(D4:E4)>0)+(COUNT(F4:H4)>0)+(COUNT(I4:J4)>0) -> 2 | R4: =IF(AND(N4>=Parameters!$C$56,Q4>=Parameters!$C$59),"Yes","No") -> No | S4: =IF(R4="Yes",O4/N4*100,"NA") -> NA | T4: =IF(R4="Yes",O4/Parameters!$E$13*100,"NA") -> NA | U4: =IF(R4="Yes",(O4+(Parameters!$E$13-N4))/Parameters!$E$13*100,"NA") -> NA | V4: =IF(R4<>"Yes","Not scored",IF(N4>=Parameters!$C$60,"Reportable","Provisional")) -> Not scored | W4: =IF(ISNUMBER(S4),RANK(S4,$S$2:$S$113,0),"NA") -> NA | X4: =IF(N4>=Parameters!$C$60,"High",IF(N4>=Parameters!$C$56,"Medium","Low")) -> Low | Y4: =Calc!T4 -> 1 | Z4: =IF(V4="Reportable",S4-ROW()*0.000000001,"") | AA4: =IF(ISNUMBER(Z4),RANK(Z4,$Z$2:$Z$113,0),"NA") -> NA
A5: =Data!$A5 -> Arches Heritage Data Management Platform | B5: =Data!$B5 -> Getty Conservation Institute (GCI) | C5: =Data!$E5 -> Data management planning tool or service | D5: =IF(Verification!C5="",Calc!B5,Verification!C5) -> 1 | E5: =IF(Verification!D5="",Calc!D5,Verification!D5) -> NA | F5: =IF(Verification!E5="",Calc!G5,Verification!E5) -> NA | G5: =IF(Verification!F5="",Calc!I5,Verification!F5) -> 1 | H5: =IF(Verification!G5="",Calc!E5,Verification!G5) -> 1 | I5: =IF(Verification!H5="",Calc!J5,Verification!H5) -> 1 | J5: =IF(Verification!I5="",Calc!K5,Verification!I5) -> 1 | K5: =IF(COUNT(D5:E5)=0,"NA",(IF(ISNUMBER(D5),D5*Parameters!$E$6,0)+IF(ISNUMBER(E5),E5*Parameters!$E$7,0))/(IF(ISNUMBER(D5),Parameters!$E$6,0)+IF(ISNUMBER(E5),Parameters!$E$7,0))*100) -> 100 | L5: =IF(COUNT(F5:H5)=0,"NA",(IF(ISNUMBER(F5),F5*Parameters!$E$8,0)+IF(ISNUMBER(G5),G5*Parameters!$E$9,0)+IF(ISNUMBER(H5),H5*Parameters!$E$10,0))/(IF(ISNUMBER(F5),Parameters!$E$8,0)+IF(ISNUMBER(G5),Parameters!$E$9,0)+IF(ISNUMBER(H5),Parameters!$E$10,0))*100) -> 100 | M5: =IF(COUNT(I5:J5)=0,"NA",(IF(ISNUMBER(I5),I5*Parameters!$E$11,0)+IF(ISNUMBER(J5),J5*Parameters!$E$12,0))/(IF(ISNUMBER(I5),Parameters!$E$11,0)+IF(ISNUMBER(J5),Parameters!$E$12,0))*100) -> 100 | N5: =IF(ISNUMBER(D5),Parameters!$E$6,0)+IF(ISNUMBER(E5),Parameters!$E$7,0)+IF(ISNUMBER(F5),Parameters!$E$8,0)+IF(ISNUMBER(G5),Parameters!$E$9,0)+IF(ISNUMBER(H5),Parameters!$E$10,0)+IF(ISNUMBER(I5),Parameters!$E$11,0)+IF(ISNUMBER(J5),Parameters!$E$12,0) -> 0.6 | O5: =IF(ISNUMBER(D5),D5*Parameters!$E$6,0)+IF(ISNUMBER(E5),E5*Parameters!$E$7,0)+IF(ISNUMBER(F5),F5*Parameters!$E$8,0)+IF(ISNUMBER(G5),G5*Parameters!$E$9,0)+IF(ISNUMBER(H5),H5*Parameters!$E$10,0)+IF(ISNUMBER(I5),I5*Parameters!$E$11,0)+IF(ISNUMBER(J5),J5*Parameters!$E$12,0) -> 0.6 | P5: =COUNT(D5:J5) -> 5 | Q5: =(COUNT(D5:E5)>0)+(COUNT(F5:H5)>0)+(COUNT(I5:J5)>0) -> 3 | R5: =IF(AND(N5>=Parameters!$C$56,Q5>=Parameters!$C$59),"Yes","No") -> Yes | S5: =IF(R5="Yes",O5/N5*100,"NA") -> 100 | T5: =IF(R5="Yes",O5/Parameters!$E$13*100,"NA") -> 60 | U5: =IF(R5="Yes",(O5+(Parameters!$E$13-N5))/Parameters!$E$13*100,"NA") -> 100 | V5: =IF(R5<>"Yes","Not scored",IF(N5>=Parameters!$C$60,"Reportable","Provisional")) -> Provisional | W5: =IF(ISNUMBER(S5),RANK(S5,$S$2:$S$113,0),"NA") -> 1 | X5: =IF(N5>=Parameters!$C$60,"High",IF(N5>=Parameters!$C$56,"Medium","Low")) -> Medium | Y5: =Calc!T5 -> 1 | Z5: =IF(V5="Reportable",S5-ROW()*0.000000001,"") | AA5: =IF(ISNUMBER(Z5),RANK(Z5,$Z$2:$Z$113,0),"NA") -> NA
A6: =Data!$A6 -> Archipelago Commons | B6: =Data!$B6 -> Metropolitan New York Library Council | C6: =Data!$E6 -> Digital library, collection or exhibit platform | Repository software | D6: =IF(Verification!C6="",Calc!B6,Verification!C6) -> 1 | E6: =IF(Verification!D6="",Calc!D6,Verification!D6) -> 0.875 | F6: =IF(Verification!E6="",Calc!G6,Verification!E6) -> 0.5 | G6: =IF(Verification!F6="",Calc!I6,Verification!F6) -> 0.5 | H6: =IF(Verification!G6="",Calc!E6,Verification!G6) -> 1 | I6: =IF(Verification!H6="",Calc!J6,Verification!H6) -> 1 | J6: =IF(Verification!I6="",Calc!K6,Verification!I6) -> 1 | K6: =IF(COUNT(D6:E6)=0,"NA",(IF(ISNUMBER(D6),D6*Parameters!$E$6,0)+IF(ISNUMBER(E6),E6*Parameters!$E$7,0))/(IF(ISNUMBER(D6),Parameters!$E$6,0)+IF(ISNUMBER(E6),Parameters!$E$7,0))*100) -> 90.833333 | L6: =IF(COUNT(F6:H6)=0,"NA",(IF(ISNUMBER(F6),F6*Parameters!$E$8,0)+IF(ISNUMBER(G6),G6*Parameters!$E$9,0)+IF(ISNUMBER(H6),H6*Parameters!$E$10,0))/(IF(ISNUMBER(F6),Parameters!$E$8,0)+IF(ISNUMBER(G6),Parameters!$E$9,0)+IF(ISNUMBER(H6),Parameters!$E$10,0))*100) -> 57.142857 | M6: =IF(COUNT(I6:J6)=0,"NA",(IF(ISNUMBER(I6),I6*Parameters!$E$11,0)+IF(ISNUMBER(J6),J6*Parameters!$E$12,0))/(IF(ISNUMBER(I6),Parameters!$E$11,0)+IF(ISNUMBER(J6),Parameters!$E$12,0))*100) -> 100 | N6: =IF(ISNUMBER(D6),Parameters!$E$6,0)+IF(ISNUMBER(E6),Parameters!$E$7,0)+IF(ISNUMBER(F6),Parameters!$E$8,0)+IF(ISNUMBER(G6),Parameters!$E$9,0)+IF(ISNUMBER(H6),Parameters!$E$10,0)+IF(ISNUMBER(I6),Parameters!$E$11,0)+IF(ISNUMBER(J6),Parameters!$E$12,0) -> 1 | O6: =IF(ISNUMBER(D6),D6*Parameters!$E$6,0)+IF(ISNUMBER(E6),E6*Parameters!$E$7,0)+IF(ISNUMBER(F6),F6*Parameters!$E$8,0)+IF(ISNUMBER(G6),G6*Parameters!$E$9,0)+IF(ISNUMBER(H6),H6*Parameters!$E$10,0)+IF(ISNUMBER(I6),I6*Parameters!$E$11,0)+IF(ISNUMBER(J6),J6*Parameters!$E$12,0) -> 0.8225 | P6: =COUNT(D6:J6) -> 7 | Q6: =(COUNT(D6:E6)>0)+(COUNT(F6:H6)>0)+(COUNT(I6:J6)>0) -> 3 | R6: =IF(AND(N6>=Parameters!$C$56,Q6>=Parameters!$C$59),"Yes","No") -> Yes | S6: =IF(R6="Yes",O6/N6*100,"NA") -> 82.25 | T6: =IF(R6="Yes",O6/Parameters!$E$13*100,"NA") -> 82.25 | U6: =IF(R6="Yes",(O6+(Parameters!$E$13-N6))/Parameters!$E$13*100,"NA") -> 82.25 | V6: =IF(R6<>"Yes","Not scored",IF(N6>=Parameters!$C$60,"Reportable","Provisional")) -> Reportable | W6: =IF(ISNUMBER(S6),RANK(S6,$S$2:$S$113,0),"NA") -> 37 | X6: =IF(N6>=Parameters!$C$60,"High",IF(N6>=Parameters!$C$56,"Medium","Low")) -> High | Y6: =Calc!T6 -> 0 | Z6: =IF(V6="Reportable",S6-ROW()*0.000000001,"") -> 82.25 | AA6: =IF(ISNUMBER(Z6),RANK(Z6,$Z$2:$Z$113,0),"NA") -> 25
A7: =Data!$A7 -> Archival Resource Key | B7: =Data!$B7 -> ARK Alliance | C7: =Data!$E7 -> Standard, specification or protocol | D7: =IF(Verification!C7="",Calc!B7,Verification!C7) -> 1 | E7: =IF(Verification!D7="",Calc!D7,Verification!D7) -> NA | F7: =IF(Verification!E7="",Calc!G7,Verification!E7) -> 0.83333333 | G7: =IF(Verification!F7="",Calc!I7,Verification!F7) -> 0.5 | H7: =IF(Verification!G7="",Calc!E7,Verification!G7) -> 1 | I7: =IF(Verification!H7="",Calc!J7,Verification!H7) -> 1 | J7: =IF(Verification!I7="",Calc!K7,Verification!I7) -> 0.5 | K7: =IF(COUNT(D7:E7)=0,"NA",(IF(ISNUMBER(D7),D7*Parameters!$E$6,0)+IF(ISNUMBER(E7),E7*Parameters!$E$7,0))/(IF(ISNUMBER(D7),Parameters!$E$6,0)+IF(ISNUMBER(E7),Parameters!$E$7,0))*100) -> 100 | L7: =IF(COUNT(F7:H7)=0,"NA",(IF(ISNUMBER(F7),F7*Parameters!$E$8,0)+IF(ISNUMBER(G7),G7*Parameters!$E$9,0)+IF(ISNUMBER(H7),H7*Parameters!$E$10,0))/(IF(ISNUMBER(F7),Parameters!$E$8,0)+IF(ISNUMBER(G7),Parameters!$E$9,0)+IF(ISNUMBER(H7),Parameters!$E$10,0))*100) -> 74.285714 | M7: =IF(COUNT(I7:J7)=0,"NA",(IF(ISNUMBER(I7),I7*Parameters!$E$11,0)+IF(ISNUMBER(J7),J7*Parameters!$E$12,0))/(IF(ISNUMBER(I7),Parameters!$E$11,0)+IF(ISNUMBER(J7),Parameters!$E$12,0))*100) -> 71.428571 | N7: =IF(ISNUMBER(D7),Parameters!$E$6,0)+IF(ISNUMBER(E7),Parameters!$E$7,0)+IF(ISNUMBER(F7),Parameters!$E$8,0)+IF(ISNUMBER(G7),Parameters!$E$9,0)+IF(ISNUMBER(H7),Parameters!$E$10,0)+IF(ISNUMBER(I7),Parameters!$E$11,0)+IF(ISNUMBER(J7),Parameters!$E$12,0) -> 0.78 | O7: =IF(ISNUMBER(D7),D7*Parameters!$E$6,0)+IF(ISNUMBER(E7),E7*Parameters!$E$7,0)+IF(ISNUMBER(F7),F7*Parameters!$E$8,0)+IF(ISNUMBER(G7),G7*Parameters!$E$9,0)+IF(ISNUMBER(H7),H7*Parameters!$E$10,0)+IF(ISNUMBER(I7),I7*Parameters!$E$11,0)+IF(ISNUMBER(J7),J7*Parameters!$E$12,0) -> 0.59 | P7: =COUNT(D7:J7) -> 6 | Q7: =(COUNT(D7:E7)>0)+(COUNT(F7:H7)>0)+(COUNT(I7:J7)>0) -> 3 | R7: =IF(AND(N7>=Parameters!$C$56,Q7>=Parameters!$C$59),"Yes","No") -> Yes | S7: =IF(R7="Yes",O7/N7*100,"NA") -> 75.641026 | T7: =IF(R7="Yes",O7/Parameters!$E$13*100,"NA") -> 59 | U7: =IF(R7="Yes",(O7+(Parameters!$E$13-N7))/Parameters!$E$13*100,"NA") -> 81 | V7: =IF(R7<>"Yes","Not scored",IF(N7>=Parameters!$C$60,"Reportable","Provisional")) -> Provisional | W7: =IF(ISNUMBER(S7),RANK(S7,$S$2:$S$113,0),"NA") -> 48 | X7: =IF(N7>=Parameters!$C$60,"High",IF(N7>=Parameters!$C$56,"Medium","Low")) -> Medium | Y7: =Calc!T7 -> 1 | Z7: =IF(V7="Reportable",S7-ROW()*0.000000001,"") | AA7: =IF(ISNUMBER(Z7),RANK(Z7,$Z$2:$Z$113,0),"NA") -> NA
A8: =Data!$A8 -> Archivematica | B8: =Data!$B8 -> Artefactual | C8: =Data!$E8 -> Digital preservation system | D8: =IF(Verification!C8="",Calc!B8,Verification!C8) -> 1 | E8: =IF(Verification!D8="",Calc!D8,Verification!D8) -> NA | F8: =IF(Verification!E8="",Calc!G8,Verification!E8) -> NA | G8: =IF(Verification!F8="",Calc!I8,Verification!F8) -> 1 | H8: =IF(Verification!G8="",Calc!E8,Verification!G8) -> 1 | I8: =IF(Verification!H8="",Calc!J8,Verification!H8) -> NA | J8: =IF(Verification!I8="",Calc!K8,Verification!I8) -> NA | K8: =IF(COUNT(D8:E8)=0,"NA",(IF(ISNUMBER(D8),D8*Parameters!$E$6,0)+IF(ISNUMBER(E8),E8*Parameters!$E$7,0))/(IF(ISNUMBER(D8),Parameters!$E$6,0)+IF(ISNUMBER(E8),Parameters!$E$7,0))*100) -> 100 | L8: =IF(COUNT(F8:H8)=0,"NA",(IF(ISNUMBER(F8),F8*Parameters!$E$8,0)+IF(ISNUMBER(G8),G8*Parameters!$E$9,0)+IF(ISNUMBER(H8),H8*Parameters!$E$10,0))/(IF(ISNUMBER(F8),Parameters!$E$8,0)+IF(ISNUMBER(G8),Parameters!$E$9,0)+IF(ISNUMBER(H8),Parameters!$E$10,0))*100) -> 100 | M8: =IF(COUNT(I8:J8)=0,"NA",(IF(ISNUMBER(I8),I8*Parameters!$E$11,0)+IF(ISNUMBER(J8),J8*Parameters!$E$12,0))/(IF(ISNUMBER(I8),Parameters!$E$11,0)+IF(ISNUMBER(J8),Parameters!$E$12,0))*100) -> NA | N8: =IF(ISNUMBER(D8),Parameters!$E$6,0)+IF(ISNUMBER(E8),Parameters!$E$7,0)+IF(ISNUMBER(F8),Parameters!$E$8,0)+IF(ISNUMBER(G8),Parameters!$E$9,0)+IF(ISNUMBER(H8),Parameters!$E$10,0)+IF(ISNUMBER(I8),Parameters!$E$11,0)+IF(ISNUMBER(J8),Parameters!$E$12,0) -> 0.25 | O8: =IF(ISNUMBER(D8),D8*Parameters!$E$6,0)+IF(ISNUMBER(E8),E8*Parameters!$E$7,0)+IF(ISNUMBER(F8),F8*Parameters!$E$8,0)+IF(ISNUMBER(G8),G8*Parameters!$E$9,0)+IF(ISNUMBER(H8),H8*Parameters!$E$10,0)+IF(ISNUMBER(I8),I8*Parameters!$E$11,0)+IF(ISNUMBER(J8),J8*Parameters!$E$12,0) -> 0.25 | P8: =COUNT(D8:J8) -> 3 | Q8: =(COUNT(D8:E8)>0)+(COUNT(F8:H8)>0)+(COUNT(I8:J8)>0) -> 2 | R8: =IF(AND(N8>=Parameters!$C$56,Q8>=Parameters!$C$59),"Yes","No") -> No | S8: =IF(R8="Yes",O8/N8*100,"NA") -> NA | T8: =IF(R8="Yes",O8/Parameters!$E$13*100,"NA") -> NA | U8: =IF(R8="Yes",(O8+(Parameters!$E$13-N8))/Parameters!$E$13*100,"NA") -> NA | V8: =IF(R8<>"Yes","Not scored",IF(N8>=Parameters!$C$60,"Reportable","Provisional")) -> Not scored | W8: =IF(ISNUMBER(S8),RANK(S8,$S$2:$S$113,0),"NA") -> NA | X8: =IF(N8>=Parameters!$C$60,"High",IF(N8>=Parameters!$C$56,"Medium","Low")) -> Low | Y8: =Calc!T8 -> 2 | Z8: =IF(V8="Reportable",S8-ROW()*0.000000001,"") | AA8: =IF(ISNUMBER(Z8),RANK(Z8,$Z$2:$Z$113,0),"NA") -> NA
A9: =Data!$A9 -> ArchivesSpace | B9: =Data!$B9 -> ArchivesSpace | C9: =Data!$E9 -> Archive information management system | Discovery system | D9: =IF(Verification!C9="",Calc!B9,Verification!C9) -> 1 | E9: =IF(Verification!D9="",Calc!D9,Verification!D9) -> 1 | F9: =IF(Verification!E9="",Calc!G9,Verification!E9) -> NA | G9: =IF(Verification!F9="",Calc!I9,Verification!F9) -> 1 | H9: =IF(Verification!G9="",Calc!E9,Verification!G9) -> 1 | I9: =IF(Verification!H9="",Calc!J9,Verification!H9) -> 1 | J9: =IF(Verification!I9="",Calc!K9,Verification!I9) -> 1 | K9: =IF(COUNT(D9:E9)=0,"NA",(IF(ISNUMBER(D9),D9*Parameters!$E$6,0)+IF(ISNUMBER(E9),E9*Parameters!$E$7,0))/(IF(ISNUMBER(D9),Parameters!$E$6,0)+IF(ISNUMBER(E9),Parameters!$E$7,0))*100) -> 100 | L9: =IF(COUNT(F9:H9)=0,"NA",(IF(ISNUMBER(F9),F9*Parameters!$E$8,0)+IF(ISNUMBER(G9),G9*Parameters!$E$9,0)+IF(ISNUMBER(H9),H9*Parameters!$E$10,0))/(IF(ISNUMBER(F9),Parameters!$E$8,0)+IF(ISNUMBER(G9),Parameters!$E$9,0)+IF(ISNUMBER(H9),Parameters!$E$10,0))*100) -> 100 | M9: =IF(COUNT(I9:J9)=0,"NA",(IF(ISNUMBER(I9),I9*Parameters!$E$11,0)+IF(ISNUMBER(J9),J9*Parameters!$E$12,0))/(IF(ISNUMBER(I9),Parameters!$E$11,0)+IF(ISNUMBER(J9),Parameters!$E$12,0))*100) -> 100 | N9: =IF(ISNUMBER(D9),Parameters!$E$6,0)+IF(ISNUMBER(E9),Parameters!$E$7,0)+IF(ISNUMBER(F9),Parameters!$E$8,0)+IF(ISNUMBER(G9),Parameters!$E$9,0)+IF(ISNUMBER(H9),Parameters!$E$10,0)+IF(ISNUMBER(I9),Parameters!$E$11,0)+IF(ISNUMBER(J9),Parameters!$E$12,0) -> 0.82 | O9: =IF(ISNUMBER(D9),D9*Parameters!$E$6,0)+IF(ISNUMBER(E9),E9*Parameters!$E$7,0)+IF(ISNUMBER(F9),F9*Parameters!$E$8,0)+IF(ISNUMBER(G9),G9*Parameters!$E$9,0)+IF(ISNUMBER(H9),H9*Parameters!$E$10,0)+IF(ISNUMBER(I9),I9*Parameters!$E$11,0)+IF(ISNUMBER(J9),J9*Parameters!$E$12,0) -> 0.82 | P9: =COUNT(D9:J9) -> 6 | Q9: =(COUNT(D9:E9)>0)+(COUNT(F9:H9)>0)+(COUNT(I9:J9)>0) -> 3 | R9: =IF(AND(N9>=Parameters!$C$56,Q9>=Parameters!$C$59),"Yes","No") -> Yes | S9: =IF(R9="Yes",O9/N9*100,"NA") -> 100 | T9: =IF(R9="Yes",O9/Parameters!$E$13*100,"NA") -> 82 | U9: =IF(R9="Yes",(O9+(Parameters!$E$13-N9))/Parameters!$E$13*100,"NA") -> 100 | V9: =IF(R9<>"Yes","Not scored",IF(N9>=Parameters!$C$60,"Reportable","Provisional")) -> Provisional | W9: =IF(ISNUMBER(S9),RANK(S9,$S$2:$S$113,0),"NA") -> 1 | X9: =IF(N9>=Parameters!$C$60,"High",IF(N9>=Parameters!$C$56,"Medium","Low")) -> Medium | Y9: =Calc!T9 -> 0 | Z9: =IF(V9="Reportable",S9-ROW()*0.000000001,"") | AA9: =IF(ISNUMBER(Z9),RANK(Z9,$Z$2:$Z$113,0),"NA") -> NA
A10: =Data!$A10 -> ARGOS | B10: =Data!$B10 -> OpenAIRE | C10: =Data!$E10 -> Data management planning tool or service | D10: =IF(Verification!C10="",Calc!B10,Verification!C10) -> 1 | E10: =IF(Verification!D10="",Calc!D10,Verification!D10) -> 1 | F10: =IF(Verification!E10="",Calc!G10,Verification!E10) -> NA | G10: =IF(Verification!F10="",Calc!I10,Verification!F10) -> NA | H10: =IF(Verification!G10="",Calc!E10,Verification!G10) -> 1 | I10: =IF(Verification!H10="",Calc!J10,Verification!H10) -> 1 | J10: =IF(Verification!I10="",Calc!K10,Verification!I10) -> 1 | K10: =IF(COUNT(D10:E10)=0,"NA",(IF(ISNUMBER(D10),D10*Parameters!$E$6,0)+IF(ISNUMBER(E10),E10*Parameters!$E$7,0))/(IF(ISNUMBER(D10),Parameters!$E$6,0)+IF(ISNUMBER(E10),Parameters!$E$7,0))*100) -> 100 | L10: =IF(COUNT(F10:H10)=0,"NA",(IF(ISNUMBER(F10),F10*Parameters!$E$8,0)+IF(ISNUMBER(G10),G10*Parameters!$E$9,0)+IF(ISNUMBER(H10),H10*Parameters!$E$10,0))/(IF(ISNUMBER(F10),Parameters!$E$8,0)+IF(ISNUMBER(G10),Parameters!$E$9,0)+IF(ISNUMBER(H10),Parameters!$E$10,0))*100) -> 100 | M10: =IF(COUNT(I10:J10)=0,"NA",(IF(ISNUMBER(I10),I10*Parameters!$E$11,0)+IF(ISNUMBER(J10),J10*Parameters!$E$12,0))/(IF(ISNUMBER(I10),Parameters!$E$11,0)+IF(ISNUMBER(J10),Parameters!$E$12,0))*100) -> 100 | N10: =IF(ISNUMBER(D10),Parameters!$E$6,0)+IF(ISNUMBER(E10),Parameters!$E$7,0)+IF(ISNUMBER(F10),Parameters!$E$8,0)+IF(ISNUMBER(G10),Parameters!$E$9,0)+IF(ISNUMBER(H10),Parameters!$E$10,0)+IF(ISNUMBER(I10),Parameters!$E$11,0)+IF(ISNUMBER(J10),Parameters!$E$12,0) -> 0.7 | O10: =IF(ISNUMBER(D10),D10*Parameters!$E$6,0)+IF(ISNUMBER(E10),E10*Parameters!$E$7,0)+IF(ISNUMBER(F10),F10*Parameters!$E$8,0)+IF(ISNUMBER(G10),G10*Parameters!$E$9,0)+IF(ISNUMBER(H10),H10*Parameters!$E$10,0)+IF(ISNUMBER(I10),I10*Parameters!$E$11,0)+IF(ISNUMBER(J10),J10*Parameters!$E$12,0) -> 0.7 | P10: =COUNT(D10:J10) -> 5 | Q10: =(COUNT(D10:E10)>0)+(COUNT(F10:H10)>0)+(COUNT(I10:J10)>0) -> 3 | R10: =IF(AND(N10>=Parameters!$C$56,Q10>=Parameters!$C$59),"Yes","No") -> Yes | S10: =IF(R10="Yes",O10/N10*100,"NA") -> 100 | T10: =IF(R10="Yes",O10/Parameters!$E$13*100,"NA") -> 70 | U10: =IF(R10="Yes",(O10+(Parameters!$E$13-N10))/Parameters!$E$13*100,"NA") -> 100 | V10: =IF(R10<>"Yes","Not scored",IF(N10>=Parameters!$C$60,"Reportable","Provisional")) -> Provisional | W10: =IF(ISNUMBER(S10),RANK(S10,$S$2:$S$113,0),"NA") -> 1 | X10: =IF(N10>=Parameters!$C$60,"High",IF(N10>=Parameters!$C$56,"Medium","Low")) -> Medium | Y10: =Calc!T10 -> 0 | Z10: =IF(V10="Reportable",S10-ROW()*0.000000001,"") | AA10: =IF(ISNUMBER(Z10),RANK(Z10,$Z$2:$Z$113,0),"NA") -> NA
A11: =Data!$A11 -> arXiv | B11: =Data!$B11 -> Cornell University | C11: =Data!$E11 -> Repository service | D11: =IF(Verification!C11="",Calc!B11,Verification!C11) -> 1 | E11: =IF(Verification!D11="",Calc!D11,Verification!D11) -> 0.125 | F11: =IF(Verification!E11="",Calc!G11,Verification!E11) -> 0.5 | G11: =IF(Verification!F11="",Calc!I11,Verification!F11) -> 0.5 | H11: =IF(Verification!G11="",Calc!E11,Verification!G11) -> 1 | I11: =IF(Verification!H11="",Calc!J11,Verification!H11) -> 1 | J11: =IF(Verification!I11="",Calc!K11,Verification!I11) -> 1 | K11: =IF(COUNT(D11:E11)=0,"NA",(IF(ISNUMBER(D11),D11*Parameters!$E$6,0)+IF(ISNUMBER(E11),E11*Parameters!$E$7,0))/(IF(ISNUMBER(D11),Parameters!$E$6,0)+IF(ISNUMBER(E11),Parameters!$E$7,0))*100) -> 35.833333 | L11: =IF(COUNT(F11:H11)=0,"NA",(IF(ISNUMBER(F11),F11*Parameters!$E$8,0)+IF(ISNUMBER(G11),G11*Parameters!$E$9,0)+IF(ISNUMBER(H11),H11*Parameters!$E$10,0))/(IF(ISNUMBER(F11),Parameters!$E$8,0)+IF(ISNUMBER(G11),Parameters!$E$9,0)+IF(ISNUMBER(H11),Parameters!$E$10,0))*100) -> 57.142857 | M11: =IF(COUNT(I11:J11)=0,"NA",(IF(ISNUMBER(I11),I11*Parameters!$E$11,0)+IF(ISNUMBER(J11),J11*Parameters!$E$12,0))/(IF(ISNUMBER(I11),Parameters!$E$11,0)+IF(ISNUMBER(J11),Parameters!$E$12,0))*100) -> 100 | N11: =IF(ISNUMBER(D11),Parameters!$E$6,0)+IF(ISNUMBER(E11),Parameters!$E$7,0)+IF(ISNUMBER(F11),Parameters!$E$8,0)+IF(ISNUMBER(G11),Parameters!$E$9,0)+IF(ISNUMBER(H11),Parameters!$E$10,0)+IF(ISNUMBER(I11),Parameters!$E$11,0)+IF(ISNUMBER(J11),Parameters!$E$12,0) -> 1 | O11: =IF(ISNUMBER(D11),D11*Parameters!$E$6,0)+IF(ISNUMBER(E11),E11*Parameters!$E$7,0)+IF(ISNUMBER(F11),F11*Parameters!$E$8,0)+IF(ISNUMBER(G11),G11*Parameters!$E$9,0)+IF(ISNUMBER(H11),H11*Parameters!$E$10,0)+IF(ISNUMBER(I11),I11*Parameters!$E$11,0)+IF(ISNUMBER(J11),J11*Parameters!$E$12,0) -> 0.6575 | P11: =COUNT(D11:J11) -> 7 | Q11: =(COUNT(D11:E11)>0)+(COUNT(F11:H11)>0)+(COUNT(I11:J11)>0) -> 3 | R11: =IF(AND(N11>=Parameters!$C$56,Q11>=Parameters!$C$59),"Yes","No") -> Yes | S11: =IF(R11="Yes",O11/N11*100,"NA") -> 65.75 | T11: =IF(R11="Yes",O11/Parameters!$E$13*100,"NA") -> 65.75 | U11: =IF(R11="Yes",(O11+(Parameters!$E$13-N11))/Parameters!$E$13*100,"NA") -> 65.75 | V11: =IF(R11<>"Yes","Not scored",IF(N11>=Parameters!$C$60,"Reportable","Provisional")) -> Reportable | W11: =IF(ISNUMBER(S11),RANK(S11,$S$2:$S$113,0),"NA") -> 61 | X11: =IF(N11>=Parameters!$C$60,"High",IF(N11>=Parameters!$C$56,"Medium","Low")) -> High | Y11: =Calc!T11 -> 0 | Z11: =IF(V11="Reportable",S11-ROW()*0.000000001,"") -> 65.75 | AA11: =IF(ISNUMBER(Z11),RANK(Z11,$Z$2:$Z$113,0),"NA") -> 35
A12: =Data!$A12 -> AtoM | B12: =Data!$B12 -> Artefactual | C12: =Data!$E12 -> Archive information management system | D12: =IF(Verification!C12="",Calc!B12,Verification!C12) -> 0.67 | E12: =IF(Verification!D12="",Calc!D12,Verification!D12) -> NA | F12: =IF(Verification!E12="",Calc!G12,Verification!E12) -> NA | G12: =IF(Verification!F12="",Calc!I12,Verification!F12) -> NA | H12: =IF(Verification!G12="",Calc!E12,Verification!G12) -> 1 | I12: =IF(Verification!H12="",Calc!J12,Verification!H12) -> NA | J12: =IF(Verification!I12="",Calc!K12,Verification!I12) -> NA | K12: =IF(COUNT(D12:E12)=0,"NA",(IF(ISNUMBER(D12),D12*Parameters!$E$6,0)+IF(ISNUMBER(E12),E12*Parameters!$E$7,0))/(IF(ISNUMBER(D12),Parameters!$E$6,0)+IF(ISNUMBER(E12),Parameters!$E$7,0))*100) -> 67 | L12: =IF(COUNT(F12:H12)=0,"NA",(IF(ISNUMBER(F12),F12*Parameters!$E$8,0)+IF(ISNUMBER(G12),G12*Parameters!$E$9,0)+IF(ISNUMBER(H12),H12*Parameters!$E$10,0))/(IF(ISNUMBER(F12),Parameters!$E$8,0)+IF(ISNUMBER(G12),Parameters!$E$9,0)+IF(ISNUMBER(H12),Parameters!$E$10,0))*100) -> 100 | M12: =IF(COUNT(I12:J12)=0,"NA",(IF(ISNUMBER(I12),I12*Parameters!$E$11,0)+IF(ISNUMBER(J12),J12*Parameters!$E$12,0))/(IF(ISNUMBER(I12),Parameters!$E$11,0)+IF(ISNUMBER(J12),Parameters!$E$12,0))*100) -> NA | N12: =IF(ISNUMBER(D12),Parameters!$E$6,0)+IF(ISNUMBER(E12),Parameters!$E$7,0)+IF(ISNUMBER(F12),Parameters!$E$8,0)+IF(ISNUMBER(G12),Parameters!$E$9,0)+IF(ISNUMBER(H12),Parameters!$E$10,0)+IF(ISNUMBER(I12),Parameters!$E$11,0)+IF(ISNUMBER(J12),Parameters!$E$12,0) -> 0.13 | O12: =IF(ISNUMBER(D12),D12*Parameters!$E$6,0)+IF(ISNUMBER(E12),E12*Parameters!$E$7,0)+IF(ISNUMBER(F12),F12*Parameters!$E$8,0)+IF(ISNUMBER(G12),G12*Parameters!$E$9,0)+IF(ISNUMBER(H12),H12*Parameters!$E$10,0)+IF(ISNUMBER(I12),I12*Parameters!$E$11,0)+IF(ISNUMBER(J12),J12*Parameters!$E$12,0) -> 0.1036 | P12: =COUNT(D12:J12) -> 2 | Q12: =(COUNT(D12:E12)>0)+(COUNT(F12:H12)>0)+(COUNT(I12:J12)>0) -> 2 | R12: =IF(AND(N12>=Parameters!$C$56,Q12>=Parameters!$C$59),"Yes","No") -> No | S12: =IF(R12="Yes",O12/N12*100,"NA") -> NA | T12: =IF(R12="Yes",O12/Parameters!$E$13*100,"NA") -> NA | U12: =IF(R12="Yes",(O12+(Parameters!$E$13-N12))/Parameters!$E$13*100,"NA") -> NA | V12: =IF(R12<>"Yes","Not scored",IF(N12>=Parameters!$C$60,"Reportable","Provisional")) -> Not scored | W12: =IF(ISNUMBER(S12),RANK(S12,$S$2:$S$113,0),"NA") -> NA | X12: =IF(N12>=Parameters!$C$60,"High",IF(N12>=Parameters!$C$56,"Medium","Low")) -> Low | Y12: =Calc!T12 -> 2 | Z12: =IF(V12="Reportable",S12-ROW()*0.000000001,"") | AA12: =IF(ISNUMBER(Z12),RANK(Z12,$Z$2:$Z$113,0),"NA") -> NA
A13: =Data!$A13 -> Avalon Media System | B13: =Data!$B13 -> Indiana University Libraries | C13: =Data!$E13 -> Digital library, collection or exhibit platform | Repository software | D13: =IF(Verification!C13="",Calc!B13,Verification!C13) -> 1 | E13: =IF(Verification!D13="",Calc!D13,Verification!D13) -> 0.625 | F13: =IF(Verification!E13="",Calc!G13,Verification!E13) -> 1 | G13: =IF(Verification!F13="",Calc!I13,Verification!F13) -> 0.5 | H13: =IF(Verification!G13="",Calc!E13,Verification!G13) -> 1 | I13: =IF(Verification!H13="",Calc!J13,Verification!H13) -> 1 | J13: =IF(Verification!I13="",Calc!K13,Verification!I13) -> 1 | K13: =IF(COUNT(D13:E13)=0,"NA",(IF(ISNUMBER(D13),D13*Parameters!$E$6,0)+IF(ISNUMBER(E13),E13*Parameters!$E$7,0))/(IF(ISNUMBER(D13),Parameters!$E$6,0)+IF(ISNUMBER(E13),Parameters!$E$7,0))*100) -> 72.5 | L13: =IF(COUNT(F13:H13)=0,"NA",(IF(ISNUMBER(F13),F13*Parameters!$E$8,0)+IF(ISNUMBER(G13),G13*Parameters!$E$9,0)+IF(ISNUMBER(H13),H13*Parameters!$E$10,0))/(IF(ISNUMBER(F13),Parameters!$E$8,0)+IF(ISNUMBER(G13),Parameters!$E$9,0)+IF(ISNUMBER(H13),Parameters!$E$10,0))*100) -> 82.857143 | M13: =IF(COUNT(I13:J13)=0,"NA",(IF(ISNUMBER(I13),I13*Parameters!$E$11,0)+IF(ISNUMBER(J13),J13*Parameters!$E$12,0))/(IF(ISNUMBER(I13),Parameters!$E$11,0)+IF(ISNUMBER(J13),Parameters!$E$12,0))*100) -> 100 | N13: =IF(ISNUMBER(D13),Parameters!$E$6,0)+IF(ISNUMBER(E13),Parameters!$E$7,0)+IF(ISNUMBER(F13),Parameters!$E$8,0)+IF(ISNUMBER(G13),Parameters!$E$9,0)+IF(ISNUMBER(H13),Parameters!$E$10,0)+IF(ISNUMBER(I13),Parameters!$E$11,0)+IF(ISNUMBER(J13),Parameters!$E$12,0) -> 1 | O13: =IF(ISNUMBER(D13),D13*Parameters!$E$6,0)+IF(ISNUMBER(E13),E13*Parameters!$E$7,0)+IF(ISNUMBER(F13),F13*Parameters!$E$8,0)+IF(ISNUMBER(G13),G13*Parameters!$E$9,0)+IF(ISNUMBER(H13),H13*Parameters!$E$10,0)+IF(ISNUMBER(I13),I13*Parameters!$E$11,0)+IF(ISNUMBER(J13),J13*Parameters!$E$12,0) -> 0.8575 | P13: =COUNT(D13:J13) -> 7 | Q13: =(COUNT(D13:E13)>0)+(COUNT(F13:H13)>0)+(COUNT(I13:J13)>0) -> 3 | R13: =IF(AND(N13>=Parameters!$C$56,Q13>=Parameters!$C$59),"Yes","No") -> Yes | S13: =IF(R13="Yes",O13/N13*100,"NA") -> 85.75 | T13: =IF(R13="Yes",O13/Parameters!$E$13*100,"NA") -> 85.75 | U13: =IF(R13="Yes",(O13+(Parameters!$E$13-N13))/Parameters!$E$13*100,"NA") -> 85.75 | V13: =IF(R13<>"Yes","Not scored",IF(N13>=Parameters!$C$60,"Reportable","Provisional")) -> Reportable | W13: =IF(ISNUMBER(S13),RANK(S13,$S$2:$S$113,0),"NA") -> 28 | X13: =IF(N13>=Parameters!$C$60,"High",IF(N13>=Parameters!$C$56,"Medium","Low")) -> High | Y13: =Calc!T13 -> 0 | Z13: =IF(V13="Reportable",S13-ROW()*0.000000001,"") -> 85.75 | AA13: =IF(ISNUMBER(Z13),RANK(Z13,$Z$2:$Z$113,0),"NA") -> 17
... A113: =Data!$A113 -> Zotero | B113: =Data!$B113 -> Digital Scholar | C113: =Data!$E113 -> Annotations system | D113: =IF(Verification!C113="",Calc!B113,Verification!C113) -> 1 | E113: =IF(Verification!D113="",Calc!D113,Verification!D113) -> 0.5 | F113: =IF(Verification!E113="",Calc!G113,Verification!E113) -> 0.5 | G113: =IF(Verification!F113="",Calc!I113,Verification!F113) -> 0.5 | H113: =IF(Verification!G113="",Calc!E113,Verification!G113) -> 1 | I113: =IF(Verification!H113="",Calc!J113,Verification!H113) -> 1 | J113: =IF(Verification!I113="",Calc!K113,Verification!I113) -> 0.5 | K113: =IF(COUNT(D113:E113)=0,"NA",(IF(ISNUMBER(D113),D113*Parameters!$E$6,0)+IF(ISNUMBER(E113),E113*Parameters!$E$7,0))/(IF(ISNUMBER(D113),Parameters!$E$6,0)+IF(ISNUMBER(E113),Parameters!$E$7,0))*100) -> 63.333333 | L113: =IF(COUNT(F113:H113)=0,"NA",(IF(ISNUMBER(F113),F113*Parameters!$E$8,0)+IF(ISNUMBER(G113),G113*Parameters!$E$9,0)+IF(ISNUMBER(H113),H113*Parameters!$E$10,0))/(IF(ISNUMBER(F113),Parameters!$E$8,0)+IF(ISNUMBER(G113),Parameters!$E$9,0)+IF(ISNUMBER(H113),Parameters!$E$10,0))*100) -> 57.142857 | M113: =IF(COUNT(I113:J113)=0,"NA",(IF(ISNUMBER(I113),I113*Parameters!$E$11,0)+IF(ISNUMBER(J113),J113*Parameters!$E$12,0))/(IF(ISNUMBER(I113),Parameters!$E$11,0)+IF(ISNUMBER(J113),Parameters!$E$12,0))*100) -> 71.428571 | N113: =IF(ISNUMBER(D113),Parameters!$E$6,0)+IF(ISNUMBER(E113),Parameters!$E$7,0)+IF(ISNUMBER(F113),Parameters!$E$8,0)+IF(ISNUMBER(G113),Parameters!$E$9,0)+IF(ISNUMBER(H113),Parameters!$E$10,0)+IF(ISNUMBER(I113),Parameters!$E$11,0)+IF(ISNUMBER(J113),Parameters!$E$12,0) -> 1 | O113: =IF(ISNUMBER(D113),D113*Parameters!$E$6,0)+IF(ISNUMBER(E113),E113*Parameters!$E$7,0)+IF(ISNUMBER(F113),F113*Parameters!$E$8,0)+IF(ISNUMBER(G113),G113*Parameters!$E$9,0)+IF(ISNUMBER(H113),H113*Parameters!$E$10,0)+IF(ISNUMBER(I113),I113*Parameters!$E$11,0)+IF(ISNUMBER(J113),J113*Parameters!$E$12,0) -> 0.64 | P113: =COUNT(D113:J113) -> 7 | Q113: =(COUNT(D113:E113)>0)+(COUNT(F113:H113)>0)+(COUNT(I113:J113)>0) -> 3 | R113: =IF(AND(N113>=Parameters!$C$56,Q113>=Parameters!$C$59),"Yes","No") -> Yes | S113: =IF(R113="Yes",O113/N113*100,"NA") -> 64 | T113: =IF(R113="Yes",O113/Parameters!$E$13*100,"NA") -> 64 | U113: =IF(R113="Yes",(O113+(Parameters!$E$13-N113))/Parameters!$E$13*100,"NA") -> 64 | V113: =IF(R113<>"Yes","Not scored",IF(N113>=Parameters!$C$60,"Reportable","Provisional")) -> Reportable | W113: =IF(ISNUMBER(S113),RANK(S113,$S$2:$S$113,0),"NA") -> 63 | X113: =IF(N113>=Parameters!$C$60,"High",IF(N113>=Parameters!$C$56,"Medium","Low")) -> High | Y113: =Calc!T113 -> 0 | Z113: =IF(V113="Reportable",S113-ROW()*0.000000001,"") -> 64 | AA113: =IF(ISNUMBER(Z113),RANK(Z113,$Z$2:$Z$113,0),"NA") -> 37

Sheet Verification
A1: Service | B1: Verification status | C1: E1 override (037) | D1: E2 override (breadth) | E1: C1 override (040) | F1: C2 override (041) | G1: C3 override (019) | H1: G1 override (042) | I1: G2 override (048) | J1: Verified by | K1: Date verified | L1: Evidence / notes | M1: Open flags (count) | N1: Action required (auto)
A2: =Data!$A2 -> 2i2c | B2: Not started | M2: =Calc!T2 -> 1 | N2: =TRIM(IF(Calc!L2=1,"Engagement listed but 037 says Considering or lower; ","")&IF(Calc!M2=1,"CoC URL but status not Implemented; ","")&IF(Calc!N2=1,"Formal governance has no URL; ","")&IF(Calc!O2=1,"Governance blank but URL given; ","")&IF(Calc!P2=1,"Text/URL given but no engagement category coded (read manually); ","")&IF(Calc!Q2=1,"Check 041 URL; ","")&IF(Calc!R2=1,"039 says Considering/Not planning but contribution evidence exists; ","")&IF(Calc!S2=1,"No repo URL (manual check); ","")) -> Text/URL given but no engagement category coded (read manually);
A3: =Data!$A3 -> Academic Preservation Trust (APTrust) | B3: Not started | M3: =Calc!T3 -> 0 | N3: =TRIM(IF(Calc!L3=1,"Engagement listed but 037 says Considering or lower; ","")&IF(Calc!M3=1,"CoC URL but status not Implemented; ","")&IF(Calc!N3=1,"Formal governance has no URL; ","")&IF(Calc!O3=1,"Governance blank but URL given; ","")&IF(Calc!P3=1,"Text/URL given but no engagement category coded (read manually); ","")&IF(Calc!Q3=1,"Check 041 URL; ","")&IF(Calc!R3=1,"039 says Considering/Not planning but contribution evidence exists; ","")&IF(Calc!S3=1,"No repo URL (manual check); ",""))
A4: =Data!$A4 -> AfricArXiv | B4: Not started | M4: =Calc!T4 -> 1 | N4: =TRIM(IF(Calc!L4=1,"Engagement listed but 037 says Considering or lower; ","")&IF(Calc!M4=1,"CoC URL but status not Implemented; ","")&IF(Calc!N4=1,"Formal governance has no URL; ","")&IF(Calc!O4=1,"Governance blank but URL given; ","")&IF(Calc!P4=1,"Text/URL given but no engagement category coded (read manually); ","")&IF(Calc!Q4=1,"Check 041 URL; ","")&IF(Calc!R4=1,"039 says Considering/Not planning but contribution evidence exists; ","")&IF(Calc!S4=1,"No repo URL (manual check); ","")) -> No repo URL (manual check);
A5: =Data!$A5 -> Arches Heritage Data Management Platform | B5: Not started | M5: =Calc!T5 -> 1 | N5: =TRIM(IF(Calc!L5=1,"Engagement listed but 037 says Considering or lower; ","")&IF(Calc!M5=1,"CoC URL but status not Implemented; ","")&IF(Calc!N5=1,"Formal governance has no URL; ","")&IF(Calc!O5=1,"Governance blank but URL given; ","")&IF(Calc!P5=1,"Text/URL given but no engagement category coded (read manually); ","")&IF(Calc!Q5=1,"Check 041 URL; ","")&IF(Calc!R5=1,"039 says Considering/Not planning but contribution evidence exists; ","")&IF(Calc!S5=1,"No repo URL (manual check); ","")) -> Text/URL given but no engagement category coded (read manually);
A6: =Data!$A6 -> Archipelago Commons | B6: Not started | M6: =Calc!T6 -> 0 | N6: =TRIM(IF(Calc!L6=1,"Engagement listed but 037 says Considering or lower; ","")&IF(Calc!M6=1,"CoC URL but status not Implemented; ","")&IF(Calc!N6=1,"Formal governance has no URL; ","")&IF(Calc!O6=1,"Governance blank but URL given; ","")&IF(Calc!P6=1,"Text/URL given but no engagement category coded (read manually); ","")&IF(Calc!Q6=1,"Check 041 URL; ","")&IF(Calc!R6=1,"039 says Considering/Not planning but contribution evidence exists; ","")&IF(Calc!S6=1,"No repo URL (manual check); ",""))
A7: =Data!$A7 -> Archival Resource Key | B7: Not started | M7: =Calc!T7 -> 1 | N7: =TRIM(IF(Calc!L7=1,"Engagement listed but 037 says Considering or lower; ","")&IF(Calc!M7=1,"CoC URL but status not Implemented; ","")&IF(Calc!N7=1,"Formal governance has no URL; ","")&IF(Calc!O7=1,"Governance blank but URL given; ","")&IF(Calc!P7=1,"Text/URL given but no engagement category coded (read manually); ","")&IF(Calc!Q7=1,"Check 041 URL; ","")&IF(Calc!R7=1,"039 says Considering/Not planning but contribution evidence exists; ","")&IF(Calc!S7=1,"No repo URL (manual check); ","")) -> Text/URL given but no engagement category coded (read manually);
A8: =Data!$A8 -> Archivematica | B8: Not started | M8: =Calc!T8 -> 2 | N8: =TRIM(IF(Calc!L8=1,"Engagement listed but 037 says Considering or lower; ","")&IF(Calc!M8=1,"CoC URL but status not Implemented; ","")&IF(Calc!N8=1,"Formal governance has no URL; ","")&IF(Calc!O8=1,"Governance blank but URL given; ","")&IF(Calc!P8=1,"Text/URL given but no engagement category coded (read manually); ","")&IF(Calc!Q8=1,"Check 041 URL; ","")&IF(Calc!R8=1,"039 says Considering/Not planning but contribution evidence exists; ","")&IF(Calc!S8=1,"No repo URL (manual check); ","")) -> CoC URL but status not Implemented; Text/URL given but no engagement category coded (read manually);
A9: =Data!$A9 -> ArchivesSpace | B9: Not started | M9: =Calc!T9 -> 0 | N9: =TRIM(IF(Calc!L9=1,"Engagement listed but 037 says Considering or lower; ","")&IF(Calc!M9=1,"CoC URL but status not Implemented; ","")&IF(Calc!N9=1,"Formal governance has no URL; ","")&IF(Calc!O9=1,"Governance blank but URL given; ","")&IF(Calc!P9=1,"Text/URL given but no engagement category coded (read manually); ","")&IF(Calc!Q9=1,"Check 041 URL; ","")&IF(Calc!R9=1,"039 says Considering/Not planning but contribution evidence exists; ","")&IF(Calc!S9=1,"No repo URL (manual check); ",""))
A10: =Data!$A10 -> ARGOS | B10: Not started | M10: =Calc!T10 -> 0 | N10: =TRIM(IF(Calc!L10=1,"Engagement listed but 037 says Considering or lower; ","")&IF(Calc!M10=1,"CoC URL but status not Implemented; ","")&IF(Calc!N10=1,"Formal governance has no URL; ","")&IF(Calc!O10=1,"Governance blank but URL given; ","")&IF(Calc!P10=1,"Text/URL given but no engagement category coded (read manually); ","")&IF(Calc!Q10=1,"Check 041 URL; ","")&IF(Calc!R10=1,"039 says Considering/Not planning but contribution evidence exists; ","")&IF(Calc!S10=1,"No repo URL (manual check); ",""))
A11: =Data!$A11 -> arXiv | B11: Not started | M11: =Calc!T11 -> 0 | N11: =TRIM(IF(Calc!L11=1,"Engagement listed but 037 says Considering or lower; ","")&IF(Calc!M11=1,"CoC URL but status not Implemented; ","")&IF(Calc!N11=1,"Formal governance has no URL; ","")&IF(Calc!O11=1,"Governance blank but URL given; ","")&IF(Calc!P11=1,"Text/URL given but no engagement category coded (read manually); ","")&IF(Calc!Q11=1,"Check 041 URL; ","")&IF(Calc!R11=1,"039 says Considering/Not planning but contribution evidence exists; ","")&IF(Calc!S11=1,"No repo URL (manual check); ",""))
A12: =Data!$A12 -> AtoM | B12: Not started | M12: =Calc!T12 -> 2 | N12: =TRIM(IF(Calc!L12=1,"Engagement listed but 037 says Considering or lower; ","")&IF(Calc!M12=1,"CoC URL but status not Implemented; ","")&IF(Calc!N12=1,"Formal governance has no URL; ","")&IF(Calc!O12=1,"Governance blank but URL given; ","")&IF(Calc!P12=1,"Text/URL given but no engagement category coded (read manually); ","")&IF(Calc!Q12=1,"Check 041 URL; ","")&IF(Calc!R12=1,"039 says Considering/Not planning but contribution evidence exists; ","")&IF(Calc!S12=1,"No repo URL (manual check); ","")) -> CoC URL but status not Implemented; Check 041 URL;
A13: =Data!$A13 -> Avalon Media System | B13: Not started | M13: =Calc!T13 -> 0 | N13: =TRIM(IF(Calc!L13=1,"Engagement listed but 037 says Considering or lower; ","")&IF(Calc!M13=1,"CoC URL but status not Implemented; ","")&IF(Calc!N13=1,"Formal governance has no URL; ","")&IF(Calc!O13=1,"Governance blank but URL given; ","")&IF(Calc!P13=1,"Text/URL given but no engagement category coded (read manually); ","")&IF(Calc!Q13=1,"Check 041 URL; ","")&IF(Calc!R13=1,"039 says Considering/Not planning but contribution evidence exists; ","")&IF(Calc!S13=1,"No repo URL (manual check); ",""))
... A113: =Data!$A113 -> Zotero | B113: Not started | M113: =Calc!T113 -> 0 | N113: =TRIM(IF(Calc!L113=1,"Engagement listed but 037 says Considering or lower; ","")&IF(Calc!M113=1,"CoC URL but status not Implemented; ","")&IF(Calc!N113=1,"Formal governance has no URL; ","")&IF(Calc!O113=1,"Governance blank but URL given; ","")&IF(Calc!P113=1,"Text/URL given but no engagement category coded (read manually); ","")&IF(Calc!Q113=1,"Check 041 URL; ","")&IF(Calc!R113=1,"039 says Considering/Not planning but contribution evidence exists; ","")&IF(Calc!S113=1,"No repo URL (manual check); ",""))

Sheet Coding
A1: Service | B1: 038: Annual meetings | C1: 038: Blogs | D1: 038: Community calls | E1: 038: Conference participation | F1: 038: Development sprints | G1: 038: Interest, working, user, or advisory groups | H1: 038: Mailing lists and discussion forums (including Slack) | I1: 038: Social media | J1: 038: Staff roles with responsibility for community engagement | K1: 038: User research | L1: 038: Volunteer or ambassador network | M1: 038: Webinars and training | N1: 938: Annual meetings | O1: 938: Blogs | P1: 938: Community calls | Q1: 938: Conference participation | R1: 938: Development sprints | S1: 938: Interest, working, user, or advisory groups | T1: 938: Mailing lists and discussion forums (including Slack) | U1: 938: Social media | V1: 938: Staff roles with responsibility for community engagement | W1: 938: User research | X1: 938: Volunteer or ambassador network | Y1: 938: Webinars and training | Z1: 038 has "Other" | AA1: 938 text given | AB1: Checklist categories (n) | AC1: Union categories (n) | AD1: Added by 938 text only | AE1: "Other" credit (needs 938 text) | AF1: E2 category count (union) | AG1: E2 count, checklist only (sensitivity) | AH1: Both 038 and 938 filled | AI1: Coded cats also in checklist | AJ1: Coded cats NOT in checklist | AK1: Checklist cats (both-filled repos)
A2: =Data!$A2 -> 2i2c | B2: =IF(ISNUMBER(SEARCH(Dictionary!$A$5,Data!$H2)),1,0) -> 0 | C2: =IF(ISNUMBER(SEARCH(Dictionary!$A$6,Data!$H2)),1,0) -> 0 | D2: =IF(ISNUMBER(SEARCH(Dictionary!$A$7,Data!$H2)),1,0) -> 0 | E2: =IF(ISNUMBER(SEARCH(Dictionary!$A$8,Data!$H2)),1,0) -> 0 | F2: =IF(ISNUMBER(SEARCH(Dictionary!$A$9,Data!$H2)),1,0) -> 0 | G2: =IF(ISNUMBER(SEARCH(Dictionary!$A$10,Data!$H2)),1,0) -> 0 | H2: =IF(ISNUMBER(SEARCH(Dictionary!$A$11,Data!$H2)),1,0) -> 0 | I2: =IF(ISNUMBER(SEARCH(Dictionary!$A$12,Data!$H2)),1,0) -> 0 | J2: =IF(ISNUMBER(SEARCH(Dictionary!$A$13,Data!$H2)),1,0) -> 0 | K2: =IF(ISNUMBER(SEARCH(Dictionary!$A$14,Data!$H2)),1,0) -> 0 | L2: =IF(ISNUMBER(SEARCH(Dictionary!$A$15,Data!$H2)),1,0) -> 0 | M2: =IF(ISNUMBER(SEARCH(Dictionary!$A$16,Data!$H2)),1,0) -> 0 | N2: =IF(SUMPRODUCT((Dictionary!$C$5:$C$96=Dictionary!$A$5)*(Dictionary!$D$5:$D$96<>"")*ISNUMBER(SEARCH(Dictionary!$D$5:$D$96,Data!$I2)))>0,1,0) -> 0 | O2: =IF(SUMPRODUCT((Dictionary!$C$5:$C$96=Dictionary!$A$6)*(Dictionary!$D$5:$D$96<>"")*ISNUMBER(SEARCH(Dictionary!$D$5:$D$96,Data!$I2)))>0,1,0) -> 0 | P2: =IF(SUMPRODUCT((Dictionary!$C$5:$C$96=Dictionary!$A$7)*(Dictionary!$D$5:$D$96<>"")*ISNUMBER(SEARCH(Dictionary!$D$5:$D$96,Data!$I2)))>0,1,0) -> 0 | Q2: =IF(SUMPRODUCT((Dictionary!$C$5:$C$96=Dictionary!$A$8)*(Dictionary!$D$5:$D$96<>"")*ISNUMBER(SEARCH(Dictionary!$D$5:$D$96,Data!$I2)))>0,1,0) -> 0 | R2: =IF(SUMPRODUCT((Dictionary!$C$5:$C$96=Dictionary!$A$9)*(Dictionary!$D$5:$D$96<>"")*ISNUMBER(SEARCH(Dictionary!$D$5:$D$96,Data!$I2)))>0,1,0) -> 0 | S2: =IF(SUMPRODUCT((Dictionary!$C$5:$C$96=Dictionary!$A$10)*(Dictionary!$D$5:$D$96<>"")*ISNUMBER(SEARCH(Dictionary!$D$5:$D$96,Data!$I2)))>0,1,0) -> 0 | T2: =IF(SUMPRODUCT((Dictionary!$C$5:$C$96=Dictionary!$A$11)*(Dictionary!$D$5:$D$96<>"")*ISNUMBER(SEARCH(Dictionary!$D$5:$D$96,Data!$I2)))>0,1,0) -> 0 | U2: =IF(SUMPRODUCT((Dictionary!$C$5:$C$96=Dictionary!$A$12)*(Dictionary!$D$5:$D$96<>"")*ISNUMBER(SEARCH(Dictionary!$D$5:$D$96,Data!$I2)))>0,1,0) -> 0 | V2: =IF(SUMPRODUCT((Dictionary!$C$5:$C$96=Dictionary!$A$13)*(Dictionary!$D$5:$D$96<>"")*ISNUMBER(SEARCH(Dictionary!$D$5:$D$96,Data!$I2)))>0,1,0) -> 0 | W2: =IF(SUMPRODUCT((Dictionary!$C$5:$C$96=Dictionary!$A$14)*(Dictionary!$D$5:$D$96<>"")*ISNUMBER(SEARCH(Dictionary!$D$5:$D$96,Data!$I2)))>0,1,0) -> 0 | X2: =IF(SUMPRODUCT((Dictionary!$C$5:$C$96=Dictionary!$A$15)*(Dictionary!$D$5:$D$96<>"")*ISNUMBER(SEARCH(Dictionary!$D$5:$D$96,Data!$I2)))>0,1,0) -> 0 | Y2: =IF(SUMPRODUCT((Dictionary!$C$5:$C$96=Dictionary!$A$16)*(Dictionary!$D$5:$D$96<>"")*ISNUMBER(SEARCH(Dictionary!$D$5:$D$96,Data!$I2)))>0,1,0) -> 0 | Z2: =IF(ISNUMBER(SEARCH("Other",Data!$H2)),1,0) -> 0 | AA2: =IF(Data!$I2<>"",1,0) -> 1 | AB2: =SUM(B2:M2) -> 0 | AC2: =SUMPRODUCT(--((B2:M2+N2:Y2)>0)) -> 0 | AD2: =AC2-AB2 -> 0 | AE2: =IF(AND(Z2=1,AA2=1),1,0) -> 0 | AF2: =AC2+AE2 -> 0 | AG2: =AB2+AE2 -> 0 | AH2: =IF(AND(Data!$H2<>"",Data!$I2<>""),1,0) -> 0 | AI2: =IF(AH2=1,SUMPRODUCT(N2:Y2*B2:M2),"") | AJ2: =IF(AH2=1,SUMPRODUCT(--(N2:Y2>B2:M2)),"") | AK2: =IF(AH2=1,AB2,"")
